Workbook

Sheet KEC BB DISPATCHED APRIL
A1: Invoice No. | B1: Invoice Dt | C1: Section | D1: PNAME | E1: QTY ISSUED | F1: VEHICLE No. | G1: Jobwork Challan No. | H1: Po. No | I1: PO ORDER DATE
A2: VIL/DC/23-24/001 | B2: 45020 | C2: MS ANGLE 90X90X6 MM | D2: KEC INTERNATIONAL LIMITED,(DUBAI) | E2: 24.507 | F2: MH31FC2568 | G2: 01/315, 02/316 | H2: LOI-1937 | I2: 44999
A3: VIL/DC/23-24/002 | B3: 45020 | C3: MS ANGLE 90X90X6 MM | D3: KEC INTERNATIONAL LIMITED,(DUBAI) | E3: 3.785 | F3: MH31FC2213 | G3: 03/316, | H3: LOI-1937 | I3: 44999
E4: =SUM(E2:E3) -> 28.292
A5: VIL/DC/23-24/003 | B5: 45021 | C5: HT ANGLE 150X150X15 MM | D5: KEC INTERNATIONAL LIMITED,(DUBAI) | E5: 24.488 | F5: MH31FC2610 | G5: 04/317, | H5: LOI-1937 | I5: 44999
A6: VIL/DC/23-24/004 | B6: 45021 | C6: HT ANGLE 100X100X7 MM | D6: KEC INTERNATIONAL LIMITED,(DUBAI) | E6: 14.528 | F6: MH31FC2629 | G6: 05/318, | H6: LOI-1937 | I6: 44999
A7: VIL/DC/23-24/004 | B7: 45021 | C7: HT ANGLE 80X80X6 MM | D7: KEC INTERNATIONAL LIMITED,(DUBAI) | E7: 9.943 | F7: MH31FC2629 | G7: 05/318, | H7: LOI-1937 | I7: 44999
E8: =SUM(E5:E7) -> 48.959
A9: VIL/DC/23-24/005 | B9: 45022 | C9: HT ANGLE 150X150X15 MM | D9: KEC INTERNATIONAL LIMITED,(DUBAI) | E9: 24.877 | F9: MH31FC2568 | G9: 06/316, 07/317 | H9: LOI-1937 | I9: 44999
A10: VIL/DC/23-24/006 | B10: 45022 | C10: MS ANGLE 90X90X6 MM | D10: KEC INTERNATIONAL LIMITED,(DUBAI) | E10: 24.567 | F10: MH31FC2213 | G10: 08/252, 9/317, 10/318, 11/319 | H10: LOI-1937 | I10: 44999
A11: VIL/DC/23-24/007 | B11: 45022 | C11: HT ANGLE 150X150X15 MM | D11: KEC INTERNATIONAL LIMITED,(DUBAI) | E11: 24.968 | F11: MH40CM3181 | G11: 12/319, 13/320 | H11: LOI-1937 | I11: 44999
A12: VIL/DC/23-24/008 | B12: 45022 | C12: MS ANGLE 90X90X6 MM | D12: KEC INTERNATIONAL LIMITED,(DUBAI) | E12: 24.758 | F12: MH40CM3182 | G12: 14/320, 15/321 | H12: LOI-1937 | I12: 44999
E13: =SUM(E9:E12) -> 99.17
A14: VIL/DC/23-24/009 | B14: 45024 | C14: HT ANGLE 150X150X15 MM | D14: KEC INTERNATIONAL LIMITED,(DUBAI) | E14: 24.488 | F14: MH31FC2623 | G14: 16/321, 17/322 | H14: LOI-1937 | I14: 44999
A15: VIL/DC/23-24/010 | B15: 45024 | C15: HT ANGLE 150X150X15 MM | D15: KEC INTERNATIONAL LIMITED,(DUBAI) | E15: 24.62 | F15: MH361155 | G15: 18/322 | H15: LOI-1937 | I15: 44999
A16: VIL/DC/23-24/011 | B16: 45024 | C16: HT ANGLE 150X150X12 MM | D16: KEC INTERNATIONAL LIMITED,(DUBAI) | E16: 11.291 | F16: MH40CM3182 | G16: 19/322, 20/323 | H16: LOI-1937 | I16: 44999
A17: VIL/DC/23-24/011 | B17: 45024 | C17: HT ANGLE 150X150X15 MM | D17: KEC INTERNATIONAL LIMITED,(DUBAI) | E17: 13.107 | F17: MH40CM3182 | G17: 19/322, 20/323 | H17: LOI-1937 | I17: 44999
E18: =SUM(E14:E17) -> 73.506
A19: VIL/DC/23-24/012 | B19: 45025 | C19: HT ANGLE 80X80X6 MM | D19: KEC INTERNATIONAL LIMITED,(DUBAI) | E19: 12.42 | F19: MH31FC2620 | G19: 21/323, 22/324 | H19: LOI-1937 | I19: 44999
A20: VIL/DC/23-24/012 | B20: 45025 | C20: MS ANGLE 100X100X7 MM | D20: KEC INTERNATIONAL LIMITED,(DUBAI) | E20: 7.37 | F20: MH31FC2620 | G20: 21/323, 22/324 | H20: LOI-1937 | I20: 44999
A21: VIL/DC/23-24/013 | B21: 45025 | C21: MS ANGLE 90X90X6 MM | D21: KEC INTERNATIONAL LIMITED,(DUBAI) | E21: 18.451 | F21: MH40N5505 | G21: 23/325, | H21: LOI-1937 | I21: 44999
A22: VIL/DC/23-24/014 | B22: 45025 | C22: HT ANGLE 75X75X6 MM | D22: KEC INTERNATIONAL LIMITED,(DUBAI) | E22: 7.208 | F22: MH34AB1845 | G22: 24/324, | H22: LOI-1937 | I22: 44999
A23: VIL/DC/23-24/015 | B23: 45025 | C23: HT ANGLE 75X75X6 MM | D23: KEC INTERNATIONAL LIMITED,(BUTIBORI) | E23: 11.386 | F23: MH46AR8099 | G23: 25/324, 26/326 | H23: LOI-2021 | I23: 45019
A24: VIL/DC/23-24/015 | B24: 45025 | C24: HT ANGLE 75X75X5 MM | D24: KEC INTERNATIONAL LIMITED,(BUTIBORI) | E24: 16.147 | F24: MH46AR8099 | G24: 25/324, 26/326 | H24: LOI-2021 | I24: 45019
A25: VIL/DC/23-24/016 | B25: 45025 | C25: HT ANGLE 75X75X6 MM | D25: KEC INTERNATIONAL LIMITED,(BUTIBORI) | E25: 3.163 | F25: MH46AR8099 | G25: 26/326 | H25: LOI-2022 | I25: 45019
E26: =SUM(E19:E25) -> 76.145
A27: VIL/DC/23-24/017 | B27: 45026 | C27: HT ANGLE 75X75X5 MM | D27: KEC INTERNATIONAL LIMITED,(BUTIBORI) | E27: 10.768 | F27: MH40Y4044 | G27: 27/325, 28/326, 29/327 | H27: LOI-2021 | I27: 45019
A28: VIL/DC/23-24/017 | B28: 45026 | C28: HT ANGLE 75X75X6 MM | D28: KEC INTERNATIONAL LIMITED,(BUTIBORI) | E28: 10.423 | F28: MH40Y4044 | G28: 27/325, 28/326, 29/327 | H28: LOI-2021 | I28: 45019
A29: VIL/DC/23-24/017 | B29: 45026 | C29: HT ANGLE 90X90X6 MM | D29: KEC INTERNATIONAL LIMITED,(BUTIBORI) | E29: 4.382 | F29: MH40Y4044 | G29: 27/325, 28/326, 29/327 | H29: LOI-2021 | I29: 45019
A30: VIL/DC/23-24/018 | B30: 45026 | C30: HT ANGLE 75X75X5 MM | D30: KEC INTERNATIONAL LIMITED,(BUTIBORI) | E30: 4.902 | F30: MH40Y4044 | G30: 29/327 | H30: LOI-2022 | I30: 45019
A31: VIL/DC/23-24/018 | B31: 45026 | C31: HT ANGLE 75X75X6 MM | D31: KEC INTERNATIONAL LIMITED,(BUTIBORI) | E31: 1.444 | F31: MH40Y4044 | G31: 29/327 | H31: LOI-2022 | I31: 45019
A32: VIL/DC/23-24/019 | B32: 45026 | C32: HT ANGLE 75X75X6 MM | D32: KEC INTERNATIONAL LIMITED,(DUBAI) | E32: 15.455 | F32: MH31FC2622 | G32: 30/327 | H32: LOI-1937 | I32: 44999
A33: VIL/DC/23-24/020 | B33: 45026 | C33: HT ANGLE 90X90X6 MM | D33: KEC INTERNATIONAL LIMITED,(BUTIBORI) | E33: 31.497 | F33: MH40Y2044 | G33: 31/328, 32/329 | H33: LOI-2021 | I33: 45019
E34: =SUM(E27:E33) -> 78.871
A35: VIL/DC/23-24/021 | B35: 45027 | C35: HT ANGLE 100X100X7 MM | D35: KEC INTERNATIONAL LIMITED,(DUBAI) | E35: 6.555 | F35: MH31FC5543 | G35: 33/327, 34/329 | H35: LOI-1937 | I35: 44999
A36: VIL/DC/23-24/021 | B36: 45027 | C36: HT ANGLE 150X150X12 MM | D36: KEC INTERNATIONAL LIMITED,(DUBAI) | E36: 12.885 | F36: MH31FC5543 | G36: 33/327, 34/329 | H36: LOI-1937 | I36: 44999
A37: VIL/DC/23-24/022 | B37: 45027 | C37: HT ANGLE 90X90X6 MM | D37: KEC INTERNATIONAL LIMITED,(BUTIBORI) | E37: 11.554 | F37: MH40Y3944 | G37: 35/330 | H37: LOI-2021 | I37: 45019
A38: VIL/DC/23-24/022 | B38: 45027 | C38: HT ANGLE 90X90X5 MM | D38: KEC INTERNATIONAL LIMITED,(BUTIBORI) | E38: 10.424 | F38: MH40Y3944 | G38: 35/330 | H38: LOI-2021 | I38: 45019
A39: VIL/DC/23-24/022 | B39: 45027 | C39: HT ANGLE 90X90X7 MM | D39: KEC INTERNATIONAL LIMITED,(BUTIBORI) | E39: 9.953 | F39: MH40Y3944 | G39: 35/330 | H39: LOI-2021 | I39: 45019
A40: VIL/DC/23-24/023 | B40: 45027 | C40: HT ANGLE 90X90X6 MM | D40: KEC INTERNATIONAL LIMITED,(BUTIBORI) | E40: 29.469 | F40: MH46AR4423 | G40: 36/329, 37/330, 38/331 | H40: LOI-2021 | I40: 45019
...

Sheet KEC BB DISP. TRADING APRIL
A1: KEC BUTIBORI DISPATCHED DETAILS
A2: Invoice No. | B2: Invoice Dt | C2: Section | D2: PARTY NAME | E2: QTY(MT) | F2: VEHICLE No. | G2: PO. NO. | H2: PO DATE | I2: RATE
A3: BB/23-24/001 | B3: 45020 | C3: MS ANGLE 80 * 80 * 6 MM | D3: KEC INTERNATIONAL LIMITED,(DUBAI) | E3: 25.229 | F3: MH40CM3182 | G3: 7300030324 | H3: 44999 | I3: 72230
A4: BB/23-24/002 | B4: 45020 | C4: MS ANGLE 90 * 90 * 7 MM | D4: KEC INTERNATIONAL LIMITED,(DUBAI) | E4: 20.652 | F4: MH31FC2213 | G4: 7300030324 | H4: 44999 | I4: 72230
E5: =SUM(E3:E4) -> 45.881
A6: BB/23-24/003 | B6: 45022 | C6: MS ANGLE 90 * 90 * 7 MM | D6: KEC INTERNATIONAL LIMITED,(DUBAI) | E6: 24.858 | F6: MH31FC2566 | G6: 7300030324 | H6: 44999 | I6: 72230
E7: =SUM(E6) -> 24.858
A8: BB/23-24/004 | B8: 45024 | C8: MS ANGLE 80 * 80 * 6 MM | D8: KEC INTERNATIONAL LIMITED,(DUBAI) | E8: 24.51 | F8: MH31FC2338 | G8: 7300030324 | H8: 44999 | I8: 72230
E9: =SUM(E8) -> 24.51
A10: BB/23-24/005 | B10: 45025 | C10: MS ANGLE 100 * 100 * 8 MM | D10: KEC INTERNATIONAL LIMITED,(DUBAI) | E10: 1.316 | F10: MH31FC2620 | G10: 7300030324 | H10: 44999 | I10: 59920
A11: BB/23-24/005 | B11: 45025 | C11: MS ANGLE 80 * 80 * 6 MM | D11: KEC INTERNATIONAL LIMITED,(DUBAI) | E11: 4.184 | F11: MH31FC2620 | G11: 7300030324 | H11: 44999 | I11: 72230
A12: BB/23-24/006 | B12: 45025 | C12: MS ANGLE 80 * 80 * 6 MM | D12: KEC INTERNATIONAL LIMITED,(DUBAI) | E12: 6.245 | F12: MH40N5505 | G12: 7300030324 | H12: 44999 | I12: 72230
A13: BB/23-24/007 | B13: 45025 | C13: MS ANGLE 100 * 100 * 8 MM | D13: KEC INTERNATIONAL LIMITED,(DUBAI) | E13: 8.015 | F13: MH34AB1845 | G13: 7300030324 | H13: 44999 | I13: 59920
A14: BB/23-24/007 | B14: 45025 | C14: MS ANGLE 75 * 75 * 6 MM | D14: KEC INTERNATIONAL LIMITED,(DUBAI) | E14: 5.617 | F14: MH34AB1845 | G14: 7300030324 | H14: 44999 | I14: 59920
A15: BB/23-24/007 | B15: 45025 | C15: MS ANGLE 75 * 75 * 6 MM | D15: KEC INTERNATIONAL LIMITED,(DUBAI) | E15: 4.51 | F15: MH34AB1845 | G15: 7300030324 | H15: 44999 | I15: 59920
A16: BB/23-24/008 | B16: 45025 | C16: MS ANGLE 100 * 100 * 6 MM | D16: KEC INTERNATIONAL LIMITED,(DUBAI) | E16: 24.308 | F16: MH40AK0269 | G16: 7300030324 | H16: 44999 | I16: 59920
A17: BB/23-24/009 | B17: 45025 | C17: MS ANGLE 65 * 65 * 5 MM | D17: KEC INTERNATIONAL LIMITED,(BUTIBORI) | E17: 0.393 | F17: MH46AR8099 | G17: LOI-2028 | H17: 45020 | I17: 59670
A18: BB/23-24/009 | B18: 45025 | C18: MS ANGLE 90 * 90 * 5 MM | D18: KEC INTERNATIONAL LIMITED,(BUTIBORI) | E18: 0.212 | F18: MH46AR8099 | G18: LOI-2028 | H18: 45020 | I18: 59920
E19: =SUM(E10:E18) -> 54.8
A20: BB/23-24/010 | B20: 45026 | C20: MS ANGLE 75 * 75 * 6 MM | D20: KEC INTERNATIONAL LIMITED,(DUBAI) | E20: 4.623 | F20: MH31FC2622 | G20: 7300030324 | H20: 44999 | I20: 59920
A21: BB/23-24/010 | B21: 45026 | C21: MS ANGLE 75 * 75 * 6 MM | D21: KEC INTERNATIONAL LIMITED,(DUBAI) | E21: 4.994 | F21: MH31FC2622 | G21: 7300030324 | H21: 44999 | I21: 59920
E22: =SUM(E20:E21) -> 9.617
A23: BB/23-24/012 | B23: 45027 | C23: MS ANGLE 100 * 100 * 6 MM | D23: KEC INTERNATIONAL LIMITED,(DUBAI) | E23: 5.539 | F23: MH31FC5543 | G23: 7300030324 | H23: 44999 | I23: 59920
A24: BB/23-24/013 | B24: 45027 | C24: MS ANGLE 100 * 100 * 6 MM | D24: KEC INTERNATIONAL LIMITED,(DUBAI) | E24: 1.653 | F24: MH31FC2564 | G24: 7300030324 | H24: 44999 | I24: 59920
A25: BB/23-24/013 | B25: 45027 | C25: MS ANGLE 100 * 100 * 8 MM | D25: KEC INTERNATIONAL LIMITED,(DUBAI) | E25: 6.943 | F25: MH31FC2564 | G25: 7300030324 | H25: 44999 | I25: 59920
A26: BB/23-24/013 | B26: 45027 | C26: MS ANGLE 100 * 100 * 9 MM | D26: KEC INTERNATIONAL LIMITED,(DUBAI) | E26: 5.222 | F26: MH31FC2564 | G26: 7300030324 | H26: 44999 | I26: 59920
A27: BB/23-24/013 | B27: 45027 | C27: MS ANGLE 80 * 80 * 6 MM | D27: KEC INTERNATIONAL LIMITED,(DUBAI) | E27: 1.927 | F27: MH31FC2564 | G27: 7300030324 | H27: 44999 | I27: 72230
E28: =SUM(E23:E27) -> 21.284
A29: BB/23-24/014 | B29: 45029 | C29: MS ANGLE 80 * 80 * 6 MM | D29: KEC INTERNATIONAL LIMITED,(DUBAI) | E29: 2.995 | F29: MH31FC2568 | G29: 7300030324 | H29: 44999 | I29: 72230
A30: BB/23-24/016 | B30: 45029 | C30: MS ANGLE 90 * 90 * 6 MM | D30: KEC INTERNATIONAL LIMITED,(BUTIBORI) | E30: 1.941 | F30: MH46AF3590 | G30: LOI-2020 | H30: 45019 | I30: 59920
E31: =SUM(E29:E30) -> 4.936
A32: BB/23-24/018 | B32: 45030 | C32: MS ANGLE 110 * 110 * 8 MM | D32: KEC INTERNATIONAL LIMITED,(BUTIBORI) | E32: 0.314 | F32: MH46AR8099 | G32: LOI-2020 | H32: 45019 | I32: 54030
A33: BB/23-24/019 | B33: 45030 | C33: MS ANGLE 90 * 90 * 6 MM | D33: KEC INTERNATIONAL LIMITED,(BUTIBORI) | E33: 1.135 | F33: MH40Y3944 | G33: 7300030625 | H33: 45019 | I33: 59920
A34: BB/23-24/020 | B34: 45030 | C34: MS ANGLE 100 * 100 * 7 MM | D34: KEC INTERNATIONAL LIMITED,(BUTIBORI) | E34: 5.749 | F34: MH40Y3944 | G34: 7300030632 | H34: 45019 | I34: 59920
A35: BB/23-24/020 | B35: 45030 | C35: MS ANGLE 80 * 80 * 6 MM | D35: KEC INTERNATIONAL LIMITED,(BUTIBORI) | E35: 0.438 | F35: MH40Y3944 | G35: 7300030632 | H35: 45019 | I35: 59920
A36: BB/23-24/021 | B36: 45030 | C36: MS ANGLE 90 * 90 * 6 MM | D36: KEC INTERNATIONAL LIMITED,(BUTIBORI) | E36: 2.075 | F36: MH40Y4044 | G36: 7300030628 | H36: 45019 | I36: 59920
A37: BB/23-24/022 | B37: 45030 | C37: MS ANGLE 80 * 80 * 6 MM | D37: KEC INTERNATIONAL LIMITED,(BUTIBORI) | E37: 2.706 | F37: MH40Y4044 | G37: 7300030632 | H37: 45019 | I37: 59920
E38: =SUM(E32:E37) -> 12.417
A39: BB/23-24/023 | B39: 45031 | C39: MS ANGLE 100 * 100 * 6 MM | D39: KEC INTERNATIONAL LIMITED,(BUTIBORI) | E39: 0.854 | F39: MH40Y3944 | G39: 7300030632 | H39: 45019 | I39: 59920
A40: BB/23-24/023 | B40: 45031 | C40: MS ANGLE 100 * 100 * 6 MM | D40: KEC INTERNATIONAL LIMITED,(BUTIBORI) | E40: 0.189 | F40: MH40Y3944 | G40: 7300030632 | H40: 45019 | I40: 59920
...

Sheet KEC BB DISPATCHED MAY
A1: KEC BUTIBORI DISPATCHED DETAILS
A2: Invoice No. | B2: Invoice Dt | C2: Section | D2: PNAME | E2: QTY ISSUED | F2: VEHICLE No. | G2: Jobwork Challan No. | H2: Po. No | I2: PO ORDER DATE
A3: VIL/DC/23-24/116 | B3: 45045 | C3: HT ANGLE 120X120X9 MM | D3: KEC INTERNATIONAL LIMITED,(BUTIBORI) | E3: 2.097 | F3: MH46AF3590 | G3: 127/375, 128/376 | H3: LOI-12 | I3: 45023
A4: VIL/DC/23-24/116 | B4: 45045 | C4: HT ANGLE 120X120X7 MM | D4: KEC INTERNATIONAL LIMITED,(BUTIBORI) | E4: 6.084 | F4: MH46AF3590 | G4: 127/375, 128/376 | H4: LOI-12 | I4: 45023
A5: VIL/DC/23-24/116 | B5: 45045 | C5: HT ANGLE 80X80X6 MM | D5: KEC INTERNATIONAL LIMITED,(BUTIBORI) | E5: =14.313+3.58 -> 17.893 | F5: MH46AF3590 | G5: 127/375, 128/376 | H5: LOI-12 | I5: 45023
A6: VIL/DC/23-24/116 | B6: 45045 | C6: HT ANGLE 100X100X7 MM | D6: KEC INTERNATIONAL LIMITED,(BUTIBORI) | E6: 5.814 | F6: MH46AF3590 | G6: 127/375, 128/376 | H6: LOI-12 | I6: 45023
E7: =SUM(E3:E6) -> 31.888
A8: VIL/DC/23-24/117 | B8: 45046 | C8: HT ANGLE 120X120X7 MM | D8: KEC INTERNATIONAL LIMITED,(BUTIBORI) | E8: 4.4 | F8: MH40Y9844 | G8: 129/376, 130/377 | H8: LOI-12 | I8: 45023
A9: VIL/DC/23-24/117 | B9: 45046 | C9: HT ANGLE 130X130X9 MM | D9: KEC INTERNATIONAL LIMITED,(BUTIBORI) | E9: =17.468+8.893 -> 26.361 | F9: MH40Y9844 | G9: 129/376, 130/377 | H9: LOI-12 | I9: 45023
A10: VIL/DC/23-24/118 | B10: 45046 | C10: HT ANGLE 130X130X9 MM | D10: KEC INTERNATIONAL LIMITED,(BUTIBORI) | E10: 1.319 | F10: MH40Y9844 | G10: 130/377 | H10: LOI-13 | I10: 45023
A11: VIL/DC/23-24/119 | B11: 45046 | C11: HT ANGLE 80X80X6 MM | D11: KEC INTERNATIONAL LIMITED,(BUTIBORI) | E11: 10.577 | F11: MH40Y5844 | G11: 131/377, 132/ 378 | H11: LOI-12 | I11: 45023
A12: VIL/DC/23-24/119 | B12: 45046 | C12: HT ANGLE 80X80X5 MM | D12: KEC INTERNATIONAL LIMITED,(BUTIBORI) | E12: =7.216+3.757 -> 10.973 | F12: MH40Y5844 | G12: 131/377, 132/ 378 | H12: LOI-12 | I12: 45023
A13: VIL/DC/23-24/119 | B13: 45046 | C13: HT ANGLE 120X120X8 MM | D13: KEC INTERNATIONAL LIMITED,(BUTIBORI) | E13: 4.58 | F13: MH40Y5844 | G13: 131/377, 132/ 378 | H13: LOI-12 | I13: 45023
A14: VIL/DC/23-24/120 | B14: 45046 | C14: HT ANGLE 80X80X6 MM | D14: KEC INTERNATIONAL LIMITED,(BUTIBORI) | E14: 6.702 | F14: MH40Y5844 | G14: 132/ 378 | H14: LOI-13 | I14: 45023
E15: =SUM(E8:E14) -> 64.912
A16: VIL/DC/23-24/121 | B16: 45048 | C16: HT ANGLE 80X80X5 MM | D16: KEC INTERNATIONAL LIMITED,(BUTIBORI) | E16: 1.388 | F16: MH46AF3590 | G16: 133/378, 134/ 379 | H16: LOI-12 | I16: 45023
A17: VIL/DC/23-24/121 | B17: 45048 | C17: HT ANGLE 120X120X8 MM | D17: KEC INTERNATIONAL LIMITED,(BUTIBORI) | E17: =11.467+10.107 -> 21.574 | F17: MH46AF3590 | G17: 133/378, 134/ 379 | H17: LOI-12 | I17: 45023
A18: VIL/DC/23-24/122 | B18: 45048 | C18: HT ANGLE 120X120X8 MM | D18: KEC INTERNATIONAL LIMITED,(BUTIBORI) | E18: 8.267 | F18: MH46AF3590 | G18: 127/375, 128/376 | H18: LOI-13 | I18: 45023
E19: =SUM(E16:E18) -> 31.229
A20: VIL/DC/23-24/123 | B20: 45050 | C20: HT ANGLE 130X130X10 MM | D20: KEC INTERNATIONAL LIMITED,(BUTIBORI) | E20: =9.612+15.683 -> 25.295 | F20: MH40Y4944 | G20: 135/379, 136/380 | H20: LOI-12 | I20: 45023
A21: VIL/DC/23-24/124 | B21: 45050 | C21: HT ANGLE 130X130X10 MM | D21: KEC INTERNATIONAL LIMITED,(BUTIBORI) | E21: 7.892 | F21: MH40Y4944 | G21: 136/380 | H21: LOI-13 | I21: 45023
A22: VIL/DC/23-24/125 | B22: 45050 | C22: HT ANGLE 130X130X10 MM | D22: KEC INTERNATIONAL LIMITED,(BUTIBORI) | E22: 25.186 | F22: MH40Y4044 | G22: 137/380, 138/381 | H22: LOI-12 | I22: 45023
A23: VIL/DC/23-24/126 | B23: 45050 | C23: HT ANGLE 130X130X10 MM | D23: KEC INTERNATIONAL LIMITED,(BUTIBORI) | E23: 8.226 | F23: MH40Y4044 | G23: 138/381 | H23: LOI-13 | I23: 45023
E24: =SUM(E20:E23) -> 66.599
A25: VIL/DC/23-24/127 | B25: 45052 | C25: HT ANGLE 100X100X6 MM | D25: KEC INTERNATIONAL LIMITED,(BUTIBORI) | E25: 5.774 | F25: MH40Y2044 | G25: 139/381, 140/382 | H25: LOI-12 | I25: 45023
A26: VIL/DC/23-24/127 | B26: 45052 | C26: HT ANGLE 130X130X9 MM | D26: KEC INTERNATIONAL LIMITED,(BUTIBORI) | E26: 3.308 | F26: MH40Y2044 | G26: 139/381, 140/382 | H26: LOI-12 | I26: 45023
A27: VIL/DC/23-24/127 | B27: 45052 | C27: HT ANGLE 120X120X10 MM | D27: KEC INTERNATIONAL LIMITED,(BUTIBORI) | E27: 2.786 | F27: MH40Y2044 | G27: 139/381, 140/382 | H27: LOI-12 | I27: 45023
A28: VIL/DC/23-24/127 | B28: 45052 | C28: HT ANGLE 130X130X8 MM | D28: KEC INTERNATIONAL LIMITED,(BUTIBORI) | E28: 3.78 | F28: MH40Y2044 | G28: 139/381, 140/382 | H28: LOI-12 | I28: 45023
A29: VIL/DC/23-24/127 | B29: 45052 | C29: HT ANGLE 130X130X13 MM | D29: KEC INTERNATIONAL LIMITED,(BUTIBORI) | E29: 1.443 | F29: MH40Y2044 | G29: 139/381, 140/382 | H29: LOI-12 | I29: 45023
A30: VIL/DC/23-24/127 | B30: 45052 | C30: HT ANGLE 130X130X10 MM | D30: KEC INTERNATIONAL LIMITED,(BUTIBORI) | E30: 3.05 | F30: MH40Y2044 | G30: 139/381, 140/382 | H30: LOI-12 | I30: 45023
A31: VIL/DC/23-24/127 | B31: 45052 | C31: HT ANGLE 80X80X6 MM | D31: KEC INTERNATIONAL LIMITED,(BUTIBORI) | E31: 2.61 | F31: MH40Y2044 | G31: 139/381, 140/382 | H31: LOI-12 | I31: 45023
A32: VIL/DC/23-24/128 | B32: 45052 | C32: HT ANGLE 80X80X6 MM | D32: KEC INTERNATIONAL LIMITED,(BUTIBORI) | E32: 2.071 | F32: MH40Y2044 | G32: 140/382 | H32: LOI-13 | I32: 45023
A33: VIL/DC/23-24/129 | B33: 45052 | C33: HT ANGLE 100X100X6 MM | D33: KEC INTERNATIONAL LIMITED,(BUTIBORI) | E33: 0.873 | F33: MH40Y2044 | G33: 140/382 | H33: LOI-41 | I33: 45026
A34: VIL/DC/23-24/130 | B34: 45052 | C34: HT ANGLE 110X110X6 MM | D34: KEC INTERNATIONAL LIMITED,(BUTIBORI) | E34: 0.367 | F34: MH40Y2044 | G34: 140/382 | H34: LOI-2021 | I34: 45019
A35: VIL/DC/23-24/130 | B35: 45052 | C35: HT ANGLE 110X110X7 MM | D35: KEC INTERNATIONAL LIMITED,(BUTIBORI) | E35: 0.142 | F35: MH40Y2044 | G35: 140/382 | H35: LOI-2021 | I35: 45019
E36: =SUM(E25:E35) -> 26.204
A37: VIL/DC/23-24/131 | B37: 45058 | C37: HT ANGLE 150X150X12 MM | D37: KEC INTERNATIONAL LIMITED,(DUBAI) | E37: 3.145 | F37: MH40CM5134 | G37: 141/382 | H37: LOI-123 | I37: 45043
A38: VIL/DC/23-24/132 | B38: 45058 | C38: HT ANGLE 150X150X12 MM | D38: KEC INTERNATIONAL LIMITED,(DUBAI) | E38: =7.008+14.668 -> 21.676 | F38: MH40CM5134 | G38: 141/382, 142/383 | H38: LOI-124 | I38: 45043
E39: =SUM(E37:E38) -> 24.821
A40: VIL/DC/23-24/133 | B40: 45059 | C40: HT ANGLE 150X150X18 MM | D40: KEC INTERNATIONAL LIMITED,(DUBAI) | E40: 24.687 | F40: MH31FC2215 | G40: 143/383 , 144/384 | H40: LOI-123 | I40: 45043
...

Sheet KEC BB DISPATCHED JUN
A1: Invoice No. | B1: Invoice Dt | C1: Section | D1: PNAME | E1: QTY ISSUED | F1: VEHICLE No. | G1: Jobwork Challan No. | H1: Po. No | I1: PO ORDER DATE
A2: VIL/DC/23-24/171 | B2: 45076 | C2: HT ANGLE 110X110X8 MM | D2: KEC INTERNATIONAL LIMITED,(BUTIBORI) | E2: 2.771 | F2: MH40Y2044 | G2: 178/16, 179/17 | H2: LOI-215 | I2: 45071
A3: VIL/DC/23-24/171 | B3: 45076 | C3: HT ANGLE 75X75X6 MM | D3: KEC INTERNATIONAL LIMITED,(BUTIBORI) | E3: =0.217+1.44 -> 1.657 | F3: MH40Y2044 | G3: 178/16, 179/17 | H3: LOI-215 | I3: 45071
A4: VIL/DC/23-24/172 | B4: 45076 | C4: HT ANGLE 75X75X6 MM | D4: KEC INTERNATIONAL LIMITED,(BUTIBORI) | E4: 2.717 | F4: MH40Y2044 | G4: 179/17 | H4: LOI-218 | I4: 45071
A5: VIL/DC/23-24/173 | B5: 45076 | C5: MS ANGLE 90X90X7 MM | D5: KEC INTERNATIONAL LIMITED,(BUTIBORI) | E5: 2.787 | F5: MH40Y2044 | G5: 179/17 | H5: LOI-214 | I5: 45071
A6: VIL/DC/23-24/174 | B6: 45076 | C6: HT ANGLE 110X110X10 MM | D6: KEC INTERNATIONAL LIMITED,(BUTIBORI) | E6: 2.191 | F6: MH40Y2044 | G6: 179/17 | H6: LOI-122 | I6: 45043
A7: VIL/DC/23-24/174 | B7: 45076 | C7: HT ANGLE 110X110X8 MM | D7: KEC INTERNATIONAL LIMITED,(BUTIBORI) | E7: 3.126 | F7: MH40Y2044 | G7: 179/17 | H7: LOI-122 | I7: 45043
A8: VIL/DC/23-24/174 | B8: 45076 | C8: HT ANGLE 100X100X7 MM | D8: KEC INTERNATIONAL LIMITED,(BUTIBORI) | E8: 1.798 | F8: MH40Y2044 | G8: 179/17 | H8: LOI-122 | I8: 45043
A9: VIL/DC/23-24/174 | B9: 45076 | C9: HT ANGLE 90X90X7 MM | D9: KEC INTERNATIONAL LIMITED,(BUTIBORI) | E9: 3.338 | F9: MH40Y2044 | G9: 179/17 | H9: LOI-122 | I9: 45043
A10: VIL/DC/23-24/175 | B10: 45076 | C10: HT ANGLE 110X110X7 MM | D10: KEC INTERNATIONAL LIMITED,(BUTIBORI) | E10: 3.575 | F10: MH40Y2044 | G10: 179/17, 180/18 | H10: LOI-138 | I10: 45053
A11: VIL/DC/23-24/175 | B11: 45076 | C11: HT ANGLE 110X110X10 MM | D11: KEC INTERNATIONAL LIMITED,(BUTIBORI) | E11: =2.375+0.547 -> 2.922 | F11: MH40Y2044 | G11: 179/17, 180/18 | H11: LOI-138 | I11: 45053
A12: VIL/DC/23-24/175 | B12: 45076 | C12: HT ANGLE 110X110X8 MM | D12: KEC INTERNATIONAL LIMITED,(BUTIBORI) | E12: 3.98 | F12: MH40Y2044 | G12: 179/17, 180/18 | H12: LOI-138 | I12: 45053
A13: VIL/DC/23-24/175 | B13: 45076 | C13: HT ANGLE 100X100X7 MM | D13: KEC INTERNATIONAL LIMITED,(BUTIBORI) | E13: 1.216 | F13: MH40Y2044 | G13: 179/17, 180/18 | H13: LOI-138 | I13: 45053
E14: =SUM(E2:E13) -> 32.078
A15: VIL/DC/23-24/179 | B15: 45078 | C15: HT ANGLE 130X130X10 MM | D15: KEC INTERNATIONAL LIMITED,(DUBAI) | E15: 17.399 | F15: MH31FC2568 | G15: 182/20 | H15: LOI-124 | I15: 45043
A16: VIL/DC/23-24/180 | B16: 45078 | C16: HT ANGLE 130X130X10 MM | D16: KEC INTERNATIONAL LIMITED,(DUBAI) | E16: 7.231 | F16: MH31FC2568 | G16: 182/20 | H16: LOI-174 | I16: 45056
A17: VIL/DC/23-24/181 | B17: 45078 | C17: HT ANGLE 100X100X7 MM | D17: KEC INTERNATIONAL LIMITED,(DUBAI) | E17: 12.082 | F17: MH31FC2629 | G17: 183/21 | H17: LOI-123 | I17: 45043
A18: VIL/DC/23-24/181 | B18: 45078 | C18: HT ANGLE 75X75X6 MM | D18: KEC INTERNATIONAL LIMITED,(DUBAI) | E18: 9.614 | F18: MH31FC2629 | G18: 183/21 | H18: LOI-123 | I18: 45043
A19: VIL/DC/23-24/181 | B19: 45078 | C19: HT ANGLE 75X75X5 MM | D19: KEC INTERNATIONAL LIMITED,(DUBAI) | E19: 2.028 | F19: MH31FC2629 | G19: 183/21 | H19: LOI-123 | I19: 45043
A20: VIL/DC/23-24/181 | B20: 45078 | C20: HT ANGLE 75X75X6 MM | D20: KEC INTERNATIONAL LIMITED,(DUBAI) | E20: 0.863 | F20: MH31FC2629 | G20: 183/21 | H20: LOI-123 | I20: 45043
A21: VIL/DC/23-24/182 | B21: 45078 | C21: HT ANGLE 75X75X5 MM | D21: KEC INTERNATIONAL LIMITED,(BUTIBORI) | E21: 3.457 | F21: MH40Y2044 | G21: 184/18 | H21: LOI-215 | I21: 45071
A22: VIL/DC/23-24/183 | B22: 45078 | C22: HT ANGLE 75X75X5 MM | D22: KEC INTERNATIONAL LIMITED,(BUTIBORI) | E22: 3.6 | F22: MH40Y2044 | G22: 184/18 | H22: LOI-218 | I22: 45071
A23: VIL/DC/23-24/184 | B23: 45078 | C23: HT ANGLE 75X75X5 MM | D23: KEC INTERNATIONAL LIMITED,(BUTIBORI) | E23: =0.819+4.732+0.78+4.614+0.995 -> 11.94 | F23: MH40Y2044 | G23: 184/18, 185/19, 186/20, 187/21, 188/22 | H23: LOI-122 | I23: 45043
A24: VIL/DC/23-24/185 | B24: 45078 | C24: HT ANGLE 120X120X12 MM | D24: KEC INTERNATIONAL LIMITED,(BUTIBORI) | E24: 4.406 | F24: MH40Y2044 | G24: 188/22 | H24: LOI-216 | I24: 45071
A25: VIL/DC/23-24/186 | B25: 45078 | C25: HT ANGLE 75X75X5 MM | D25: KEC INTERNATIONAL LIMITED,(BUTIBORI) | E25: 2.615 | F25: MH40Y2044 | G25: 188/22 | H25: LOI-138 | I25: 45053
A26: VIL/DC/23-24/186 | B26: 45078 | C26: HT ANGLE 100X100X8 MM | D26: KEC INTERNATIONAL LIMITED,(BUTIBORI) | E26: 3.97 | F26: MH40Y2044 | G26: 188/22 | H26: LOI-138 | I26: 45053
A27: VIL/DC/23-24/186 | B27: 45078 | C27: HT ANGLE 100X100X7 MM | D27: KEC INTERNATIONAL LIMITED,(BUTIBORI) | E27: 1.738 | F27: MH40Y2044 | G27: 188/22 | H27: LOI-138 | I27: 45053
A28: VIL/DC/23-24/187 | B28: 45078 | C28: HT ANGLE 90X90X7 MM | D28: KEC INTERNATIONAL LIMITED,(BUTIBORI) | E28: 0.699 | F28: MH40Y2044 | G28: 188/22 | H28: LOI-214 | I28: 45071
A29: VIL/DC/23-24/188 | B29: 45078 | C29: HT ANGLE 120X120X12 MM | D29: KEC INTERNATIONAL LIMITED,(BUTIBORI) | E29: 7.258 | F29: MH40Y4944 | G29: 189/22 | H29: LOI-216 | I29: 45071
A30: VIL/DC/23-24/189 | B30: 45078 | C30: HT ANGLE 120X120X9 MM | D30: KEC INTERNATIONAL LIMITED,(BUTIBORI) | E30: =7.501+13.394 -> 20.895 | F30: MH40Y4944 | G30: 189/22, 190/23 | H30: LOI-138 | I30: 45053
A31: VIL/DC/23-24/190 | B31: 45078 | C31: HT ANGLE 100X100X12 MM | D31: KEC INTERNATIONAL LIMITED,(BUTIBORI) | E31: 3.944 | F31: MH40Y4944 | G31: 190/23 | H31: LOI-122 | I31: 45043
E32: =SUM(E15:E31) -> 113.739
A33: VIL/DC/23-24/191 | B33: 45079 | C33: HT ANGLE 130X130X10 MM | D33: KEC INTERNATIONAL LIMITED,(DUBAI) | E33: 2.709 | F33: MH31FC2567 | G33: 191/23 | H33: LOI-124 | I33: 45043
A34: VIL/DC/23-24/191 | B34: 45079 | C34: HT ANGLE 130X130X10 MM | D34: KEC INTERNATIONAL LIMITED,(DUBAI) | E34: 8.57 | F34: MH31FC2567 | G34: 191/23 | H34: LOI-124 | I34: 45043
A35: VIL/DC/23-24/192 | B35: 45079 | C35: HT ANGLE 130X130X10 MM | D35: KEC INTERNATIONAL LIMITED,(DUBAI) | E35: 0.164 | F35: MH31FC2567 | G35: 191/23 , 192/24 | H35: LOI-123 | I35: 45043
A36: VIL/DC/23-24/192 | B36: 45079 | C36: HT ANGLE 130X130X10 MM | D36: KEC INTERNATIONAL LIMITED,(DUBAI) | E36: =0.53+7.761 -> 8.291 | F36: MH31FC2567 | G36: 191/23 , 192/24 | H36: LOI-123 | I36: 45043
A37: VIL/DC/23-24/192 | B37: 45079 | C37: HT ANGLE 130X130X10 MM | D37: KEC INTERNATIONAL LIMITED,(DUBAI) | E37: 3.873 | F37: MH31FC2567 | G37: 191/23 , 192/24 | H37: LOI-123 | I37: 45043
A38: VIL/DC/23-24/193 | B38: 45079 | C38: HT ANGLE 130X130X10 MM | D38: KEC INTERNATIONAL LIMITED,(DUBAI) | E38: 1.671 | F38: MH31FC2567 | G38: 192/24 | H38: LOI-125 | I38: 45043
E39: =SUM(E33:E38) -> 25.278
A40: VIL/DC/23-24/194 | B40: 45080 | C40: HT ANGLE 120X120X9 MM | D40: KEC INTERNATIONAL LIMITED,(BUTIBORI) | E40: 4.838 | F40: MH40Y2044 | G40: 193/25 | H40: LOI-138 | I40: 45053
...

Sheet KEC JBP DISPATCHED JUN 
A1: Invoice No. | B1: Invoice Dt | C1: Section | D1: PNAME | E1: QTY ISSUED | F1: VEHICLE No. | G1: Jobwork Challan No. | H1: Po. No | I1: PO ORDER DATE
A2: VIL/DC/23-24/223 | B2: 45085 | C2: MS ANGLE 75X75X8 MM | D2: KEC INTERNATIONAL LIMITED,(JABALPUR) | E2: 32.387 | F2: MH40BG0308 | G2: 219/65, 220/66, 221/67 | H2: LOI-191 | I2: 45064
A3: VIL/DC/23-24/224 | B3: 45085 | C3: MS ANGLE 75X75X8 MM | D3: KEC INTERNATIONAL LIMITED,(JABALPUR) | E3: 32.768 | F3: MH49AT1953 | G3: 222/67, 223/68 | H3: LOI-191 | I3: 45064
A4: VIL/DC/23-24/225 | B4: 45085 | C4: MS ANGLE 75X75X8 MM | D4: KEC INTERNATIONAL LIMITED,(JABALPUR) | E4: 20.448 | F4: MH40N7379 | G4: 224/68, 225/69 | H4: LOI-191 | I4: 45064
E5: =SUM(E2:E4) -> 85.603
A6: VIL/DC/23-24/226 | B6: 45086 | C6: MS ANGLE 75X75X8 MM | D6: KEC INTERNATIONAL LIMITED,(JABALPUR) | E6: 32.801 | F6: MH49AT0506 | G6: 226/61, 227/69, 228/70 | H6: LOI-191 | I6: 45064
A7: VIL/DC/23-24/227 | B7: 45086 | C7: MS ANGLE 75X75X8 MM | D7: KEC INTERNATIONAL LIMITED,(JABALPUR) | E7: 32.765 | F7: MH49AT0503 | G7: 229/70, 230/71 | H7: LOI-191 | I7: 45064
A8: VIL/DC/23-24/228 | B8: 45086 | C8: MS ANGLE 75X75X8 MM | D8: KEC INTERNATIONAL LIMITED,(JABALPUR) | E8: =14.958+9.541 -> 24.499 | F8: MH49AT2926 | G8: 231/71, 232/72 | H8: LOI-191 | I8: 45064
A9: VIL/DC/23-24/229 | B9: 45086 | C9: MS ANGLE 75X75X8 MM | D9: KEC INTERNATIONAL LIMITED,(JABALPUR) | E9: 1.738 | F9: MH49AT2926 | G9: 232/72 | H9: LOI-219 | I9: 45071
A10: VIL/DC/23-24/230 | B10: 45086 | C10: MS ANGLE 90X90X6 MM | D10: KEC INTERNATIONAL LIMITED,(JABALPUR) | E10: 6.39 | F10: MH49AT2926 | G10: 232/72 | H10: LOI-213 | I10: 45071
A11: VIL/DC/23-24/231 | B11: 45086 | C11: MS ANGLE 75X75X8 MM | D11: KEC INTERNATIONAL LIMITED,(JABALPUR) | E11: =11.583+8.136 -> 19.719 | F11: MH40AK6005 | G11: 233/72, 234/73 | H11: LOI-191 | I11: 45064
A12: VIL/DC/23-24/232 | B12: 45086 | C12: MS ANGLE 75X75X8 MM | D12: KEC INTERNATIONAL LIMITED,(JABALPUR) | E12: 12.798 | F12: MH40AK6005 | G12: 234/73 | H12: LOI-219 | I12: 45071
E13: =SUM(E6:E12) -> 130.71
A14: VIL/DC/23-24/233 | B14: 45087 | C14: MS ANGLE 90X90X6 MM | D14: KEC INTERNATIONAL LIMITED,(JABALPUR) | E14: =6.302+11.721 -> 18.023 | F14: MH40AK2189 | G14: 235/73, 236/74 | H14: LOI-213 | I14: 45071
A15: VIL/DC/23-24/234 | B15: 45087 | C15: MS ANGLE 90X90X6 MM | D15: KEC INTERNATIONAL LIMITED,(JABALPUR) | E15: 0.733 | F15: MH40AK2189 | G15: 236/74 | H15: LOI-219 | I15: 45071
A16: VIL/DC/23-24/234 | B16: 45087 | C16: MS ANGLE 75X75X8 MM | D16: KEC INTERNATIONAL LIMITED,(JABALPUR) | E16: 5.297 | F16: MH40AK2189 | G16: 236/74 | H16: LOI-219 | I16: 45071
A17: VIL/DC/23-24/235 | B17: 45087 | C17: MS ANGLE 75X75X6 MM | D17: KEC INTERNATIONAL LIMITED,(JABALPUR) | E17: 5.282 | F17: MH40AK2189 | G17: 236/74 | H17: LOI-191 | I17: 45064
A18: VIL/DC/23-24/235 | B18: 45087 | C18: MS ANGLE 75X75X8 MM | D18: KEC INTERNATIONAL LIMITED,(JABALPUR) | E18: 3.195 | F18: MH40AK2189 | G18: 236/74 | H18: LOI-191 | I18: 45064
A19: VIL/DC/23-24/236 | B19: 45087 | C19: MS ANGLE 90X90X6 MM | D19: KEC INTERNATIONAL LIMITED,(JABALPUR) | E19: =2.66+3.792 -> 6.452 | F19: MH49AT2907 | G19: 237/74, 238/ 75 | H19: LOI-213 | I19: 45071
A20: VIL/DC/23-24/237 | B20: 45087 | C20: MS ANGLE 75X75X8 MM | D20: KEC INTERNATIONAL LIMITED,(JABALPUR) | E20: 2.967 | F20: MH49AT2907 | G20: 238/ 75 | H20: LOI-219 | I20: 45071
A21: VIL/DC/23-24/238 | B21: 45087 | C21: MS ANGLE 75X75X6 MM | D21: KEC INTERNATIONAL LIMITED,(JABALPUR) | E21: 5.073 | F21: MH49AT2907 | G21: 238/ 75 | H21: LOI-191 | I21: 45064
A22: VIL/DC/23-24/238 | B22: 45087 | C22: MS ANGLE 75X75X8 MM | D22: KEC INTERNATIONAL LIMITED,(JABALPUR) | E22: =17.056+1.427 -> 18.483 | F22: MH49AT2907 | G22: 238/ 75 | H22: LOI-191 | I22: 45064
E23: =SUM(E14:E22) -> 65.505
D40: JUN -23 Total Dispatched | E40: =SUM(E2:E39)/2 -> 281.818

Sheet KEC BB DISPATCHED JULY
A1: Invoice No. | B1: Invoice Dt | C1: Section | D1: PNAME | E1: QTY ISSUED | F1: VEHICLE No. | G1: Jobwork Challan No. | H1: Po. No | I1: PO ORDER DATE
A2: VIL/DC/23-24/374 | B2: 45106 | C2: HT ANGLE 100X100X6 MM | D2: KEC INTERNATIONAL LIMITED,(BUTIBORI) | E2: 18.656 | F2: MH40Y3944 | G2: 348/87 , 349/88 | H2: LOI-337 | I2: 45092
A3: VIL/DC/23-24/374 | B3: 45106 | C3: HT ANGLE 150X150X14 MM | D3: KEC INTERNATIONAL LIMITED,(BUTIBORI) | E3: 3.413 | F3: MH40Y3944 | G3: 348/87 , 349/88 | H3: LOI-337 | I3: 45092
A4: VIL/DC/23-24/374 | B4: 45106 | C4: HT ANGLE 150X150X15 MM | D4: KEC INTERNATIONAL LIMITED,(BUTIBORI) | E4: =1.818+4.793 -> 6.611 | F4: MH40Y3944 | G4: 348/87 , 349/88 | H4: LOI-337 | I4: 45092
A5: VIL/DC/23-24/375 | B5: 45106 | C5: HT ANGLE 100X100X6 MM | D5: KEC INTERNATIONAL LIMITED,(BUTIBORI) | E5: 3.768 | F5: MH40Y3944 | G5: 349/88 | H5: LOI-336 | I5: 45092
A6: VIL/DC/23-24/376 | B6: 45106 | C6: HT ANGLE 100X100X8 MM | D6: KEC INTERNATIONAL LIMITED,(BUTIBORI) | E6: 15.92 | F6: MH40AK5044 | G6: 350/88, 351/89 | H6: LOI-337 | I6: 45092
A7: VIL/DC/23-24/376 | B7: 45106 | C7: HT ANGLE 150X150X15 MM | D7: KEC INTERNATIONAL LIMITED,(BUTIBORI) | E7: 13.858 | F7: MH40AK5044 | G7: 350/88, 351/89 | H7: LOI-337 | I7: 45092
A8: VIL/DC/23-24/377 | B8: 45106 | C8: HT ANGLE 110X110X10 MM | D8: KEC INTERNATIONAL LIMITED,(BUTIBORI) | E8: 2.122 | F8: MH40AK5044 | G8: 351/89 | H8: LOI-336 | I8: 45092
E9: =SUM(E2:E8) -> 64.348
A10: VIL/DC/23-24/378 | B10: 45107 | C10: HT ANGLE 100X100X7 MM | D10: KEC INTERNATIONAL LIMITED,(BUTIBORI) | E10: 14.717 | F10: MH46AF3590 | G10: 352/89, 353/90 | H10: LOI-337 | I10: 45092
A11: VIL/DC/23-24/378 | B11: 45107 | C11: HT ANGLE 100X100X8 MM | D11: KEC INTERNATIONAL LIMITED,(BUTIBORI) | E11: 2.684 | F11: MH46AF3590 | G11: 352/89, 353/90 | H11: LOI-337 | I11: 45092
A12: VIL/DC/23-24/378 | B12: 45107 | C12: HT ANGLE 90X90X6 MM | D12: KEC INTERNATIONAL LIMITED,(BUTIBORI) | E12: =0.172+1.798 -> 1.97 | F12: MH46AF3590 | G12: 352/89, 353/90 | H12: LOI-337 | I12: 45092
A13: VIL/DC/23-24/378 | B13: 45107 | C13: HT ANGLE 110X110X9 MM | D13: KEC INTERNATIONAL LIMITED,(BUTIBORI) | E13: 2.954 | F13: MH46AF3590 | G13: 352/89, 353/90 | H13: LOI-337 | I13: 45092
A14: VIL/DC/23-24/378 | B14: 45107 | C14: HT ANGLE 110X110X10 MM | D14: KEC INTERNATIONAL LIMITED,(BUTIBORI) | E14: 3.753 | F14: MH46AF3590 | G14: 352/89, 353/90 | H14: LOI-337 | I14: 45092
A15: VIL/DC/23-24/379 | B15: 45107 | C15: HT ANGLE 100X100X7 MM | D15: KEC INTERNATIONAL LIMITED,(BUTIBORI) | E15: 2.311 | F15: MH46AF3590 | G15: 352/89, 353/90 | H15: LOI-336 | I15: 45092
A16: VIL/DC/23-24/379 | B16: 45107 | C16: HT ANGLE 110X110X10 MM | D16: KEC INTERNATIONAL LIMITED,(BUTIBORI) | E16: 0.783 | F16: MH46AF3590 | G16: 352/89, 353/90 | H16: LOI-336 | I16: 45092
A17: VIL/DC/23-24/379 | B17: 45107 | C17: HT ANGLE 100X100X8 MM | D17: KEC INTERNATIONAL LIMITED,(BUTIBORI) | E17: 2.923 | F17: MH46AF3590 | G17: 352/89, 353/90 | H17: LOI-336 | I17: 45092
A18: VIL/DC/23-24/380 | B18: 45107 | C18: HT ANGLE 110X110X8 MM | D18: KEC INTERNATIONAL LIMITED,(DUBAI) | E18: 4.268 | F18: MH40CM3183 | G18: 354/90, 355/91 | H18: LOI-347 | I18: 45092
A19: VIL/DC/23-24/380 | B19: 45107 | C19: HT ANGLE 150X150X14 MM | D19: KEC INTERNATIONAL LIMITED,(DUBAI) | E19: 2.13 | F19: MH40CM3183 | G19: 354/90, 355/91 | H19: LOI-347 | I19: 45092
A20: VIL/DC/23-24/380 | B20: 45107 | C20: HT ANGLE 150X150X16 MM | D20: KEC INTERNATIONAL LIMITED,(DUBAI) | E20: =8.502+0.397 -> 8.899 | F20: MH40CM3183 | G20: 354/90, 355/91 | H20: LOI-347 | I20: 45092
A21: VIL/DC/23-24/381 | B21: 45107 | C21: MS ANGLE 120X120X8 MM | D21: KEC INTERNATIONAL LIMITED,(DUBAI) | E21: 5.037 | F21: MH40CM3183 | G21: 355/91 | H21: LOI-272 | I21: 45082
A22: VIL/DC/23-24/381 | B22: 45107 | C22: HT ANGLE 130X130X9 MM | D22: KEC INTERNATIONAL LIMITED,(DUBAI) | E22: 4.3 | F22: MH40CM3183 | G22: 355/91 | H22: LOI-272 | I22: 45082
A23: VIL/DC/23-24/382 | B23: 45107 | C23: HT ANGLE 150X150X15 MM | D23: KEC INTERNATIONAL LIMITED,(BUTIBORI) | E23: 6.71 | F23: MH40Y3944 | G23: 356/ 91,357/92 | H23: LOI-337 | I23: 45092
A24: VIL/DC/23-24/382 | B24: 45107 | C24: HT ANGLE 90X90X6 MM | D24: KEC INTERNATIONAL LIMITED,(BUTIBORI) | E24: 6.989 | F24: MH40Y3944 | G24: 356/ 91,357/92 | H24: LOI-337 | I24: 45092
A25: VIL/DC/23-24/382 | B25: 45107 | C25: HT ANGLE 110X110X8 MM | D25: KEC INTERNATIONAL LIMITED,(BUTIBORI) | E25: 4.247 | F25: MH40Y3944 | G25: 356/ 91,357/92 | H25: LOI-337 | I25: 45092
A26: VIL/DC/23-24/382 | B26: 45107 | C26: HT ANGLE 100X100X8 MM | D26: KEC INTERNATIONAL LIMITED,(BUTIBORI) | E26: =1.631+3.737 -> 5.368 | F26: MH40Y3944 | G26: 356/ 91,357/92 | H26: LOI-337 | I26: 45092
A27: VIL/DC/23-24/382 | B27: 45107 | C27: MS ANGLE 90X90X7 MM | D27: KEC INTERNATIONAL LIMITED,(BUTIBORI) | E27: 0.638 | F27: MH40Y3944 | G27: 356/ 91,357/92 | H27: LOI-337 | I27: 45092
A28: VIL/DC/23-24/382 | B28: 45107 | C28: MS ANGLE 100X100X6 MM | D28: KEC INTERNATIONAL LIMITED,(BUTIBORI) | E28: 1.809 | F28: MH40Y3944 | G28: 356/ 91,357/92 | H28: LOI-337 | I28: 45092
A29: VIL/DC/23-24/383 | B29: 45107 | C29: HT ANGLE 110X110X8 MM | D29: KEC INTERNATIONAL LIMITED,(BUTIBORI) | E29: 1.829 | F29: MH40Y3944 | G29: 357/92 | H29: LOI-336 | I29: 45092
A30: VIL/DC/23-24/383 | B30: 45107 | C30: HT ANGLE 100X100X8 MM | D30: KEC INTERNATIONAL LIMITED,(BUTIBORI) | E30: 1.535 | F30: MH40Y3944 | G30: 357/92 | H30: LOI-336 | I30: 45092
A31: VIL/DC/23-24/383 | B31: 45107 | C31: MS ANGLE 100X100X6 MM | D31: KEC INTERNATIONAL LIMITED,(BUTIBORI) | E31: 1.991 | F31: MH40Y3944 | G31: 357/92 | H31: LOI-336 | I31: 45092
A32: VIL/DC/23-24/384 | B32: 45107 | C32: HT ANGLE 150X150X15 MM | D32: KEC INTERNATIONAL LIMITED,(DUBAI) | E32: =17.496+3.819 -> 21.315 | F32: MH31FC2215 | G32: 358/92, 359/93 | H32: LOI-193 | I32: 45064
A33: VIL/DC/23-24/385 | B33: 45107 | C33: HT ANGLE 150X150X15 MM | D33: KEC INTERNATIONAL LIMITED,(DUBAI) | E33: 3.65 | F33: MH31FC2215 | G33: 359/93 | H33: LOI-272 | I33: 45082
A34: VIL/DC/23-24/386 | B34: 45107 | C34: HT ANGLE 120X120X9 MM | D34: KEC INTERNATIONAL LIMITED,(BUTIBORI) | E34: 31.767 | F34: MH46AR8099 | G34: 360/93, 361/94 | H34: LOI-337 | I34: 45092
E35: =SUM(E10:E34) -> 144.577
A36: VIL/DC/23-24/387 | B36: 45108 | C36: HT ANGLE 150X150X15 MM | D36: KEC INTERNATIONAL LIMITED,(BUTIBORI) | E36: 6.615 | F36: MH40Y3944 | G36: 362/94, 363/95 | H36: LOI-337 | I36: 45092
A37: VIL/DC/23-24/387 | B37: 45108 | C37: HT ANGLE 100X100X8 MM | D37: KEC INTERNATIONAL LIMITED,(BUTIBORI) | E37: 11.406 | F37: MH40Y3944 | G37: 362/94, 363/95 | H37: LOI-337 | I37: 45092
A38: VIL/DC/23-24/387 | B38: 45108 | C38: HT ANGLE 100X100X6 MM | D38: KEC INTERNATIONAL LIMITED,(BUTIBORI) | E38: =0.777+4.754 -> 5.531 | F38: MH40Y3944 | G38: 362/94, 363/95 | H38: LOI-337 | I38: 45092
A39: VIL/DC/23-24/387 | B39: 45108 | C39: HT ANGLE 120X120X9 MM | D39: KEC INTERNATIONAL LIMITED,(BUTIBORI) | E39: 7.271 | F39: MH40Y3944 | G39: 362/94, 363/95 | H39: LOI-337 | I39: 45092
A40: VIL/DC/23-24/388 | B40: 45108 | C40: HT ANGLE 100X100X6 MM | D40: KEC INTERNATIONAL LIMITED,(BUTIBORI) | E40: 0.382 | F40: MH40Y3944 | G40: 363/95 | H40: LOI-336 | I40: 45092
...

Sheet KEC JBP DISPATCHED JULY
A1: Invoice No. | B1: Invoice Dt | C1: Section | D1: PNAME | E1: QTY ISSUED | F1: VEHICLE No. | G1: Jobwork Challan No. | H1: Po. No | I1: PO ORDER DATE
A2: VIL/DC/23-24/306 | B2: 45099 | C2: MS ANGLE 75X75X8 MM | D2: KEC INTERNATIONAL LIMITED,(JABALPUR) | E2: 9.144 | F2: MH49AT4594 | G2: 288/76 | H2: LOI-191 | I2: 45064
A3: VIL/DC/23-24/307 | B3: 45099 | C3: MS ANGLE 90X90X8 MM | D3: KEC INTERNATIONAL LIMITED,(JABALPUR) | E3: 0.655 | F3: MH49AT4594 | G3: 288/76 | H3: LOI-339 | I3: 45092
A4: VIL/DC/23-24/308 | B4: 45099 | C4: MS ANGLE 70X70X5 MM | D4: KEC INTERNATIONAL LIMITED,(JABALPUR) | E4: 2.356 | F4: MH49AT4594 | G4: 288/76 | H4: LOI-341 | I4: 45092
A5: VIL/DC/23-24/308 | B5: 45099 | C5: MS ANGLE 75X75X5 MM | D5: KEC INTERNATIONAL LIMITED,(JABALPUR) | E5: 2.358 | F5: MH49AT4594 | G5: 288/76 | H5: LOI-341 | I5: 45092
A6: VIL/DC/23-24/308 | B6: 45099 | C6: MS ANGLE 75X75X6 MM | D6: KEC INTERNATIONAL LIMITED,(JABALPUR) | E6: 2.792 | F6: MH49AT4594 | G6: 288/76 | H6: LOI-341 | I6: 45092
E7: =SUM(E2:E6) -> 17.305
A8: VIL/DC/23-24/394 | B8: 45108 | C8: MS ANGLE 100X100X8 MM | D8: KEC INTERNATIONAL LIMITED,(JABALPUR) | E8: 0.895 | F8: MH04FD6732 | G8: 368/76 | H8: LOI-341 | I8: 45092
E9: =SUM(E8) -> 0.895
A10: VIL/DC/23-24/398 | B10: 45109 | C10: MS ANGLE 100X100X7 MM | D10: KEC INTERNATIONAL LIMITED,(JABALPUR) | E10: 1.03 | F10: MH40AK4183 | G10: 371/76 | H10: LOI-388 | I10: 45095
A11: VIL/DC/23-24/399 | B11: 45109 | C11: MS ANGLE 100X100X7 MM | D11: KEC INTERNATIONAL LIMITED,(JABALPUR) | E11: 0.773 | F11: MH40AK4183 | G11: 371/76 | H11: LOI-341 | I11: 45092
A12: VIL/DC/23-24/400 | B12: 45109 | C12: MS ANGLE 100X100X7 MM | D12: KEC INTERNATIONAL LIMITED,(JABALPUR) | E12: 1.156 | F12: MH40AK4183 | G12: 371/76 | H12: LOI-389 | I12: 45095
A13: VIL/DC/23-24/401 | B13: 45109 | C13: MS ANGLE 75X75X8 MM | D13: KEC INTERNATIONAL LIMITED,(JABALPUR) | E13: =3.762+18.882 -> 22.644 | F13: MH40AK4183 | G13: 371/76, 372/77 | H13: LOI-339 | I13: 45092
A14: VIL/DC/23-24/406 | B14: 45109 | C14: MS ANGLE 75X75X8 MM | D14: KEC INTERNATIONAL LIMITED,(JABALPUR) | E14: 29.556 | F14: MH40AK6075 | G14: 377/76, 372/77 | H14: LOI-339 | I14: 45092
E15: =SUM(E10:E14) -> 55.159
A16: VIL/DC/23-24/409 | B16: 45110 | C16: MS ANGLE 100X100X8 MM | D16: KEC INTERNATIONAL LIMITED,(JABALPUR) | E16: 1.72 | F16: MH49AT0403 | G16: 381/ 78 | H16: LOI-389 | I16: 45095
A17: VIL/DC/23-24/410 | B17: 45110 | C17: MS ANGLE 75X75X8 MM | D17: KEC INTERNATIONAL LIMITED,(JABALPUR) | E17: 1.728 | F17: MH49AT0403 | G17: 381/ 78, 382/79 | H17: LOI-339 | I17: 45092
A18: VIL/DC/23-24/410 | B18: 45110 | C18: MS ANGLE 80X80X8 MM | D18: KEC INTERNATIONAL LIMITED,(JABALPUR) | E18: =3.826+21.123 -> 24.949 | F18: MH49AT0403 | G18: 381/ 78, 382/79 | H18: LOI-339 | I18: 45092
E19: =SUM(E16:E18) -> 28.397
A20: VIL/DC/23-24/420 | B20: 45112 | C20: MS ANGLE 75X75X8 MM | D20: KEC INTERNATIONAL LIMITED,(JABALPUR) | E20: 0.824 | F20: MH40AK1958 | G20: 395/79 | H20: LOI-340 | I20: 45092
A21: VIL/DC/23-24/421 | B21: 45112 | C21: MS ANGLE 90X90X8 MM | D21: KEC INTERNATIONAL LIMITED,(JABALPUR) | E21: 2.408 | F21: MH40AK1958 | G21: 395/79 | H21: LOI-339 | I21: 45092
A22: VIL/DC/23-24/422 | B22: 45112 | C22: MS ANGLE 90X90X6 MM | D22: KEC INTERNATIONAL LIMITED,(JABALPUR) | E22: 2.957 | F22: MH40AK1958 | G22: 395/79 | H22: LOI-341 | I22: 45092
A23: VIL/DC/23-24/422 | B23: 45112 | C23: MS ANGLE 75X75X5 MM | D23: KEC INTERNATIONAL LIMITED,(JABALPUR) | E23: 0.554 | F23: MH40AK1958 | G23: 395/79 | H23: LOI-341 | I23: 45092
E24: =SUM(E20:E23) -> 6.743
A25: VIL/DC/23-24/454 | B25: 45117 | C25: MS ANGLE 75X75X8 MM | D25: KEC INTERNATIONAL LIMITED,(JABALPUR) | E25: 1.404 | F25: MH40N7379 | G25: 423/79 | H25: LOI-339 | I25: 45092
A26: VIL/DC/23-24/455 | B26: 45117 | C26: MS ANGLE 75X75X6 MM | D26: KEC INTERNATIONAL LIMITED,(JABALPUR) | E26: 0.165 | F26: MH40N7379 | G26: 423/79 | H26: LOI-340 | I26: 45092
E27: =SUM(E25:E26) -> 1.569
D39: JULY -23 Total Dispatched | E39: =SUM(E8:E38)/2 -> 92.763
D41: JUN -23 Dispatched Shift qty | E41: =+E7 -> 17.305
E43: =+E41+E39 -> 110.068

Sheet KEC JBP TRADING DISPATCHED JULY
A1: Invoice No. | B1: Invoice Dt | C1: Section | D1: PNAME | E1: QTYISSUED | F1: VEHICLE No. | G1: Po. No | H1: PORDERDATE | I1: RATE
A2: BB/23-24/0039 | B2: 45108 | C2: MS ANGLE 100X100X6 MM | D2: KEC INTERNATIONAL LTD.,JABALPUR | E2: 6.112 | F2: MH04FD6732 | G2: LOI-389 | H2: 45095 | I2: 72230
A3: BB/23-24/0040 | B3: 45108 | C3: HT ANGLE 90X90X7 MM | D3: KEC INTERNATIONAL LTD.,JABALPUR | E3: 6.458 | F3: MH04FD6732 | G3: LOI-388 | H3: 45095 | I3: 75670
A4: BB/23-24/0040 | B4: 45108 | C4: HT ANGLE 110X110X7 MM | D4: KEC INTERNATIONAL LTD.,JABALPUR | E4: 2.407 | F4: MH04FD6732 | G4: LOI-388 | H4: 45095 | I4: 51120
A5: BB/23-24/0040 | B5: 45108 | C5: HT ANGLE 100X100X6 MM | D5: KEC INTERNATIONAL LTD.,JABALPUR | E5: 3.556 | F5: MH04FD6732 | G5: LOI-388 | H5: 45095 | I5: 75670
A6: BB/23-24/0040 | B6: 45108 | C6: HT ANGLE 100X100X7 MM | D6: KEC INTERNATIONAL LTD.,JABALPUR | E6: 2.575 | F6: MH04FD6732 | G6: LOI-388 | H6: 45095 | I6: 75670
A7: BB/23-24/0040 | B7: 45108 | C7: HT ANGLE 90X90X6 MM | D7: KEC INTERNATIONAL LTD.,JABALPUR | E7: 5.791 | F7: MH04FD6732 | G7: LOI-388 | H7: 45095 | I7: 75670
A8: BB/23-24/0041 | B8: 45108 | C8: HT ANGLE 110X110X10 MM | D8: KEC INTERNATIONAL LTD.,JABALPUR | E8: 2.388 | F8: MH04FD6732 | G8: LOI-341 | H8: 45095 | I8: 51120
A9: BB/23-24/0041 | B9: 45108 | C9: HT ANGLE 90X90X6 MM | D9: KEC INTERNATIONAL LTD.,JABALPUR | E9: 0.765 | F9: MH04FD6732 | G9: LOI-341 | H9: 45095 | I9: 75670
A10: BB/23-24/0041 | B10: 45108 | C10: HT ANGLE 75X75X6 MM | D10: KEC INTERNATIONAL LTD.,JABALPUR | E10: 1.262 | F10: MH04FD6732 | G10: LOI-341 | H10: 45095 | I10: 75670
A11: BB/23-24/0041 | B11: 45108 | C11: HT ANGLE 100X100X8 MM | D11: KEC INTERNATIONAL LTD.,JABALPUR | E11: 0.579 | F11: MH04FD6732 | G11: LOI-341 | H11: 45095 | I11: 75670
E12: =SUM(E2:E11) -> 31.893
A13: BB/23-24/0042 | B13: 45109 | C13: HT ANGLE 100X100X7 MM | D13: KEC INTERNATIONAL LTD.,JABALPUR | E13: 1.03 | F13: MH40AK4183 | G13: LOI-388 | H13: 45095 | I13: 75670
A14: BB/23-24/0042 | B14: 45109 | C14: HT ANGLE 100X100X8 MM | D14: KEC INTERNATIONAL LTD.,JABALPUR | E14: 1.462 | F14: MH40AK4183 | G14: LOI-388 | H14: 45095 | I14: 75670
A15: BB/23-24/0042 | B15: 45109 | C15: HT ANGLE 110X110X7 MM | D15: KEC INTERNATIONAL LTD.,JABALPUR | E15: 1.989 | F15: MH40AK4183 | G15: LOI-388 | H15: 45095 | I15: 51120
A16: BB/23-24/0043 | B16: 45109 | C16: HT ANGLE 100X100X8 MM | D16: KEC INTERNATIONAL LTD.,JABALPUR | E16: 0.463 | F16: MH40AK4183 | G16: LOI-341 | H16: 45095 | I16: 75670
A17: BB/23-24/0043 | B17: 45109 | C17: HT ANGLE 75X75X6 MM | D17: KEC INTERNATIONAL LTD.,JABALPUR | E17: 0.412 | F17: MH40AK4183 | G17: LOI-341 | H17: 45095 | I17: 75670
A18: BB/23-24/0043 | B18: 45109 | C18: HT ANGLE 70X70X5 MM | D18: KEC INTERNATIONAL LTD.,JABALPUR | E18: 0.46 | F18: MH40AK4183 | G18: LOI-341 | H18: 45095 | I18: 57090
A19: BB/23-24/0043 | B19: 45109 | C19: HT ANGLE 70X70X6 MM | D19: KEC INTERNATIONAL LTD.,JABALPUR | E19: 0.227 | F19: MH40AK4183 | G19: LOI-341 | H19: 45095 | I19: 57090
A20: BB/23-24/0043 | B20: 45109 | C20: HT ANGLE 100X100X7 MM | D20: KEC INTERNATIONAL LTD.,JABALPUR | E20: 0.949 | F20: MH40AK4183 | G20: LOI-341 | H20: 45095 | I20: 75670
A21: BB/23-24/0045 | B21: 45109 | C21: MS ANGLE 90X90X6 MM | D21: KEC INTERNATIONAL LTD.,JABALPUR | E21: 2.988 | F21: MH40AK6075 | G21: LOI-389 | H21: 45095 | I21: 72230
E22: =SUM(E13:E21) -> 9.98
A23: BB/23-24/0046 | B23: 45110 | C23: MS ANGLE 90X90X5 MM | D23: KEC INTERNATIONAL LTD.,JABALPUR | E23: 1.673 | F23: MH49AT0403 | G23: LOI-388 | H23: 45095 | I23: 72230
A24: BB/23-24/0047 | B24: 45110 | C24: MS ANGLE 90X90X6 MM | D24: KEC INTERNATIONAL LTD.,JABALPUR | E24: 2.49 | F24: MH49AT0403 | G24: LOI-389 | H24: 45095 | I24: 72230
E25: =SUM(E23:E24) -> 4.163
A26: BB/23-24/0051 | B26: 45112 | C26: HT ANGLE 120X120X10 MM | D26: KEC INTERNATIONAL LTD.,JABALPUR | E26: 1.525 | F26: MH40AK1958 | G26: LOI-341 | H26: 45095 | I26: 51120
A27: BB/23-24/0051 | B27: 45112 | C27: HT ANGLE 120X120X8 MM | D27: KEC INTERNATIONAL LTD.,JABALPUR | E27: 0.513 | F27: MH40AK1958 | G27: LOI-341 | H27: 45095 | I27: 51120
A28: BB/23-24/0051 | B28: 45112 | C28: HT ANGLE 130X130X10 MM | D28: KEC INTERNATIONAL LTD.,JABALPUR | E28: 1.088 | F28: MH40AK1958 | G28: LOI-341 | H28: 45095 | I28: 51120
A29: BB/23-24/0051 | B29: 45112 | C29: HT ANGLE 80X80X6 MM | D29: KEC INTERNATIONAL LTD.,JABALPUR | E29: 1.409 | F29: MH40AK1958 | G29: LOI-341 | H29: 45095 | I29: 57340
A30: BB/23-24/0052 | B30: 45112 | C30: HT ANGLE 110X110X8 MM | D30: KEC INTERNATIONAL LTD.,JABALPUR | E30: 3.419 | F30: MH40AK1958 | G30: LOI-388 | H30: 45095 | I30: 51120
A31: BB/23-24/0052 | B31: 45112 | C31: HT ANGLE 120X120X8 MM | D31: KEC INTERNATIONAL LTD.,JABALPUR | E31: 1.407 | F31: MH40AK1958 | G31: LOI-388 | H31: 45095 | I31: 51120
A32: BB/23-24/0052 | B32: 45112 | C32: HT ANGLE 120X120X9 MM | D32: KEC INTERNATIONAL LTD.,JABALPUR | E32: 3.564 | F32: MH40AK1958 | G32: LOI-388 | H32: 45095 | I32: 51120
A33: BB/23-24/0052 | B33: 45112 | C33: HT ANGLE 80X80X5 MM | D33: KEC INTERNATIONAL LTD.,JABALPUR | E33: 3.258 | F33: MH40AK1958 | G33: LOI-388 | H33: 45095 | I33: 75670
A34: BB/23-24/0052 | B34: 45112 | C34: HT ANGLE 80X80X6 MM | D34: KEC INTERNATIONAL LTD.,JABALPUR | E34: 6.182 | F34: MH40AK1958 | G34: LOI-388 | H34: 45095 | I34: 75670
A35: BB/23-24/0052 | B35: 45112 | C35: HT ANGLE 90X90X5 MM | D35: KEC INTERNATIONAL LTD.,JABALPUR | E35: 2.994 | F35: MH40AK1958 | G35: LOI-388 | H35: 45095 | I35: 75670
E36: =SUM(E26:E35) -> 25.359
A37: BB/23-24/0053 | B37: 45113 | C37: MS ANGLE 80X80X6 MM | D37: KEC INTERNATIONAL LTD.,JABALPUR | E37: 3.699 | F37: MH49AT1947 | G37: LOI-434 | H37: 45106 | I37: 59920
A38: BB/23-24/0054 | B38: 45113 | C38: MS ANGLE 80X80X6 MM | D38: KEC INTERNATIONAL LTD.,JABALPUR | E38: 0.747 | F38: MH49AT1947 | G38: LOI-435 | H38: 45106 | I38: 59920
A39: BB/23-24/0054 | B39: 45113 | C39: HT ANGLE 80X80X5 MM | D39: KEC INTERNATIONAL LTD.,JABALPUR | E39: 4.241 | F39: MH49AT1947 | G39: LOI-435 | H39: 45106 | I39: 75670
A40: BB/23-24/0056 | B40: 45113 | C40: MS ANGLE 75X75X6 MM | D40: KEC INTERNATIONAL LTD.,JABALPUR | E40: 1.973 | F40: MH49AT1947 | G40: LOI-439 | H40: 45109 | I40: 59920
...

Sheet KEC BB DISPATCHED AUG
A1: Invoice No. | B1: Invoice Dt | C1: Section | D1: PNAME | E1: QTY ISSUED | F1: VEHICLE No. | G1: Jobwork Challan No. | H1: Po. No | I1: PO ORDER DATE
A2: VIL/DC/23-24/589 | B2: 45136 | C2: HT ANGLE 130X130X10 MM | D2: KEC INTERNATIONAL LIMITED,(BUTIBORI) | E2: =7.63+7.147 -> 14.777 | F2: MH40Y3944 | G2: 516/171, 517/172 | H2: LOI-497 | I2: 45111
A3: VIL/DC/23-24/590 | B3: 45136 | C3: HT ANGLE 130X130X10 MM | D3: KEC INTERNATIONAL LIMITED,(BUTIBORI) | E3: =9.72+7.137 -> 16.857 | F3: MH40Y3944 | G3: 517/172, 518/173 | H3: LOI-498 | I3: 45111
A4: VIL/DC/23-24/591 | B4: 45136 | C4: HT ANGLE 130X130X8 MM | D4: KEC INTERNATIONAL LIMITED,(BUTIBORI) | E4: 12.41 | F4: MH40AK5144 | G4: 519/174 | H4: LOI-497 | I4: 45111
A5: VIL/DC/23-24/591 | B5: 45136 | C5: HT ANGLE 130X130X9 MM | D5: KEC INTERNATIONAL LIMITED,(BUTIBORI) | E5: 7.756 | F5: MH40AK5144 | G5: 519/174 | H5: LOI-497 | I5: 45111
A6: VIL/DC/23-24/592 | B6: 45136 | C6: HT ANGLE 130X130X8 MM | D6: KEC INTERNATIONAL LIMITED,(BUTIBORI) | E6: 3 | F6: MH40AK5144 | G6: 519/174 | H6: LOI-498 | I6: 45111
A7: VIL/DC/23-24/592 | B7: 45136 | C7: HT ANGLE 130X130X9 MM | D7: KEC INTERNATIONAL LIMITED,(BUTIBORI) | E7: 5.514 | F7: MH40AK5144 | G7: 519/174 | H7: LOI-498 | I7: 45111
A8: VIL/DC/23-24/593 | B8: 45136 | C8: HT ANGLE 120X120X8 MM | D8: KEC INTERNATIONAL LIMITED,(BUTIBORI) | E8: 2.559 | F8: MH40AK5144 | G8: 519/174 | H8: LOI-494 | I8: 45111
E9: =SUM(E2:E8) -> 62.873
A10: VIL/DC/23-24/594 | B10: 45137 | C10: HT ANGLE 130X130X10 MM | D10: KEC INTERNATIONAL LIMITED,(BUTIBORI) | E10: =5.504+1.384 -> 6.888 | F10: MH40AK5044 | G10: 520/173, 521/174 | H10: LOI-497 | I10: 45111
A11: VIL/DC/23-24/595 | B11: 45137 | C11: HT ANGLE 130X130X10 MM | D11: KEC INTERNATIONAL LIMITED,(BUTIBORI) | E11: =4.941+1.003 -> 5.944 | F11: MH40AK5044 | G11: 521/174, 522/175 | H11: LOI-498 | I11: 45111
A12: VIL/DC/23-24/596 | B12: 45137 | C12: HT ANGLE 150X150X18 MM | D12: KEC INTERNATIONAL LIMITED,(BUTIBORI) | E12: =1.104+10.534+6.399 -> 18.037 | F12: MH40AK5044 | G12: 522/175, 523/176, 524/177 | H12: LOI-494 | I12: 45111
A13: VIL/DC/23-24/597 | B13: 45137 | C13: HT ANGLE 150X150X18 MM | D13: KEC INTERNATIONAL LIMITED,(BUTIBORI) | E13: =6.242+23.48 -> 29.722 | F13: MH40Y3944 | G13: 525/177, 526/178 | H13: LOI-494 | I13: 45111
A14: VIL/DC/23-24/598 | B14: 45137 | C14: HT ANGLE 150X150X18 MM | D14: KEC INTERNATIONAL LIMITED,(BUTIBORI) | E14: =1.332+0.256 -> 1.588 | F14: MH40Y3944 | G14: 526/178, 527/179 | H14: LOI-495 | I14: 45111
A15: VIL/DC/23-24/599 | B15: 45137 | C15: HT ANGLE 150X150X18 MM | D15: KEC INTERNATIONAL LIMITED,(BUTIBORI) | E15: =12.059+12.641+0.236 -> 24.936 | F15: MH40Y4944 | G15: 528/179, 529/180, 530/181 | H15: LOI-494 | I15: 45111
A16: VIL/DC/23-24/600 | B16: 45137 | C16: HT ANGLE 150X150X18 MM | D16: KEC INTERNATIONAL LIMITED,(BUTIBORI) | E16: 3.176 | F16: MH40Y4944 | G16: 530/181 | H16: LOI-495 | I16: 45111
A17: VIL/DC/23-24/601 | B17: 45137 | C17: HT ANGLE 150X150X20 MM | D17: KEC INTERNATIONAL LIMITED,(BUTIBORI) | E17: 3.757 | F17: MH40Y4944 | G17: 530/181 | H17: LOI-498 | I17: 45111
E18: =SUM(E10:E17) -> 94.048
A19: VIL/DC/23-24/602 | B19: 45138 | C19: HT ANGLE 150X150X18 MM | D19: KEC INTERNATIONAL LIMITED,(BUTIBORI) | E19: =3.365+2.107+12.641+0.51 -> 18.623 | F19: MH40Y3944 | G19: 531/181, 532/182, 533/183, 534/184 | H19: LOI-494 | I19: 45111
A20: VIL/DC/23-24/603 | B20: 45138 | C20: HT ANGLE 150X150X18 MM | D20: KEC INTERNATIONAL LIMITED,(BUTIBORI) | E20: 5.125 | F20: MH40Y3944 | G20: 534/184 | H20: LOI-495 | I20: 45111
A21: VIL/DC/23-24/604 | B21: 45138 | C21: HT ANGLE 150X150X18 MM | D21: KEC INTERNATIONAL LIMITED,(BUTIBORI) | E21: 2.647 | F21: MH40Y3944 | G21: 534/184 | H21: LOI-497 | I21: 45111
A22: VIL/DC/23-24/605 | B22: 45138 | C22: HT ANGLE 150X150X18 MM | D22: KEC INTERNATIONAL LIMITED,(BUTIBORI) | E22: 1.973 | F22: MH40Y3944 | G22: 534/184 | H22: LOI-500 | I22: 45111
A23: VIL/DC/23-24/606 | B23: 45138 | C23: HT ANGLE 150X150X18 MM | D23: KEC INTERNATIONAL LIMITED,(BUTIBORI) | E23: 3.617 | F23: MH40Y3944 | G23: 534/184 | H23: LOI-498 | I23: 45111
A24: VIL/DC/23-24/607 | B24: 45138 | C24: HT ANGLE 150X150X15 MM | D24: KEC INTERNATIONAL LIMITED,(BUTIBORI) | E24: 31.93 | F24: MH40Y2044 | G24: 535/184, 536/185, 537/186 | H24: LOI-498 | I24: 45111
E25: =SUM(E19:E24) -> 63.915
A26: VIL/DC/23-24/608 | B26: 45139 | C26: HT ANGLE 150X150X15 MM | D26: KEC INTERNATIONAL LIMITED,(BUTIBORI) | E26: 3.596 | F26: MH40Y3944 | G26: 538/186 | H26: LOI-497 | I26: 45111
A27: VIL/DC/23-24/609 | B27: 45139 | C27: HT ANGLE 150X150X15 MM | D27: KEC INTERNATIONAL LIMITED,(BUTIBORI) | E27: =0.42+6.824 -> 7.244 | F27: MH40Y3944 | G27: 538/186, 539/187 | H27: LOI-495 | I27: 45111
A28: VIL/DC/23-24/610 | B28: 45139 | C28: HT ANGLE 150X150X15 MM | D28: KEC INTERNATIONAL LIMITED,(BUTIBORI) | E28: =5.817+12.654+3.332 -> 21.803 | F28: MH40Y3944 | G28: 539/187, 540/188, 541/189 | H28: LOI-498 | I28: 45111
A29: VIL/DC/23-24/611 | B29: 45139 | C29: HT ANGLE 150X150X15 MM | D29: KEC INTERNATIONAL LIMITED,(DUBAI) | E29: =8.906+12.628+3.344 -> 24.878 | F29: MH31FC2623 | G29: 542/189, 543/190, 544/191 | H29: LOI-193 | I29: 45064
A30: VIL/DC/23-24/612 | B30: 45139 | C30: HT ANGLE 150X150X14 MM | D30: KEC INTERNATIONAL LIMITED,(BUTIBORI) | E30: =6.211+2.561 -> 8.772 | F30: MH40Y4944 | G30: 545/ 200, 546/205 | H30: LOI-498 | I30: 45111
A31: VIL/DC/23-24/612 | B31: 45139 | C31: HT ANGLE 150X150X15 MM | D31: KEC INTERNATIONAL LIMITED,(BUTIBORI) | E31: 7.261 | F31: MH40Y4944 | G31: 545/ 200, 546/205 | H31: LOI-498 | I31: 45111
A32: VIL/DC/23-24/612 | B32: 45139 | C32: HT ANGLE 130X130X11 MM | D32: KEC INTERNATIONAL LIMITED,(BUTIBORI) | E32: 2.083 | F32: MH40Y4944 | G32: 545/ 200, 546/205 | H32: LOI-498 | I32: 45111
A33: VIL/DC/23-24/613 | B33: 45139 | C33: HT ANGLE 150X150X14 MM | D33: KEC INTERNATIONAL LIMITED,(BUTIBORI) | E33: 4.595 | F33: MH40Y4944 | G33: 546/205 | H33: LOI-497 | I33: 45111
A34: VIL/DC/23-24/613 | B34: 45139 | C34: HT ANGLE 130X130X11 MM | D34: KEC INTERNATIONAL LIMITED,(BUTIBORI) | E34: 3.431 | F34: MH40Y4944 | G34: 546/205 | H34: LOI-497 | I34: 45111
A35: VIL/DC/23-24/614 | B35: 45139 | C35: HT ANGLE 150X150X15 MM | D35: KEC INTERNATIONAL LIMITED,(BUTIBORI) | E35: 5.577 | F35: MH40Y4944 | G35: 546/205 | H35: LOI-495 | I35: 45111
A36: VIL/DC/23-24/615 | B36: 45139 | C36: HT ANGLE 150X150X15 MM | D36: KEC INTERNATIONAL LIMITED,(DUBAI) | E36: 19.436 | F36: MH31FC2622 | G36: 547/206 | H36: LOI-193 | I36: 45064
A37: VIL/DC/23-24/616 | B37: 45139 | C37: HT ANGLE 150X150X15 MM | D37: KEC INTERNATIONAL LIMITED,(DUBAI) | E37: 5.779 | F37: MH31FC2622 | G37: 547/206 | H37: LOI-553 | I37: 45125
A38: VIL/DC/23-24/617 | B38: 45139 | C38: HT ANGLE 150X150X14 MM | D38: KEC INTERNATIONAL LIMITED,(BUTIBORI) | E38: 24.581 | F38: MH40Y3944 | G38: 548/191 | H38: LOI-497 | I38: 45111
A39: VIL/DC/23-24/618 | B39: 45139 | C39: HT ANGLE 150X150X14 MM | D39: KEC INTERNATIONAL LIMITED,(BUTIBORI) | E39: 6.831 | F39: MH40Y3944 | G39: 548/191 | H39: LOI-498 | I39: 45111
E40: =SUM(E26:E39) -> 145.867
...

Sheet KEC JBP DISPATCHED AUG
A1: Invoice No. | B1: Invoice Dt | C1: Section | D1: PNAME | E1: QTY ISSUED | F1: VEHICLE No. | G1: Jobwork Challan No. | H1: Po. No | I1: PO ORDER DATE
A2: VIL/DC/23-24/769 | B2: 45155 | C2: HT ANGLE 120X120X7 MM | D2: KEC INTERNATIONAL LIMITED,(JABALPUR) | E2: 2.167 | F2: MH40BG0308 | G2: 679/ 69 | H2: LOI-570 | I2: 45135
A3: VIL/DC/23-24/769 | B3: 45155 | C3: HT ANGLE 130X130X9 MM | D3: KEC INTERNATIONAL LIMITED,(JABALPUR) | E3: 0.629 | F3: MH40BG0308 | G3: 679/ 69 | H3: LOI-570 | I3: 45135
A4: VIL/DC/23-24/769 | B4: 45155 | C4: HT ANGLE 75X75X6 MM | D4: KEC INTERNATIONAL LIMITED,(JABALPUR) | E4: 0.494 | F4: MH40BG0308 | G4: 679/ 69 | H4: LOI-570 | I4: 45135
A5: VIL/DC/23-24/769 | B5: 45155 | C5: HT ANGLE 80X80X5 MM | D5: KEC INTERNATIONAL LIMITED,(JABALPUR) | E5: 4.146 | F5: MH40BG0308 | G5: 679/ 69 | H5: LOI-570 | I5: 45135
A6: VIL/DC/23-24/769 | B6: 45155 | C6: HT ANGLE 80X80X6 MM | D6: KEC INTERNATIONAL LIMITED,(JABALPUR) | E6: 3.003 | F6: MH40BG0308 | G6: 679/ 69 | H6: LOI-570 | I6: 45135
A7: VIL/DC/23-24/769 | B7: 45155 | C7: HT ANGLE 90X90X6 MM | D7: KEC INTERNATIONAL LIMITED,(JABALPUR) | E7: 5.391 | F7: MH40BG0308 | G7: 679/ 69 | H7: LOI-570 | I7: 45135
A8: VIL/DC/23-24/769 | B8: 45155 | C8: HT ANGLE 90X90X7 MM | D8: KEC INTERNATIONAL LIMITED,(JABALPUR) | E8: 1.845 | F8: MH40BG0308 | G8: 679/ 69 | H8: LOI-570 | I8: 45135
A9: VIL/DC/23-24/769 | B9: 45155 | C9: MS ANGLE 120X120X7 MM | D9: KEC INTERNATIONAL LIMITED,(JABALPUR) | E9: 0.774 | F9: MH40BG0308 | G9: 679/ 69 | H9: LOI-570 | I9: 45135
A10: VIL/DC/23-24/769 | B10: 45155 | C10: MS ANGLE 75X75X5 MM | D10: KEC INTERNATIONAL LIMITED,(JABALPUR) | E10: 1.108 | F10: MH40BG0308 | G10: 679/ 69 | H10: LOI-570 | I10: 45135
A11: VIL/DC/23-24/769 | B11: 45155 | C11: MS ANGLE 75X75X6 MM | D11: KEC INTERNATIONAL LIMITED,(JABALPUR) | E11: 2.305 | F11: MH40BG0308 | G11: 679/ 69 | H11: LOI-570 | I11: 45135
A12: VIL/DC/23-24/769 | B12: 45155 | C12: MS ANGLE 80X80X5 MM | D12: KEC INTERNATIONAL LIMITED,(JABALPUR) | E12: 3.116 | F12: MH40BG0308 | G12: 679/ 69 | H12: LOI-570 | I12: 45135
A13: VIL/DC/23-24/769 | B13: 45155 | C13: MS ANGLE 80X80X6 MM | D13: KEC INTERNATIONAL LIMITED,(JABALPUR) | E13: 1.766 | F13: MH40BG0308 | G13: 679/ 69 | H13: LOI-570 | I13: 45135
E14: =SUM(E2:E13) -> 26.744
A15: VIL/DC/23-24/0812 | B15: 45158 | C15: HT ANGLE 90X90X5 MM | D15: KEC INTERNATIONAL LIMITED,(JABALPUR) | E15: 13.564 | F15: MH49AT4596 | G15: 705/ 68 | H15: LOI-570 | I15: 45135
A16: VIL/DC/23-24/0812 | B16: 45158 | C16: MS ANGLE 90X90X5 MM | D16: KEC INTERNATIONAL LIMITED,(JABALPUR) | E16: 2.287 | F16: MH49AT4596 | G16: 705/ 68 | H16: LOI-570 | I16: 45135
A17: VIL/DC/23-24/0812 | B17: 45158 | C17: MS ANGLE 90X90X6 MM | D17: KEC INTERNATIONAL LIMITED,(JABALPUR) | E17: 3.794 | F17: MH49AT4596 | G17: 705/ 68 | H17: LOI-570 | I17: 45135
A18: VIL/DC/23-24/0813 | B18: 45158 | C18: MS ANGLE 90X90X6 MM | D18: KEC INTERNATIONAL LIMITED,(JABALPUR) | E18: =9.593+8.469 -> 18.062 | F18: MH49AT4596 | G18: 705/ 68, 706/70 | H18: LOI-721 | I18: 45150
A19: VIL/DC/23-24/0813 | B19: 45158 | C19: MS ANGLE 90X90X7 MM | D19: KEC INTERNATIONAL LIMITED,(JABALPUR) | E19: 1.283 | F19: MH49AT4596 | G19: 705/ 68, 706/70 | H19: LOI-721 | I19: 45150
E20: =SUM(E15:E19) -> 38.99
A21: VIL/DC/23-24/0838 | B21: 45160 | C21: HT ANGLE 130X130X11 MM | D21: KEC INTERNATIONAL LIMITED,(JABALPUR) | E21: =9.048+15.106+7.978 -> 32.132 | F21: MH49AT1950 | G21: 720/69, 721/70, 722/71 | H21: LOI-571 | I21: 45135
A22: VIL/DC/23-24/0839 | B22: 45160 | C22: HT ANGLE 130X130X11 MM | D22: KEC INTERNATIONAL LIMITED,(JABALPUR) | E22: 0.241 | F22: MH49AT1950 | G22: 722/71 | H22: LOI-569 | I22: 45135
A23: VIL/DC/23-24/0840 | B23: 45160 | C23: HT ANGLE 120X120X7 MM | D23: KEC INTERNATIONAL LIMITED,(JABALPUR) | E23: 25.845 | F23: MH40N7378 | G23: 723/71, 724/ 72 | H23: LOI-574 | I23: 45135
A24: VIL/DC/23-24/0840 | B24: 45160 | C24: HT ANGLE 120X120X8 MM | D24: KEC INTERNATIONAL LIMITED,(JABALPUR) | E24: =3.987+0.477 -> 4.464 | F24: MH40N7378 | G24: 723/71, 724/ 72 | H24: LOI-574 | I24: 45135
A25: VIL/DC/23-24/0841 | B25: 45160 | C25: HT ANGLE 120X120X7 MM | D25: KEC INTERNATIONAL LIMITED,(JABALPUR) | E25: 2.349 | F25: MH40N7378 | G25: 724/ 72 | H25: LOI-569 | I25: 45135
A26: VIL/DC/23-24/0842 | B26: 45160 | C26: HT ANGLE 130X130X9 MM | D26: KEC INTERNATIONAL LIMITED,(JABALPUR) | E26: 27.75 | F26: MH40AK6002 | G26: 725/ 72 | H26: LOI-574 | I26: 45135
A27: VIL/DC/23-24/0843 | B27: 45160 | C27: HT ANGLE 130X130X9 MM | D27: KEC INTERNATIONAL LIMITED,(JABALPUR) | E27: 1.604 | F27: MH40AK6002 | G27: 725/ 72 | H27: LOI-569 | I27: 45135
E28: =SUM(E21:E27) -> 94.385
A29: VIL/DC/23-24/0845 | B29: 45161 | C29: HT ANGLE 130X130X8 MM | D29: KEC INTERNATIONAL LIMITED,(JABALPUR) | E29: =5.87+22.651+0.115 -> 28.636 | F29: MH49AT0506 | G29: 728/ 72, 729/ 74 | H29: LOI-574 | I29: 45135
A30: VIL/DC/23-24/0846 | B30: 45161 | C30: HT ANGLE 130X130X8 MM | D30: KEC INTERNATIONAL LIMITED,(JABALPUR) | E30: 4.513 | F30: MH49AT0506 | G30: 729/ 74 | H30: LOI-569 | I30: 45135
A31: VIL/DC/23-24/0847 | B31: 45161 | C31: HT ANGLE 120X120X7 MM | D31: KEC INTERNATIONAL LIMITED,(JABALPUR) | E31: 16.718 | F31: MH40AK6074 | G31: 731/ 73, 732/74, | H31: LOI-574 | I31: 45135
A32: VIL/DC/23-24/0849 | B32: 45161 | C32: HT ANGLE 120X120X7 MM | D32: KEC INTERNATIONAL LIMITED,(JABALPUR) | E32: =8.122+1.338 -> 9.46 | F32: MH40AK6074 | G32: 732/74, 733/ 75 | H32: LOI-569 | I32: 45135
A33: VIL/DC/23-24/0849 | B33: 45161 | C33: HT ANGLE 120X120X8 MM | D33: KEC INTERNATIONAL LIMITED,(JABALPUR) | E33: =0.791+5.634 -> 6.425 | F33: MH40AK6074 | G33: 732/74, 733/ 75 | H33: LOI-569 | I33: 45135
A34: VIL/DC/23-24/0851 | B34: 45161 | C34: HT ANGLE 130X130X9 MM | D34: KEC INTERNATIONAL LIMITED,(JABALPUR) | E34: 8.732 | F34: MH49AT0509 | G34: 736/75 | H34: LOI-569 | I34: 45135
A35: VIL/DC/23-24/0852 | B35: 45161 | C35: HT ANGLE 130X130X9 MM | D35: KEC INTERNATIONAL LIMITED,(JABALPUR) | E35: 9.997 | F35: MH49AT0509 | G35: 736/75 | H35: LOI-574 | I35: 45135
