Workbook

Sheet 3048 01.01.24 JBP
A1: VINAR ISPAT LIMTED
A2: PLOT NO J 3,MIDC INDUSTRIAL AREA, BUTIBORI
K3: DOC.NO.VIL/PLN/F/05
A4: PACKING LIST
D6: LR- 27579
B8: CUSTOMER | C8: KEC INTERNATIONAL LTD. JABALPUR | J8: Date: | K8: 01.01.24
B10: CUSTOMER | C10: KEC INTERNATIONAL LTD. JABALPUR | J10: Lorry No. | K10: MH49AT3048
A12: Sr. No. | B12: P.O.No. | C12: Grade | D12: Colour Code | E12: Grade/Section | F12: Section WT. | G12: Length in mtr. | H12: No. Of Pcs | I12: Qty. in MT. | J12: HEAT NO | K12: Challan Qty. | L12: Challan No.
A13: 1 | B13: LOI-1228 | C13: HT PG | D13: Yellow-Yellow | E13: HAE350A 130X130X9 | F13: 17.82 | G13: 10.3 | H13: 12 | I13: 2.203 | K13: =+I16 -> 20.734 | L13: 1774/ 377 | N13: 12 | O13: 2.202552
F14: 17.82 | G14: 11.8 | H14: 48 | I14: 10.093 | N14: 48 | O14: 10.093248
F15: 17.82 | G15: 12 | H15: 40 | I15: 8.438 | N15: 48 | O15: 10.26432
H16: =SUM(H13:H15) -> 100 | I16: =SUM(I13:I15) -> 20.734 | N16: 108 | O16: 22.56012
F17: 17.82 | G17: 12 | H17: =48-40 -> 8 | I17: =10.264-8.438 -> 1.826 | K17: =+I18+I20+I24 -> 12.043 | L17: 1775/ 378
H18: =SUM(H17) -> 8 | I18: =SUM(I17) -> 1.826
A19: 2 | B19: LOI-1229 | C19: HT PG | D19: Yellow-Yellow | E19: HAE350A 120X120X10 | F19: 18.15 | G19: 12 | H19: 39 | I19: 8.494 | N19: 39 | O19: 8.4942
H20: =SUM(H19:H19) -> 39 | I20: =SUM(I19:I19) -> 8.494 | N20: 39 | O20: 8.4942
A21: 3 | B21: LOI-1134 | C21: MS NPG | D21: Green-Pink | E21: MAE250A 90X90X8 | F21: 10.92 | G21: 10.1 | H21: 3 | I21: 0.331 | N21: 3 | O21: 0.330876
F22: 10.92 | G22: 10.5 | H22: 3 | I22: 0.344 | N22: 3 | O22: 0.34398
F23: 10.92 | G23: 12 | H23: 8 | I23: 1.048 | N23: 8 | O23: 1.04832
H24: =SUM(H21:H23) -> 14 | I24: =SUM(I21:I23) -> 1.723 | N24: 14 | O24: 1.723176
H25: =SUM(H24,H20,H18,H16) -> 161 | I25: =SUM(I24,I20,I18,I16) -> 32.777 | N25: 161 | O25: 32.777496
E29: Total | H29: =SUM(H25) -> 161 | I29: =SUM(I25) -> 32.777 | K29: =+K13+K17 -> 32.777 | N29: 161 | O29: 32.777496
B30: Receiver | E30: CHECKED & VERIFIED BY | I30: FOR VINAR ISPAT LTD,
B33: Signature | E33: Dispatch/Quality Incharge | I33: Authorised Signatory
I42: =F42*G42*H42/1000 -> 0 | K42: =+I29+'[1]9844 29.12.23 BB '!I39+'[1]2190 29.12.23 JBP '!K31+'[1]0403 29.12.23 JBP (2)'!I23+'[1]0406 29.12.23 JBP'!I28 -> 161.80162

Sheet 0308 01.01.24 JBP
A1: VINAR ISPAT LIMTED
A2: PLOT NO J 3,MIDC INDUSTRIAL AREA, BUTIBORI
K3: DOC.NO.VIL/PLN/F/05
A4: PACKING LIST
D6: LR- 27573
B8: CUSTOMER | C8: KEC INTERNATIONAL LTD. JABALPUR | K8: 01.01.24
B10: CUSTOMER | C10: KEC INTERNATIONAL LTD. JABALPUR | J10: Lorry No. | K10: MH40BG0308
A12: Sr. No. | B12: P.O.No. | C12: Grade | D12: Colour Code | E12: Grade/Section | F12: Section WT. | G12: Length in mtr. | H12: No. Of Pcs | I12: Qty. in MT. | J12: HEAT NO | K12: Challan Qty. | L12: Challan No.
A13: 1 | B13: LOI-1340 | C13: HT NPG | D13: Yellow-Pink | E13: HAE350A 110X110X8 | F13: 13.4 | G13: 10 | H13: 7 | I13: 0.938 | K13: =+I15+I18+I23+I27+I29+I34+I36 -> 19.092 | L13: 1776/ 378 | N13: 7 | O13: 0.938
F14: 13.4 | G14: 12 | H14: 8 | I14: 1.286 | N14: 8 | O14: 1.2864
H15: =SUM(H13:H14) -> 15 | I15: =SUM(I13:I14) -> 2.224 | N15: 15 | O15: 2.2244
A16: 2 | B16: LOI-1340 | C16: HT NPG | D16: Yellow-Pink | E16: HAE350A 90X90X6 | F16: 8.32 | G16: 10 | H16: 11 | I16: 0.915 | N16: 11 | O16: 0.9152
F17: 8.32 | G17: 12 | H17: 6 | I17: 0.599 | N17: 6 | O17: 0.59904
H18: =SUM(H16:H17) -> 17 | I18: =SUM(I16:I17) -> 1.514 | N18: 17 | O18: 1.51424
A19: 3 | B19: LOI-1340 | C19: HT NPG | D19: Yellow-Pink | E19: HAE350A 90X90X7 | F19: 9.61 | G19: 7 | H19: 2 | I19: 0.135 | N19: 2 | O19: 0.13454
F20: 9.61 | G20: 7.05 | H20: 6 | I20: 0.407 | N20: 6 | O20: 0.406503
F21: 9.61 | G21: 10 | H21: 9 | I21: 0.865 | N21: 9 | O21: 0.8649
F22: 9.61 | G22: 12 | H22: 11 | I22: 1.269 | N22: 11 | O22: 1.26852
H23: =SUM(H19:H22) -> 28 | I23: =SUM(I19:I22) -> 2.676 | N23: 28 | O23: 2.674463
A24: 4 | B24: LOI-1228 | C24: MS PG | D24: Green-Green | E24: MAE250A 75X75X5 | F24: 5.77 | G24: 12 | H24: 24 | I24: 1.662 | N24: 24 | O24: 1.66176
F25: 5.77 | G25: 10.5 | H25: 13 | I25: 0.788 | N25: 13 | O25: 0.787605
F26: 5.77 | G26: 11 | H26: 24 | I26: 1.523 | N26: 24 | O26: 1.52328
H27: =SUM(H24:H26) -> 61 | I27: =SUM(I24:I26) -> 3.973 | N27: 61 | O27: 3.972645
A28: 5 | B28: LOI-1228 | C28: MS PG | D28: Green-Green | E28: MAE250A 100X100X6 | F28: 9.26 | G28: 10.2 | H28: 5 | I28: 0.472 | N28: 5 | O28: 0.47226
H29: =SUM(H28) -> 5 | I29: =SUM(I28) -> 0.472 | N29: 5 | O29: 0.47226
A30: 6 | B30: LOI-1229 | C30: MS PG | D30: Green-Green | E30: MAE250A 75X75X5 | F30: 5.77 | G30: 12 | H30: 51 | I30: 3.531 | N30: 51 | O30: 3.53124
F31: 5.77 | G31: 11 | H31: 16 | I31: 1.016 | N31: 16 | O31: 1.01552
F32: 5.77 | G32: 8.05 | H32: 11 | I32: 0.511 | N32: 11 | O32: 0.5109335
F33: 5.77 | G33: 7.4 | H33: 48 | I33: 2.05 | N33: 48 | O33: 2.049504
H34: =SUM(H30:H33) -> 126 | I34: =SUM(I30:I33) -> 7.108 | N34: 126 | O34: 7.1071975
A35: 7 | B35: LOI-1229 | C35: MS PG | D35: Green-Green | E35: MAE250A 100X100X6 | F35: 9.26 | G35: 10.05 | H35: 12 | I35: 1.125 | N35: 110 | O35: 10.23693
H36: =SUM(H35) -> 12 | I36: =SUM(I35) -> 1.125
F37: 9.26 | G37: 10.05 | H37: =110-12 -> 98 | I37: =10.237-1.125 -> 9.112 | K37: =+I40 -> 13.631 | L37: 1777/ 379
F38: 9.26 | G38: 10.5 | H38: 36 | I38: 3.5 | N38: 36 | O38: 3.50028
F39: 9.26 | G39: 11 | H39: 10 | I39: 1.019 | N39: 10 | O39: 1.0186
H40: =SUM(H37:H39) -> 144 | I40: =SUM(I37:I39) -> 13.631 | N40: 156 | O40: 14.75581
H41: =SUM(H40,H36,H34,H29,H27,H23,H18,H15) -> 408 | I41: =SUM(I40,I36,I34,I29,I27,I23,I18,I15) -> 32.723
N42: 408 | O42: 32.721016
E44: Total | H44: =+H41 -> 408 | I44: =+I41 -> 32.723 | K44: =+K37+K13 -> 32.723
B45: Receiver | E45: CHECKED & VERIFIED BY | I45: FOR VINAR ISPAT LTD,
...

Sheet 0310 01.01.24 JBP 
A1: VINAR ISPAT LIMTED
A2: PLOT NO J 3,MIDC INDUSTRIAL AREA, BUTIBORI
K3: DOC.NO.VIL/PLN/F/05
A4: PACKING LIST
D6: LR- 27580
B8: CUSTOMER | C8: KEC INTERNATIONAL LTD. JABALPUR | K8: 01.01.24
B10: CUSTOMER | C10: KEC INTERNATIONAL LTD. JABALPUR | J10: Lorry No. | K10: MH40BG0310
A12: Sr. No. | B12: P.O.No. | C12: Grade | D12: Colour Code | E12: Grade/Section | F12: Section WT. | G12: Length in mtr. | H12: No. Of Pcs | I12: Qty. in MT. | J12: HEAT NO | K12: Challan Qty. | L12: Challan No.
A13: 1 | B13: LOI-1228 | C13: HT PG | D13: Yellow-Yellow | E13: HAE350A 100X100X6 | F13: 9.26 | G13: 10 | H13: 22 | I13: 2.037 | K13: =+I15+I17 -> 17.456 | L13: 1778/ 379 | N13: 22 | O13: 2.0372
F14: 9.26 | G14: 12 | H14: 133 | I14: 14.779 | N14: 133 | O14: 14.77896
H15: =SUM(H13:H14) -> 155 | I15: =SUM(I13:I14) -> 16.816 | N15: 155 | O15: 16.81616
A16: 2 | B16: LOI-1229 | C16: HT PG | D16: Yellow-Yellow | E16: HAE350A 100X100X6 | F16: 9.26 | G16: 12 | H16: 6 | I16: 0.64 | N16: 75 | O16: 8.334
H17: =SUM(H16) -> 6 | I17: =SUM(I16) -> 0.64
F18: 9.26 | G18: 12 | H18: =75-6 -> 69 | I18: =8.334-0.64 -> 7.694 | K18: =+I21 -> 15.043 | L18: 1779/ 380
F19: 9.26 | G19: 7.3 | H19: 99 | I19: 6.692 | N19: 99 | O19: 6.692202
F20: 9.26 | G20: 7.1 | H20: 10 | I20: 0.657 | N20: 10 | O20: 0.65746
H21: =SUM(H18:H20) -> 178 | I21: =SUM(I18:I20) -> 15.043 | N21: 184 | O21: 15.683662
H23: =SUM(H21,H17,H15) -> 339 | I23: =SUM(I21,I17,I15) -> 32.499 | N23: 339 | O23: 32.499822
E26: Total | H26: =+H23 -> 339 | I26: =+I23 -> 32.499 | K26: =+K13+K18 -> 32.499 | N26: 339 | O26: 32.499822
B27: Receiver | E27: CHECKED & VERIFIED BY | I27: FOR VINAR ISPAT LTD,
B30: Signature | E30: Dispatch/Quality Incharge | I30: Authorised Signatory
I39: =F39*G39*H39/1000 -> 0 | K39: =+I26+'[2]1951 31.12.23 JBP '!I27 -> 65.223

Sheet  0508 02.01.24 JBP 
A1: VINAR ISPAT LIMTED
A2: PLOT NO J 3,MIDC INDUSTRIAL AREA, BUTIBORI
K3: DOC.NO.VIL/PLN/F/05
A4: PACKING LIST
D6: LR- 27426
B8: CUSTOMER | C8: KEC INTERNATIONAL LTD. JABALPUR | J8: Date: | K8: 02.01.24
B10: CUSTOMER | C10: KEC INTERNATIONAL LTD. JABALPUR | J10: Lorry No. | K10: MH49AT0508
A12: Sr. No. | B12: P.O.No. | C12: Grade | D12: Colour Code | E12: Grade/Section | F12: Section WT. | G12: Length in mtr. | H12: No. Of Pcs | I12: Qty. in MT. | J12: HEAT NO | K12: Challan Qty. | L12: Challan No.
A13: 1 | B13: LOI-1228 | C13: HT PG | D13: Yellow-Yellow | E13: HAE350A 110X110X7 | F13: 11.8 | G13: 8.2 | H13: 10 | I13: 0.968 | K13: =+I17 -> 14.038 | L13: 1780/ 380 | N13: 10 | O13: 0.9676
F14: 11.8 | G14: 10.5 | H14: =12+24+24 -> 60 | I14: 7.434 | N14: 60 | O14: 7.434
F15: 11.8 | G15: 10.8 | H15: =12+8+21 -> 41 | I15: 5.225 | N15: 41 | O15: 5.22504
F16: 11.8 | G16: 11.7 | H16: 3 | I16: 0.411 | N16: 39 | O16: 5.38434
H17: =SUM(H13:H16) -> 114 | I17: =SUM(I13:I16) -> 14.038 | N17: 150 | O17: 19.01098
F18: 11.8 | G18: 11.7 | H18: =13+26-3 -> 36 | I18: =5.384-0.411 -> 4.973 | K18: =+I19+I25 -> 19.022 | L18: 1781/ 381
H19: =SUM(H18) -> 36 | I19: =SUM(I18) -> 4.973
A20: 2 | B20: LOI-1228 | C20: HT PG | D20: Yellow-Yellow | E20: HAE350A 110X110X6 | F20: 10.2 | G20: 8.3 | H20: 17 | I20: 1.439 | N20: 17 | O20: 1.43922
F21: 10.2 | G21: 9.2 | H21: 15 | I21: 1.408 | N21: 15 | O21: 1.4076
F22: 10.2 | G22: 9.8 | H22: 13 | I22: 1.299 | N22: 13 | O22: 1.29948
F23: 10.2 | G23: 11 | H23: 17 | I23: 1.907 | N23: 17 | O23: 1.9074
F24: 10.2 | G24: 11.7 | H24: =26+15+26 -> 67 | I24: 7.996 | N24: 26 | O24: 3.10284
H25: =SUM(H20:H24) -> 129 | I25: =SUM(I20:I24) -> 14.049 | N25: 88 | O25: 9.15654
H26: =SUM(H25,H19,H17) -> 279 | I26: =SUM(I25,I19,I17) -> 33.06 | N26: 238 | O26: 28.16752
E29: Total | H29: =SUM(H26) -> 279 | I29: =SUM(I26) -> 33.06 | K29: =+K18+K13 -> 33.06 | N29: 238 | O29: 28.16752
B30: Receiver | E30: CHECKED & VERIFIED BY | I30: FOR VINAR ISPAT LTD,
B33: Signature | E33: Dispatch/Quality Incharge | I33: Authorised Signatory
I42: =F42*G42*H42/1000 -> 0 | K42: =+I29+'[2]9844 29.12.23 BB '!I39+'[2]2190 29.12.23 JBP '!K31+'[2]0403 29.12.23 JBP (2)'!I23+'[2]0406 29.12.23 JBP'!I28 -> 162.08462

Sheet 4944 02.01.24 BUB
A1: VINAR ISPAT LIMTED
A2: PLOT NO J 3,MIDC INDUSTRIAL AREA, BUTIBORI
K3: DOC.NO.VIL/PLN/F/05
A4: PACKING LIST
D6: LR- 2065
B8: CUSTOMER | C8: KEC INTERNATIONAL LTD. BUTIBORI | J8: Date: | K8: 02.01.24
B10: CUSTOMER | C10: KEC INTERNATIONAL LTD. BUTIBORI | J10: Lorry No. | K10: MH40Y4944
A12: Sr. No. | B12: P.O.No. | C12: Grade | D12: Colour Code | E12: Grade/Section | F12: Section WT. | G12: Length in mtr. | H12: No. Of Pcs | I12: Qty. in MT. | J12: HEAT NO | K12: Challan Qty. | L12: Challan No.
A13: 1 | B13: LOI-1131 | C13: HT NPG | D13: White-Black | E13: HA355J2 100X100X10 | F13: 15 | G13: 6 | H13: 1 | I13: 0.09 | K13: =+I15+I23+I34+I38+I40+I42+I44+I46+I49 -> 32.271 | L13: 1782/ 662 | N13: 1 | O13: 0.09
F14: 15 | G14: 12 | H14: 1 | I14: 0.18 | N14: 1 | O14: 0.18
H15: =SUM(H13:H14) -> 2 | I15: =SUM(I13:I14) -> 0.27 | N15: 2 | O15: 0.27
A16: 2 | B16: LOI-1131 | C16: HT NPG | D16: White-Black | E16: HA355J2 110X110X8 | F16: 13.4 | G16: 8.1 | H16: 5 | I16: 0.543 | N16: 5 | O16: 0.5427
F17: 13.4 | G17: 8.3 | H17: 2 | I17: 0.222 | N17: 2 | O17: 0.22244
F18: 13.4 | G18: 8.5 | H18: 1 | I18: 0.114 | N18: 1 | O18: 0.1139
F19: 13.4 | G19: 8.75 | H19: 3 | I19: 0.352 | N19: 3 | O19: 0.35175
F20: 13.4 | G20: 10 | H20: 2 | I20: 0.268 | N20: 2 | O20: 0.268
F21: 13.4 | G21: 10.4 | H21: 1 | I21: 0.139 | N21: 1 | O21: 0.13936
F22: 13.4 | G22: 11.7 | H22: 1 | I22: 0.157 | N22: 1 | O22: 0.15678
H23: =SUM(H16:H22) -> 15 | I23: =SUM(I16:I22) -> 1.795 | N23: 15 | O23: 1.79493
A24: 3 | B24: LOI-1131 | C24: HT NPG | D24: White-Black | E24: HA355J2 130X130X8 | F24: 16 | G24: 6.7 | H24: 1 | I24: 0.107 | N24: 1 | O24: 0.1072
F25: 16 | G25: 7.1 | H25: 2 | I25: 0.227 | N25: 2 | O25: 0.2272
F26: 16 | G26: 7.3 | H26: 1 | I26: 0.117 | N26: 1 | O26: 0.1168
F27: 16 | G27: 7.9 | H27: 2 | I27: 0.253 | N27: 2 | O27: 0.2528
F28: 16 | G28: 10.6 | H28: 1 | I28: 0.17 | N28: 1 | O28: 0.1696
F29: 16 | G29: 10 | H29: 1 | I29: 0.16 | N29: 1 | O29: 0.16
F30: 16 | G30: 10.7 | H30: 1 | I30: 0.171 | N30: 1 | O30: 0.1712
F31: 16 | G31: 11 | H31: 1 | I31: 0.176 | N31: 1 | O31: 0.176
F32: 16 | G32: 9.1 | H32: 1 | I32: 0.146 | N32: 1 | O32: 0.1456
F33: 16 | G33: 10.8 | H33: 1 | I33: 0.173 | N33: 1 | O33: 0.1728
H34: =SUM(H24:H33) -> 12 | I34: =SUM(I24:I33) -> 1.7 | N34: 12 | O34: 1.6992
A35: 4 | B35: LOI-1131 | C35: HT NPG | D35: White-Black | E35: HA355J2 75X75X5 | F35: 5.76 | G35: 10.3 | H35: 1 | I35: 0.059 | N35: 1 | O35: 0.059328
F36: 5.76 | G36: 9.8 | H36: 1 | I36: 0.056 | N36: 1 | O36: 0.056448
F37: 5.76 | G37: 9.7 | H37: 8 | I37: 0.447 | N37: 8 | O37: 0.446976
H38: =SUM(H35:H37) -> 10 | I38: =SUM(I35:I37) -> 0.562 | N38: 10 | O38: 0.562752
A39: 5 | B39: LOI-1131 | C39: MS NPG | D39: Grey-Black | E39: MA275J2 130X130X10 | F39: 19.8 | G39: 6 | H39: 1 | I39: 0.119 | N39: 1 | O39: 0.1188
H40: =SUM(H39:H39) -> 1 | I40: =SUM(I39:I39) -> 0.119 | N40: 1 | O40: 0.1188
A41: 6 | B41: LOI-1131 | C41: MS NPG | D41: Grey-Black | E41: MA275J2 110X110X7 | F41: 11.8 | G41: 9.3 | H41: 4 | I41: 0.439 | N41: 4 | O41: 0.43896
H42: =SUM(H41:H41) -> 4 | I42: =SUM(I41:I41) -> 0.439 | N42: 4 | O42: 0.43896
A43: 7 | B43: LOI-1356 | C43: HT NPG | D43: White-Black | E43: HA355J2 110X110X8 | F43: 13.4 | G43: 8.1 | H43: 1 | I43: 0.109 | N43: 1 | O43: 0.10854
H44: =SUM(H43:H43) -> 1 | I44: =SUM(I43:I43) -> 0.109 | N44: 1 | O44: 0.10854
...

Sheet  0311 02.01.24 JBP 
A1: VINAR ISPAT LIMTED
A2: PLOT NO J 3,MIDC INDUSTRIAL AREA, BUTIBORI
K3: DOC.NO.VIL/PLN/F/05
A4: PACKING LIST
D6: LR- 27425
B8: CUSTOMER | C8: KEC INTERNATIONAL LTD. JABALPUR | K8: 02.01.24
B10: CUSTOMER | C10: KEC INTERNATIONAL LTD. JABALPUR | J10: Lorry No. | K10: MH40BG0311
A12: Sr. No. | B12: P.O.No. | C12: Grade | D12: Colour Code | E12: Grade/Section | F12: Section WT. | G12: Length in mtr. | H12: No. Of Pcs | I12: Qty. in MT. | J12: HEAT NO | K12: Challan Qty. | L12: Challan No.
A13: 1 | B13: LOI-1228 | C13: HT PG | D13: Yellow-Yellow | E13: HAE350A 100X100X6 | F13: 9.26 | G13: 6.25 | H13: 59 | I13: 3.415 | K13: =+I15 -> 8.907 | L13: 1783/ 381 | N13: 59 | O13: 3.414625
F14: 9.26 | G14: 11 | H14: 54 | I14: 5.492 | N14: 59 | O14: 6.00974
H15: =SUM(H13:H14) -> 113 | I15: =SUM(I13:I14) -> 8.907
F16: 9.26 | G16: 11 | H16: =59-54 -> 5 | I16: =6.01-5.492 -> 0.518 | K16: =+I18+I24+I26 -> 23.475 | L16: 1784/ 382
F17: 9.26 | G17: 11.5 | H17: 113 | I17: 12.033 | N17: 113 | O17: 12.03337
H18: =SUM(H16:H17) -> 118 | I18: =SUM(I16:I17) -> 12.551 | N18: 231 | O18: 21.457735
A19: 2 | B19: LOI-1229 | C19: HT PG | D19: Yellow-Yellow | E19: HAE350A 100X100X6 | F19: 9.26 | G19: 12 | H19: 9 | I19: 1 | N19: 9 | O19: 1.00008
F20: 9.26 | G20: 9.5 | H20: =38+13 -> 51 | I20: 4.486 | N20: 38 | O20: 3.34286
F21: 9.26 | G21: 10.5 | H21: 14 | I21: 1.361 | N21: 14 | O21: 1.36122
F22: 9.26 | G22: 11 | H22: 2 | I22: 0.204 | N22: 2 | O22: 0.20372
F23: 9.26 | G23: 11.3 | H23: 14 | I23: 1.465 | N23: 14 | O23: 1.464932
H24: =SUM(H19:H23) -> 90 | I24: =SUM(I19:I23) -> 8.516 | N24: 77 | O24: 7.372812
A25: 3 | B25: LOI-1231 | C25: MS NPG | D25: Green-Pink | E25: MAE250A 90X90X8 | F25: 10.92 | G25: 10.5 | H25: 21 | I25: 2.408 | N25: 21 | O25: 2.40786
H26: =SUM(H25) -> 21 | I26: =I25 -> 2.408 | N26: 21 | O26: 2.40786
H27: =SUM(H26,H24,H18,H15) -> 342 | I27: =SUM(I26,I24,I18,I15) -> 32.382 | N27: 329 | O27: 31.238407
E32: Total | H32: =+H27 -> 342 | I32: =+I27 -> 32.382 | K32: =+K13+K16 -> 32.382 | N32: 329 | O32: 31.238407
B33: Receiver | E33: CHECKED & VERIFIED BY | I33: FOR VINAR ISPAT LTD,
B36: Signature | E36: Dispatch/Quality Incharge | I36: Authorised Signatory
I45: =F45*G45*H45/1000 -> 0 | K45: =+I32+'[2]1951 31.12.23 JBP '!I27 -> 65.106

Sheet 3944  02.01.24 BUB
A1: VINAR ISPAT LIMTED
A2: PLOT NO J 3,MIDC INDUSTRIAL AREA, BUTIBORI
K3: DOC.NO.VIL/PLN/F/05
A4: PACKING LIST
D6: LR- 2066
B8: CUSTOMER | C8: KEC INTERNATIONAL LTD. BUTIBORI | J8: Date: | K8: 02.01.24
B10: CUSTOMER | C10: KEC INTERNATIONAL LTD. BUTIBORI | J10: Lorry No. | K10: MH40Y3944
A12: Sr. No. | B12: P.O.No. | C12: Grade | D12: Colour Code | E12: Grade/Section | F12: Section WT. | G12: Length in mtr. | H12: No. Of Pcs | I12: Qty. in MT. | J12: HEAT NO | K12: Challan Qty. | L12: Challan No.
A13: 1 | B13: LOI-643 | C13: HT NPG | D13: White-Black | E13: HA355J2 75X75X4 | F13: 4.65 | G13: 10.3 | H13: =38+40+26+40 -> 144 | I13: 6.897 | K13: =+I19+I25+I27+I29+I31+I33 -> 32.026 | L13: 1785/ 668 | N13: 144 | O13: 6.89688
F14: 4.65 | G14: 11 | H14: 118 | I14: 6.036 | N14: 118 | O14: 6.0357
F15: 4.65 | G15: 12 | H15: =38+40 -> 78 | I15: 4.352 | N15: 78 | O15: 4.3524
F16: 4.65 | G16: 10 | H16: 16 | I16: 0.744 | N16: 16 | O16: 0.744
F17: 4.65 | G17: 10.5 | H17: 5 | I17: 0.244 | N17: 5 | O17: 0.244125
F18: 4.65 | G18: 11.5 | H18: 17 | I18: 0.909 | N18: 17 | O18: 0.909075
H19: =SUM(H13:H18) -> 378 | I19: =SUM(I13:I18) -> 19.182 | N19: 378 | O19: 19.18218
A20: 2 | B20: LOI-645 | C20: HT NPG | D20: White-Black | E20: HA355J2 120X120X8 | F20: 14.7 | G20: 10.3 | H20: 15 | I20: 2.271 | N20: 15 | O20: 2.27115
F21: 14.7 | G21: 9 | H21: 10 | I21: 1.323 | N21: 10 | O21: 1.323
F22: 14.7 | G22: 11 | H22: 13 | I22: 2.102 | N22: 13 | O22: 2.1021
F23: 14.7 | G23: 11.7 | H23: 6 | I23: 1.032 | N23: 6 | O23: 1.03194
F24: 14.7 | G24: 9.3 | H24: =15+18 -> 33 | I24: 4.511 | N24: 33 | O24: 4.51143
H25: =SUM(H20:H24) -> 77 | I25: 11.239 | N25: 77 | O25: 11.23962
A26: 3 | B26: LOI-1047 | C26: MS NPG | D26: Green-Pink | E26: MAE250A 130X130X12 | F26: 23.45 | G26: 7 | H26: 1 | I26: 0.164 | N26: 1 | O26: 0.16415
H27: =SUM(H26) -> 1 | I27: =SUM(I26) -> 0.164 | N27: 1 | O27: 0.16415
A28: 4 | B28: LOI-1047 | C28: MS NPG | D28: Green-Pink | E28: MAE250A 90X90X7 | F28: 9.61 | G28: 12 | H28: 1 | I28: 0.115 | N28: 1 | O28: 0.11532
H29: =SUM(H28) -> 1 | I29: =SUM(I28) -> 0.115 | N29: 1 | O29: 0.11532
A30: 5 | B30: LOI-1047 | C30: MS NPG | D30: Green-Pink | E30: MAE250A 75X75X6 | F30: 6.86 | G30: 12 | H30: 14 | I30: 1.152 | N30: 14 | O30: 1.15248
H31: =SUM(H30) -> 14 | I31: =SUM(I30) -> 1.152 | N31: 14 | O31: 1.15248
A32: 6 | B32: LOI-1047 | C32: MS NPG | D32: Green-Pink | E32: MAE250A 110X110X10 | F32: 16.58 | G32: 10.5 | H32: 1 | I32: 0.174 | N32: 1 | O32: 0.17409
H33: =SUM(H32) -> 1 | I33: =SUM(I32) -> 0.174 | N33: 1 | O33: 0.17409
H34: =SUM(H33,H31,H29,H27,H25,H19) -> 472 | I34: =SUM(I33,I31,I29,I27,I25,I19) -> 32.026 | N34: 472 | O34: 32.02784
E37: Total | H37: =SUM(H34) -> 472 | I37: =SUM(I34) -> 32.026 | K37: =+K13 -> 32.026 | N37: 472 | O37: 32.02784
B38: Receiver | E38: CHECKED & VERIFIED BY | I38: FOR VINAR ISPAT LTD,
B41: Signature | E41: Dispatch/Quality Incharge | I41: Authorised Signatory
I50: =F50*G50*H50/1000 -> 0 | K50: =+I37+'[2]9844 29.12.23 BB '!I39+'[2]2190 29.12.23 JBP '!K31+'[2]0403 29.12.23 JBP (2)'!I23+'[2]0406 29.12.23 JBP'!I28 -> 161.05062

Sheet 0398  02.01.24 JBP 
A1: VINAR ISPAT LIMTED
A2: PLOT NO J 3,MIDC INDUSTRIAL AREA, BUTIBORI
K3: DOC.NO.VIL/PLN/F/05
A4: PACKING LIST
D6: LR- 27427
B8: CUSTOMER | C8: KEC INTERNATIONAL LTD. JABALPUR | J8: Date | K8: 02.01.23
B10: CUSTOMER | C10: KEC INTERNATIONAL LTD. JABALPUR | J10: Lorry No. | K10: MH49AT0398
A12: Sr. No. | B12: P.O.No. | C12: Grade | D12: Colour Code | E12: Grade/Section | F12: Section WT. | G12: Length in mtr. | H12: No. Of Pcs | I12: Qty. in MT. | J12: HEAT NO | K12: Challan Qty. | L12: Challan No.
A13: 1 | B13: LOI-1228 | C13: HT PG | D13: Yellow-Yellow | E13: HAE350A 120X120X7 | F13: 12.9 | G13: 10 | H13: 23 | I13: 2.967 | K13: =+I15 -> 5.452 | L13: 1786/ 382 | N13: 23 | O13: 2.967 | P13: =I13-O13 -> 0
F14: 12.9 | G14: 10.5 | H14: 18 | I14: 2.485 | N14: 46 | O14: 6.2307 | P14: =I14-O14 -> -3.7457
H15: =SUM(H13:H14) -> 41 | I15: =SUM(I13:I14) -> 5.452
F16: 12.9 | G16: 10.5 | H16: =24+22-18 -> 28 | I16: =6.231-2.485 -> 3.746 | K16: =+I20+I23+I25+I27+I29 -> 27.787 | L16: 1787/ 383
F17: 12.9 | G17: 11 | H17: 20 | I17: 2.838 | N17: 20 | O17: 2.838 | P17: =I17-O17 -> 0
F18: 12.9 | G18: 11.5 | H18: =21+2 -> 23 | I18: 3.412 | N18: 23 | O18: 3.41205 | P18: =I18-O18 -> -5e-05
F19: 12.9 | G19: 12 | H19: =18+23+3 -> 44 | I19: 6.811 | N19: 44 | O19: 6.8112 | P19: =I19-O19 -> -0.0002
H20: =SUM(H16:H19) -> 115 | I20: =SUM(I16:I19) -> 16.807 | N20: 156 | O20: 22.25895 | P20: =I20-O20 -> -5.45195
A21: 2 | B21: LOI-1228 | C21: HT PG | D21: Yellow-Yellow | E21: HAE350A 100X100X6 | F21: 9.26 | G21: 6.25 | H21: =23+2 -> 25 | I21: 1.447 | N21: 23 | O21: 1.331125 | P21: =I21-O21 -> 0.115875
F22: 9.26 | G22: 10 | H22: =30+23 -> 53 | I22: 4.908 | N22: 53 | O22: 4.9078 | P22: =I22-O22 -> 0.0002
H23: =SUM(H21:H22) -> 78 | I23: =SUM(I21:I22) -> 6.355 | N23: 76 | O23: 6.238925 | P23: =I23-O23 -> 0.116075
A24: 3 | B24: LOI-1232 | C24: MS NPG | D24: Green-Pink | E24: MAE250A 90X90X8 | F24: 10.92 | G24: 10.5 | H24: 16 | I24: 1.835 | N24: 16 | O24: 1.83456 | P24: =I24-O24 -> 0.00044
H25: =SUM(H24) -> 16 | I25: =SUM(I24) -> 1.835 | N25: 16 | O25: 1.83456 | P25: =I25-O25 -> 0.00044
A26: 4 | B26: LOI-1232 | C26: MS NPG | D26: Green-Pink | E26: MAE250A 100X100X8 | F26: 12.18 | G26: 11.8 | H26: 8 | I26: 1.15 | N26: 8 | O26: 1.149792 | P26: =I26-O26 -> 0.000208
H27: =SUM(H26) -> 8 | I27: =SUM(I26) -> 1.15 | N27: 8 | O27: 1.149792 | P27: =I27-O27 -> 0.000208
A28: 5 | B28: LOI-1226 | C28: MS NPG | D28: Green-Pink | E28: MAE250A 100X100X12 | F28: 17.83 | G28: 11.5 | H28: 8 | I28: 1.64 | N28: 8 | O28: 1.64036 | P28: =I28-O28 -> -0.00036
H29: =SUM(H28) -> 8 | I29: =SUM(I28) -> 1.64 | N29: 8 | O29: 1.64036 | P29: =I29-O29 -> -0.00036
H30: =SUM(H29,H27,H25,H23,H20,H15) -> 266 | I30: =SUM(I29,I27,I25,I23,I20,I15) -> 33.239
N31: 264 | O31: 33.122587
E33: Total | H33: =+H30 -> 266 | I33: =+I30 -> 33.239 | K33: =+K16+K13 -> 33.239 | N33: 264 | O33: 33.122587
B34: Receiver | E34: CHECKED & VERIFIED BY | I34: FOR VINAR ISPAT LTD,
B37: Signature | E37: Dispatch/Quality Incharge | I37: Authorised Signatory
I46: =F46*G46*H46/1000 -> 0 | K46: =+I33+'[2]9844 29.12.23 BB '!I39+'[2]2190 29.12.23 JBP '!K31+'[2]0403 29.12.23 JBP (2)'!I23+'[2]0406 29.12.23 JBP'!I28 -> 162.26362

Sheet 0502  02.01.24 JBP
A1: VINAR ISPAT LIMTED
A2: PLOT NO J 3,MIDC INDUSTRIAL AREA, BUTIBORI
K3: DOC.NO.VIL/PLN/F/05
A4: PACKING LIST
D6: LR- 27428
B8: CUSTOMER | C8: KEC INTERNATIONAL LTD. JABALPUR | J8: Date: | K8: 02.01.2024
B10: CUSTOMER | C10: KEC INTERNATIONAL LTD. JABALPUR | J10: Lorry No. | K10: MH 49 AT 0502
A12: Sr. No. | B12: P.O.No. | C12: Grade | D12: Colour Code | E12: Grade/Section | F12: Section WT. | G12: Length in mtr. | H12: No. Of Pcs | I12: Qty. in MT. | J12: HEAT NO | K12: Challan Qty. | L12: Challan No.
A13: 1 | B13: LOI-1228 | C13: HT PG | D13: Yellow-Yellow | E13: HAE350A 110X110X8 | F13: 13.4 | G13: 10 | H13: 10 | I13: =1.34-0.002 -> 1.338 | K13: =+I14 -> 1.338 | L13: 1788/ 383 | N13: 10 | O13: 1.34
H14: =SUM(H13:H13) -> 10 | I14: =SUM(I13:I13) -> 1.338
F15: 13.4 | G15: 10.5 | H15: =34 -> 34 | I15: =4.784+0.002 -> 4.786 | K15: =+I18+I23 -> 30.084 | L15: 1789/ 384
F16: 13.4 | G16: 11.5 | H16: 58 | I16: 8.938 | N16: 58 | O16: 8.9378
F17: 13.4 | G17: 12 | H17: 23 | I17: 3.698 | N17: 23 | O17: 3.6984
H18: =SUM(H15:H17) -> 115 | I18: =SUM(I15:I17) -> 17.422 | N18: 125 | O18: 18.76
A19: 2 | B19: LOI-1228 | C19: HT PG | D19: Yellow-Yellow | E19: HAE350A 110X110X7 | F19: 11.8 | G19: 8.2 | H19: 17 | I19: 1.645 | N19: 17 | O19: 1.6048
F20: 11.8 | G20: 10.5 | H20: 40 | I20: 4.956 | N20: 40 | O20: 4.956
F21: 11.8 | G21: 10.8 | H21: 43 | I21: 5.48 | N21: 43 | O21: 5.47992
F22: 11.8 | G22: 11.7 | H22: 4 | I22: 0.581
H23: =SUM(H19:H22) -> 104 | I23: =SUM(I19:I22) -> 12.662
F24: 11.8 | G24: 11.7 | H24: =12-4 -> 8 | I24: =1.6566-0.581 -> 1.0756 | K24: =+I25 -> 1.0756 | L24: 1790/ 385 | N24: 12 | O24: 1.65672
H25: =SUM(H24) -> 8 | I25: =SUM(I24) -> 1.0756 | N25: 112 | O25: 13.69744
H26: =SUM(H25,H23,H18,H14) -> 237 | I26: =SUM(I25,I23,I18,I14) -> 32.4976
E29: Total | H29: =+H26 -> 237 | I29: =+I26 -> 32.4976 | K29: =+K13+K15+K24 -> 32.4976 | N29: 237 | O29: 32.45744
B30: Receiver | E30: CHECKED & VERIFIED BY | I30: FOR VINAR ISPAT LTD,
B33: Signature | E33: Dispatch/Quality Incharge | I33: Authorised Signatory
I42: =F42*G42*H42/1000 -> 0 | K42: =+' 0508 02.01.24 JBP '!I29+'4944 02.01.24 BUB'!I53+' 0311 02.01.24 JBP '!I32+'3944 02.01.24 BUB'!I37+'0398 02.01.24 JBP '!I33+'0502 02.01.24 JBP'!I29 -> 195.4756

Sheet 7423  03.01.24 JBP
A1: VINAR ISPAT LIMTED
A2: PLOT NO J 3,MIDC INDUSTRIAL AREA, BUTIBORI
K3: DOC.NO.VIL/PLN/F/05
A4: PACKING LIST
D6: LR- 27435
B8: CUSTOMER | C8: KEC INTERNATIONAL LTD. JABALPUR | J8: Date: | K8: 03.01.2024
B10: CUSTOMER | C10: KEC INTERNATIONAL LTD. JABALPUR | J10: Lorry No. | K10: MH40N7423
A12: Sr. No. | B12: P.O.No. | C12: Grade | D12: Colour Code | E12: Grade/Section | F12: Section WT. | G12: Length in mtr. | H12: No. Of Pcs | I12: Qty. in MT. | J12: HEAT NO | K12: Challan Qty. | L12: Challan No.
A13: 1 | B13: LOI-1228 | C13: HT PG | D13: Yellow-Yellow | E13: HAE350A 80X80X5 | F13: 6.17 | G13: 10 | H13: 10 | I13: 0.617 | K13: =+I16+I21+I25 -> 29.008 | L13: 1791/ 385 | N13: 10 | O13: 0.617 | P13: =I13-O13 -> 0
F14: 6.17 | G14: 11 | H14: 8 | I14: 0.543 | N14: 8 | O14: 0.54296 | P14: =I14-O14 -> 4e-05
F15: 6.17 | G15: 11.5 | H15: 3 | I15: 0.213 | N15: 3 | O15: 0.212865 | P15: =I15-O15 -> 0.000135
H16: =SUM(H13:H15) -> 21 | I16: =SUM(I13:I15) -> 1.373 | N16: 21 | O16: 1.372825 | P16: =I16-O16 -> 0.000175
A17: 2 | B17: LOI-1228 | C17: HT PG | D17: Yellow-Yellow | E17: HAE350A 110X110X8 | F17: 13.4 | G17: 10 | H17: 15 | I17: 2.01 | N17: 15 | O17: 2.01 | P17: =I17-O17 -> 0
F18: 13.4 | G18: 10.5 | H18: 14 | I18: 1.97 | N18: 14 | O18: 1.9698 | P18: =I18-O18 -> 0.0002
F19: 13.4 | G19: 11.5 | H19: 30 | I19: 4.623 | N19: 30 | O19: 4.623 | P19: =I19-O19 -> 0
F20: 13.4 | G20: 12 | H20: 49 | I20: 7.879 | N20: 49 | O20: 7.8792 | P20: =I20-O20 -> -0.0002
H21: =SUM(H17:H20) -> 108 | I21: =SUM(I17:I20) -> 16.482 | N21: 108 | O21: 16.482 | P21: =I21-O21 -> 0
A22: 3 | B22: LOI-1229 | C22: HT PG | D22: Yellow-Yellow | E22: HAE350A 80X80X5 | F22: 6.17 | G22: 10 | H22: 3 | I22: 0.185 | N22: 3 | O22: 0.1851 | P22: =I22-O22 -> -0.0001
F23: 6.17 | G23: 10.5 | H23: 16 | I23: 1.037 | N23: 16 | O23: 1.03656 | P23: =I23-O23 -> 0.00044
F24: 6.17 | G24: 10.75 | H24: 151 | I24: 9.931 | N24: 189 | O24: 12.535898 | P24: =I24-O24 -> -2.6048975
H25: =SUM(H22:H24) -> 170 | I25: =SUM(I22:I24) -> 11.153
F26: 6.17 | G26: 10.75 | H26: =35+36+36+38+38+6-151 -> 38 | I26: =12.536-9.931 -> 2.605 | K26: =+I28 -> 4.382 | L26: 1792/ 386
F27: 6.17 | G27: 12 | H27: 24 | I27: 1.777 | N27: 24 | O27: 1.77696 | P27: =I27-O27 -> 4e-05
H28: =SUM(H26:H27) -> 62 | I28: =SUM(I26:I27) -> 4.382 | N28: 232 | O28: 15.534517 | P28: =I28-O28 -> -11.152517
H29: =SUM(H28,H25,H21,H16) -> 361 | I29: =SUM(I28,I25,I21,I16) -> 33.39 | N29: 361 | O29: 33.389342 | P29: =I29-O29 -> 0.0006575
P30: =I30-O30 -> 0
P31: =I31-O31 -> 0
E32: Total | H32: =+H29 -> 361 | I32: =+I29 -> 33.39 | K32: =+K26+K13 -> 33.39 | N32: 361 | O32: 33.389342 | P32: =I32-O32 -> 0.0006575
B33: Receiver | E33: CHECKED & VERIFIED BY | I33: FOR VINAR ISPAT LTD,
B36: Signature | E36: Dispatch/Quality Incharge | I36: Authorised Signatory
I45: =F45*G45*H45/1000 -> 0 | K45: =+' 0508 02.01.24 JBP '!I29+'4944 02.01.24 BUB'!I53+' 0311 02.01.24 JBP '!I32+'3944 02.01.24 BUB'!I37+'0398 02.01.24 JBP '!I33+'7423 03.01.24 JBP'!I32 -> 196.368

Sheet 4944  03.01.24 BUB 
A1: VINAR ISPAT LIMTED
A2: PLOT NO J 3,MIDC INDUSTRIAL AREA, BUTIBORI
K3: DOC.NO.VIL/PLN/F/05
A4: PACKING LIST
D6: LR- 2068
B8: CUSTOMER | C8: KEC INTERNATIONAL LTD. BUTIBORI | J8: Date: | K8: 03.01.24
B10: CUSTOMER | C10: KEC INTERNATIONAL LTD. BUTIBORI | J10: Lorry No. | K10: MH40Y4944
A12: Sr. No. | B12: P.O.No. | C12: Grade | D12: Colour Code | E12: Grade/Section | F12: Section WT. | G12: Length in mtr. | H12: No. Of Pcs | I12: Qty. in MT. | J12: HEAT NO | K12: Challan Qty. | L12: Challan No.
A13: 1 | B13: LOI-645 | C13: HT NPG | D13: White-Black | E13: HA355J2 120X120X8 | F13: 14.7 | G13: 9 | H13: 36 | I13: 4.763 | K13: =+I17 -> 7.247 | L13: 1793/ 661 | N13: 36 | O13: 4.7628 | P13: =I13-O13 -> 0.0002
F14: 14.7 | G14: 9.3 | H14: 8 | I14: 1.094 | N14: 8 | O14: 1.09368 | P14: =I14-O14 -> 0.00032
F15: 14.7 | G15: 10.3 | H15: 5 | I15: 0.757 | N15: 5 | O15: 0.75705 | P15: =I15-O15 -> -5e-05
F16: 14.7 | G16: 11 | H16: 4 | I16: 0.633 | N16: 20 | O16: 3.234 | P16: =I16-O16 -> -2.601
H17: =SUM(H13:H16) -> 53 | I17: =SUM(I13:I16) -> 7.247
F18: 14.7 | G18: 11 | H18: =20-4 -> 16 | I18: =3.234-0.633 -> 2.601 | K18: =+I20 -> 4.79587 | L18: 1794/ 662
F19: 14.7 | G19: 11.7 | H19: 13 | I19: =F19*G19*H19/1000-0.041 -> 2.19487 | N19: 60 | O19: 10.3194 | P19: =I19-O19 -> -8.12453
H20: =SUM(H18:H19) -> 29 | I20: =SUM(I18:I19) -> 4.79587 | N20: 129 | O20: 20.16693 | P20: =I20-O20 -> -15.37106
F21: 14.7 | G21: 11.7 | H21: =60-13 -> 47 | I21: =10.319-2.195 -> 8.124 | K21: =+I22+I26 -> 19.467 | L21: 1795/ 663
H22: =SUM(H21) -> 47 | I22: =SUM(I21) -> 8.124
A23: 2 | B23: LOI-645 | C23: HT NPG | D23: White-Black | E23: HA355J2 150X150X12 | F23: 27.3 | G23: 8.1 | H23: 24 | I23: 5.307 | N23: 24 | O23: 2.271 | P23: =I23-O23 -> 3.036
F24: 27.3 | G24: 8.9 | H24: 3 | I24: 0.729 | N24: 3 | O24: 1.323 | P24: =I24-O24 -> -0.594
F25: 27.3 | G25: 12.15 | H25: 16 | I25: 5.307 | N25: 16 | O25: 2.102 | P25: =I25-O25 -> 3.205
H26: =SUM(H23:H25) -> 43 | I26: =SUM(I23:I25) -> 11.343 | N26: 43 | O26: 11.239 | P26: =I26-O26 -> 0.104
H27: =SUM(H26,H22,H20,H17) -> 172 | I27: =SUM(I26,I22,I20,I17) -> 31.50987 | N27: 172 | O27: 31.40593 | P27: =I27-O27 -> 0.10394
P28: =I28-O28 -> 0
P29: =I29-O29 -> 0
E30: Total | H30: =SUM(H27) -> 172 | I30: =SUM(I27) -> 31.50987 | K30: =+K13+K18+K21 -> 31.50987 | N30: 172 | O30: 31.40593 | P30: =I30-O30 -> 0.10394
B31: Receiver | E31: CHECKED & VERIFIED BY | I31: FOR VINAR ISPAT LTD,
B34: Signature | E34: Dispatch/Quality Incharge | I34: Authorised Signatory
I43: =F43*G43*H43/1000 -> 0 | K43: =+I30+'[2]9844 29.12.23 BB '!I39+'[2]2190 29.12.23 JBP '!K31+'[2]0403 29.12.23 JBP (2)'!I23+'[2]0406 29.12.23 JBP'!I28 -> 160.53449

Sheet 0403  03.01.24 JBP 
A1: VINAR ISPAT LIMTED
A2: PLOT NO J 3,MIDC INDUSTRIAL AREA, BUTIBORI
K3: DOC.NO.VIL/PLN/F/05
A4: PACKING LIST
D6: LR- 27438
B8: CUSTOMER | C8: KEC INTERNATIONAL LTD. JABALPUR | J8: Date: | K8: 03.01.2024
B10: CUSTOMER | C10: KEC INTERNATIONAL LTD. JABALPUR | J10: Lorry No. | K10: MH49AT0403
A12: Sr. No. | B12: P.O.No. | C12: Grade | D12: Colour Code | E12: Grade/Section | F12: Section WT. | G12: Length in mtr. | H12: No. Of Pcs | I12: Qty. in MT. | J12: HEAT NO | K12: Challan Qty. | L12: Challan No.
A13: 1 | B13: LOI-1228 | C13: HT PG | D13: Yellow-Yellow | E13: HAE350A 80X80X6 | F13: 7.36 | G13: 10 | H13: 17 | I13: 1.251 | K13: =+I16+I20 -> 24.166 | L13: 1800/ 386 | N13: 17 | O13: 1.2512 | P13: =I13-O13 -> -0.0002
F14: 7.36 | G14: 11.1 | H14: 4 | I14: 0.327 | N14: 4 | O14: 0.326784 | P14: =I14-O14 -> 0.000216
F15: 7.36 | G15: 11.9 | H15: 8 | I15: 0.701 | N15: 8 | O15: 0.700672 | P15: =I15-O15 -> 0.000328
H16: =SUM(H13:H15) -> 29 | I16: =SUM(I13:I15) -> 2.279 | N16: 29 | O16: 2.278656 | P16: =I16-O16 -> 0.000344
A17: 2 | B17: LOI-1229 | C17: HT PG | D17: Yellow-Yellow | E17: HAE350A 80X80X6 | F17: 7.36 | G17: 7.5 | H17: 32 | I17: 1.766 | N17: 32 | O17: 1.7664 | P17: =I17-O17 -> -0.0004
F18: 7.36 | G18: 9.25 | H18: =33+36+39 -> 108 | I18: 7.353 | N18: 108 | O18: 7.35264 | P18: =I18-O18 -> 0.00036
F19: 7.36 | G19: 10.3 | H19: 168 | I19: 12.768 | N19: 186 | O19: 14.100288 | P19: =I19-O19 -> -1.332288
H20: =SUM(H17:H19) -> 308 | I20: =SUM(I17:I19) -> 21.887 | N20: 372 | O20: 27.282048
F21: 7.36 | G21: 10.3 | H21: =32+30+30+32+30+32-168 -> 18 | I21: =14.1-12.768 -> 1.332 | K21: =+I23+I26+I28 -> 8.858 | L21: 1801/ 387 | N21: 46 | O21: 4.06272
F22: 7.36 | G22: 12 | H22: =31+15 -> 46 | I22: 4.063
H23: =SUM(H21:H22) -> 64 | I23: =SUM(I21:I22) -> 5.395 | N23: 46 | O23: 4.06272
A24: 3 | B24: LOI-1340 | C24: HT NPG | D24: Yellow-Pink | E24: HAE350A 150X150X20 | F24: 44.12 | G24: 11.5 | H24: 2 | I24: 1.015 | N24: 2 | O24: 1.01476 | P24: =I24-O24 -> 0.00024
F25: 44.12 | G25: 12 | H25: 3 | I25: 1.588 | N25: 3 | O25: 1.58832 | P25: =I25-O25 -> -0.00032
H26: =SUM(H24:H25) -> 5 | I26: =SUM(I24:I25) -> 2.603 | N26: 5 | O26: 2.60308 | P26: =I26-O26 -> -8e-05
A27: 4 | B27: LOI-1340 | C27: HT NPG | D27: Yellow-Pink | E27: HAE350A 150X150X16 | F27: 35.84 | G27: 12 | H27: 2 | I27: 0.86 | N27: 2 | O27: 0.86016 | P27: =I27-O27 -> -0.00016
H28: =SUM(H27:H27) -> 2 | I28: =SUM(I27:I27) -> 0.86 | N28: 2 | O28: 0.86016 | P28: =I28-O28 -> -0.00016
H29: =SUM(H28,H26,H23,H20,H16) -> 408 | I29: =SUM(I28,I26,I23,I20,I16) -> 33.024 | N29: 408 | O29: 33.023944 | P29: =I29-O29 -> 5.6e-05
P30: =I30-O30 -> 0
P31: =I31-O31 -> 0
E32: Total | H32: =+H29 -> 408 | I32: =+I29 -> 33.024 | K32: =+K13+K21 -> 33.024 | N32: 408 | O32: 33.023944 | P32: =I32-O32 -> 5.6e-05
B33: Receiver | E33: CHECKED & VERIFIED BY | I33: FOR VINAR ISPAT LTD,
B36: Signature | E36: Dispatch/Quality Incharge | I36: Authorised Signatory
I45: =F45*G45*H45/1000 -> 0 | K45: =+' 0508 02.01.24 JBP '!I29+'4944 02.01.24 BUB'!I53+' 0311 02.01.24 JBP '!I32+'3944 02.01.24 BUB'!I37+'0398 02.01.24 JBP '!I33+'0403 03.01.24 JBP '!I32 -> 196.002

Sheet 3044  03.01.24 BB 
A1: VINAR ISPAT LIMTED
A2: PLOT NO J 3,MIDC INDUSTRIAL AREA, BUTIBORI
K3: DOC.NO.VIL/PLN/F/05
A4: PACKING LIST
D6: LR- 2067
B8: CUSTOMER | C8: KEC INTERNATIONAL LTD. BUTIBORI | J8: Date: | K8: 03.01.2024
B10: CUSTOMER | C10: KEC INTERNATIONAL LTD. BUTIBORI | J10: Lorry No. | K10: MH40AK3044
A12: Sr. No. | B12: P.O.No. | C12: Grade | D12: Colour Code | E12: Grade/Section | F12: Section WT. | G12: Length in mtr. | H12: No. Of Pcs | I12: Qty. in MT. | J12: HEAT NO | K12: Challan Qty. | L12: Challan No.
A13: 1 | B13: LOI-645 | C13: HT NPG | D13: White-Black | E13: HA355J2 90X90X7 | F13: 9.61 | G13: 11 | H13: 17 | I13: 1.797 | K13: =+I16+I20+I22+I25+I27 -> 21.664 | L13: 1802/ 664 | N13: 17 | O13: 1.79707 | P13: =I13-O13 -> -7e-05
F14: 9.61 | G14: 11.5 | H14: 28 | I14: 3.094 | N14: 28 | O14: 3.09442 | P14: =I14-O14 -> -0.00042
F15: 9.61 | G15: 12 | H15: 13 | I15: 1.499 | N15: 13 | O15: 1.49916 | P15: =I15-O15 -> -0.00016
H16: =SUM(H13:H15) -> 58 | I16: =SUM(I13:I15) -> 6.39 | N16: 58 | O16: 6.39065 | P16: =I16-O16 -> -0.00065
A17: 2 | B17: LOI-645 | C17: HT NPG | D17: White-Black | E17: HA355J2 100X100X8 | F17: 12.2 | G17: 7.5 | H17: 26 | I17: 2.379 | N17: 26 | O17: 2.379 | P17: =I17-O17 -> 0
F18: 12.2 | G18: 7.6 | H18: 15 | I18: 1.391 | N18: 15 | O18: 1.3908 | P18: =I18-O18 -> 0.0002
F19: 12.2 | G19: 10.4 | H19: 24 | I19: 3.045 | N19: 24 | O19: 3.04512 | P19: =I19-O19 -> -0.00012
H20: =SUM(H17:H19) -> 65 | I20: =SUM(I17:I19) -> 6.815 | N20: 65 | O20: 6.81492 | P20: =I20-O20 -> 8e-05
A21: 3 | B21: LOI-645 | C21: HT NPG | D21: White-Black | E21: HA355J2 110X110X8 | F21: 13.4 | G21: 9.2 | H21: 14 | I21: 1.726 | N21: 14 | O21: 1.72592 | P21: =I21-O21 -> 8e-05
H22: =SUM(H21) -> 14 | I22: =SUM(I21) -> 1.726 | N22: 14 | O22: 1.72592 | P22: =I22-O22 -> 8e-05
A23: 4 | B23: LOI-645 | C23: HT NPG | D23: White-Black | E23: HA355J2 120X120X8 | F23: 14.7 | G23: 11 | H23: 8 | I23: 1.294 | N23: 8 | O23: 1.2936 | P23: =I23-O23 -> 0.0004
F24: 14.7 | G24: 11.7 | H24: 20 | I24: 3.44 | N24: 20 | O24: 3.4398 | P24: =I24-O24 -> 0.0002
H25: =SUM(H23:H24) -> 28 | I25: =SUM(I23:I24) -> 4.734 | N25: 28 | O25: 4.7334 | P25: =I25-O25 -> 0.0006
A26: 5 | B26: LOI-645 | C26: HT NPG | D26: White-Black | E26: HA355J2 90X90X8 | F26: 10.9 | G26: 11.4 | H26: 16 | I26: 1.999 | N26: 64 | O26: 7.95264 | P26: =I26-O26 -> -5.95364
H27: =SUM(H26) -> 16 | I27: =SUM(I26) -> 1.999 | N27: 64 | O27: 7.95264 | P27: =I27-O27 -> -5.95364
F28: 10.9 | G28: 11.4 | H28: =64-16 -> 48 | I28: =7.953-1.999 -> 5.954 | K28: =+I29+I31+I34+I38+I40 -> 11.037 | L28: 1803/ 666
H29: =SUM(H28) -> 48 | I29: =SUM(I28) -> 5.954
A30: 5 | B30: LOI-643 | C30: HT NPG | D30: White-Black | E30: HA355J2 100X100X6 | F30: 9.26 | G30: 6.2 | H30: 21 | I30: 1.206 | N30: 21 | O30: 1.205652 | P30: =I30-O30 -> 0.000348
H31: =SUM(H30) -> 21 | I31: =SUM(I30) -> 1.206 | N31: 21 | O31: 1.205652 | P31: =I31-O31 -> 0.000348
A32: 6 | B32: LOI-643 | C32: HT NPG | D32: White-Black | E32: HA355J2 75X75X6 | F32: 6.85 | G32: 10 | H32: 2 | I32: 0.137 | N32: 2 | O32: 0.137 | P32: =I32-O32 -> 0
F33: 6.85 | G33: 11.5 | H33: 21 | I33: 1.654 | N33: 21 | O33: 1.654275 | P33: =I33-O33 -> -0.000275
H34: =SUM(H32:H33) -> 23 | I34: =SUM(I32:I33) -> 1.791 | N34: 23 | O34: 1.791275 | P34: =I34-O34 -> -0.000275
A35: 7 | B35: LOI-643 | C35: HT NPG | D35: White-Black | E35: HA355J2 90X90X6 | F35: 8.3 | G35: 10.8 | H35: 2 | I35: 0.179 | N35: 2 | O35: 0.17928 | P35: =I35-O35 -> -0.00028
F36: 8.3 | G36: 11 | H36: 1 | I36: 0.091 | N36: 1 | O36: 0.0913 | P36: =I36-O36 -> -0.0003
F37: 8.3 | G37: 11.1 | H37: 17 | I37: 1.566 | N37: 17 | O37: 1.56621 | P37: =I37-O37 -> -0.00021
H38: =SUM(H35:H37) -> 20 | I38: =SUM(I35:I37) -> 1.836 | N38: 20 | O38: 1.83679 | P38: =I38-O38 -> -0.00079
A39: 9 | B39: LOI-1022 | C39: PG HT | D39: Yellow-Yellow | E39: HAE350A 90X90X6 | F39: 8.32 | G39: 7.5 | H39: 4 | I39: 0.25 | N39: 4 | O39: 0.2496 | P39: =I39-O39 -> 0.0004
H40: =SUM(H39:H39) -> 4 | I40: =SUM(I39:I39) -> 0.25 | N40: 4 | O40: 0.2496 | P40: =I40-O40 -> 0.0004
H41: =SUM(H40,H38,H34,H31,H29,H27,H25,H22,H20,H16) -> 297 | I41: =SUM(I40,I38,I34,I31,I29,I27,I25,I22,I20,I16) -> 32.701 | N41: 297 | O41: 32.700847 | P41: =I41-O41 -> 0.000153
P42: =I42-O42 -> 0
P43: =I43-O43 -> 0
E44: Total | H44: =+H41 -> 297 | I44: =+I41 -> 32.701 | K44: =+K28+K13 -> 32.701 | N44: 297 | O44: 32.700847 | P44: =I44-O44 -> 0.000153
...

Sheet 5844  03.01.24 BUB
A1: VINAR ISPAT LIMTED
A2: PLOT NO J 3,MIDC INDUSTRIAL AREA, BUTIBORI
K3: DOC.NO.VIL/PLN/F/05
A4: PACKING LIST
D6: LR- 2069
B8: CUSTOMER | C8: KEC INTERNATIONAL LTD. BUTIBORI | J8: Date: | K8: 03.01.24
B10: CUSTOMER | C10: KEC INTERNATIONAL LTD. BUTIBORI | J10: Lorry No. | K10: MH40Y5844
A12: Sr. No. | B12: P.O.No. | C12: Grade | D12: Colour Code | E12: Grade/Section | F12: Section WT. | G12: Length in mtr. | H12: No. Of Pcs | I12: Qty. in MT. | J12: HEAT NO | K12: Challan Qty. | L12: Challan No.
A13: 1 | B13: LOI-1358 | C13: HT NPG | D13: Yellow-Violet | E13: HAA572GR50 130X130X12 | F13: 23.6 | G13: 10.3 | H13: 12 | I13: 2.917 | K13: =+I15 -> 11.693 | L13: 1796/ 663 | N13: 36 | O13: 4.7628 | P13: =I13-O13 -> -1.8458
F14: 23.6 | G14: 10.4 | H14: 36 | I14: 8.776 | N14: 8 | O14: 1.09368 | P14: =I14-O14 -> 7.68232
H15: =SUM(H13:H14) -> 48 | I15: =SUM(I13:I14) -> 11.693
F16: 23.6 | G16: 10.4 | H16: 32 | I16: =F16*G16*H16/1000+0.039 -> 7.89308 | K16: =+I17 -> 7.89308 | L16: 1797/ 665
H17: =SUM(H16) -> 32 | I17: =SUM(I16) -> 7.89308
F18: 23.6 | G18: 10.4 | H18: 21 | I18: 5.271 | K18: =+I19 -> 5.271 | L18: 1798/ 668
H19: =SUM(H18) -> 21 | I19: =SUM(I18) -> 5.271
F20: 23.6 | G20: 10.4 | H20: =117-36-32-21 -> 28 | I20: =28.716-8.776-7.893-5.271 -> 6.776 | K20: =+I22 -> 7.555 | L20: 1799/ 664
F21: 23.6 | G21: 11 | H21: 3 | I21: 0.779 | N21: 5 | O21: 0.75705 | P21: =I21-O21 -> 0.02195
H22: =SUM(H20:H21) -> 31 | I22: =SUM(I20:I21) -> 7.555
H23: =SUM(H22,H19,H17,H15) -> 132 | I23: =SUM(I22,I19,I17,I15) -> 32.41208 | N23: 172 | O23: 31.40593 | P23: =I23-O23 -> 1.00615
P24: =I24-O24 -> 0
P25: =I25-O25 -> 0
E26: Total | H26: =SUM(H23) -> 132 | I26: =SUM(I23) -> 32.41208 | K26: =+K13+K16+K18+K20 -> 32.41208 | N26: 172 | O26: 31.40593 | P26: =I26-O26 -> 1.00615
B27: Receiver | E27: CHECKED & VERIFIED BY | I27: FOR VINAR ISPAT LTD,
B30: Signature | E30: Dispatch/Quality Incharge | I30: Authorised Signatory
I39: =F39*G39*H39/1000 -> 0 | K39: =+I26+'[2]9844 29.12.23 BB '!I39+'[2]2190 29.12.23 JBP '!K31+'[2]0403 29.12.23 JBP (2)'!I23+'[2]0406 29.12.23 JBP'!I28 -> 161.4367

Sheet 2189  04.01.24 JBP 
A1: VINAR ISPAT LIMTED
A2: PLOT NO J 3,MIDC INDUSTRIAL AREA, BUTIBORI
K3: DOC.NO.VIL/PLN/F/05
A4: PACKING LIST
D6: LR- 27440
B8: CUSTOMER | C8: KEC INTERNATIONAL LTD. JABALPUR | J8: Date: | K8: 04.01.2024
B10: CUSTOMER | C10: KEC INTERNATIONAL LTD. JABALPUR | J10: Lorry No. | K10: MH40AK2189
A12: Sr. No. | B12: P.O.No. | C12: Grade | D12: Colour Code | E12: Grade/Section | F12: Section WT. | G12: Length in mtr. | H12: No. Of Pcs | I12: Qty. in MT. | J12: HEAT NO | K12: Challan Qty. | L12: Challan No.
A13: 1 | B13: LOI-1228 | C13: HT PG | D13: Yellow-Yellow | E13: HAE350A 120X120X8 | F13: 14.66 | G13: 11.5 | H13: 21 | I13: 3.54 | K13: =+I16 -> 9.943 | L13: 1804/ 387 | N13: 17 | O13: 1.2512 | P13: =I13-O13 -> 2.2888
F14: 14.66 | G14: 12 | H14: 8 | I14: 1.407 | N14: 4 | O14: 0.326784 | P14: =I14-O14 -> 1.080216
F15: 14.66 | G15: 7.1 | H15: 48 | I15: 4.996 | N15: 8 | O15: 0.700672 | P15: =I15-O15 -> 4.295328
H16: =SUM(H13:H15) -> 77 | I16: =SUM(I13:I15) -> 9.943 | N16: 29 | O16: 2.278656 | P16: =I16-O16 -> 7.664344
H17: =SUM(H16) -> 77 | I17: =SUM(I16) -> 9.943 | N17: 408 | O17: 33.023944 | P17: =I17-O17 -> -23.080944
P18: =I18-O18 -> 0
P19: =I19-O19 -> 0
E20: Total | H20: =+H17 -> 77 | I20: =+I17 -> 9.943 | K20: =+K13 -> 9.943 | N20: 408 | O20: 33.023944 | P20: =I20-O20 -> -23.080944
B21: Receiver | E21: CHECKED & VERIFIED BY | I21: FOR VINAR ISPAT LTD,
B24: Signature | E24: Dispatch/Quality Incharge | I24: Authorised Signatory
I33: =F33*G33*H33/1000 -> 0 | K33: =+' 0508 02.01.24 JBP '!I29+'4944 02.01.24 BUB'!I53+' 0311 02.01.24 JBP '!I32+'3944 02.01.24 BUB'!I37+'0398 02.01.24 JBP '!I33+'2189 04.01.24 JBP '!I20 -> 172.921

Sheet 0509  04.01.24 JBP
A1: VINAR ISPAT LIMTED
A2: PLOT NO J 3,MIDC INDUSTRIAL AREA, BUTIBORI
K3: DOC.NO.VIL/PLN/F/05
A4: PACKING LIST
D6: LR- 27437
B8: CUSTOMER | C8: KEC INTERNATIONAL LTD. JABALPUR | J8: Date: | K8: 04.01.2024
B10: CUSTOMER | C10: KEC INTERNATIONAL LTD. JABALPUR | J10: Lorry No. | K10: MH49AT0509
A12: Sr. No. | B12: P.O.No. | C12: Grade | D12: Colour Code | E12: Grade/Section | F12: Section WT. | G12: Length in mtr. | H12: No. Of Pcs | I12: Qty. in MT. | J12: HEAT NO | K12: Challan Qty. | L12: Challan No.
A13: 1 | B13: LOI-1228 | C13: MS PG | D13: Green-Green | E13: MAE250A 100X100X6 | F13: 9.26 | G13: 8.2 | H13: 24 | I13: 1.822 | K13: =+I17+I19+I21 -> 11.715 | L13: 1805/ 387 | N13: 17 | O13: 1.2512 | P13: =I13-O13 -> 0.5708
F14: 9.26 | G14: 10.05 | H14: 12 | I14: 1.117 | N14: 4 | O14: 0.326784 | P14: =I14-O14 -> 0.790216
F15: 9.26 | G15: 10.2 | H15: 7 | I15: 0.661 | N15: 4 | O15: 0.326784 | P15: =I15-O15 -> 0.334216
F16: 9.26 | G16: 10.5 | H16: 24 | I16: 2.334 | N16: 4 | O16: 0.326784 | P16: =I16-O16 -> 2.007216
H17: =SUM(H13:H16) -> 67 | I17: =SUM(I13:I16) -> 5.934 | N17: 29 | O17: 2.278656 | P17: =I17-O17 -> 3.655344
A18: 2 | B18: LOI-1228 | C18: MS PG | D18: Green-Green | E18: MAE250A 75X75X5 | F18: 5.77 | G18: 10.5 | H18: 53 | I18: 3.211 | N18: 17 | O18: 1.2512 | P18: =I18-O18 -> 1.9598
H19: =SUM(H18:H18) -> 53 | I19: =SUM(I18:I18) -> 3.211 | N19: 29 | O19: 2.278656 | P19: =I19-O19 -> 0.932344
A20: 3 | B20: LOI-1229 | C20: MS PG | D20: Green-Green | E20: MAE250A 100X100X6 | F20: 9.26 | G20: 10.05 | H20: 28 | I20: 2.57 | N20: 17 | O20: 1.2512 | P20: =I20-O20 -> 1.3188
H21: =SUM(H20) -> 28 | I21: =SUM(I20) -> 2.57
F22: 9.26 | G22: 10.05 | H22: 123 | I22: 11.5 | K22: =+I23 -> 11.5 | L22: 1806/ 388
H23: =SUM(H22:H22) -> 123 | I23: =SUM(I22:I22) -> 11.5
F24: 9.26 | G24: 10.05 | H24: =126+36-28-123 -> 11 | I24: =11.726+3.35-2.57-11.5 -> 1.006 | K24: =+I28+I32 -> 9.398 | L24: 1807/ 389
F25: 9.26 | G25: 10.5 | H25: 6 | I25: 0.583
F26: 9.26 | G26: 11 | H26: =20-10+13 -> 23 | I26: =1.019+1.324 -> 2.343
F27: 9.26 | G27: 12 | H27: 10 | I27: 1.111 | N27: 4 | O27: 0.326784 | P27: =I27-O27 -> 0.784216
H28: =SUM(H24:H27) -> 50 | I28: =SUM(I24:I27) -> 5.043 | N28: 29 | O28: 2.278656 | P28: =I28-O28 -> 2.764344
A29: 4 | B29: LOI-1229 | C29: MS PG | D29: Green-Green | E29: MAE250A 75X75X5 | F29: 5.77 | G29: 7.4 | H29: 37 | I29: 1.58 | N29: 17 | O29: 1.2512 | P29: =I29-O29 -> 0.3288
F30: 5.77 | G30: 8.05 | H30: 21 | I30: 0.975
F31: 5.77 | G31: 12 | H31: 26 | I31: 1.8
H32: =SUM(H29:H31) -> 84 | I32: =SUM(I29:I31) -> 4.355 | N32: 29 | O32: 2.278656 | P32: =I32-O32 -> 2.076344
H33: =SUM(H32,H28,H23,H21,H19,H17) -> 405 | I33: =SUM(I32,I28,I23,I21,I19,I17) -> 32.613 | N33: 408 | O33: 33.023944 | P33: =I33-O33 -> -0.410944
P34: =I34-O34 -> 0
P35: =I35-O35 -> 0
E36: Total | H36: =+H33 -> 405 | I36: =+I33 -> 32.613 | K36: =+K24+K22+K13 -> 32.613 | N36: 408 | O36: 33.023944 | P36: =I36-O36 -> -0.410944
B37: Receiver | E37: CHECKED & VERIFIED BY | I37: FOR VINAR ISPAT LTD,
B40: Signature | E40: Dispatch/Quality Incharge | I40: Authorised Signatory
I49: =F49*G49*H49/1000 -> 0 | K49: =+' 0508 02.01.24 JBP '!I29+'4944 02.01.24 BUB'!I53+' 0311 02.01.24 JBP '!I32+'3944 02.01.24 BUB'!I37+'0398 02.01.24 JBP '!I33+'0509 04.01.24 JBP'!I36 -> 195.591

Sheet 3081  04.01.24 JAIPUR
A1: VINAR ISPAT LIMTED
A2: PLOT NO J 3,MIDC INDUSTRIAL AREA, BUTIBORI
K3: DOC.NO.VIL/PLN/F/05
A4: PACKING LIST
D6: LR- 27436
B8: CUSTOMER | C8: KEC INTERNATIONAL LTD. BUTIBORI | J8: Date: | K8: 04.01.24
B10: CUSTOMER | C10: KEC INTERNATIONAL LTD. BUTIBORI | J10: Lorry No. | K10: MH49AT3081
A12: Sr. No. | B12: P.O.No. | C12: Grade | D12: Colour Code | E12: Grade/Section | F12: Section WT. | G12: Length in mtr. | H12: No. Of Pcs | I12: Qty. in MT. | J12: HEAT NO | K12: Challan Qty. | L12: Challan No.
A13: 1 | B13: LOI-1138 | C13: HT NPG | D13: White-Black | E13: HA355J2 75X75X5 | F13: 5.76 | G13: 10 | H13: 26 | I13: 1.498 | K13: =+I14+I25+I27 -> 7.12 | L13: 1808/ 666 | N13: 26 | O13: 1.4976 | P13: =I13-O13 -> 0.0004
H14: =SUM(H13) -> 26 | I14: =SUM(I13) -> 1.498 | N14: 26 | O14: 1.4976 | P14: =I14-O14 -> 0.0004
A15: 2 | B15: LOI-1138 | C15: HT NPG | D15: White-Black | E15: HA355J2 75X75X6 | F15: 6.85 | G15: 12 | H15: 10 | I15: 0.822 | N15: 10 | O15: 0.822 | P15: =I15-O15 -> 0
F16: 6.85 | G16: 11.5 | H16: 2 | I16: 0.158 | N16: 2 | O16: 0.15755 | P16: =I16-O16 -> 0.00045
F17: 6.85 | G17: 11.3 | H17: 2 | I17: 0.155 | N17: 2 | O17: 0.15481 | P17: =I17-O17 -> 0.00019
F18: 6.85 | G18: 11 | H18: 2 | I18: 0.151 | N18: 2 | O18: 0.1507 | P18: =I18-O18 -> 0.0003
F19: 6.85 | G19: 10.5 | H19: 1 | I19: 0.072 | N19: 1 | O19: 0.071925 | P19: =I19-O19 -> 7.5e-05
F20: 6.85 | G20: 10 | H20: 1 | I20: 0.069 | N20: 1 | O20: 0.0685 | P20: =I20-O20 -> 0.0005
F21: 6.85 | G21: 10.3 | H21: 1 | I21: 0.071 | N21: 1 | O21: 0.070555 | P21: =I21-O21 -> 0.000445
F22: 6.85 | G22: 6.5 | H22: 1 | I22: 0.045 | N22: 1 | O22: 0.044525 | P22: =I22-O22 -> 0.000475
F23: 6.85 | G23: 6.8 | H23: 1 | I23: 0.047 | N23: 1 | O23: 0.04658 | P23: =I23-O23 -> 0.00042
F24: 6.85 | G24: 10.5 | H24: 18 | I24: 1.295 | N24: 18 | O24: 1.29465 | P24: =I24-O24 -> 0.00035
H25: =SUM(H15:H24) -> 39 | I25: =SUM(I15:I24) -> 2.885 | N25: 39 | O25: 2.881795 | P25: =I25-O25 -> 0.003205
A26: 3 | B26: LOI-1138 | C26: HT NPG | D26: White-Black | E26: HA355J2 90X90X6 | F26: 8.3 | G26: 7.5 | H26: 44 | I26: 2.737 | N26: 45 | O26: 2.80125 | P26: =I26-O26 -> -0.06425
H27: =SUM(H26) -> 44 | I27: =SUM(I26) -> 2.737
F28: 8.3 | G28: 7.5 | H28: =12+30+3-44 -> 1 | I28: =2.801-2.737 -> 0.064 | K28: =+I32+I40+I42+I46+I51 -> 17.718632 | L28: 1809/ 667
F29: 8.3 | G29: 9 | H29: =6+14+1 -> 21 | I29: 1.569 | N29: 21 | O29: 1.5687 | P29: =I29-O29 -> 0.0003
F30: 8.3 | G30: 11 | H30: =2+6+7+4 -> 19 | I30: 1.735 | N30: 19 | O30: 1.7347 | P30: =I30-O30 -> 0.0003
F31: 8.3 | G31: 11.5 | H31: 26 | I31: 2.482 | N31: 26 | O31: 2.4817 | P31: =I31-O31 -> 0.0003
H32: =SUM(H28:H31) -> 67 | I32: =SUM(I28:I31) -> 5.85 | N32: 111 | O32: 8.58635 | P32: =I32-O32 -> -2.73635
A33: 4 | B33: LOI-1138 | C33: HT NPG | D33: White-Black | E33: HA355J2 90X90X7 | F33: 9.61 | G33: 6 | H33: 4 | I33: 0.231 | N33: 4 | O33: 0.23064 | P33: =I33-O33 -> 0.00036
F34: 9.61 | G34: 6.6 | H34: 1 | I34: 0.063 | N34: 1 | O34: 0.063426 | P34: =I34-O34 -> -0.000426
F35: 9.61 | G35: 7 | H35: 5 | I35: 0.336 | N35: 5 | O35: 0.33635 | P35: =I35-O35 -> -0.00035
F36: 9.61 | G36: 9 | H36: 4 | I36: 0.346 | N36: 4 | O36: 0.34596 | P36: =I36-O36 -> 4e-05
F37: 9.61 | G37: 9.5 | H37: 4 | I37: 0.365 | N37: 4 | O37: 0.36518 | P37: =I37-O37 -> -0.00018
F38: 9.61 | G38: 10 | H38: 4 | I38: 0.384 | N38: 4 | O38: 0.3844 | P38: =I38-O38 -> -0.0004
F39: 9.61 | G39: 11.25 | H39: 3 | I39: 0.324 | N39: 3 | O39: 0.3243375 | P39: =I39-O39 -> -0.0003375
H40: =SUM(H33:H39) -> 25 | I40: =SUM(I33:I39) -> 2.049 | N40: 25 | O40: 2.0502935 | P40: =I40-O40 -> -0.0012935
A41: 5 | B41: LOI-1138 | C41: MS NPG | D41: Grey-Black | E41: MA275J2 75X75X5 | F41: 5.76 | G41: 6.5 | H41: 14 | I41: 0.524 | N41: 14 | O41: 0.52416 | P41: =I41-O41 -> -0.00016
H42: =SUM(H41) -> 14 | I42: =SUM(I41) -> 0.524 | N42: 14 | O42: 0.52416 | P42: =I42-O42 -> -0.00016
A43: 6 | B43: LOI-1341 | C43: MS NPG | D43: Green-Pink | E43: MAE250A 90X90X5 | F43: 6.97 | G43: 9.5 | H43: 10 | I43: 0.662 | N43: 10 | O43: 0.66215 | P43: =I43-O43 -> -0.00015
F44: 6.97 | G44: 10 | H44: 27 | I44: 1.882 | N44: 27 | O44: 1.8819 | P44: =I44-O44 -> 0.0001
...

Sheet 5844  04.01.24 BB  
A1: VINAR ISPAT LIMTED
A2: PLOT NO J 3,MIDC INDUSTRIAL AREA, BUTIBORI
K3: DOC.NO.VIL/PLN/F/05
A4: PACKING LIST
D6: LR- 2070
B8: CUSTOMER | C8: KEC INTERNATIONAL LTD. BUTIBORI | J8: Date: | K8: 04.01.2024
B10: CUSTOMER | C10: KEC INTERNATIONAL LTD. BUTIBORI | J10: Lorry No. | K10: MH40Y5844
A12: Sr. No. | B12: P.O.No. | C12: Grade | D12: Colour Code | E12: Grade/Section | F12: Section WT. | G12: Length in mtr. | H12: No. Of Pcs | I12: Qty. in MT. | J12: HEAT NO | K12: Challan Qty. | L12: Challan No.
A13: 1 | B13: LOI-643 | C13: HT NPG | D13: White-Black | E13: HA355J2 80X80X6 | F13: 7.34 | G13: 10 | H13: 39 | I13: 2.863 | K13: =+I18+I22+I24+I26 -> 21.654 | L13: 1811/ 669 | N13: 39 | O13: 2.8626 | P13: =I13-O13 -> 0.0004
F14: 7.34 | G14: 10.5 | H14: 23 | I14: 1.773 | N14: 23 | O14: 1.77261 | P14: =I14-O14 -> 0.00039
F15: 7.34 | G15: 11 | H15: 20 | I15: 1.615 | N15: 20 | O15: 1.6148
F16: 7.34 | G16: 11.5 | H16: 8 | I16: 0.675 | N16: 8 | O16: 0.67528
F17: 7.34 | G17: 12 | H17: 1 | I17: 0.088 | N17: 1 | O17: 0.08808
H18: =SUM(H13:H17) -> 91 | I18: =SUM(I13:I17) -> 7.014 | N18: 91 | O18: 7.01337 | P18: =I18-O18 -> 0.00063
A19: 2 | B19: LOI-643 | C19: HT NPG | D19: White-Black | E19: HA355J2 90X90X6 | F19: 8.3 | G19: 9 | H19: 52 | I19: 3.884 | N19: 52 | O19: 3.8844
F20: 8.3 | G20: 11 | H20: 28 | I20: 2.556 | N20: 28 | O20: 2.5564
F21: 8.3 | G21: 11.1 | H21: 30 | I21: 2.764 | N21: 30 | O21: 2.7639
H22: =SUM(H19:H21) -> 110 | I22: =SUM(I19:I21) -> 9.204 | N22: 110 | O22: 9.2047
A23: 3 | B23: LOI-643 | C23: HT NPG | D23: White-Black | E23: HA355J2 75X75X4 | F23: 4.65 | G23: 11.5 | H23: 38 | I23: 2.032 | N23: 38 | O23: 2.03205
H24: =SUM(H23) -> 38 | I24: =SUM(I23) -> 2.032 | N24: 38 | O24: 2.03205
A25: 4 | B25: LOI-645 | C25: HT NPG | D25: White-Black | E25: HA355J2 120X120X10 | F25: 18.2 | G25: 6.7 | H25: 28 | I25: 3.404 | N25: 35 | O25: 4.2679
H26: =SUM(H25) -> 28 | I26: =SUM(I25) -> 3.404
F27: 18.2 | G27: 6.7 | H27: =35-28 -> 7 | I27: =4.268-3.404 -> 0.864 | K27: =+I29+I31+I33+I35+I37+I39+I42+I44+I46 -> 11.351 | L27: 1812/ 670
F28: 18.2 | G28: 11.1 | H28: 6 | I28: 1.212 | N28: 6 | O28: 1.21212
H29: =SUM(H27:H28) -> 13 | I29: =SUM(I27:I28) -> 2.076 | N29: 41 | O29: 5.48002
A30: 5 | B30: LOI-645 | C30: HT NPG | D30: White-Black | E30: HA355J2 120X120X8 | F30: 14.7 | G30: 11.7 | H30: 14 | I30: 2.408 | N30: 14 | O30: 2.40786
H31: =SUM(H30:H30) -> 14 | I31: =SUM(I30:I30) -> 2.408 | N31: 14 | O31: 2.40786
A32: 6 | B32: LOI-645 | C32: HT NPG | D32: White-Black | E32: HA355J2 100X100X9 | F32: 13.6 | G32: 7.6 | H32: 24 | I32: 2.481 | N32: 24 | O32: 2.48064
H33: =SUM(H32:H32) -> 24 | I33: =SUM(I32:I32) -> 2.481 | N33: 24 | O33: 2.48064
A34: 7 | B34: LOI-1131 | C34: HT NPG | D34: White-Black | E34: HA355J2 110X110X9 | F34: 15 | G34: 9.5 | H34: 2 | I34: 0.285 | N34: 2 | O34: 0.285
H35: =SUM(H34:H34) -> 2 | I35: =SUM(I34:I34) -> 0.285 | N35: 2 | O35: 0.285
A36: 8 | B36: LOI-1131 | C36: HT NPG | D36: White-Black | E36: HA355J2 130X130X9 | F36: 17.9 | G36: 12 | H36: 3 | I36: 0.644 | N36: 3 | O36: 0.6444
H37: =SUM(H36:H36) -> 3 | I37: =SUM(I36:I36) -> 0.644 | N37: 3 | O37: 0.6444
A38: 9 | B38: LOI-1131 | C38: HT NPG | D38: White-Black | E38: HA355J2 90X90X7 | F38: 9.61 | G38: 7.6 | H38: 7 | I38: 0.511 | N38: 7 | O38: 0.511252
H39: =SUM(H38:H38) -> 7 | I39: =SUM(I38:I38) -> 0.511 | N39: 7 | O39: 0.511252
A40: 10 | B40: LOI-1131 | C40: MS NPG | D40: Green-Black | E40: MA275J2 90X90X6 | F40: 8.3 | G40: 10 | H40: 1 | I40: 0.083 | N40: 1 | O40: 0.083
F41: 8.3 | G41: 10.5 | H41: 1 | I41: 0.087 | N41: 1 | O41: 0.08715
H42: =SUM(H40:H41) -> 2 | I42: =SUM(I40:I41) -> 0.17 | N42: 2 | O42: 0.17015
A43: 11 | B43: LOI-1047 | C43: HT NPG | D43: Yellow-Pink | E43: HAE350A 130X130X10 | F43: 19.8 | G43: 7.1 | H43: 6 | I43: 0.843 | N43: 6 | O43: 0.84348
H44: =SUM(H43:H43) -> 6 | I44: =SUM(I43:I43) -> 0.843 | N44: 6 | O44: 0.84348
...

Sheet  5644 04.01.24 BB
A1: VINAR ISPAT LIMTED
A2: PLOT NO J 3,MIDC INDUSTRIAL AREA, BUTIBORI
K3: DOC.NO.VIL/PLN/F/05
A4: PACKING LIST
D6: LR- 2071
B8: CUSTOMER | C8: KEC INTERNATIONAL LTD. BUTIBORI | J8: Date: | K8: 04.01.2024
B10: CUSTOMER | C10: KEC INTERNATIONAL LTD. BUTIBORI | J10: Lorry No. | K10: MH40Y5644
A12: Sr. No. | B12: P.O.No. | C12: Grade | D12: Colour Code | E12: Grade/Section | F12: Section WT. | G12: Length in mtr. | H12: No. Of Pcs | I12: Qty. in MT. | J12: HEAT NO | K12: Challan Qty. | L12: Challan No.
A13: 1 | B13: LOI-645 | C13: HT NPG | D13: White-Black | E13: HA355J2 150X150X12 | F13: 27.3 | G13: 12.75 | H13: 51 | I13: 17.973 | K13: =+I14 -> 17.973 | L13: 1813/ 670 | N13: 53 | O13: 18.447975
H14: =SUM(H13:H13) -> 51 | I14: =SUM(I13:I13) -> 17.973 | N14: 98 | O14: 33.37425
F15: 27.3 | G15: 12.75 | H15: =53-51 -> 2 | I15: =18.448-17.973 -> 0.475 | K15: =+I17 -> 15.401 | L15: 1814/ 672
F16: 27.3 | G16: 12.15 | H16: 45 | I16: 14.926
H17: =SUM(H15:H16) -> 47 | I17: =SUM(I15:I16) -> 15.401
H18: =SUM(H17,H14) -> 98 | I18: =SUM(I17,I14) -> 33.374
P19: =I19-O19 -> 0
E20: Total | H20: =+H18 -> 98 | I20: =+I18 -> 33.374 | K20: =+K13+K15 -> 33.374 | N20: 297 | O20: 32.700847 | P20: =I20-O20 -> 0.673153
B21: Receiver | E21: CHECKED & VERIFIED BY | I21: FOR VINAR ISPAT LTD,
B24: Signature | E24: Dispatch/Quality Incharge | I24: Authorised Signatory
I33: =F33*G33*H33/1000 -> 0 | J33: =+I20+'0403 03.01.24 JBP '!I32+'5844 03.01.24 BUB'!I26+'4944 03.01.24 BUB '!I30+'7423 03.01.24 JBP'!I32 -> 163.70995 | K33: =+'7423 03.01.24 JBP'!I32+'4944 03.01.24 BUB '!I30+'5844 03.01.24 BUB'!I26+'0403 03.01.24 JBP '!I32+' 5644 04.01.24 BB'!I20 -> 163.70995

Sheet 6003  04.01.24 JBP
A1: VINAR ISPAT LIMTED
A2: PLOT NO J 3,MIDC INDUSTRIAL AREA, BUTIBORI
K3: DOC.NO.VIL/PLN/F/05
A4: PACKING LIST
D6: LR- 27439
B8: CUSTOMER | C8: KEC INTERNATIONAL LTD. JABALPUR | J8: Date: | K8: 04.01.2024
B10: CUSTOMER | C10: KEC INTERNATIONAL LTD. JABALPUR | J10: Lorry No. | K10: MH40AK6003
A12: Sr. No. | B12: P.O.No. | C12: Grade | D12: Colour Code | E12: Grade/Section | F12: Section WT. | G12: Length in mtr. | H12: No. Of Pcs | I12: Qty. in MT. | J12: HEAT NO | K12: Challan Qty. | L12: Challan No.
A13: 1 | B13: LOI-1229 | C13: HT PG | D13: Yellow-Yellow | E13: HAE350A 80X80X5 | F13: 6.17 | G13: 10 | H13: 14 | I13: 0.86 | K13: =+I14 -> 0.86 | L13: 1815/ 389 | N13: 30 | O13: 1.851 | P13: =I13-O13 -> -0.991
H14: =SUM(H13) -> 14 | I14: =SUM(I13) -> 0.86
F15: 6.17 | G15: 10 | H15: =30-14 -> 16 | I15: =1.851-0.86 -> 0.991 | K15: =+I17+I22+I25 -> 29.284 | L15: 1816/ 390
F16: 6.17 | G16: 10.75 | H16: 95 | I16: 6.301 | N16: 95 | O16: 6.3011125 | P16: =I16-O16 -> -0.0001125
H17: =SUM(H15:H16) -> 111 | I17: =SUM(I15:I16) -> 7.292 | N17: 125 | O17: 8.1521125 | P17: =I17-O17 -> -0.8601125
A18: 2 | B18: LOI-1229 | C18: HT PG | D18: Yellow-Yellow | E18: HAE350A 80X80X6 | F18: 7.36 | G18: 7.5 | H18: 32 | I18: 1.766 | N18: 32 | O18: 1.7664 | P18: =I18-O18 -> -0.0004
F19: 7.36 | G19: 9.25 | H19: 80 | I19: 5.446 | N19: 80 | O19: 5.4464 | P19: =I19-O19 -> -0.0004
F20: 7.36 | G20: 10.3 | H20: 165 | I20: 12.508 | N20: 165 | O20: 12.50832 | P20: =I20-O20 -> -0.00032
F21: 7.36 | G21: 12 | H21: 18 | I21: 1.59 | N21: 18 | O21: 1.58976 | P21: =I21-O21 -> 0.00024
H22: =SUM(H18:H21) -> 295 | I22: =SUM(I18:I21) -> 21.31 | N22: 295 | O22: 21.31088 | P22: =I22-O22 -> -0.00088
A23: 3 | B23: LOI-1228 | C23: HT PG | D23: Yellow-Yellow | E23: HAE350A 80X80X6 | F23: 7.36 | G23: 10 | H23: 5 | I23: 0.368 | N23: 5 | O23: 0.368 | P23: =I23-O23 -> 0
F24: 7.36 | G24: 11.9 | H24: 3 | I24: 0.314 | N24: 7 | O24: 0.613088 | P24: =I24-O24 -> -0.299088
H25: =SUM(H23:H24) -> 8 | I25: =SUM(I23:I24) -> 0.682
F26: 7.36 | G26: 11.9 | H26: =7-3 -> 4 | I26: =0.613-0.314 -> 0.299 | K26: =+I28 -> 2.507 | L26: 1817/ 391
F27: 7.36 | G27: 12 | H27: 25 | I27: 2.208 | N27: 25 | O27: 2.208 | P27: =I27-O27 -> 0
H28: =SUM(H26:H27) -> 29 | I28: =SUM(I26:I27) -> 2.507 | N28: 37 | O28: 3.189088 | P28: =I28-O28 -> -0.682088
H29: =SUM(H28,H25,H22,H17,H14) -> 457 | I29: =SUM(I28,I25,I22,I17,I14) -> 32.651 | N29: 457 | O29: 32.652081 | P29: =I29-O29 -> -0.0010805
P30: =I30-O30 -> 0
E31: Total | H31: =+H29 -> 457 | I31: =+I29 -> 32.651 | K31: =+K26+K15+K13 -> 32.651 | N31: 457 | O31: 32.652081 | P31: =I31-O31 -> -0.0010805
B32: Receiver | E32: CHECKED & VERIFIED BY | I32: FOR VINAR ISPAT LTD,
B35: Signature | E35: Dispatch/Quality Incharge | I35: Authorised Signatory
I44: =F44*G44*H44/1000 -> 0 | K44: =+I31+' 5644 04.01.24 BB'!I20+'5844 04.01.24 BB '!I49+'3081 04.01.24 JAIPUR'!I68+'0509 04.01.24 JBP'!I36+'2189 04.01.24 JBP '!I20 -> 174.18263

Sheet 6074  05.01.24 JBP
A1: VINAR ISPAT LIMTED
A2: PLOT NO J 3,MIDC INDUSTRIAL AREA, BUTIBORI
K3: DOC.NO.VIL/PLN/F/05
A4: PACKING LIST
D6: LR- 27441
B8: CUSTOMER | C8: KEC INTERNATIONAL LTD. JABALPUR | J8: Date: | K8: 05.01.2024
B10: CUSTOMER | C10: KEC INTERNATIONAL LTD. JABALPUR | J10: Lorry No. | K10: MH40AK6074
A12: Sr. No. | B12: P.O.No. | C12: Grade | D12: Colour Code | E12: Grade/Section | F12: Section WT. | G12: Length in mtr. | H12: No. Of Pcs | I12: Qty. in MT. | J12: HEAT NO | K12: Challan Qty. | L12: Challan No.
A13: 1 | B13: LOI-1228 | C13: HT PG | D13: Yellow-Yellow | E13: HAE350A 120X120X7 | F13: 12.9 | G13: 10 | H13: 9 | I13: 1.161 | K13: =+I18+I22+I25+I29 -> 26.767 | L13: 1818/ 391 | N13: 9 | O13: 1.161 | P13: =I13-O13 -> 0
F14: 12.9 | G14: 10.5 | H14: 26 | I14: 3.522 | N14: 26 | O14: 3.5217 | P14: =I14-O14 -> 0.0003
F15: 12.9 | G15: 11 | H15: 3 | I15: 0.426 | N15: 3 | O15: 0.4257 | P15: =I15-O15 -> 0.0003
F16: 12.9 | G16: 11.5 | H16: 23 | I16: 3.412 | N16: 23 | O16: 3.41205 | P16: =I16-O16 -> -5e-05
F17: 12.9 | G17: 12 | H17: 39 | I17: 6.037 | N17: 39 | O17: 6.0372 | P17: =I17-O17 -> -0.0002
H18: =SUM(H13:H17) -> 100 | I18: =SUM(I13:I17) -> 14.558 | N18: 100 | O18: 14.55765 | P18: =I18-O18 -> 0.00035
A19: 2 | B19: LOI-1228 | C19: HT PG | D19: Yellow-Yellow | E19: HAE350A 120X120X9 | F19: 16.5 | G19: 10.3 | H19: 4 | I19: 0.68 | N19: 4 | O19: 0.6798 | P19: =I19-O19 -> 0.0002
F20: 16.5 | G20: 11.2 | H20: 13 | I20: 2.402 | N20: 13 | O20: 2.4024 | P20: =I20-O20 -> -0.0004
F21: 16.5 | G21: 11.5 | H21: 8 | I21: 1.518 | N21: 8 | O21: 1.518 | P21: =I21-O21 -> 0
H22: =SUM(H19:H21) -> 25 | I22: =SUM(I19:I21) -> 4.6 | N22: 25 | O22: 4.6002 | P22: =I22-O22 -> -0.0002
A23: 3 | B23: LOI-1228 | C23: HT PG | D23: Yellow-Yellow | E23: HAE350A 110X110X7 | F23: 11.8 | G23: 10.5 | H23: 16 | I23: 1.982 | N23: 16 | O23: 1.9824 | P23: =I23-O23 -> -0.0004
F24: 11.8 | G24: 11.7 | H24: 29 | I24: 4.004 | N24: 29 | O24: 4.00374 | P24: =I24-O24 -> 0.00026
H25: =SUM(H23:H24) -> 45 | I25: =SUM(I23:I24) -> 5.986 | N25: 45 | O25: 5.98614 | P25: =I25-O25 -> -0.00014
A26: 4 | B26: LOI-1228 | C26: HT PG | D26: Yellow-Yellow | E26: HAE350A 110X110X6 | F26: 10.2 | G26: 8.3 | H26: 8 | I26: 0.677 | N26: 8 | O26: 0.67728 | P26: =I26-O26 -> -0.00028
F27: 10.2 | G27: 9.2 | H27: 9 | I27: 0.845 | N27: 9 | O27: 0.84456 | P27: =I27-O27 -> 0.00044
F28: 10.2 | G28: 9.8 | H28: 1 | I28: 0.101 | N28: 13 | O28: 1.29948 | P28: =I28-O28 -> -1.19848
H29: =SUM(H26:H28) -> 18 | I29: =SUM(I26:I28) -> 1.623
F30: 10.2 | G30: 9.8 | H30: =13-1 -> 12 | I30: =1.299-0.101 -> 1.198 | K30: =+I33 -> 5.444 | L30: 1819/ 392
F31: 10.2 | G31: 11 | H31: 7 | I31: 0.785 | N31: 7 | O31: 0.7854 | P31: =I31-O31 -> -0.0004
F32: 10.2 | G32: 11.7 | H32: 29 | I32: 3.461 | N32: 29 | O32: 3.46086 | P32: =I32-O32 -> 0.00014
H33: =SUM(H30:H32) -> 48 | I33: =SUM(I30:I32) -> 5.444 | N33: 66 | O33: 7.06758 | P33: =I33-O33 -> -1.62358
H34: =SUM(H33,H29,H25,H22,H18) -> 236 | I34: =SUM(I33,I29,I25,I22,I18) -> 32.211 | N34: 236 | O34: 32.21157 | P34: =I34-O34 -> -0.00057
