Workbook

Sheet SUMMARY 
A1: Vinar BUB Angle Section wt. & Kata wt. Difference 2023-2024 | I1: Dispatched
A2: MONTHS | B2: KATA WT | C2: SEC.WT | D2: (+) WT | E2: (-)WT | F2: Net (+/-) mt | G2: Net (+/-) % | I2: PG Qty | J2: NPG Qty | K2: TOTAL
A3: Apr,23 | B3: =+'APRIL-23'!D76 -> 2093.706 | C3: =+'APRIL-23'!E76 -> 2100.519 | D3: =+'APRIL-23'!F76 -> 3.004 | E3: =+'APRIL-23'!G76 -> -9.817 | F3: =SUM(D3:E3) -> -6.813 | G3: =F3/C3 -> -0.0032434841 | J3: =C3-I3 -> 2100.519 | K3: =+J3+I3 -> 2100.519
A4: 45064 | B4: =+'May -23 '!D30 -> 716.38 | C4: =+'May -23 '!E30 -> 717.3 | D4: =+'May -23 '!F30 -> 0.927 | E4: =+'May -23 '!G30 -> -1.847 | F4: =SUM(D4:E4) -> -0.92 | G4: =F4/C4 -> -0.0012825875 | J4: =C4-I4 -> 717.3 | K4: =+J4+I4 -> 717.3
A5: 45095 | B5: =+'JUN -23'!D97 -> 2545.97 | C5: =+'JUN -23'!E97 -> 2546.762 | D5: =+'JUN -23'!F97 -> 4.716 | E5: =+'JUN -23'!G97 -> -5.508 | F5: =SUM(D5:E5) -> -0.792 | G5: =F5/C5 -> -0.00031098312 | J5: =C5-I5 -> 2546.762 | K5: =+J5+I5 -> 2546.762
A6: 45125 | B6: =+'JULY -23 '!D94 -> 2575.02 | C6: =+'JULY -23 '!E94 -> 2578.611 | D6: =+'JULY -23 '!F94 -> 5.857 | E6: =+'JULY -23 '!G94 -> -9.448 | F6: =SUM(D6:E6) -> -3.591 | G6: =F6/C6 -> -0.0013926102 | J6: =C6-I6 -> 2578.611 | K6: =+J6+I6 -> 2578.611
A7: 45156 | B7: =+'AUG -23 '!D132 -> 3794.337 | C7: =+'AUG -23 '!E132 -> 3801.575 | D7: =+'AUG -23 '!F132 -> 7.62 | E7: =+'AUG -23 '!G132 -> -14.858 | F7: =SUM(D7:E7) -> -7.238 | G7: =F7/C7 -> -0.0019039477 | J7: =C7-I7 -> 3801.575 | K7: =+J7+I7 -> 3801.575
A8: 45187 | B8: =+'SEP -23'!D109 -> 2948.87 | C8: =+'SEP -23'!E109 -> 2935.752 | D8: =+'SEP -23'!F109 -> 15.553 | E8: =+'SEP -23'!G109 -> -2.435 | F8: =SUM(D8:E8) -> 13.118 | G8: =F8/C8 -> 0.0044683611 | J8: =C8-I8 -> 2935.752 | K8: =+J8+I8 -> 2935.752
A9: 45217 | B9: =+'OCT -23 '!D111 -> 3372.077 | C9: =+'OCT -23 '!E111 -> 3365.74 | D9: =+'OCT -23 '!F111 -> 13.32 | E9: =+'OCT -23 '!G111 -> -6.983 | F9: =SUM(D9:E9) -> 6.337 | G9: =F9/C9 -> 0.0018827955 | J9: =C9-I9 -> 3365.74 | K9: =+J9+I9 -> 3365.74
A10: 45248 | B10: =+'NOV -23 '!D128 -> 3765.076 | C10: =+'NOV -23 '!E128 -> 3768.776 | D10: =+'NOV -23 '!F128 -> 5.937285 | E10: =+'NOV -23 '!G128 -> -9.63729 | F10: =SUM(D10:E10) -> -3.700005 | G10: =F10/C10 -> -0.00098175243 | J10: =C10-I10 -> 3768.776 | K10: =+J10+I10 -> 3768.776
A11: 45278 | B11: =+'DEC -23'!D146 -> 4478.94 | C11: =+'DEC -23'!E146 -> 4497.1434 | D11: =+'DEC -23'!F146 -> 6.16204 | E11: =+'DEC -23'!G146 -> -24.365402 | F11: =+'DEC -23'!H146 -> -18.203362 | G11: =F11/C11 -> -0.004047761 | J11: =C11-I11 -> 4497.1434 | K11: =+J11+I11 -> 4497.1434
A12: 45310 | B12: =+'JAN -24 '!D147 -> 2047.18 | C12: =+'JAN -24 '!E147 -> 2053.242 | D12: =+'JAN -24 '!F147 -> 2.929 | E12: =+'JAN -24 '!G147 -> -8.991 | F12: =+'JAN -24 '!H147 -> -6.062 | G12: =F12/C12 -> -0.0029524041 | J12: =C12-I12 -> 2053.242 | K12: =+J12+I12 -> 2053.242
A13: 45342 | G13: =F13/C13 -> #DIV/0! | J13: =C13-I13 -> 0 | K13: =+J13+I13 -> 0
A14: 45371 | G14: =F14/C14 -> #DIV/0! | J14: =C14-I14 -> 0 | K14: =+J14+I14 -> 0
G15: =F15/C15 -> #DIV/0! | J15: =C15-I15 -> 0 | K15: =+J15+I15 -> 0
J16: =C16-I16 -> 0 | K16: =+J16+I16 -> 0
B18: =SUM(B3:B16) -> 28337.556 | C18: =SUM(C3:C16) -> 28365.42 | D18: =SUM(D3:D16) -> 66.025325 | E18: =SUM(E3:E16) -> -93.889692 | F18: =SUM(F3:F16) -> -27.864367 | G18: =F18/C18 -> -0.00098233575 | I18: =SUM(I3:I16) -> 0 | J18: =SUM(J3:J16) -> 28365.42 | K18: =SUM(K3:K16) -> 28365.42

Sheet APRIL-23
B2: SEC.& KATA WT,DIFFERENCE ANGLE aPRIL 2023 (vil bub)
B4: DISP.DATE | C4: PARTY | D4: KATA WT | E4: SEC.WT | F4: (+) WT | G4: (-)WT | H4: VEHICLE.NO. | I4: SECTION | J4: Net (+/-) %
B5: 04.04.23 | C5: KEC BUB | D5: 24.27 | E5: 24.507 | F5: =IF(D5-E5<=0,0,D5-E5) -> 0 | G5: =IF(D5-E5>=0,0,D5-E5) -> -0.237 | H5: MH31FC2568 | I5: MS-90X6 | J5: =G5/E5 -> -0.0096707063
B6: 04.04.23 | C6: KEC BUB | D6: 24.96 | E6: 25.229 | F6: =IF(D6-E6<=0,0,D6-E6) -> 0 | G6: =IF(D6-E6>=0,0,D6-E6) -> -0.269 | H6: MH40CM3182 | I6: MS-80X6 | J6: =G6/E6 -> -0.010662333
B7: 04.04.23 | C7: KEC BUB | D7: 24.21 | E7: 24.437 | F7: =IF(D7-E7<=0,0,D7-E7) -> 0 | G7: =IF(D7-E7>=0,0,D7-E7) -> -0.227 | H7: MH31FCC2213 | I7: MS-90X90X7,6 | J7: =G7/E7 -> -0.0092891926
B8: 05.04.23 | C8: KEC BUB | D8: 24.58 | E8: 24.488 | F8: =IF(D8-E8<=0,0,D8-E8) -> 0.092 | G8: =IF(D8-E8>=0,0,D8-E8) -> 0 | H8: MH31FC2620 | I8: HT-150X20 | J8: =F8/E8 -> 0.0037569422
B9: 05.04.23 | C9: KEC BUB | D9: 24.55 | E9: 24.471 | F9: =IF(D9-E9<=0,0,D9-E9) -> 0.079 | G9: =IF(D9-E9>=0,0,D9-E9) -> 0 | H9: MH31FC2629 | I9: HT-100X7,80X80X6 | J9: =F9/E9 -> 0.0032283111
B10: 06.04.23 | C10: KEC BUB | D10: 24.81 | E10: 24.877 | F10: =IF(D10-E10<=0,0,D10-E10) -> 0 | G10: =IF(D10-E10>=0,0,D10-E10) -> -0.067 | H10: MH31FC2568 | I10: HT-150X16 | J10: =G10/E10 -> -0.0026932508
B11: 06.04.23 | C11: KEC BUB | D11: 24.95 | E11: 24.968 | F11: =IF(D11-E11<=0,0,D11-E11) -> 0 | G11: =IF(D11-E11>=0,0,D11-E11) -> -0.018 | H11: MH40CM3181 | I11: HT-150X16 | J11: =G11/E11 -> -0.00072092278
B12: 06.04.23 | C12: KEC BUB | D12: 24.42 | E12: 24.567 | F12: =IF(D12-E12<=0,0,D12-E12) -> 0 | G12: =IF(D12-E12>=0,0,D12-E12) -> -0.147 | H12: MH31FC2213 | I12: MS-90X6 | J12: =G12/E12 -> -0.0059836366
B13: 06.04.23 | C13: KEC BUB | D13: 24.59 | E13: 24.858 | F13: =IF(D13-E13<=0,0,D13-E13) -> 0 | G13: =IF(D13-E13>=0,0,D13-E13) -> -0.268 | H13: MH31FC2566 | I13: MS-90X7 | J13: =G13/E13 -> -0.010781237
B14: 06.04.23 | C14: KEC BUB | D14: 24.39 | E14: 24.758 | F14: =IF(D14-E14<=0,0,D14-E14) -> 0 | G14: =IF(D14-E14>=0,0,D14-E14) -> -0.368 | H14: MH40CM3182 | I14: MS-90X6 | J14: =G14/E14 -> -0.014863882
B15: 08.04.23 | C15: KEC BUB | D15: 24.5 | E15: 24.488 | F15: =IF(D15-E15<=0,0,D15-E15) -> 0.012 | G15: =IF(D15-E15>=0,0,D15-E15) -> 0 | H15: MH31FC2623 | I15: HT-150X16 | J15: =F15/E15 -> 0.00049003594
B16: 08.04.23 | C16: KEC BUB | D16: 24.46 | E16: 24.62 | F16: =IF(D16-E16<=0,0,D16-E16) -> 0 | G16: =IF(D16-E16>=0,0,D16-E16) -> -0.16 | H16: MH361155 | I16: HT-150X15 | J16: =G16/E16 -> -0.0064987815
B17: 08.04.23 | C17: KEC BUB | D17: 24.47 | E17: 24.51 | F17: =IF(D17-E17<=0,0,D17-E17) -> 0 | G17: =IF(D17-E17>=0,0,D17-E17) -> -0.04 | H17: MH31FC2338 | I17: MS-80X6 | J17: =G17/E17 -> -0.0016319869
B18: 08.04.23 | C18: KEC BUB | D18: 24.5 | E18: 24.398 | F18: =IF(D18-E18<=0,0,D18-E18) -> 0.102 | G18: =IF(D18-E18>=0,0,D18-E18) -> 0 | H18: MH40CM3182 | I18: HT-150X12 | J18: =F18/E18 -> 0.0041806705
B19: 09.04.23 | C19: KEC BUB | D19: 25.12 | E19: 25.29 | F19: =IF(D19-E19<=0,0,D19-E19) -> 0 | G19: =IF(D19-E19>=0,0,D19-E19) -> -0.17 | H19: MH31FC2620 | I19: HT-150X15 | J19: =G19/E19 -> -0.0067220245
B20: 09.04.23 | C20: KEC BUB | D20: 24.63 | E20: 24.696 | F20: =IF(D20-E20<=0,0,D20-E20) -> 0 | G20: =IF(D20-E20>=0,0,D20-E20) -> -0.066 | H20: MH40N5505 | I20: HT-80X6 MS-10X6,8 80X6 | J20: =G20/E20 -> -0.0026724976
B21: 09.04.23 | C21: KEC BUB | D21: 25.08 | E21: 25.35 | F21: =IF(D21-E21<=0,0,D21-E21) -> 0 | G21: =IF(D21-E21>=0,0,D21-E21) -> -0.27 | H21: MH34AB1845 | I21: MS-9X6,80X6, 75X6 | J21: =G21/E21 -> -0.010650888
B22: 09.04.23 | C22: KEC BUB | D22: 24.16 | E22: 24.308 | F22: =IF(D22-E22<=0,0,D22-E22) -> 0 | G22: =IF(D22-E22>=0,0,D22-E22) -> -0.148 | H22: MH40AK0269 | I22: MS-100X6 | J22: =G22/E22 -> -0.0060885305
B23: 09.04.23 | C23: KEC BUB | D23: 31.26 | E23: 31.301 | F23: =IF(D23-E23<=0,0,D23-E23) -> 0 | G23: =IF(D23-E23>=0,0,D23-E23) -> -0.041 | H23: MH46AR8099 | I23: MS-65X5,90X5,75X6,5 | J23: =G23/E23 -> -0.0013098623
B24: 10.04.23 | C24: KEC BUB | D24: 31.82 | E24: 31.919 | F24: =IF(D24-E24<=0,0,D24-E24) -> 0 | G24: =IF(D24-E24>=0,0,D24-E24) -> -0.099 | H24: MH40Y4044 | I24: HT-75X5,6 90X6, | J24: =G24/E24 -> -0.0031016009
B25: 10.04.23 | C25: KEC BUB | D25: 24.49 | E25: 25.072 | F25: =IF(D25-E25<=0,0,D25-E25) -> 0 | G25: =IF(D25-E25>=0,0,D25-E25) -> -0.582 | H25: MH31FC2622 | I25: HT-75X6, MS-75X6 | J25: =G25/E25 -> -0.023213146
B26: 10.04.23 | C26: KEC BUB | D26: 31.26 | E26: 31.497 | F26: =IF(D26-E26<=0,0,D26-E26) -> 0 | G26: =IF(D26-E26>=0,0,D26-E26) -> -0.237 | H26: MH40Y2044 | I26: HT-90X6 | J26: =G26/E26 -> -0.0075245261
B27: 11.04.23 | C27: KEC BUB | D27: 25.21 | E27: 24.979 | F27: =IF(D27-E27<=0,0,D27-E27) -> 0.231 | G27: =IF(D27-E27>=0,0,D27-E27) -> 0 | H27: MH31FC5543 | I27: HT-100X7, 150X12 MS-75X6 | J27: =F27/E27 -> 0.0092477681
B28: 11.04.23 | C28: KEC BUB | D28: 31.91 | E28: 31.931 | F28: =IF(D28-E28<=0,0,D28-E28) -> 0 | G28: =IF(D28-E28>=0,0,D28-E28) -> -0.021 | H28: MH40Y3944 | I28: HT-90X6,90X5, 90X7 | J28: =G28/E28 -> -0.0006576681
B29: 11.04.23 | C29: KEC BUB | D29: 30.88 | E29: 31.021 | F29: =IF(D29-E29<=0,0,D29-E29) -> 0 | G29: =IF(D29-E29>=0,0,D29-E29) -> -0.141 | H29: MH46AR4423 | I29: HT-90X6 | J29: =G29/E29 -> -0.004545308
B30: 11.04.23 | C30: KEC BUB | D30: 24.69 | E30: 24.943 | F30: =IF(D30-E30<=0,0,D30-E30) -> 0 | G30: =IF(D30-E30>=0,0,D30-E30) -> -0.253 | H30: MH31FC2564 | I30: MS-100X6,8,9,MS-80X6 HT-150X15,12 | J30: =G30/E30 -> -0.010143126
B31: 12.04.23 | C31: KEC BUB | D31: 32.58 | E31: 32.52 | F31: =IF(D31-E31<=0,0,D31-E31) -> 0.06 | G31: =IF(D31-E31>=0,0,D31-E31) -> 0 | H31: MH46AR4423 | I31: HT-90X5, 90X7, 110X10 | J31: =F31/E31 -> 0.0018450185
B32: 12.04.23 | C32: KEC BUB | D32: 32.54 | E32: 32.949 | F32: =IF(D32-E32<=0,0,D32-E32) -> 0 | G32: =IF(D32-E32>=0,0,D32-E32) -> -0.409 | H32: MH46AF3590 | I32: HT-90X6,7 | J32: =G32/E32 -> -0.012413123
B33: 13.04.23 | C33: KEC BUB | D33: =24.83+0.306 -> 25.136 | E33: 25.145 | F33: =IF(D33-E33<=0,0,D33-E33) -> 0 | G33: =IF(D33-E33>=0,0,D33-E33) -> -0.009 | H33: MH31FC2568 | I33: HT-75X6 HT-150X12,15 MS-80X6 | J33: =G33/E33 -> -0.00035792404
B34: 13.04.23 | C34: KEC BUB | D34: 32.24 | E34: 32.291 | F34: =IF(D34-E34<=0,0,D34-E34) -> 0 | G34: =IF(D34-E34>=0,0,D34-E34) -> -0.051 | H34: MH46AF3590 | I34: HT-110X6,110X8, MS-90X6 | J34: =G34/E34 -> -0.0015793874
B35: 14.04.23 | C35: KEC BUB | D35: 30.75 | E35: 31.029 | F35: =IF(D35-E35<=0,0,D35-E35) -> 0 | G35: =IF(D35-E35>=0,0,D35-E35) -> -0.279 | H35: MH46AR8099 | I35: HT-100X6, 110X6,110X8 | J35: =G35/E35 -> -0.0089915885
B36: 14.04.23 | C36: KEC BUB | D36: 24.47 | E36: 24.602 | F36: =IF(D36-E36<=0,0,D36-E36) -> 0 | G36: =IF(D36-E36>=0,0,D36-E36) -> -0.132 | H36: MH31FC2215 | I36: MS-100X7, HT-80X6 150X12 | J36: =G36/E36 -> -0.0053654174
B37: 14.04.23 | C37: KEC BUB | D37: 31.85 | E37: 32.049 | F37: =IF(D37-E37<=0,0,D37-E37) -> 0 | G37: =IF(D37-E37>=0,0,D37-E37) -> -0.199 | H37: MH40Y3944 | I37: MS-90X6, 100X7 HT-100X6 HT-130X10 | J37: =G37/E37 -> -0.0062092421
B38: 14.04.23 | C38: KEC BUB | D38: 31.46 | E38: 31.454 | F38: =IF(D38-E38<=0,0,D38-E38) -> 0.006 | G38: =IF(D38-E38>=0,0,D38-E38) -> 0 | H38: MH40Y4044 | I38: HT-150X150X14, 110X8,MS-90X6 | J38: =F38/E38 -> 0.00019075475
B39: 15.04.23 | C39: KEC BUB | D39: 32.05 | E39: 32.032 | F39: =IF(D39-E39<=0,0,D39-E39) -> 0.018 | G39: =IF(D39-E39>=0,0,D39-E39) -> 0 | H39: MH40Y3944 | I39: HT-110X8, MS-100X6 | J39: =F39/E39 -> 0.00056193806
B40: 15.04.23 | C40: KEC BUB | D40: 32.13 | E40: 32.303 | F40: =IF(D40-E40<=0,0,D40-E40) -> 0 | G40: =IF(D40-E40>=0,0,D40-E40) -> -0.173 | H40: MH46AF3590 | I40: HT-110X9, 110X7, HT-100X6 | J40: =G40/E40 -> -0.0053555397
B41: 16.04.23 | C41: KEC BUB | D41: 32.45 | E41: 32.502 | F41: =IF(D41-E41<=0,0,D41-E41) -> 0 | G41: =IF(D41-E41>=0,0,D41-E41) -> -0.052 | H41: MH46AR4423 | I41: HT-110X8,75X6, 5 | J41: =G41/E41 -> -0.0015999015
B42: 16.04.23 | C42: KEC BUB | D42: 32.38 | E42: 32.287 | F42: =IF(D42-E42<=0,0,D42-E42) -> 0.093 | G42: =IF(D42-E42>=0,0,D42-E42) -> 0 | H42: MH40Y4044 | I42: HT-130X130X12 | J42: =F42/E42 -> 0.0028804163
...

Sheet May -23 
B2: SEC.& KATA WT,DIFFERENCE ANGLE MAY 2023 (vil bub)
B4: DISP.DATE | C4: PARTY | D4: KATA WT | E4: SEC.WT | F4: (+) WT | G4: (-)WT | H4: VEHICLE.NO. | I4: SECTION | J4: Net (+/-) %
B5: 02.05.23 | C5: KEC BB | D5: 31.37 | E5: 31.229 | F5: =IF(D5-E5<=0,0,D5-E5) -> 0.141 | G5: =IF(D5-E5>=0,0,D5-E5) -> 0 | H5: MH46AF3590 | I5: HT-80X5, 120X8 | J5: =F5/E5 -> 0.0045150341
B6: 04.05.23 | C6: KEC BB | D6: 33.07 | E6: 33.187 | F6: =IF(D6-E6<=0,0,D6-E6) -> 0 | G6: =IF(D6-E6>=0,0,D6-E6) -> -0.117 | H6: MH40Y4944 | I6: HT-130X130X10 | J6: =G6/E6 -> -0.0035254768
B7: 04.05.23 | C7: KEC BB | D7: 33.32 | E7: 33.412 | F7: =IF(D7-E7<=0,0,D7-E7) -> 0 | G7: =IF(D7-E7>=0,0,D7-E7) -> -0.092 | H7: MH40Y4044 | I7: HT-130X130X10 | J7: =G7/E7 -> -0.0027535017
B8: 06.05.23 | C8: KEC BB | D8: 26.19 | E8: 26.204 | F8: =IF(D8-E8<=0,0,D8-E8) -> 0 | G8: =IF(D8-E8>=0,0,D8-E8) -> -0.014 | H8: MH40Y2044 | I8: HT-100X6, 130X9, 120X10, 130X8,10 80X6 110X6,7 | J8: =G8/E8 -> -0.00053426958
B9: 12.05.23 | C9: KEC BB | D9: 24.99 | E9: 24.821 | F9: =IF(D9-E9<=0,0,D9-E9) -> 0.169 | G9: =IF(D9-E9>=0,0,D9-E9) -> 0 | H9: MH40CM5134 | I9: HT-150X12 | J9: =F9/E9 -> 0.0068087507
B10: 13.05.23 | C10: KEC BB | D10: 24.59 | E10: 24.687 | F10: =IF(D10-E10<=0,0,D10-E10) -> 0 | G10: =IF(D10-E10>=0,0,D10-E10) -> -0.097 | H10: MH31FC2215 | I10: HT-150X18 | J10: =G10/E10 -> -0.0039291935
B11: 13.05.23 | C11: KEC BB | D11: 24.61 | E11: 24.355 | F11: =IF(D11-E11<=0,0,D11-E11) -> 0.255 | G11: =IF(D11-E11>=0,0,D11-E11) -> 0 | H11: MH31FC2567 | I11: HT-150X14/10 | J11: =F11/E11 -> 0.010470129
B12: 14.05.23 | C12: KEC BB | D12: 25.19 | E12: 25.115 | F12: =IF(D12-E12<=0,0,D12-E12) -> 0.075 | G12: =IF(D12-E12>=0,0,D12-E12) -> 0 | H12: MH40CM3181 | I12: HT-150X12 | J12: =F12/E12 -> 0.0029862632
B13: 14.05.23 | C13: KEC BB | D13: 25.01 | E13: 24.855 | F13: =IF(D13-E13<=0,0,D13-E13) -> 0.155 | G13: =IF(D13-E13>=0,0,D13-E13) -> 0 | H13: MH40CM5134 | I13: HT-150X150X14/16/10/15/10 | J13: =F13/E13 -> 0.0062361698
B14: 15.05.23 | C14: KEC BB | D14: 24.69 | E14: 24.615 | F14: =IF(D14-E14<=0,0,D14-E14) -> 0.075 | G14: =IF(D14-E14>=0,0,D14-E14) -> 0 | H14: MH31FC2627 | I14: HT-150X12/15/18 | J14: =F14/E14 -> 0.0030469226
B15: 15.05.23 | C15: KEC BB | D15: 24.89 | E15: 24.855 | F15: =IF(D15-E15<=0,0,D15-E15) -> 0.035 | G15: =IF(D15-E15>=0,0,D15-E15) -> 0 | H15: MH40CM3184 | I15: HT-150X16/18/20/12 | J15: =F15/E15 -> 0.0014081674
B16: 16.05.23 | C16: KEC BB | D16: 3.81 | E16: 3.817 | F16: =IF(D16-E16<=0,0,D16-E16) -> 0 | G16: =IF(D16-E16>=0,0,D16-E16) -> -0.007 | H16: MH40BG1844 | I16: HT-150X12 /17 110X8/7 80X6, | J16: =G16/E16 -> -0.001833901
B17: 24.05.23 | C17: KEC BB | D17: 24.5 | E17: 24.497 | F17: =IF(D17-E17<=0,0,D17-E17) -> 0.003 | G17: =IF(D17-E17>=0,0,D17-E17) -> 0 | H17: MH40CM3182 | I17: HT-150X16/18/15/12/10 130X10 100X9 | J17: =F17/E17 -> 0.00012246398
B18: 25.05.23 | C18: KEC BB | D18: 33.82 | E18: =13.279+20.6 -> 33.879 | F18: =IF(D18-E18<=0,0,D18-E18) -> 0 | G18: =IF(D18-E18>=0,0,D18-E18) -> -0.059 | H18: MH46AF3590 | I18: HT-100X100X8 | J18: =G18/E18 -> -0.0017414918
B19: 25.05.23 | C19: KEC BB | D19: 32.35 | E19: 32.556 | F19: =IF(D19-E19<=0,0,D19-E19) -> 0 | G19: =IF(D19-E19>=0,0,D19-E19) -> -0.206 | H19: MH40Y3944 | I19: HT-100X100X8/7 | J19: =G19/E19 -> -0.0063275587
B20: 26.05.23 | C20: KEC BB | D20: 33.51 | E20: 33.566 | F20: =IF(D20-E20<=0,0,D20-E20) -> 0 | G20: =IF(D20-E20>=0,0,D20-E20) -> -0.056 | H20: MH46AF3590 | I20: HT-100X6/7 | J20: =G20/E20 -> -0.0016683549
B21: 26.05.23 | C21: KEC BB | D21: 33.45 | E21: 33.61 | F21: =IF(D21-E21<=0,0,D21-E21) -> 0 | G21: =IF(D21-E21>=0,0,D21-E21) -> -0.16 | H21: MH40Y3944 | I21: HT-130X10/8/12 100X7 | J21: =G21/E21 -> -0.004760488
B22: 28.05.23 | C22: KEC BB | D22: 32.24 | E22: 32.445 | F22: =IF(D22-E22<=0,0,D22-E22) -> 0 | G22: =IF(D22-E22>=0,0,D22-E22) -> -0.205 | H22: MH46AF3590 | I22: HT-100X7/ 75X75X6 | J22: =G22/E22 -> -0.006318385
B23: 28.05.23 | C23: KEC BB | D23: 32.46 | E23: 32.732 | F23: =IF(D23-E23<=0,0,D23-E23) -> 0 | G23: =IF(D23-E23>=0,0,D23-E23) -> -0.272 | H23: MH40Y2044 | I23: HT-90X90X6/7/6 | J23: =G23/E23 -> -0.0083099108
B24: 29.05.23 | C24: KEC BB | D24: 31.91 | E24: 31.891 | F24: =IF(D24-E24<=0,0,D24-E24) -> 0.019 | G24: =IF(D24-E24>=0,0,D24-E24) -> 0 | H24: MH46AF3590 | I24: HT-75X75X6 90X90X7 110X9 | J24: =F24/E24 -> 0.00059577937
B25: 29.05.23 | C25: KEC BB | D25: 32.29 | E25: 32.304 | F25: =IF(D25-E25<=0,0,D25-E25) -> 0 | G25: =IF(D25-E25>=0,0,D25-E25) -> -0.014 | H25: MH40Y3944 | I25: HT-110X110X8/9 | J25: =G25/E25 -> -0.00043338286
B26: 29.05.23 | C26: KEC BB | D26: 32.24 | E26: 32.415 | F26: =IF(D26-E26<=0,0,D26-E26) -> 0 | G26: =IF(D26-E26>=0,0,D26-E26) -> -0.175 | H26: MH40Y2044 | I26: HT-110X110X8 90X90X6 | J26: =F26/E26 -> 0
B27: 30.05.23 | C27: KEC BB | D27: 31.61 | E27: 31.831 | F27: =IF(D27-E27<=0,0,D27-E27) -> 0 | G27: =IF(D27-E27>=0,0,D27-E27) -> -0.221 | H27: MH46AF3590 | I27: HT-90X6 100X7 110X110X10 /7 | J27: =G27/E27 -> -0.0069429173
B28: 30.05.23 | C28: KEC BB | D28: 31.97 | E28: 32.078 | F28: =IF(D28-E28<=0,0,D28-E28) -> 0 | G28: =IF(D28-E28>=0,0,D28-E28) -> -0.108 | H28: MH40Y2044 | I28: HT-110X8/ 75X6 90X7 100X7 | J28: =G28/E28 -> -0.0033667934
B29: 30.05.23 | C29: KEC BB | D29: 32.3 | E29: 32.344 | F29: =IF(D29-E29<=0,0,D29-E29) -> 0 | G29: =IF(D29-E29>=0,0,D29-E29) -> -0.044 | H29: MH40Y3944 | I29: MS-90X7 100X7 120X9 | J29: =G29/E29 -> -0.001360376
D30: =SUM(D5:D29) -> 716.38 | E30: =SUM(E5:E29) -> 717.3 | F30: =SUM(F5:F29) -> 0.927 | G30: =SUM(G5:G29) -> -1.847 | H30: =SUM(F30:G30) -> -0.92 | J30: =H30/E30 -> -0.0012825875

Sheet JUN -23
B2: SEC.& KATA WT,DIFFERENCE ANGLE JUN 2023 (vil bub)
B4: DISP.DATE | C4: PARTY | D4: KATA WT | E4: SEC.WT | F4: (+) WT | G4: (-)WT | H4: VEHICLE.NO. | I4: SECTION | J4: Net (+/-) %
B5: 01.06.23 | C5: KEC BB | D5: 24.38 | E5: 24.63 | F5: =IF(D5-E5<=0,0,D5-E5) -> 0 | G5: =IF(D5-E5>=0,0,D5-E5) -> -0.25 | H5: MH31FC2568 | I5: HT-130X130X10 | J5: =G5/E5 -> -0.010150223
B6: 01.06.23 | C6: KEC BB | D6: 32.27 | E6: 32.425 | F6: =IF(D6-E6<=0,0,D6-E6) -> 0 | G6: =IF(D6-E6>=0,0,D6-E6) -> -0.155 | H6: MH40Y2044 | I6: HT-75X75X5 120X12 100X8 100X7 90X7 | J6: =G6/E6 -> -0.0047802621
B7: 01.06.23 | C7: KEC BB | D7: 31.97 | E7: 32.097 | F7: =IF(D7-E7<=0,0,D7-E7) -> 0 | G7: =IF(D7-E7>=0,0,D7-E7) -> -0.127 | H7: MH40Y4944 | I7: MS-120X120X12 120X9 100X12 | J7: =G7/E7 -> -0.0039567561
B8: 01.06.23 | C8: KEC BB | D8: 24.63 | E8: 24.587 | F8: =IF(D8-E8<=0,0,D8-E8) -> 0.043 | G8: =IF(D8-E8>=0,0,D8-E8) -> 0 | H8: MH31FC2629 | I8: HT-100X100X7/75X75X6 75X75X5 | J8: =F8/E8 -> 0.0017488917
B9: 02.06.23 | C9: KEC BB | D9: 25.2 | E9: 25.27 | F9: =IF(D9-E9<=0,0,D9-E9) -> 0 | G9: =IF(D9-E9>=0,0,D9-E9) -> -0.07 | H9: MH31FC2567 | I9: HT-130X130X10 | J9: =G9/E9 -> -0.0027700831
B10: 03.06.23 | C10: KEC BB | D10: 29.85 | E10: 29.892 | F10: =IF(D10-E10<=0,0,D10-E10) -> 0 | G10: =IF(D10-E10>=0,0,D10-E10) -> -0.042 | H10: MH40Y2044 | I10: HT-120X9, 110X10,7 100X7, 8 , 12 | J10: =G10/E10 -> -0.0014050582
B11: 03.06.23 | C11: KEC BB | D11: 25.15 | E11: 25.151 | F11: =IF(D11-E11<=0,0,D11-E11) -> 0 | G11: =IF(D11-E11>=0,0,D11-E11) -> -0.001 | H11: MH31FC2213 | I11: HT-130X130X9 | J11: =G11/E11 -> -3.9759851e-05
B12: 03.06.23 | C12: KEC BB | D12: 24.87 | E12: 24.833 | F12: =IF(D12-E12<=0,0,D12-E12) -> 0.037 | G12: =IF(D12-E12>=0,0,D12-E12) -> 0 | H12: MH40CM4419 | I12: HT-100X100X8/7 130X9 110X8 | J12: =F12/E12 -> 0.0014899529
B13: 04.06.23 | C13: KEC BB | D13: 25.46 | E13: 25.236 | F13: =IF(D13-E13<=0,0,D13-E13) -> 0.224 | G13: =IF(D13-E13>=0,0,D13-E13) -> 0 | H13: MH40CM3182 | I13: HT-90X7 110X10 75X6 130X10 | J13: =F13/E13 -> 0.0088762086
B14: 04.06.23 | C14: KEC BB | D14: 24.72 | E14: 24.817 | F14: =IF(D14-E14<=0,0,D14-E14) -> 0 | G14: =IF(D14-E14>=0,0,D14-E14) -> -0.097 | H14: MH40CM3181 | I14: HT-100X7/6 | J14: =G14/E14 -> -0.003908611
B15: 04.06.23 | C15: KEC BB | D15: 24.74 | E15: 24.8 | F15: =IF(D15-E15<=0,0,D15-E15) -> 0 | G15: =IF(D15-E15>=0,0,D15-E15) -> -0.06 | H15: MH31FC2564 | I15: HT-90X6, 110X8 100X10 ,6 | J15: =G15/E15 -> -0.0024193548
B16: 04.06.23 | C16: KEC BB | D16: 31.97 | E16: 31.614 | F16: =IF(D16-E16<=0,0,D16-E16) -> 0.356 | G16: =IF(D16-E16>=0,0,D16-E16) -> 0 | H16: MH46AF3590 | I16: HT-120X9, 130X10, 130X9 | J16: =F16/E16 -> 0.011260834
B17: 05.06.23 | C17: KEC BB | D17: 25.17 | E17: 25.196 | F17: =IF(D17-E17<=0,0,D17-E17) -> 0 | G17: =IF(D17-E17>=0,0,D17-E17) -> -0.026 | H17: MH31FC2567 | I17: HT-120X9 | J17: =G17/E17 -> -0.0010319098
B18: 06.06.23 | C18: KEC BB | D18: 25.09 | E18: 25.123 | F18: =IF(D18-E18<=0,0,D18-E18) -> 0 | G18: =IF(D18-E18>=0,0,D18-E18) -> -0.033 | H18: MH31FC2216 | I18: HT-120X9 | J18: =G18/E18 -> -0.0013135374
B19: 06.06.23 | C19: KEC BB | D19: 31.91 | E19: 32.232 | F19: =IF(D19-E19<=0,0,D19-E19) -> 0 | G19: =IF(D19-E19>=0,0,D19-E19) -> -0.322 | H19: MH46AF3590 | I19: HT-100X7, 90X7 | J19: =G19/E19 -> -0.009990072
B20: 06.06.23 | C20: KEC BB | D20: 12.8 | E20: 12.934 | F20: =IF(D20-E20<=0,0,D20-E20) -> 0 | G20: =IF(D20-E20>=0,0,D20-E20) -> -0.134 | H20: MH40Y9844 | I20: HT-120X120X10 | J20: =G20/E20 -> -0.010360291
B21: 06.06.23 | C21: KEC BB | D21: 24.69 | E21: 24.666 | F21: =IF(D21-E21<=0,0,D21-E21) -> 0.024 | G21: =IF(D21-E21>=0,0,D21-E21) -> 0 | H21: MH31FC2629 | I21: HT-120X120X9 | J21: =F21/E21 -> 0.00097299927
B22: 08.06.23 | C22: KEC BB | D22: 25.41 | E22: 25.454 | F22: =IF(D22-E22<=0,0,D22-E22) -> 0 | G22: =IF(D22-E22>=0,0,D22-E22) -> -0.044 | H22: MH40CM3182 | I22: HT-120X9/10, 100X8/7 | J22: =G22/E22 -> -0.0017286085
B23: 08.06.23 | C23: KEC BB | D23: 24.99 | E23: 25.035 | F23: =IF(D23-E23<=0,0,D23-E23) -> 0 | G23: =IF(D23-E23>=0,0,D23-E23) -> -0.045 | H23: MH31FC2215 | I23: HT-120X9,110X8, 130X10, 100X7 | J23: =G23/E23 -> -0.0017974835
B24: 08.06.23 | C24: KEC JBP | D24: 32.51 | E24: 32.387 | F24: =IF(D24-E24<=0,0,D24-E24) -> 0.123 | G24: =IF(D24-E24>=0,0,D24-E24) -> 0 | H24: MH40BG0308 | I24: MS-75X75X8 | J24: =F24/E24 -> 0.0037978201
B25: 08.06.23 | C25: KEC JBP | D25: 32.56 | E25: 32.768 | F25: =IF(D25-E25<=0,0,D25-E25) -> 0 | G25: =IF(D25-E25>=0,0,D25-E25) -> -0.208 | H25: MH49AT1953 | I25: MS-75X75X8 | J25: =G25/E25 -> -0.0063476562
B26: 08.06.23 | C26: KEC JBP | D26: 20.46 | E26: 20.448 | F26: =IF(D26-E26<=0,0,D26-E26) -> 0.012 | G26: =IF(D26-E26>=0,0,D26-E26) -> 0 | H26: MH40N7379 | I26: MS-75X75X8 | J26: =F26/E26 -> 0.00058685446
B27: 09.06.23 | C27: KEC JBP | D27: 32.77 | E27: 32.801 | F27: =IF(D27-E27<=0,0,D27-E27) -> 0 | G27: =IF(D27-E27>=0,0,D27-E27) -> -0.031 | H27: MH49AY0506 | I27: MS-75X75X8 | J27: =G27/E27 -> -0.00094509314
B28: 09.06.23 | C28: KEC JBP | D28: 32.99 | E28: 32.765 | F28: =IF(D28-E28<=0,0,D28-E28) -> 0.225 | G28: =IF(D28-E28>=0,0,D28-E28) -> 0 | H28: MH49AY0503 | I28: MS-75X75X8 | J28: =F28/E28 -> 0.0068670838
B29: 09.06.23 | C29: KEC JBP | D29: 32.71 | E29: 32.627 | F29: =IF(D29-E29<=0,0,D29-E29) -> 0.083 | G29: =IF(D29-E29>=0,0,D29-E29) -> 0 | H29: MH49AT2926 | I29: MS-75X75X8 90X90X6 | J29: =F29/E29 -> 0.0025439054
B30: 09.06.23 | C30: KEC JBP | D30: 32.45 | E30: 32.517 | F30: =IF(D30-E30<=0,0,D30-E30) -> 0 | G30: =IF(D30-E30>=0,0,D30-E30) -> -0.067 | H30: MH40AK6005 | I30: MS-75X75X8 | J30: =G30/E30 -> -0.0020604607
B31: 10.06.23 | C31: KEC JBP | D31: 32.44 | E31: 32.53 | F31: =IF(D31-E31<=0,0,D31-E31) -> 0 | G31: =IF(D31-E31>=0,0,D31-E31) -> -0.09 | H31: MH40AK2189 | I31: MS-90X6 75X8/6/8 | J31: =G31/E31 -> -0.0027666769
B32: 10.06.23 | C32: KEC JBP | D32: 32.83 | E32: 32.975 | F32: =IF(D32-E32<=0,0,D32-E32) -> 0 | G32: =IF(D32-E32>=0,0,D32-E32) -> -0.145 | H32: MH49AT2907 | I32: MS-90X6 75X8/6/8 | J32: =G32/E32 -> -0.0043972707
B33: 11.06.23 | C33: KEC BB | D33: 25.14 | E33: 25.113 | F33: =IF(D33-E33<=0,0,D33-E33) -> 0.027 | G33: =IF(D33-E33>=0,0,D33-E33) -> 0 | H33: MH34M6622 | I33: MS-90X6 | J33: =F33/E33 -> 0.0010751404
B34: 11.06.23 | C34: KEC BB | D34: 32.22 | E34: 32.358 | F34: =IF(D34-E34<=0,0,D34-E34) -> 0 | G34: =IF(D34-E34>=0,0,D34-E34) -> -0.138 | H34: MH40Y4944 | I34: HT-80X80X6/5 MS-120X8 | J34: =G34/E34 -> -0.0042647877
B35: 12.06.23 | C35: KEC BB | D35: 25.04 | E35: 24.8 | F35: =IF(D35-E35<=0,0,D35-E35) -> 0.24 | G35: =IF(D35-E35>=0,0,D35-E35) -> 0 | H35: MH40CM3180 | I35: HT-130X130X10,100X10,120X9 | J35: =F35/E35 -> 0.0096774194
B36: 13.06.23 | C36: KEC BB | D36: 32.89 | E36: 32.91 | F36: =IF(D36-E36<=0,0,D36-E36) -> 0 | G36: =IF(D36-E36>=0,0,D36-E36) -> -0.02 | H36: MH40Y3944 | I36: HT-150X12, 80X6/5, 80X5 | J36: =G36/E36 -> -0.00060771802
B37: 13.06.23 | C37: KEC BB | D37: 32.48 | E37: 32.686 | F37: =IF(D37-E37<=0,0,D37-E37) -> 0 | G37: =IF(D37-E37>=0,0,D37-E37) -> -0.206 | H37: MH40Y4944 | I37: HT-15X12, 15, 16, 18 80X6, 100X7 120X9 | J37: =G37/E37 -> -0.0063023925
B38: 14.06.23 | C38: KEC BB | D38: 24.87 | E38: 25.209 | F38: =IF(D38-E38<=0,0,D38-E38) -> 0 | G38: =IF(D38-E38>=0,0,D38-E38) -> -0.339 | H38: MH31FC2620 | I38: HT-130X130X10 | J38: =G38/E38 -> -0.013447578
B39: 14.06.23 | C39: KEC BB | D39: 24.87 | E39: 24.571 | F39: =IF(D39-E39<=0,0,D39-E39) -> 0.299 | G39: =IF(D39-E39>=0,0,D39-E39) -> 0 | H39: MH31FC2216 | I39: HT-150X10,12,15,16,18 | J39: =F39/E39 -> 0.012168817
B40: 14.06.23 | C40: KEC BB | D40: 24.73 | E40: 24.801 | F40: =IF(D40-E40<=0,0,D40-E40) -> 0 | G40: =IF(D40-E40>=0,0,D40-E40) -> -0.071 | H40: MH31FC2623 | I40: MS-120X9 HT-130X9 | J40: =G40/E40 -> -0.0028627878
B41: 14.06.23 | C41: KEC BB | D41: 25.05 | E41: 24.969 | F41: =IF(D41-E41<=0,0,D41-E41) -> 0.081 | G41: =IF(D41-E41>=0,0,D41-E41) -> 0 | H41: MH40CM3183 | I41: HT-130X9 | J41: =F41/E41 -> 0.0032440226
B42: 14.06.23 | C42: KEC BB | D42: 31.4 | E42: 31.462 | F42: =IF(D42-E42<=0,0,D42-E42) -> 0 | G42: =IF(D42-E42>=0,0,D42-E42) -> -0.062 | H42: MH40Y3944 | I42: MS-120X8 | J42: =G42/E42 -> -0.0019706312
...

Sheet JULY -23 
B2: SEC.& KATA WT,DIFFERENCE ANGLE JULY 2023 (vil bub)
B4: DISP.DATE | C4: PARTY | D4: KATA WT | E4: SEC.WT | F4: (+) WT | G4: (-)WT | H4: VEHICLE.NO. | I4: SECTION | J4: Net (+/-) %
B5: 01.07.23 | C5: KEC BB | D5: 31.83 | E5: 31.916 | F5: =IF(D5-E5<=0,0,D5-E5) -> 0 | G5: =IF(D5-E5>=0,0,D5-E5) -> -0.086 | H5: MH40Y3944 | J5: =G5/E5 -> -0.0026945733
B6: 01.07.23 | C6: KEC BB | D6: 24 | E6: 24.731 | F6: =IF(D6-E6<=0,0,D6-E6) -> 0 | G6: =IF(D6-E6>=0,0,D6-E6) -> -0.731 | H6: MH40CM3180 | J6: =G6/E6 -> -0.029558045
B7: 01.07.23 | C7: KEC BB | D7: 32.48 | E7: 32.208 | F7: =IF(D7-E7<=0,0,D7-E7) -> 0.272 | G7: =IF(D7-E7>=0,0,D7-E7) -> 0 | H7: MH40Y4044 | J7: =F7/E7 -> 0.0084451068
B8: 01.07.23 | C8: KEC BB | D8: 32.76 | E8: 32.788 | F8: =IF(D8-E8<=0,0,D8-E8) -> 0 | G8: =IF(D8-E8>=0,0,D8-E8) -> -0.028 | H8: MH04FD6732 | J8: =G8/E8 -> -0.00085397096
B9: 02.07.23 | C9: KEC BB | D9: 25.37 | E9: 25.25 | F9: =IF(D9-E9<=0,0,D9-E9) -> 0.12 | G9: =IF(D9-E9>=0,0,D9-E9) -> 0 | H9: MH40CM3182 | J9: =F9/E9 -> 0.0047524752
B10: 02.07.23 | C10: KEC BB | D10: 31.96 | E10: 31.939 | F10: =IF(D10-E10<=0,0,D10-E10) -> 0.021 | G10: =IF(D10-E10>=0,0,D10-E10) -> 0 | H10: MH40Y3944 | J10: =F10/E10 -> 0.00065750337
B11: 02.07.23 | C11: KEC BB | D11: 32.15 | E11: 32.595 | F11: =IF(D11-E11<=0,0,D11-E11) -> 0 | G11: =IF(D11-E11>=0,0,D11-E11) -> -0.445 | H11: MH40AK4183 | J11: =G11/E11 -> -0.013652401
B12: 02.07.23 | C12: KEC BB | D12: 31.6 | E12: 31.669 | F12: =IF(D12-E12<=0,0,D12-E12) -> 0 | G12: =IF(D12-E12>=0,0,D12-E12) -> -0.069 | H12: MH40Y4044 | J12: =G12/E12 -> -0.0021787868
B13: 02.07.23 | C13: KEC BB | D13: 32.57 | E13: 32.544 | F13: =IF(D13-E13<=0,0,D13-E13) -> 0.026 | G13: =IF(D13-E13>=0,0,D13-E13) -> 0 | H13: MH40AK6075 | J13: =F13/E13 -> 0.00079891839
B14: 03.07.23 | C14: KEC BB | D14: 24.92 | E14: 24.947 | F14: =IF(D14-E14<=0,0,D14-E14) -> 0 | G14: =IF(D14-E14>=0,0,D14-E14) -> -0.027 | H14: MH40CM3181 | J14: =G14/E14 -> -0.0010822945
B15: 03.07.23 | C15: KEC BB | D15: 32.11 | E15: 32.56 | F15: =IF(D15-E15<=0,0,D15-E15) -> 0 | G15: =IF(D15-E15>=0,0,D15-E15) -> -0.45 | H15: MH49AT0403 | J15: =G15/E15 -> -0.013820639
B16: 03.07.23 | C16: KEC BB | D16: 25.12 | E16: 25.01 | F16: =IF(D16-E16<=0,0,D16-E16) -> 0.11 | G16: =IF(D16-E16>=0,0,D16-E16) -> 0 | H16: MH31FC2623 | J16: =F16/E16 -> 0.0043982407
B17: 03.07.23 | C17: KEC BB | D17: 31.87 | E17: 32.33 | F17: =IF(D17-E17<=0,0,D17-E17) -> 0 | G17: =IF(D17-E17>=0,0,D17-E17) -> -0.46 | H17: MH40Y3944 | J17: =G17/E17 -> -0.014228271
B18: 03.07.23 | C18: KEC BB | D18: 32.57 | E18: 32.538 | F18: =IF(D18-E18<=0,0,D18-E18) -> 0.032 | G18: =IF(D18-E18>=0,0,D18-E18) -> 0 | H18: MH46AF3590 | J18: =F18/E18 -> 0.00098346549
B19: 04.07.23 | C19: KEC BB | D19: 31.33 | E19: 31.394 | F19: =IF(D19-E19<=0,0,D19-E19) -> 0 | G19: =IF(D19-E19>=0,0,D19-E19) -> -0.064 | H19: MH46AF3590 | J19: =G19/E19 -> -0.0020386061
B20: 04.07.23 | C20: KEC BB | D20: 25.45 | E20: 25.351 | F20: =IF(D20-E20<=0,0,D20-E20) -> 0.099 | G20: =IF(D20-E20>=0,0,D20-E20) -> 0 | H20: MH46H6074 | J20: =F20/E20 -> 0.0039051714
B21: 04.07.23 | C21: KEC BB | D21: 24.54 | E21: 24.836 | F21: =IF(D21-E21<=0,0,D21-E21) -> 0 | G21: =IF(D21-E21>=0,0,D21-E21) -> -0.296 | H21: MH46H6281 | J21: =G21/E21 -> -0.011918183
B22: 05.07.23 | C22: KEC BB | D22: 31.99 | E22: 32.101 | F22: =IF(D22-E22<=0,0,D22-E22) -> 0 | G22: =IF(D22-E22>=0,0,D22-E22) -> -0.111 | H22: MH40AK1958 | J22: =G22/E22 -> -0.0034578362
B23: 06.07.23 | C23: KEC BB | D23: 25.04 | E23: 25.092 | F23: =IF(D23-E23<=0,0,D23-E23) -> 0 | G23: =IF(D23-E23>=0,0,D23-E23) -> -0.052 | H23: MH31FC2216 | J23: =G23/E23 -> -0.0020723737
B24: 06.07.23 | C24: KEC BB | D24: 24.97 | E24: 25.073 | F24: =IF(D24-E24<=0,0,D24-E24) -> 0 | G24: =IF(D24-E24>=0,0,D24-E24) -> -0.103 | H24: MH40CM3180 | J24: =G24/E24 -> -0.0041080046
B25: 06.07.23 | C25: KEC BB | D25: 30.79 | E25: 31.078 | F25: =IF(D25-E25<=0,0,D25-E25) -> 0 | G25: =IF(D25-E25>=0,0,D25-E25) -> -0.288 | H25: MH46AF3590 | J25: =G25/E25 -> -0.0092670056
B26: 06.07.23 | C26: KEC BB | D26: 24.33 | E26: 24.741 | F26: =IF(D26-E26<=0,0,D26-E26) -> 0 | G26: =IF(D26-E26>=0,0,D26-E26) -> -0.411 | H26: MH31FC2392 | J26: =G26/E26 -> -0.016612101
B27: 06.07.23 | C27: KEC BB | D27: 19.45 | E27: 19.672 | F27: =IF(D27-E27<=0,0,D27-E27) -> 0 | G27: =IF(D27-E27>=0,0,D27-E27) -> -0.222 | H27: MH49AT1947 | J27: =G27/E27 -> -0.011285075
B28: 07.07.23 | C28: KEC BB | D28: 24.58 | E28: 24.716 | F28: =IF(D28-E28<=0,0,D28-E28) -> 0 | G28: =IF(D28-E28>=0,0,D28-E28) -> -0.136 | H28: MH31FC2216 | J28: =G28/E28 -> -0.0055025085
B29: 07.07.23 | C29: KEC BB | D29: 24.3 | E29: 24.567 | F29: =IF(D29-E29<=0,0,D29-E29) -> 0 | G29: =IF(D29-E29>=0,0,D29-E29) -> -0.267 | H29: MH40CM3180 | J29: =G29/E29 -> -0.010868238
B30: 07.07.23 | C30: KEC BB | D30: 32 | E30: 32.101 | F30: =IF(D30-E30<=0,0,D30-E30) -> 0 | G30: =IF(D30-E30>=0,0,D30-E30) -> -0.101 | H30: MH46AF3590 | J30: =G30/E30 -> -0.0031463194
B31: 08.07.23 | C31: KEC BB | D31: 32.49 | E31: 32.827 | F31: =IF(D31-E31<=0,0,D31-E31) -> 0 | G31: =IF(D31-E31>=0,0,D31-E31) -> -0.337 | H31: MH46AF3590 | J31: =G31/E31 -> -0.01026594
B32: 08.07.23 | C32: KEC BB | D32: 24.75 | E32: 24.751 | F32: =IF(D32-E32<=0,0,D32-E32) -> 0 | G32: =IF(D32-E32>=0,0,D32-E32) -> -0.001 | H32: MH40CM3184 | J32: =G32/E32 -> -4.0402408e-05
B33: 09.07.23 | C33: KEC BB | D33: 30.41 | E33: 30.725 | F33: =IF(D33-E33<=0,0,D33-E33) -> 0 | G33: =IF(D33-E33>=0,0,D33-E33) -> -0.315 | H33: MH46AF3590 | J33: =G33/E33 -> -0.010252238
B34: 09.07.23 | C34: KEC BB | D34: 17.03 | E34: 16.923 | F34: =IF(D34-E34<=0,0,D34-E34) -> 0.107 | G34: =IF(D34-E34>=0,0,D34-E34) -> 0 | H34: CG07JD0717 | J34: =F34/E34 -> 0.006322756
B35: 10.07.23 | C35: KEC BB | D35: 24.71 | E35: 24.921 | F35: =IF(D35-E35<=0,0,D35-E35) -> 0 | G35: =IF(D35-E35>=0,0,D35-E35) -> -0.211 | H35: MH31FC2337 | J35: =G35/E35 -> -0.0084667549
B36: 10.07.23 | C36: KEC BB | D36: 31.41 | E36: 31.44 | F36: =IF(D36-E36<=0,0,D36-E36) -> 0 | G36: =IF(D36-E36>=0,0,D36-E36) -> -0.03 | H36: MH46AF3590 | J36: =G36/E36 -> -0.00095419847
B37: 10.07.23 | C37: KEC BB | D37: 24.55 | E37: 24.752 | F37: =IF(D37-E37<=0,0,D37-E37) -> 0 | G37: =IF(D37-E37>=0,0,D37-E37) -> -0.202 | H37: MH31FC2623 | J37: =G37/E37 -> -0.0081609567
B38: 10.07.23 | C38: KEC BB | D38: 33.14 | E38: 32.822 | F38: =IF(D38-E38<=0,0,D38-E38) -> 0.318 | G38: =IF(D38-E38>=0,0,D38-E38) -> 0 | H38: MH40Y2044 | J38: =F38/E38 -> 0.0096886235
B39: 10.07.23 | C39: KEC BB | D39: 11.24 | E39: 11.253 | F39: =IF(D39-E39<=0,0,D39-E39) -> 0 | G39: =IF(D39-E39>=0,0,D39-E39) -> -0.013 | H39: MH40N7379 | J39: =G39/E39 -> -0.0011552475
B40: 11.07.23 | C40: KEC BB | D40: 24.71 | E40: 24.707 | F40: =IF(D40-E40<=0,0,D40-E40) -> 0.003 | G40: =IF(D40-E40>=0,0,D40-E40) -> 0 | H40: MH40CM3183 | J40: =F40/E40 -> 0.00012142308
B41: 11.07.23 | C41: KEC BB | D41: 31.04 | E41: 31.425 | F41: =IF(D41-E41<=0,0,D41-E41) -> 0 | G41: =IF(D41-E41>=0,0,D41-E41) -> -0.385 | H41: MH40Y2044 | J41: =G41/E41 -> -0.012251392
B42: 11.07.23 | C42: KEC BB | D42: 30.63 | E42: 30.971 | F42: =IF(D42-E42<=0,0,D42-E42) -> 0 | G42: =IF(D42-E42>=0,0,D42-E42) -> -0.341 | H42: MH40Y1047 | J42: =G42/E42 -> -0.0110103
...

Sheet AUG -23  
B2: SEC.& KATA WT,DIFFERENCE ANGLE AUG 2023 (vil bub)
B4: DISP.DATE | C4: PARTY | D4: KATA WT | E4: SEC.WT | F4: (+) WT | G4: (-)WT | H4: VEHICLE.NO. | I4: SECTION | J4: Net (+/-) %
B5: 01.08.23 | C5: KEC BB | D5: 32.43 | E5: 32.643 | F5: =IF(D5-E5<=0,0,D5-E5) -> 0 | G5: =IF(D5-E5>=0,0,D5-E5) -> -0.213 | H5: MH40Y3944 | J5: =G5/E5 -> -0.0065251356
B6: 01.08.23 | C6: KEC BB | D6: 31.77 | E6: 31.719 | F6: =IF(D6-E6<=0,0,D6-E6) -> 0.051 | G6: =IF(D6-E6>=0,0,D6-E6) -> 0 | H6: MH40Y4944 | J6: =F6/E6 -> 0.0016078691
B7: 01.08.23 | C7: KEC BB | D7: 25.05 | E7: 24.878 | F7: =IF(D7-E7<=0,0,D7-E7) -> 0.172 | G7: =IF(D7-E7>=0,0,D7-E7) -> 0 | H7: MH31FC2623 | J7: =F7/E7 -> 0.006913739
B8: 01.08.23 | C8: KEC BB | D8: 25.17 | E8: 25.215 | F8: =IF(D8-E8<=0,0,D8-E8) -> 0 | G8: =IF(D8-E8>=0,0,D8-E8) -> -0.045 | H8: MH31FC2622 | J8: =G8/E8 -> -0.001784652
B9: 01.08.23 | C9: KEC BB | D9: 31.52 | E9: 31.412 | F9: =IF(D9-E9<=0,0,D9-E9) -> 0.108 | G9: =IF(D9-E9>=0,0,D9-E9) -> 0 | H9: MH40Y3144 | J9: =F9/E9 -> 0.0034381765
B10: 03.08.23 | C10: KEC BB | D10: 24.57 | E10: 24.815 | F10: =IF(D10-E10<=0,0,D10-E10) -> 0 | G10: =IF(D10-E10>=0,0,D10-E10) -> -0.245 | H10: MH40CM3180 | J10: =G10/E10 -> -0.0098730606
B11: 03.08.23 | C11: KEC BB | D11: 32.64 | E11: 32.88 | F11: =IF(D11-E11<=0,0,D11-E11) -> 0 | G11: =IF(D11-E11>=0,0,D11-E11) -> -0.24 | H11: MH40Y3144 | J11: =G11/E11 -> -0.0072992701
B12: 03.08.23 | C12: KEC BB | D12: 32.01 | E12: 32.215 | F12: =IF(D12-E12<=0,0,D12-E12) -> 0 | G12: =IF(D12-E12>=0,0,D12-E12) -> -0.205 | H12: MH40Y3944 | J12: =G12/E12 -> -0.0063634953
B13: 03.08.23 | C13: KEC BB | D13: 31.04 | E13: 31.266 | F13: =IF(D13-E13<=0,0,D13-E13) -> 0 | G13: =IF(D13-E13>=0,0,D13-E13) -> -0.226 | H13: MH40BG0544 | J13: =G13/E13 -> -0.0072282991
B14: 04.08.23 | C14: KEC BB | D14: 25.1 | E14: 25.153 | F14: =IF(D14-E14<=0,0,D14-E14) -> 0 | G14: =IF(D14-E14>=0,0,D14-E14) -> -0.053 | H14: MH40CD3182 | J14: =G14/E14 -> -0.0021071045
B15: 04.08.23 | C15: KEC BB | D15: 32.74 | E15: 32.431 | F15: =IF(D15-E15<=0,0,D15-E15) -> 0.309 | G15: =IF(D15-E15>=0,0,D15-E15) -> 0 | H15: MH40Y9744 | J15: =F15/E15 -> 0.0095279208
B16: 04.08.23 | C16: KEC BB | D16: 31.73 | E16: 31.625 | F16: =IF(D16-E16<=0,0,D16-E16) -> 0.105 | G16: =IF(D16-E16>=0,0,D16-E16) -> 0 | H16: MH40Y2044 | J16: =F16/E16 -> 0.0033201581
B17: 04.08.23 | C17: KEC BB | D17: 24.89 | E17: 24.754 | F17: =IF(D17-E17<=0,0,D17-E17) -> 0.136 | G17: =IF(D17-E17>=0,0,D17-E17) -> 0 | H17: MH31FC2629 | J17: =F17/E17 -> 0.0054940616
B18: 05.08.23 | C18: KEC BB | D18: 25.01 | E18: 24.702 | F18: =IF(D18-E18<=0,0,D18-E18) -> 0.308 | G18: =IF(D18-E18>=0,0,D18-E18) -> 0 | H18: MH31FC2338 | J18: =F18/E18 -> 0.012468626
B19: 05.08.23 | C19: KEC BB | D19: 25.29 | E19: 25.297 | F19: =IF(D19-E19<=0,0,D19-E19) -> 0 | G19: =IF(D19-E19>=0,0,D19-E19) -> -0.007 | H19: MH40CM3180 | J19: =G19/E19 -> -0.00027671265
B20: 05.08.23 | C20: KEC BB | D20: 22.13 | E20: 22.11 | F20: =IF(D20-E20<=0,0,D20-E20) -> 0.02 | G20: =IF(D20-E20>=0,0,D20-E20) -> 0 | H20: MH40BG0307 | J20: =F20/E20 -> 0.00090456807
B21: 05.08.23 | C21: KEC BB | D21: 32.59 | E21: 32.277 | F21: =IF(D21-E21<=0,0,D21-E21) -> 0.313 | G21: =IF(D21-E21>=0,0,D21-E21) -> 0 | H21: MH40Y3944 | J21: =F21/E21 -> 0.0096973077
B22: 05.08.23 | C22: KEC BB | D22: 31.76 | E22: 31.907 | F22: =IF(D22-E22<=0,0,D22-E22) -> 0 | G22: =IF(D22-E22>=0,0,D22-E22) -> -0.147 | H22: MH40Y4044 | J22: =G22/E22 -> -0.0046071395
B23: 05.08.23 | C23: KEC BB | D23: 31.22 | E23: 31.484 | F23: =IF(D23-E23<=0,0,D23-E23) -> 0 | G23: =IF(D23-E23>=0,0,D23-E23) -> -0.264 | H23: MH40Y9944 | J23: =G23/E23 -> -0.0083852115
B24: 06.08.23 | C24: KEC BB | D24: 25.09 | E24: 25.176 | F24: =IF(D24-E24<=0,0,D24-E24) -> 0 | G24: =IF(D24-E24>=0,0,D24-E24) -> -0.086 | H24: MH40CM4419 | J24: =G24/E24 -> -0.0034159517
B25: 06.08.23 | C25: KEC BB | D25: 25.21 | E25: 25.208 | F25: =IF(D25-E25<=0,0,D25-E25) -> 0.002 | G25: =IF(D25-E25>=0,0,D25-E25) -> 0 | H25: MH31FC2620 | J25: =F25/E25 -> 7.9339892e-05
B26: 06.08.23 | C26: KEC BB | D26: 31.2 | E26: 31.727 | F26: =IF(D26-E26<=0,0,D26-E26) -> 0 | G26: =IF(D26-E26>=0,0,D26-E26) -> -0.527 | H26: MH40Y4044 | J26: =G26/E26 -> -0.016610458
B27: 06.08.23 | C27: KEC BB | D27: 32.1 | E27: 32.664 | F27: =IF(D27-E27<=0,0,D27-E27) -> 0 | G27: =IF(D27-E27>=0,0,D27-E27) -> -0.564 | H27: MH46AF3590 | J27: =G27/E27 -> -0.017266716
B28: 06.08.23 | C28: KEC BB | D28: 32.8 | E28: 32.964 | F28: =IF(D28-E28<=0,0,D28-E28) -> 0 | G28: =IF(D28-E28>=0,0,D28-E28) -> -0.164 | H28: MH40AK1958 | J28: =G28/E28 -> -0.0049751244
B29: 07.08.23 | C29: KEC BB | D29: 32.72 | E29: 32.787 | F29: =IF(D29-E29<=0,0,D29-E29) -> 0 | G29: =IF(D29-E29>=0,0,D29-E29) -> -0.067 | H29: MH40Y3944 | J29: =G29/E29 -> -0.0020434928
B30: 07.08.23 | C30: KEC BB | D30: 24.88 | E30: 24.955 | F30: =IF(D30-E30<=0,0,D30-E30) -> 0 | G30: =IF(D30-E30>=0,0,D30-E30) -> -0.075 | H30: MH31FC2216 | J30: =G30/E30 -> -0.0030054097
B31: 07.08.23 | C31: KEC BB | D31: 25.34 | E31: 25.324 | F31: =IF(D31-E31<=0,0,D31-E31) -> 0.016 | G31: =IF(D31-E31>=0,0,D31-E31) -> 0 | H31: MH31FC2215 | J31: =F31/E31 -> 0.00063181172
B32: 07.08.23 | C32: KEC BB | D32: 29.98 | E32: 30.052 | F32: =IF(D32-E32<=0,0,D32-E32) -> 0 | G32: =IF(D32-E32>=0,0,D32-E32) -> -0.072 | H32: MH46AR8099 | J32: =G32/E32 -> -0.0023958472
B33: 07.08.23 | C33: KEC BB | D33: 32.86 | E33: 33.168 | F33: =IF(D33-E33<=0,0,D33-E33) -> 0 | G33: =IF(D33-E33>=0,0,D33-E33) -> -0.308 | H33: MH40AK5044 | J33: =G33/E33 -> -0.0092860589
B34: 07.08.23 | C34: KEC BB | D34: 11.67 | E34: 11.626 | F34: =IF(D34-E34<=0,0,D34-E34) -> 0.044 | G34: =IF(D34-E34>=0,0,D34-E34) -> 0 | H34: MH40AK6003 | J34: =F34/E34 -> 0.0037846207
B35: 08.08.23 | C35: KEC BB | D35: 24.89 | E35: 25.077 | F35: =IF(D35-E35<=0,0,D35-E35) -> 0 | G35: =IF(D35-E35>=0,0,D35-E35) -> -0.187 | H35: MH31FC2567 | J35: =G35/E35 -> -0.0074570323
A36: 0 | B36: 08.08.23 | C36: KEC BB | D36: 25.23 | E36: 25.28 | F36: =IF(D36-E36<=0,0,D36-E36) -> 0 | G36: =IF(D36-E36>=0,0,D36-E36) -> -0.05 | H36: MH31FC2568 | J36: =G36/E36 -> -0.0019778481
B37: 08.08.23 | C37: KEC BB | D37: 31.91 | E37: 31.839 | F37: =IF(D37-E37<=0,0,D37-E37) -> 0.071 | G37: =IF(D37-E37>=0,0,D37-E37) -> 0 | H37: MH40Y4944 | J37: =F37/E37 -> 0.0022299695
B38: 08.08.23 | C38: KEC BB | D38: 32.58 | E38: 32.993 | F38: =IF(D38-E38<=0,0,D38-E38) -> 0 | G38: =IF(D38-E38>=0,0,D38-E38) -> -0.413 | H38: MH40Y3944 | J38: =G38/E38 -> -0.012517807
B39: 08.08.23 | C39: KEC BB | D39: 32.68 | E39: 33.097 | F39: =IF(D39-E39<=0,0,D39-E39) -> 0 | G39: =IF(D39-E39>=0,0,D39-E39) -> -0.417 | H39: MH40Y3144 | J39: =G39/E39 -> -0.012599329
B40: 09.08.23 | C40: KEC BB | D40: 30.64 | E40: 30.645 | F40: =IF(D40-E40<=0,0,D40-E40) -> 0 | G40: =IF(D40-E40>=0,0,D40-E40) -> -0.005 | H40: MH40AK5144 | J40: =G40/E40 -> -0.00016315875
B41: 09.08.23 | C41: KEC BB | D41: 25.33 | E41: 25.494 | F41: =IF(D41-E41<=0,0,D41-E41) -> 0 | G41: =IF(D41-E41>=0,0,D41-E41) -> -0.164 | H41: MH31FC2216 | J41: =G41/E41 -> -0.0064328862
B42: 09.08.23 | C42: KEC BB | D42: 25.24 | E42: 25.281 | F42: =IF(D42-E42<=0,0,D42-E42) -> 0 | G42: =IF(D42-E42>=0,0,D42-E42) -> -0.041 | H42: MH40CM4419 | J42: =G42/E42 -> -0.0016217713
...

Sheet SEP -23
B2: SEC.& KATA WT,DIFFERENCE ANGLE SEP 2023 (vil bub)
B4: DISP.DATE | C4: PARTY | D4: KATA WT | E4: SEC.WT | F4: (+) WT | G4: (-)WT | H4: VEHICLE.NO. | I4: Net (+/-) % | J4: PG/NPG
B5: 01.09.23 | C5: KEC BB | D5: =L5-0.01 -> 26.72 | E5: 26.387 | F5: =IF(D5-E5<=0,0,D5-E5) -> 0.333 | G5: =IF(D5-E5>=0,0,D5-E5) -> 0 | H5: MH40CM5395 | I5: =F5/E5 -> 0.012619851 | J5: NPG | L5: 26.73
B6: 01.09.23 | C6: KEC BBE | D6: =L6-0.01 -> 32.76 | E6: 32.654 | F6: =IF(D6-E6<=0,0,D6-E6) -> 0.106 | G6: =IF(D6-E6>=0,0,D6-E6) -> 0 | H6: MH04FD0626 | I6: =F6/E6 -> 0.0032461567 | J6: NPG | L6: 32.77
B7: 01.09.23 | C7: KEC BB | D7: =L7-0.01 -> 33.64 | E7: 33.099 | F7: =IF(D7-E7<=0,0,D7-E7) -> 0.541 | G7: =IF(D7-E7>=0,0,D7-E7) -> 0 | H7: MH40Y3944 | I7: =F7/E7 -> 0.016344905 | J7: NPG | L7: 33.65
B8: 02.09.23 | C8: KEC BB | D8: =L8-0.01 -> 25.32 | E8: 24.934 | F8: =IF(D8-E8<=0,0,D8-E8) -> 0.386 | G8: =IF(D8-E8>=0,0,D8-E8) -> 0 | H8: DD01P9222 | I8: =F8/E8 -> 0.015480869 | J8: NPG | L8: 25.33
B9: 02.09.23 | C9: KEC BB | D9: =L9-0.01 -> 24.99 | E9: 24.695 | F9: =IF(D9-E9<=0,0,D9-E9) -> 0.295 | G9: =IF(D9-E9>=0,0,D9-E9) -> 0 | H9: MH43Y8877 | I9: =F9/E9 -> 0.011945738 | J9: NPG | L9: 25
B10: 02.09.23 | C10: KEC BB | D10: =L10-0.01 -> 24.34 | E10: 24.489 | F10: =IF(D10-E10<=0,0,D10-E10) -> 0 | G10: =IF(D10-E10>=0,0,D10-E10) -> -0.149 | H10: RJ06GC1521 | I10: =G10/E10 -> -0.0060843644 | J10: NPG | L10: 24.35
B11: 03.09.23 | C11: KEC BBE | D11: =L11-0.01 -> 32.44 | E11: 31.828 | F11: =IF(D11-E11<=0,0,D11-E11) -> 0.612 | G11: =IF(D11-E11>=0,0,D11-E11) -> 0 | H11: MH40BL2575 | I11: =F11/E11 -> 0.019228352 | J11: NPG | L11: 32.45
B12: 03.09.23 | C12: KEC BB | D12: =L12-0.01 -> 32.32 | E12: 31.87 | F12: =IF(D12-E12<=0,0,D12-E12) -> 0.45 | G12: =IF(D12-E12>=0,0,D12-E12) -> 0 | H12: MH46AF3590 | I12: =F12/E12 -> 0.014119862 | J12: NPG | L12: 32.33
B13: 03.09.23 | C13: KEC BB | D13: =L13-0.01 -> 24.64 | E13: 24.715 | F13: =IF(D13-E13<=0,0,D13-E13) -> 0 | G13: =IF(D13-E13>=0,0,D13-E13) -> -0.075 | H13: MH40CM5195 | I13: =G13/E13 -> -0.0030345944 | J13: NPG | L13: 24.65
B14: 03.09.23 | C14: KEC BB | D14: =L14-0.01 -> 24.91 | E14: 24.505 | F14: =IF(D14-E14<=0,0,D14-E14) -> 0.405 | G14: =IF(D14-E14>=0,0,D14-E14) -> 0 | H14: NL02Q2829 | I14: =F14/E14 -> 0.016527239 | J14: NPG | L14: 24.92
B15: 03.09.23 | C15: KEC BB | D15: =L15-0.01 -> 25.05 | E15: 25.057 | F15: =IF(D15-E15<=0,0,D15-E15) -> 0 | G15: =IF(D15-E15>=0,0,D15-E15) -> -0.007 | H15: NL01AE1488 | I15: =F15/E15 -> 0 | J15: NPG | L15: 25.06
B16: 04.09.23 | C16: KEC BB | D16: =L16-0.01 -> 16.19 | E16: 15.912 | F16: =IF(D16-E16<=0,0,D16-E16) -> 0.278 | G16: =IF(D16-E16>=0,0,D16-E16) -> 0 | H16: MH49AT1947 | I16: =F16/E16 -> 0.017471091 | J16: NPG | L16: 16.2
B17: 04.09.23 | C17: KEC BB | D17: =L17-0.01 -> 32.16 | E17: 32.021 | F17: =IF(D17-E17<=0,0,D17-E17) -> 0.139 | G17: =IF(D17-E17>=0,0,D17-E17) -> 0 | H17: MH40Y9844 | I17: =F17/E17 -> 0.0043409013 | J17: NPG | L17: 32.17
B18: 04.09.23 | C18: KEC BB | D18: =L18-0.01 -> 24.74 | E18: 24.351 | F18: =IF(D18-E18<=0,0,D18-E18) -> 0.389 | G18: =IF(D18-E18>=0,0,D18-E18) -> 0 | H18: MH46BF4104 | I18: =F18/E18 -> 0.015974703 | J18: NPG | L18: 24.75
B19: 04.09.23 | C19: KEC BB | D19: =L19-0.01 -> 24.92 | E19: 24.791 | F19: =IF(D19-E19<=0,0,D19-E19) -> 0.129 | G19: =IF(D19-E19>=0,0,D19-E19) -> 0 | H19: MH49AT6261 | I19: =F19/E19 -> 0.0052035013 | J19: NPG | L19: 24.93
B20: 05.09.23 | C20: KEC BB | D20: =L20-0.01 -> 24.6 | E20: 24.315 | F20: =IF(D20-E20<=0,0,D20-E20) -> 0.285 | G20: =IF(D20-E20>=0,0,D20-E20) -> 0 | H20: MH46BU7742 | I20: =F20/E20 -> 0.01172116 | J20: NPG | L20: 24.61
B21: 05.09.23 | C21: KEC BB | D21: =L21-0.01 -> 31.16 | E21: 31.042 | F21: =IF(D21-E21<=0,0,D21-E21) -> 0.118 | G21: =IF(D21-E21>=0,0,D21-E21) -> 0 | H21: MH46AF3590 | I21: =F21/E21 -> 0.0038013015 | J21: NPG | L21: 31.17
B22: 05.09.23 | C22: KEC BB | D22: =L22-0.01 -> 24.14 | E22: 24.251 | F22: =IF(D22-E22<=0,0,D22-E22) -> 0 | G22: =IF(D22-E22>=0,0,D22-E22) -> -0.111 | H22: MH46H3436 | I22: =G22/E22 -> -0.0045771308 | J22: NPG | L22: 24.15
B23: 05.09.23 | C23: KEC BB | D23: =L23-0.01 -> 32.63 | E23: 32.565 | F23: =IF(D23-E23<=0,0,D23-E23) -> 0.065 | G23: =IF(D23-E23>=0,0,D23-E23) -> 0 | H23: MH40Y3144 | I23: =F23/E23 -> 0.001996008 | J23: NPG | L23: 32.64
B24: 06.09.23 | C24: KEC BB | D24: =L24-0.01 -> 24.66 | E24: 24.596 | F24: =IF(D24-E24<=0,0,D24-E24) -> 0.064 | G24: =IF(D24-E24>=0,0,D24-E24) -> 0 | H24: NL01AC2480 | I24: =F24/E24 -> 0.0026020491 | J24: NPG | L24: 24.67
B25: 06.09.23 | C25: KEC BB | D25: =L25-0.01 -> 32.87 | E25: 32.724 | F25: =IF(D25-E25<=0,0,D25-E25) -> 0.146 | G25: =IF(D25-E25>=0,0,D25-E25) -> 0 | H25: MH40AK6002 | I25: =F25/E25 -> 0.0044615573 | J25: PG | L25: 32.88
B26: 06.09.23 | C26: KEC BB | D26: =L26-0.01 -> 32.32 | E26: 32.359 | F26: =IF(D26-E26<=0,0,D26-E26) -> 0 | G26: =IF(D26-E26>=0,0,D26-E26) -> -0.039 | H26: MH49AT0397 | I26: =G26/E26 -> -0.0012052288 | J26: PG | L26: 32.33
B27: 07.09.23 | C27: KEC BB | D27: =L27-0.01 -> 32.91 | E27: 32.873 | F27: =IF(D27-E27<=0,0,D27-E27) -> 0.037 | G27: =IF(D27-E27>=0,0,D27-E27) -> 0 | H27: MH40Y4944 | I27: =F27/E27 -> 0.0011255438 | J27: PG | L27: 32.92
B28: 07.09.23 | C28: KEC BB | D28: =L28-0.01 -> 24.32 | E28: 24.539 | F28: =IF(D28-E28<=0,0,D28-E28) -> 0 | G28: =IF(D28-E28>=0,0,D28-E28) -> -0.219 | H28: MH46BF0155 | I28: =G28/E28 -> -0.0089245691 | J28: NPG | L28: 24.33
B29: 07.09.23 | C29: KEC BB | D29: =L29-0.01 -> 32.21 | E29: 32.111 | F29: =IF(D29-E29<=0,0,D29-E29) -> 0.099 | G29: =IF(D29-E29>=0,0,D29-E29) -> 0 | H29: MH40BG0396 | I29: =F29/E29 -> 0.0030830557 | J29: NPG | L29: 32.22
B30: 08.09.23 | C30: KEC BB | D30: =L30-0.01 -> 32.55 | E30: 32.984 | F30: =IF(D30-E30<=0,0,D30-E30) -> 0 | G30: =IF(D30-E30>=0,0,D30-E30) -> -0.434 | H30: MH40AK6074 | I30: =G30/E30 -> -0.013157895 | J30: PG | L30: 32.56
B31: 08.09.23 | C31: KEC BB | D31: =L31-0.01 -> 32.35 | E31: 32.565 | F31: =IF(D31-E31<=0,0,D31-E31) -> 0 | G31: =IF(D31-E31>=0,0,D31-E31) -> -0.215 | H31: MH40Y3944 | I31: =G31/E31 -> -0.0066021803 | J31: NPG | L31: 32.36
B32: 08.09.23 | C32: KEC BB | D32: =L32-0.01 -> 31.9 | E32: 31.908 | F32: =IF(D32-E32<=0,0,D32-E32) -> 0 | G32: =IF(D32-E32>=0,0,D32-E32) -> -0.008 | H32: MH40Y3144 | I32: =F32/E32 -> 0 | J32: NPG | L32: 31.91
B33: 09.09.23 | C33: KEC BB | D33: =L33-0.01 -> 24.7 | E33: 24.771 | F33: =IF(D33-E33<=0,0,D33-E33) -> 0 | G33: =IF(D33-E33>=0,0,D33-E33) -> -0.071 | H33: MH46CL0553 | I33: =G33/E33 -> -0.0028662549 | J33: NPG | L33: 24.71
B34: 09.09.23 | C34: KEC BB | D34: =L34-0.01 -> 32.95 | E34: 32.843 | F34: =IF(D34-E34<=0,0,D34-E34) -> 0.107 | G34: =IF(D34-E34>=0,0,D34-E34) -> 0 | H34: MH40Y4944 | I34: =F34/E34 -> 0.0032579241 | J34: NPG | L34: 32.96
B35: 09.09.23 | C35: KEC JBP | D35: =L35-0.01 -> 21.35 | E35: 21.286 | F35: =IF(D35-E35<=0,0,D35-E35) -> 0.064 | G35: =IF(D35-E35>=0,0,D35-E35) -> 0 | H35: MH49AT2913 | I35: =F35/E35 -> 0.0030066711 | J35: PG | L35: 21.36
A36: 0 | B36: 10.09.23 | C36: KEC BBE | D36: =L36-0.01 -> 28.46 | E36: 28.385 | F36: =IF(D36-E36<=0,0,D36-E36) -> 0.075 | G36: =IF(D36-E36>=0,0,D36-E36) -> 0 | H36: MH40Y0781 | I36: =F36/E36 -> 0.0026422406 | J36: NPG | L36: 28.47
B37: 10.09.23 | C37: KEC BB | D37: =L37-0.01 -> 31.55 | E37: 31.529 | F37: =IF(D37-E37<=0,0,D37-E37) -> 0.021 | G37: =IF(D37-E37>=0,0,D37-E37) -> 0 | H37: MH40Y5644 | I37: =F37/E37 -> 0.00066605347 | J37: NPG | L37: 31.56
B38: 10.09.23 | C38: KEC BB | D38: =L38-0.01 -> 31.86 | E38: 31.86 | F38: =IF(D38-E38<=0,0,D38-E38) -> 0 | G38: =IF(D38-E38>=0,0,D38-E38) -> 0 | H38: MH46AR8099 | I38: =F38/E38 -> 0 | J38: NPG | L38: 31.87
B39: 11.09.23 | C39: KEC BB | D39: =L39-0.01 -> 31.9 | E39: 31.911 | F39: =IF(D39-E39<=0,0,D39-E39) -> 0 | G39: =IF(D39-E39>=0,0,D39-E39) -> -0.011 | H39: MH40Y4944 | I39: =G39/E39 -> -0.00034470872 | J39: NPG | L39: 31.91
B40: 11.09.23 | C40: KEC BB | D40: =L40-0.01 -> 32.61 | E40: 32.429 | F40: =IF(D40-E40<=0,0,D40-E40) -> 0.181 | G40: =IF(D40-E40>=0,0,D40-E40) -> 0 | H40: MH40Y3144 | I40: =F40/E40 -> 0.005581424 | J40: NPG | L40: 32.62
B41: 12.09.23 | C41: KEC BB | D41: =L41-0.01 -> 33.03 | E41: 32.797 | F41: =IF(D41-E41<=0,0,D41-E41) -> 0.233 | G41: =IF(D41-E41>=0,0,D41-E41) -> 0 | H41: MH40Y4944 | I41: =F41/E41 -> 0.0071043083 | J41: NPG | L41: 33.04
B42: 12.09.23 | C42: KEC BB | D42: =L42-0.01 -> 23 | E42: 23.013 | F42: =IF(D42-E42<=0,0,D42-E42) -> 0 | G42: =IF(D42-E42>=0,0,D42-E42) -> -0.013 | H42: MH46AR3342 | I42: =G42/E42 -> -0.0005648981 | J42: NPG | L42: 23.01
...

Sheet OCT -23 
B2: SEC.& KATA WT,DIFFERENCE ANGLE OCT 2023 (vil bub)
B4: DISP.DATE | C4: PARTY | D4: KATA WT | E4: SEC.WT | F4: (+) WT | G4: (-)WT | H4: VEHICLE.NO. | I4: Net (+/-) % | J4: SECTION | K4: PG/NPG
B5: 01.10.23 | C5: KEC BB | D5: 25.14 | E5: 25.035 | F5: =IF(D5-E5<=0,0,D5-E5) -> 0.105 | G5: =IF(D5-E5>=0,0,D5-E5) -> 0 | H5: MH40AK7728 | I5: =F5/E5 -> 0.0041941282 | J5: HT-150X11/12/10/15 HT-130X11/10 | K5: NPG
B6: 01.10.23 | C6: KEC BB | D6: 32.25 | E6: 32.062 | F6: =IF(D6-E6<=0,0,D6-E6) -> 0.188 | G6: =IF(D6-E6>=0,0,D6-E6) -> 0 | H6: MH40Y3944 | I6: =F6/E6 -> 0.0058636392 | J6: HT-150X12/14 | K6: PG
B7: 01.10.23 | C7: KEC BB | D7: 32.64 | E7: 32.319 | F7: =IF(D7-E7<=0,0,D7-E7) -> 0.321 | G7: =IF(D7-E7>=0,0,D7-E7) -> 0 | H7: MH46AF3590 | I7: =F7/E7 -> 0.009932238 | J7: HT-90X6 | K7: PG
B8: 02.10.23 | C8: KEC BB | D8: 32 | E8: 31.537 | F8: =IF(D8-E8<=0,0,D8-E8) -> 0.463 | G8: =IF(D8-E8>=0,0,D8-E8) -> 0 | H8: MH40Y3944 | I8: =F8/E8 -> 0.014681168 | J8: HT-110X7 HT-150X11/12 | K8: PG
B9: 02.10.23 | C9: KEC BB | D9: 33.3 | E9: 33.224 | F9: =IF(D9-E9<=0,0,D9-E9) -> 0.076 | G9: =IF(D9-E9>=0,0,D9-E9) -> 0 | H9: MH46AF3590 | I9: =F9/E9 -> 0.002287503 | J9: HT-75X6/5 HT-90X6 | K9: PG
B10: 02.10.23 | C10: KEC BB | D10: 32.48 | E10: 32.48 | F10: =IF(D10-E10<=0,0,D10-E10) -> 0 | G10: =IF(D10-E10>=0,0,D10-E10) -> 0 | H10: MH40BG0308 | I10: =F10/E10 -> 0 | J10: HT-110X7/6/ MS-110X6 | K10: PG
B11: 02.10.23 | C11: KEC BB | D11: 33.32 | E11: 33.128 | F11: =IF(D11-E11<=0,0,D11-E11) -> 0.192 | G11: =IF(D11-E11>=0,0,D11-E11) -> 0 | H11: MH49AT2913 | I11: =F11/E11 -> 0.0057957015 | J11: MS-75X75X5/ 80X80X5 | K11: NPG
B12: 02.10.23 | C12: KEC BB | D12: 32.77 | E12: 32.399 | F12: =IF(D12-E12<=0,0,D12-E12) -> 0.371 | G12: =IF(D12-E12>=0,0,D12-E12) -> 0 | H12: MH40N7423 | I12: =F12/E12 -> 0.011450971 | J12: HT-150X15/14/17/ HT-110X7 HT-110X8 75X5/6 | K12: PG
B13: 02.10.23 | C13: KEC BB | D13: 33.25 | E13: 32.919 | F13: =IF(D13-E13<=0,0,D13-E13) -> 0.331 | G13: =IF(D13-E13>=0,0,D13-E13) -> 0 | H13: MH40Y4044 | I13: =F13/E13 -> 0.010054983 | J13: HT-150X150X16/18 | K13: NPG
B14: 02.10.23 | C14: KEC BB | D14: 33.34 | E14: 33.018 | F14: =IF(D14-E14<=0,0,D14-E14) -> 0.322 | G14: =IF(D14-E14>=0,0,D14-E14) -> 0 | H14: MH46AR8099 | I14: =F14/E14 -> 0.0097522563 | J14: HT-110X6/110X8 | K14: PG
B15: 03.10.23 | C15: KEC BB | D15: 32.79 | E15: 32.327 | F15: =IF(D15-E15<=0,0,D15-E15) -> 0.463 | G15: =IF(D15-E15>=0,0,D15-E15) -> 0 | H15: MH46AF3590 | I15: =F15/E15 -> 0.014322393 | K15: PG
B16: 03.10.23 | C16: KEC BB | D16: 31.69 | E16: 31.636 | F16: =IF(D16-E16<=0,0,D16-E16) -> 0.054 | G16: =IF(D16-E16>=0,0,D16-E16) -> 0 | H16: MH40Y3944 | I16: =F16/E16 -> 0.0017069162 | K16: NPG
B17: 03.10.23 | C17: KEC BB | D17: 32.46 | E17: 31.957 | F17: =IF(D17-E17<=0,0,D17-E17) -> 0.503 | G17: =IF(D17-E17>=0,0,D17-E17) -> 0 | H17: MH40Y4044 | I17: =F17/E17 -> 0.0157399 | K17: PG
B18: 03.10.23 | C18: KEC BB | D18: 31.54 | E18: 31.15 | F18: =IF(D18-E18<=0,0,D18-E18) -> 0.39 | G18: =IF(D18-E18>=0,0,D18-E18) -> 0 | H18: MH40Y4944 | I18: =F18/E18 -> 0.012520064 | K18: PG
B19: 04.10.23 | C19: KEC JBP | D19: 27.61 | E19: 27.477 | F19: =IF(D19-E19<=0,0,D19-E19) -> 0.133 | G19: =IF(D19-E19>=0,0,D19-E19) -> 0 | H19: MH40AK1958 | I19: =F19/E19 -> 0.004840412 | K19: NPG
B20: 04.10.23 | C20: KEC BB | D20: 32.54 | E20: 32.669 | F20: =IF(D20-E20<=0,0,D20-E20) -> 0 | G20: =IF(D20-E20>=0,0,D20-E20) -> -0.129 | H20: MH40Y4944 | I20: =G20/E20 -> -0.0039486975 | K20: PG/NPG
B21: 04.10.23 | C21: KEC BB | D21: 31.98 | E21: 31.544 | F21: =IF(D21-E21<=0,0,D21-E21) -> 0.436 | G21: =IF(D21-E21>=0,0,D21-E21) -> 0 | H21: MH40Y2044 | I21: =F21/E21 -> 0.013821963 | K21: PG
B22: 04.10.23 | C22: KEC BB | D22: 24.53 | E22: 24.684 | F22: =IF(D22-E22<=0,0,D22-E22) -> 0 | G22: =IF(D22-E22>=0,0,D22-E22) -> -0.154 | H22: MH49AT6275 | I22: =G22/E22 -> -0.0062388592 | K22: NPG
B23: 04.10.23 | C23: KEC BB | D23: 32.01 | E23: 32.02 | F23: =IF(D23-E23<=0,0,D23-E23) -> 0 | G23: =IF(D23-E23>=0,0,D23-E23) -> -0.01 | H23: MH46AF3590 | I23: =G23/E23 -> -0.00031230481 | K23: NPG
B24: 05.10.23 | C24: KEC BB | D24: 32.71 | E24: 32.627 | F24: =IF(D24-E24<=0,0,D24-E24) -> 0.083 | G24: =IF(D24-E24>=0,0,D24-E24) -> 0 | H24: MH40Y9744 | I24: =F24/E24 -> 0.0025439054 | K24: NPG
B25: 05.10.23 | C25: KEC BB | D25: 31.45 | E25: 30.893 | F25: =IF(D25-E25<=0,0,D25-E25) -> 0.557 | G25: =IF(D25-E25>=0,0,D25-E25) -> 0 | H25: MH40Y9844 | I25: =F25/E25 -> 0.018029974 | K25: NPG
B26: 06.10.23 | C26: KEC BB | D26: 32.34 | E26: 32.05 | F26: =IF(D26-E26<=0,0,D26-E26) -> 0.29 | G26: =IF(D26-E26>=0,0,D26-E26) -> 0 | H26: MH46AF3590 | I26: =F26/E26 -> 0.0090483619 | K26: PG/NPG
B27: 06.10.23 | C27: KEC BB | D27: 28.61 | E27: 28.44 | F27: =IF(D27-E27<=0,0,D27-E27) -> 0.17 | G27: =IF(D27-E27>=0,0,D27-E27) -> 0 | H27: MH40Y9844 | I27: =F27/E27 -> 0.0059774965 | K27: NPG
B28: 07.10.23 | C28: KEC JBP | D28: 32.94 | E28: 32.72 | F28: =IF(D28-E28<=0,0,D28-E28) -> 0.22 | G28: =IF(D28-E28>=0,0,D28-E28) -> 0 | H28: MH49AT1954 | I28: =F28/E28 -> 0.0067237164 | K28: PG/NPG
B29: 07.10.23 | C29: KEC JBP | D29: 32.91 | E29: 32.804 | F29: =IF(D29-E29<=0,0,D29-E29) -> 0.106 | G29: =IF(D29-E29>=0,0,D29-E29) -> 0 | H29: MH40AK6073 | I29: =F29/E29 -> 0.0032313133 | K29: PG
B30: 07.10.23 | C30: KEC JBP | D30: 32.56 | E30: 32.609 | F30: =IF(D30-E30<=0,0,D30-E30) -> 0 | G30: =IF(D30-E30>=0,0,D30-E30) -> -0.049 | H30: MH49AT1956 | I30: =G30/E30 -> -0.0015026526 | K30: PG
B31: 07.10.23 | C31: KEC JBP | D31: 32.82 | E31: 32.683 | F31: =IF(D31-E31<=0,0,D31-E31) -> 0.137 | G31: =IF(D31-E31>=0,0,D31-E31) -> 0 | H31: MH40AK6001 | I31: =F31/E31 -> 0.0041917817 | K31: PG
B32: 08.10.23 | C32: KEC JBP | D32: 32.99 | E32: 32.807 | F32: =IF(D32-E32<=0,0,D32-E32) -> 0.183 | G32: =IF(D32-E32>=0,0,D32-E32) -> 0 | H32: MH49AT1955 | I32: =F32/E32 -> 0.0055780778 | K32: PG/NPG
B33: 08.10.23 | C33: KEC BB | D33: 28.92 | E33: 28.721 | F33: =IF(D33-E33<=0,0,D33-E33) -> 0.199 | G33: =IF(D33-E33>=0,0,D33-E33) -> 0 | H33: MH40Y3944 | I33: =F33/E33 -> 0.0069287281 | K33: NPG
B34: 09.10.23 | C34: KEC BB | D34: 32.9 | E34: 32.906 | F34: =IF(D34-E34<=0,0,D34-E34) -> 0 | G34: =IF(D34-E34>=0,0,D34-E34) -> -0.006 | H34: MH49AT0504 | I34: =G34/E34 -> -0.00018233757 | K34: PG
B35: 09.10.23 | C35: KEC BB | D35: 39.72 | E35: 39.605 | F35: =IF(D35-E35<=0,0,D35-E35) -> 0.115 | G35: =IF(D35-E35>=0,0,D35-E35) -> 0 | H35: MH49AT4593 | I35: =F35/E35 -> 0.0029036738 | K35: PG
B36: 11.10.23 | C36: KEC BB | D36: 33.51 | E36: 32.892 | F36: =IF(D36-E36<=0,0,D36-E36) -> 0.618 | G36: =IF(D36-E36>=0,0,D36-E36) -> 0 | H36: MH46AF3590 | I36: =F36/E36 -> 0.018788763 | K36: NPG
B37: 11.10.23 | C37: KEC JBP | D37: 32.99 | E37: 32.845 | F37: =IF(D37-E37<=0,0,D37-E37) -> 0.145 | G37: =IF(D37-E37>=0,0,D37-E37) -> 0 | H37: MH40BG0309 | I37: =F37/E37 -> 0.004414675 | K37: PG
B38: 11.10.23 | C38: KEC JBP | D38: 32.69 | E38: 32.213 | F38: =IF(D38-E38<=0,0,D38-E38) -> 0.477 | G38: =IF(D38-E38>=0,0,D38-E38) -> 0 | H38: MH49AT3051 | I38: =F38/E38 -> 0.014807686 | K38: PG
B39: 11.10.23 | C39: KEC BB | D39: 32.26 | E39: 32.065 | F39: =IF(D39-E39<=0,0,D39-E39) -> 0.195 | G39: =IF(D39-E39>=0,0,D39-E39) -> 0 | H39: MH40Y2044 | I39: =F39/E39 -> 0.0060813972 | K39: NPG
B40: 11.10.23 | C40: KEC JBP | D40: 33.03 | E40: 32.777 | F40: =IF(D40-E40<=0,0,D40-E40) -> 0.253 | G40: =IF(D40-E40>=0,0,D40-E40) -> 0 | H40: MH49AT0403 | I40: =F40/E40 -> 0.0077188272 | K40: PG
B41: 11.10.23 | C41: KEC BB | D41: 32.62 | E41: 32.206 | F41: =IF(D41-E41<=0,0,D41-E41) -> 0.414 | G41: =IF(D41-E41>=0,0,D41-E41) -> 0 | H41: MH40Y4944 | I41: =F41/E41 -> 0.012854748 | K41: NPG
B42: 12.10.23 | C42: KEC JBP | D42: 32.54 | E42: 32.417 | F42: =IF(D42-E42<=0,0,D42-E42) -> 0.123 | G42: =IF(D42-E42>=0,0,D42-E42) -> 0 | H42: MH49AT0401 | I42: =F42/E42 -> 0.0037943055 | K42: NPG
...

Sheet NOV -23  
B2: SEC.& KATA WT,DIFFERENCE ANGLE nOV 2023 (vil bub)
B4: DISP.DATE | C4: PARTY | D4: KATA WT | E4: SEC.WT | F4: (+) WT | G4: (-)WT | H4: VEHICLE.NO. | I4: Net (+/-) % | J4: SECTION | K4: PG/NPG
B5: 01.11.23 | C5: KEC JBP | D5: 33.15 | E5: 33.04 | F5: =IF(D5-E5<=0,0,D5-E5) -> 0.11 | G5: =IF(D5-E5>=0,0,D5-E5) -> 0 | H5: MH49AT1950 | I5: =F5/E5 -> 0.0033292978 | J5: HT-150X11/12/10/15 HT-130X11/10 | K5: NPG
B6: 01.11.23 | C6: KEC BB | D6: 31.51 | E6: 31.535 | F6: =IF(D6-E6<=0,0,D6-E6) -> 0 | G6: =IF(D6-E6>=0,0,D6-E6) -> -0.025 | H6: MH46AF3590 | I6: =G6/E6 -> -0.00079276994 | J6: HT-150X12/14 | K6: NPG
B7: 01.11.23 | C7: KEC BB | D7: 32.02 | E7: 32.204 | F7: =IF(D7-E7<=0,0,D7-E7) -> 0 | G7: =IF(D7-E7>=0,0,D7-E7) -> -0.184 | H7: MH40Y3944 | I7: =G7/E7 -> -0.005713576 | J7: HT-90X6 | K7: NPG
B8: 01.11.23 | C8: KEC JBP | D8: 32.28 | E8: 32.242 | F8: =IF(D8-E8<=0,0,D8-E8) -> 0.038 | G8: =IF(D8-E8>=0,0,D8-E8) -> 0 | H8: MH40BG0311 | I8: =F8/E8 -> 0.0011785869 | J8: HT-110X7 HT-150X11/12 | K8: NPG
B9: 01.11.23 | C9: KEC BB | D9: 32.96 | E9: 32.925 | F9: =IF(D9-E9<=0,0,D9-E9) -> 0.035 | G9: =IF(D9-E9>=0,0,D9-E9) -> 0 | H9: MH49AT0507 | I9: =F9/E9 -> 0.001063022 | J9: HT-75X6/5 HT-90X6 | K9: NPG
B10: 01.11.23 | C10: KEC BB | D10: 31.28 | E10: 31.25 | F10: =IF(D10-E10<=0,0,D10-E10) -> 0.03 | G10: =IF(D10-E10>=0,0,D10-E10) -> 0 | H10: MH40Y5644 | I10: =F10/E10 -> 0.00096 | J10: HT-110X7/6/ MS-110X6 | K10: NPG
B11: 02.11.23 | C11: KEC JBP | D11: 40.06 | E11: 40.12 | F11: =IF(D11-E11<=0,0,D11-E11) -> 0 | G11: =IF(D11-E11>=0,0,D11-E11) -> -0.06 | H11: MH49AT04597 | I11: =G11/E11 -> -0.0014955135 | J11: MS-75X75X5/ 80X80X5 | K11: NPG
B12: 02.11.23 | C12: KEC BB | D12: 32.61 | E12: 32.993 | F12: =IF(D12-E12<=0,0,D12-E12) -> 0 | G12: =IF(D12-E12>=0,0,D12-E12) -> -0.383 | H12: MH46AF3590 | I12: =G12/E12 -> -0.011608523 | J12: HT-150X15/14/17/ HT-110X7 HT-110X8 75X5/6 | K12: NPG
B13: 02.11.23 | C13: KEC BB | D13: 32.25 | E13: 32.569 | F13: =IF(D13-E13<=0,0,D13-E13) -> 0 | G13: =IF(D13-E13>=0,0,D13-E13) -> -0.319 | H13: MH40Y4944 | I13: =G13/E13 -> -0.0097945899 | J13: HT-150X150X16/18 | K13: NPG
B14: 02.11.23 | C14: KEC BB | D14: 31.28 | E14: 31.643 | F14: =IF(D14-E14<=0,0,D14-E14) -> 0 | G14: =IF(D14-E14>=0,0,D14-E14) -> -0.363 | H14: MH40Y5644 | I14: =G14/E14 -> -0.011471732 | J14: HT-110X6/110X8 | K14: NPG
B15: 02.11.23 | C15: KEC BB | D15: 32.93 | E15: 32.91 | F15: =IF(D15-E15<=0,0,D15-E15) -> 0.02 | G15: =IF(D15-E15>=0,0,D15-E15) -> 0 | H15: MH40Y3944 | I15: =F15/E15 -> 0.00060771802 | K15: NPG
B16: 02.11.23 | C16: KEC BB | D16: 32.68 | E16: 32.56 | F16: =IF(D16-E16<=0,0,D16-E16) -> 0.12 | G16: =IF(D16-E16>=0,0,D16-E16) -> 0 | H16: MH49AT0409 | I16: =F16/E16 -> 0.0036855037 | K16: NPG
B17: 03.11.23 | C17: KEC JBP | D17: 32.24 | E17: 32.38564 | F17: =IF(D17-E17<=0,0,D17-E17) -> 0 | G17: =IF(D17-E17>=0,0,D17-E17) -> -0.14564 | H17: MH40AK2189 | I17: =G17/E17 -> -0.0044970549 | K17: NPG
B18: 03.11.23 | C18: KEC JBP | D18: 32.16 | E18: 32.502 | F18: =IF(D18-E18<=0,0,D18-E18) -> 0 | G18: =IF(D18-E18>=0,0,D18-E18) -> -0.342 | H18: MH49AT1956 | I18: =G18/E18 -> -0.010522429 | K18: NPG
B19: 03.11.23 | C19: KEC JBP | D19: 32.51 | E19: 32.758 | F19: =IF(D19-E19<=0,0,D19-E19) -> 0 | G19: =IF(D19-E19>=0,0,D19-E19) -> -0.248 | H19: MH49AT2914 | I19: =G19/E19 -> -0.0075706698 | K19: NPG
B20: 03.11.23 | C20: KEC BB | D20: 32.51 | E20: 32.382 | F20: =IF(D20-E20<=0,0,D20-E20) -> 0.128 | G20: =IF(D20-E20>=0,0,D20-E20) -> 0 | H20: MH49AT0502 | I20: =F20/E20 -> 0.0039528133 | K20: NPG
B21: 03.11.23 | C21: KEC BB | D21: 32.79 | E21: 32.77 | F21: =IF(D21-E21<=0,0,D21-E21) -> 0.02 | G21: =IF(D21-E21>=0,0,D21-E21) -> 0 | H21: MH49AT2946 | I21: =F21/E21 -> 0.00061031431 | K21: NPG
B22: 04.11.23 | C22: KEC JPR | D22: 32.15 | E22: 32.219 | F22: =IF(D22-E22<=0,0,D22-E22) -> 0 | G22: =IF(D22-E22>=0,0,D22-E22) -> -0.069 | H22: MH49AT3051 | I22: =G22/E22 -> -0.0021415935 | K22: PG
B23: 04.11.23 | C23: KEC JBP | D23: 32.08 | E23: 32.022 | F23: =IF(D23-E23<=0,0,D23-E23) -> 0.058 | G23: =IF(D23-E23>=0,0,D23-E23) -> 0 | H23: MH40AK1961 | I23: =F23/E23 -> 0.0018112548 | K23: NPG
