Workbook

Sheet COAL DETAILS
A1: COAL CONSUMPTION REPORT MONTH OF April- 23
A2: Rolling Date | B2: Mill | C2: Firing Source | D2: Mill Start time | E2: Mill Stop time | F2: Sections | G2: Prod. (MT.) | H2: Billet Used | I2: Furnace pre-heating time Hrs. | J2: Coal cons. for pre-heating MT | K2: Mill running time Hrs. | L2: Coal cons.for MT | M2: Avg.Coal cons.for per MT in Kgs. | N2: Total Coal cons. MT | O2: Avg. Total Coal cons. per MT in Kgs. | P2: Avg. Production per Hr. | Q2: Miss Roll Pcs. | R2: Miss Roll Qty | S2: Miss Roll Qty % | T2: Hot Out Pcs. | U2: Hot Out Qty | V2: Hot Out Qty % | W2: Power Consumed | X2: Power unit /mt
A3: 01to 05.04.23 | B3: 20" | C3: Pulv | F3: No section planning
A4: 06.04.23 | B4: 20" | C4: Pulv | D4: 08.00 AM | E4: 08.00 PM | F4: HT/MS-75X75X6/5 | G4: 74.786 | H4: DSP-125 / JSPL150 | K4: 12 | L4: 13.6 | M4: =L4/G4*1000 -> 181.85222 | N4: =+J4+L4 -> 13.6 | O4: =N4/G4*1000 -> 181.85222 | P4: =G4/K4 -> 6.2321667 | Q4: 13 | R4: 2.796 | S4: =R4/G4 -> 0.037386677 | V4: =U4/G4 -> 0 | W4: 8940 | X4: =W4/G4 -> 119.54109
A5: 07.04.23 | B5: 20" | C5: Pulv | D5: 08.00 AM | E5: 01.15 PM | F5: HT-75X75X6/5 | G5: 56.669 | H5: DSP-125 / JSPL150 | K5: 1.15 | L5: 8.2 | M5: =L5/G5*1000 -> 144.69992 | N5: =+J5+L5 -> 8.2 | O5: =N5/G5*1000 -> 144.69992 | P5: =G5/K5 -> 49.277391 | Q5: 1 | R5: 0.246 | S5: =R5/G5 -> 0.0043409977 | T5: 1 | U5: 0.246 | V5: =U5/G5 -> 0.0043409977 | W5: 5760 | X5: =W5/G5 -> 101.64287
A6: 08.04.23 | B6: 20" | C6: Pulv | D6: 8.00 AM | E6: 9.45 PM | F6: HT-90X90X7/6/5 | G6: 171.088 | H6: JSPL-150 | K6: 13.45 | L6: 23.2 | M6: =L6/G6*1000 -> 135.60273 | N6: =+J6+L6 -> 23.2 | O6: =N6/G6*1000 -> 135.60273 | P6: =G6/K6 -> 12.720297 | Q6: 6 | R6: 1.735 | S6: =R6/G6 -> 0.01014098 | T6: 13 | U6: =1.102+2.004 -> 3.106 | V6: =U6/G6 -> 0.0181544 | W6: 14760 | X6: =W6/G6 -> 86.271392 | Y6: 4
A7: 09.04.23 | B7: 20" | C7: Pulv | D7: 9.00 AM | E7: 8.00 PM | F7: HT-110X110X6/7/8 | G7: =136.491-5 -> 131.491 | H7: JSPL-150 | K7: 11 | L7: 18.7 | M7: =L7/G7*1000 -> 142.21506 | N7: =+J7+L7 -> 18.7 | O7: =N7/G7*1000 -> 142.21506 | P7: =G7/K7 -> 11.953727 | Q7: 1 | R7: 0.396 | S7: =R7/G7 -> 0.003011613 | T7: 1 | U7: 0.334 | V7: =U7/G7 -> 0.0025400978 | W7: 11040 | X7: =W7/G7 -> 83.960119
A8: 10.04.23 | B8: 20" | C8: Pulv | D8: 8.00 AM | E8: 7.45 PM | F8: HT-110X110X8/9/10 | G8: 164.158 | H8: JSPL-150 | K8: 11.45 | L8: 22.3 | M8: =L8/G8*1000 -> 135.84473 | N8: =+J8+L8 -> 22.3 | O8: =N8/G8*1000 -> 135.84473 | P8: =G8/K8 -> 14.336943 | S8: =R8/G8 -> 0 | T8: 1 | U8: 0.41 | V8: =U8/G8 -> 0.0024975938 | W8: 10980 | X8: =W8/G8 -> 66.88678
A9: 11.04.23 | B9: 20" | C9: Pulv | D9: 8.00 AM | E9: 4.10 PM | F9: HT-100X100X6/7 | G9: =103.355-5 -> 98.355 | H9: JSPL-150 | K9: 8.1 | L9: 15.2 | M9: =L9/G9*1000 -> 154.54222 | N9: =+J9+L9 -> 15.2 | O9: =N9/G9*1000 -> 154.54222 | P9: =G9/K9 -> 12.142593 | Q9: 1 | R9: 0.27 | S9: =R9/G9 -> 0.0027451578 | T9: 1 | U9: 0.27 | V9: =U9/G9 -> 0.0027451578 | W9: 8280 | X9: =W9/G9 -> 84.184841
A10: 12.04.23 | B10: 20" | C10: Pulv | F10: WEEKLY OFF
A11: 13.04.23 | B11: 20" | C11: Pulv | D11: 8.00 AM | E11: 4.10 PM | G11: =93.493-5 -> 88.493 | H11: JSPL-150 | K11: 6.3 | L11: 13.1 | M11: =L11/G11*1000 -> 148.03431 | N11: =+J11+L11 -> 13.1 | O11: =N11/G11*1000 -> 148.03431 | P11: =G11/K11 -> 14.046508 | S11: =R11/G11 -> 0 | V11: =U11/G11 -> 0 | W11: 6300 | X11: =W11/G11 -> 71.192072
A12: 14.04.23 | B12: 20" | C12: Pulv | D12: 8.00 AM | E12: 8.00 PM | F12: HT-130X130X12/13/11 | G12: 216.819 | H12: JSPL-150 | K12: 12 | L12: 28.4 | M12: =L12/G12*1000 -> 130.98483 | N12: =+J12+L12 -> 28.4 | O12: =N12/G12*1000 -> 130.98483 | P12: =G12/K12 -> 18.06825 | Q12: 1 | R12: 0.569 | S12: =R12/G12 -> 0.0026243088 | V12: =U12/G12 -> 0 | W12: 11340 | X12: =W12/G12 -> 52.301689
A13: 15.04.23 | B13: 20" | C13: Pulv | D13: 10.30 AM | E13: 6.00 PM | F13: HT-130X130X11/10 | G13: 117.038 | H13: JSPL-150 | K13: 7.3 | L13: 16.3 | M13: =L13/G13*1000 -> 139.27101 | N13: =+J13+L13 -> 16.3 | O13: =N13/G13*1000 -> 139.27101 | P13: =G13/K13 -> 16.032603 | S13: =R13/G13 -> 0 | T13: 1 | U13: 0.646 | V13: =U13/G13 -> 0.0055195748 | W13: 6840 | X13: =W13/G13 -> 58.442557
A14: 16.04.23 | B14: 20" | C14: Pulv | F14: SHUT DOWN DUE TO PENDING STRAIGHTENING MATERIAL
A15: 17.04.23 | B15: 20" | C15: Pulv | D15: 8.00 AM | E15: 5.00 PM | F15: HT-130X130X10/9 | G15: 154.791 | H15: JSPL-150 | K15: 9 | L15: 23.4 | M15: =L15/G15*1000 -> 151.17158 | N15: =+J15+L15 -> 23.4 | O15: =N15/G15*1000 -> 151.17158 | P15: =G15/K15 -> 17.199 | Q15: 1 | R15: 0.531 | S15: =R15/G15 -> 0.003430432 | T15: 3 | U15: =1.34+0.531 -> 1.871 | V15: =U15/G15 -> 0.012087266 | W15: 7980 | X15: =W15/G15 -> 51.553385
A16: 18.04.23 | B16: 20" | C16: Pulv | D16: 8.00 AM | E16: 9.00 PM | F16: HT-130X130X9/120X10/9 | G16: 181.445 | H16: JSPL-150 | K16: 14 | L16: 25.8 | M16: =L16/G16*1000 -> 142.19185 | N16: =+J16+L16 -> 25.8 | O16: =N16/G16*1000 -> 142.19185 | P16: =G16/K16 -> 12.960357 | Q16: 3 | R16: 1.564 | S16: =R16/G16 -> 0.0086196919 | T16: 2 | U16: =0.544+0.436 -> 0.98 | V16: =U16/G16 -> 0.0054010857 | W16: 10320 | X16: =W16/G16 -> 56.87674
A17: 19.04.23 | B17: 20" | C17: Pulv | F17: WEEKLY OFF
A18: 20.04.23 | B18: 20" | C18: Pulv | F18: No section planning
A19: 21.04.23 | B19: 20" | C19: Pulv | D19: 7.00 AM | E19: 1.30 PM | F19: HT-120X120X9/8/7 | G19: 108.675 | H19: JSPL-150 | K19: 6.3 | L19: 15.7 | M19: =L19/G19*1000 -> 144.46745 | N19: =+J19+L19 -> 15.7 | O19: =N19/G19*1000 -> 144.46745 | P19: =G19/K19 -> 17.25 | S19: =R19/G19 -> 0 | T19: 1 | U19: 0.552 | V19: =U19/G19 -> 0.0050793651 | W19: 5640 | X19: =W19/G19 -> 51.897861
A20: 22/23.04.23 | B20: 20" | C20: Pulv | F20: No section planning
A21: 24.04.23 | B21: 20" | C21: Pulv | D21: 8.00 AM | E21: 7.30 PM | F21: HT-150X150X18,16,15,14,12,10 | G21: 167.749 | H21: JSPL-150 | K21: 11.3 | L21: 25.3 | M21: =L21/G21*1000 -> 150.82057 | N21: =+J21+L21 -> 25.3 | O21: =N21/G21*1000 -> 150.82057 | P21: =G21/K21 -> 14.845044 | S21: =R21/G21 -> 0 | T21: 4 | U21: =1.852+0.7+0.833 -> 3.385 | V21: =U21/G21 -> 0.020178958 | W21: 9720 | X21: =W21/G21 -> 57.943714
A22: 25.04.23 | B22: 20" | C22: Pulv | D22: 8.00 AM | E22: 4.00 PM | F22: HT-80X80X6/5 | G22: =76.366-5 -> 71.366 | H22: JSPL-150 | K22: 8 | L22: 10.9 | M22: =L22/G22*1000 -> 152.73379 | N22: =+J22+L22 -> 10.9 | O22: =N22/G22*1000 -> 152.73379 | P22: =G22/K22 -> 8.92075 | S22: =R22/G22 -> 0 | T22: 3 | U22: 0.748 | V22: =U22/G22 -> 0.010481182 | W22: 8160 | X22: =W22/G22 -> 114.34016
A23: 26/30.04.23 | B23: 20" | C23: Pulv | F23: No section planning & SHUT DOWN DUE TO PENDING STRAIGHTENING MATERIAL
B24: 20" | C24: Pulv | M24: =L24/G24*1000 -> #DIV/0! | N24: =+J24+L24 -> 0 | O24: =N24/G24*1000 -> #DIV/0! | P24: =G24/K24 -> #DIV/0! | S24: =R24/G24 -> #DIV/0! | V24: =U24/G24 -> #DIV/0! | X24: =W24/G24 -> #DIV/0!
B25: 20" | C25: Pulv | M25: =L25/G25*1000 -> #DIV/0! | N25: =+J25+L25 -> 0 | O25: =N25/G25*1000 -> #DIV/0! | P25: =G25/K25 -> #DIV/0! | S25: =R25/G25 -> #DIV/0! | V25: =U25/G25 -> #DIV/0! | X25: =W25/G25 -> #DIV/0!
B26: 20" | C26: Pulv | M26: =L26/G26*1000 -> #DIV/0! | N26: =+J26+L26 -> 0 | O26: =N26/G26*1000 -> #DIV/0! | P26: =G26/K26 -> #DIV/0! | S26: =R26/G26 -> #DIV/0! | V26: =U26/G26 -> #DIV/0! | X26: =W26/G26 -> #DIV/0!
B27: 20" | C27: Pulv | M27: =L27/G27*1000 -> #DIV/0! | N27: =+J27+L27 -> 0 | O27: =N27/G27*1000 -> #DIV/0! | P27: =G27/K27 -> #DIV/0! | S27: =R27/G27 -> #DIV/0! | V27: =U27/G27 -> #DIV/0! | X27: =W27/G27 -> #DIV/0!
G28: =SUM(G3:G27) -> 1802.923 | J28: =SUM(J3:J27) -> 0 | K28: =SUM(K3:K27) -> 131.35 | L28: =SUM(L3:L27) -> 260.1 | M28: =L28/G28*1000 -> 144.26573 | N28: =SUM(N3:N27) -> 260.1 | O28: =N28/G28*1000 -> 144.26573 | P28: =G28/K28 -> 13.726098 | Q28: =SUM(Q3:Q27) -> 27 | R28: =SUM(R3:R27) -> 8.107 | S28: =R28/G28 -> 0.0044965869 | T28: =SUM(T3:T27) -> 31 | U28: =SUM(U3:U27) -> 12.548 | V28: =U28/G28 -> 0.0069598092 | W28: =SUM(W3:W27) -> 126060 | X28: =W28/G28 -> 69.919791
G30: =+G28 -> 1802.923 | J30: =+#REF!+J28 -> #REF! | K30: =+K28 -> 131.35 | L30: =+L28 -> 260.1 | M30: =+M28 -> 144.26573 | N30: =+N28 -> 260.1 | O30: =+O28 -> 144.26573 | P30: =+P28 -> 13.726098 | Q30: =+Q28 -> 27 | R30: =+R28 -> 8.107 | S30: =R30/G30 -> 0.0044965869 | T30: =+T28 -> 31 | U30: =+U28 -> 12.548 | V30: =U30/G30 -> 0.0069598092 | W30: =+W28 -> 126060 | X30: =W30/G30 -> 69.919791
A32: COAL CONSUMPTION REPORT MONTH OF MAY- 22
A33: Rolling Date | B33: Mill | C33: Gassifier Start time | D33: Mill Start time | E33: Mill Stop time | F33: Sections | G33: Prod. (MT.) | H33: Billet Used | I33: Furnace pre-heating time Hrs. | J33: Coal cons. for pre-heating MT | K33: Mill running time Hrs. | L33: Coal cons.for running MT | M33: Avg.Coal cons.for running per MT in Kgs. | N33: Total Coal cons. MT | O33: Avg. Total Coal cons. per MT in Kgs. | P33: Avg. Production per Hr. | R33: Miss Roll Qty | S33: Miss Roll Qty % | U33: Hot Out Qty | V33: Hot Out Qty % | W33: Power Consumed | X33: Power unit /mt
A34: 01.05.22 | B34: 20" | C34: Pulv | F34: Labour day
A35: 02.05.22 | B35: 20" | C35: Pulv | F35: Coal short | M35: =L35/G35*1000 -> #DIV/0! | N35: =+J35+L35 -> 0 | O35: =N35/G35*1000 -> #DIV/0! | P35: =G35/K35 -> #DIV/0! | S35: =R35/G35 -> #DIV/0! | V35: =U35/G35 -> #DIV/0! | X35: =W35/G35 -> #DIV/0!
B36: 20" | C36: Pulv | M36: =L36/G36*1000 -> #DIV/0! | N36: =+J36+L36 -> 0 | O36: =N36/G36*1000 -> #DIV/0! | P36: =G36/K36 -> #DIV/0! | S36: =R36/G36 -> #DIV/0! | V36: =U36/G36 -> #DIV/0! | X36: =W36/G36 -> #DIV/0!
B37: 20" | C37: Pulv | M37: =L37/G37*1000 -> #DIV/0! | N37: =+J37+L37 -> 0 | O37: =N37/G37*1000 -> #DIV/0! | P37: =G37/K37 -> #DIV/0! | S37: =R37/G37 -> #DIV/0! | V37: =U37/G37 -> #DIV/0! | X37: =W37/G37 -> #DIV/0!
B38: 20" | C38: Pulv | M38: =L38/G38*1000 -> #DIV/0! | N38: =+J38+L38 -> 0 | O38: =N38/G38*1000 -> #DIV/0! | P38: =G38/K38 -> #DIV/0! | S38: =R38/G38 -> #DIV/0! | V38: =U38/G38 -> #DIV/0! | X38: =W38/G38 -> #DIV/0!
M39: =L39/G39*1000 -> #DIV/0! | N39: =+J39+L39 -> 0 | O39: =N39/G39*1000 -> #DIV/0! | P39: =G39/K39 -> #DIV/0! | S39: =R39/G39 -> #DIV/0! | V39: =U39/G39 -> #DIV/0! | X39: =W39/G39 -> #DIV/0!
G40: =SUM(G34:G39) -> 0 | J40: =SUM(J34:J39) -> 0 | K40: =SUM(K34:K39) -> 0 | L40: =SUM(L34:L39) -> 0 | M40: =L40/G40*1000 -> #DIV/0! | N40: =SUM(N34:N39) -> 0 | O40: =N40/G40*1000 -> #DIV/0! | P40: =G40/K40 -> #DIV/0! | R40: =SUM(R34:R39) -> 0 | S40: =R40/G40 -> #DIV/0! | U40: =SUM(U34:U39) -> 0 | V40: =U40/G40 -> #DIV/0! | W40: =SUM(W34:W39) -> 0 | X40: =W40/G40 -> #DIV/0!
G42: =+G40 -> 0 | J42: =+#REF!+J40 -> #REF! | K42: =+K40 -> 0 | L42: =+L40 -> 0 | M42: =+M40 -> #DIV/0! | N42: =+N40 -> 0 | O42: =+O40 -> #DIV/0! | P42: =+P40 -> #DIV/0! | R42: =+R40 -> 0 | S42: =R42/G42 -> #DIV/0! | U42: =+U40 -> 0 | V42: =U42/G42 -> #DIV/0! | W42: =+W40 -> 0 | X42: =W42/G42 -> #DIV/0!
A44: COAL CONSUMPTION REPORT MONTH OF MAY- 23
...

Sheet summary
A1: PRODUCTION & COAL CONSUMPTION REPORT - ON WARDS APRIL-24
A2: Month | B2: Mill | C2: Production | D2: coal cons. Heating | E2: Coal cons.for MT | F2: Avg.Coal cons.for per MT in Kgs. | G2: Total Coal cons. MT | H2: Avg. Total Coal cons. per MT in Kg. | I2: Avg. Production per Hr. | J2: Miss Roll Qty | K2: Miss Roll Qty % | L2: Hot Out Qty | M2: Hot Out Qty % | N2: Power Consumed | O2: Power unit /mt
A3: April-23 | B3: 20" | C3: 1802.923 | D3: 0 | E3: 260.1 | F3: 144.26573 | G3: 227.1 | H3: 184.24543 | I3: 13.726098 | J3: 8.107 | K3: 0.0044965869 | L3: 12.548 | M3: 0.0069598092 | N3: 126060 | O3: 69.919791
A4: May-23 | B4: 20" | C4: 1321.317 | E4: 190.9 | F4: 144.47706 | G4: 227.1 | H4: 184.24543 | I4: 11.459818 | J4: 9.73 | K4: 0.007363865 | L4: 9.318 | M4: 0.0070520549 | N4: 105540 | O4: 79.874852
A5: Jun-23 | B5: 20" | C5: 2294.804 | E5: 334.7 | F5: 145.85124 | I5: 11.177808 | J5: 19.247 | K5: 0.0083872087 | L5: 8.408 | M5: 0.0036639295 | N5: 182470 | O5: 79.514416
A6: July-23 | B6: 20" | C6: 2819.069 | E6: 413.1 | F6: 146.53774 | I6: 13.033144 | J6: 18.985 | K6: 0.0067344928 | L6: 3.037 | M6: 0.001077306 | N6: 234341 | O6: 83.127089
A7: Aug-23 | B7: 20" | C7: =+'COAL DETAILS'!G180 -> 4024.154 | E7: =+'COAL DETAILS'!L180 -> 535.7 | F7: =+'COAL DETAILS'!M180 -> 133.12115 | I7: =+'COAL DETAILS'!P180 -> 13.400446 | J7: =+'COAL DETAILS'!R180 -> 12.229 | K7: =+'COAL DETAILS'!S180 -> 0.0030388996 | L7: =+'COAL DETAILS'!U180 -> 9.067 | M7: =+'COAL DETAILS'!V180 -> 0.0022531444 | N7: =+'COAL DETAILS'!W180 -> 312348 | O7: =+'COAL DETAILS'!X180 -> 77.618302
A8: Sep-23 | B8: 20" | C8: =+'COAL DETAILS'!G218 -> 2962.095 | E8: =+'COAL DETAILS'!L218 -> 398.4 | F8: =+'COAL DETAILS'!M218 -> 134.4994 | I8: =+'COAL DETAILS'!P218 -> 13.913081 | J8: =+'COAL DETAILS'!R218 -> 18.39 | K8: =+'COAL DETAILS'!S218 -> 0.0062084437 | L8: =+'COAL DETAILS'!U218 -> 18.382 | M8: =+'COAL DETAILS'!V218 -> 0.0062057429 | N8: =+'COAL DETAILS'!W218 -> 209500 | O8: =+'COAL DETAILS'!X218 -> 70.726969
A9: Oct-23 | B9: 20" | C9: =+'COAL DETAILS'!G254 -> 3947.125 | E9: =+'COAL DETAILS'!L254 -> 529.35 | F9: =+'COAL DETAILS'!M254 -> 134.11027 | I9: =+'COAL DETAILS'!P254 -> 13.861721 | J9: =+'COAL DETAILS'!R254 -> 16.904 | K9: =+'COAL DETAILS'!S254 -> 0.0042826108 | L9: =+'COAL DETAILS'!U254 -> 12.421 | M9: =+'COAL DETAILS'!V254 -> 0.0031468474 | N9: =+'COAL DETAILS'!W254 -> 305390 | O9: =+'COAL DETAILS'!X254 -> 77.370238
A10: Nov-23 | B10: 20" | C10: =+'COAL DETAILS'!G290 -> 4136.374 | E10: =+'COAL DETAILS'!L290 -> 540.23 | F10: =+'COAL DETAILS'!M290 -> 130.60473 | I10: =+'COAL DETAILS'!P290 -> 14.12696 | J10: =+'COAL DETAILS'!R290 -> 15.885 | K10: =+'COAL DETAILS'!S290 -> 0.00384032 | L10: =+'COAL DETAILS'!U290 -> 9.04 | M10: =+'COAL DETAILS'!V290 -> 0.002185489 | N10: =+'COAL DETAILS'!W290 -> 299940 | O10: =+'COAL DETAILS'!X290 -> 72.512785
A11: Dec-23 | B11: 20" | C11: =+'COAL DETAILS'!G326 -> 4643.35 | E11: =+'COAL DETAILS'!L324 -> 593.4 | F11: =++'COAL DETAILS'!M326 -> 127.79566 | I11: =+'COAL DETAILS'!P326 -> 14.645482 | J11: =+'COAL DETAILS'!R326 -> 17.564 | K11: =+'COAL DETAILS'!S326 -> 0.0037826138 | L11: =+'COAL DETAILS'!U326 -> 12.764 | M11: =+'COAL DETAILS'!V326 -> 0.0027488774 | N11: =+'COAL DETAILS'!W326 -> 347220 | O11: =+'COAL DETAILS'!X326 -> 74.777908
A12: Jan-24 | B12: 20" | C12: =+'COAL DETAILS'!G362 -> 3018.97 | E12: =+'COAL DETAILS'!L362 -> 390.9 | F12: =+'COAL DETAILS'!M362 -> 129.48125 | I12: =+'COAL DETAILS'!P362 -> 14.376048 | J12: =+'COAL DETAILS'!R362 -> 9.822 | K12: =+'COAL DETAILS'!S362 -> 0.0032534275 | L12: =+'COAL DETAILS'!U362 -> 11.572 | M12: =+'COAL DETAILS'!V362 -> 0.0038330954 | N12: =+'COAL DETAILS'!W362 -> 213780 | O12: =+'COAL DETAILS'!X360 -> 70.812231
A13: Feb-24 | B13: 20"
A14: Mar-24 | B14: 20"
A15: Grand Total | C15: =SUM(C3:C14) -> 30970.181 | D15: =+#REF!+#REF! -> #REF! | E15: =SUM(E3:E14) -> 4186.78 | F15: =E15/C15*1000 -> 135.18746 | G15: =#REF!+#REF!+#REF!+#REF!+G14 -> #REF! | H15: =(#REF!+#REF!+#REF!+#REF!+H14)/5 -> #REF! | I15: =+'COAL DETAILS'!P368 -> 13.601214 | J15: =SUM(J3:J14) -> 146.863 | K15: =J15/C15 -> 0.0047420775 | L15: =SUM(L3:L14) -> 106.557 | M15: =L15/C15 -> 0.0034406321 | N15: =SUM(N3:N14) -> 2336589 | O15: =N15/C15 -> 75.446411

Sheet Party wise Production
A1: Agreement Year | K1: Financial Year
A2: Production | F2: Dispatchecd | K2: Production | P2: Dispatchecd
A3: Month | B3: KEC | C3: OTHER | D3: Total | F3: Month | G3: KEC | H3: OTHER | I3: Total | K3: Month | L3: KEC | M3: OTHER | N3: Total | P3: Month | Q3: KEC | R3: OTHER | S3: Total
A4: Jan-21 | D4: =SUM(B4:C4) -> 0 | F4: Jan-21 | I4: =SUM(G4:H4) -> 0 | K4: April-21 | N4: =SUM(L4:M4) -> 0 | P4: April-21 | S4: =SUM(Q4:R4) -> 0
A5: Feb -21 | D5: =SUM(B5:C5) -> 0 | F5: Feb -21 | I5: =SUM(G5:H5) -> 0 | K5: May-21 | N5: =SUM(L5:M5) -> 0 | P5: May-21 | S5: =SUM(Q5:R5) -> 0
A6: Mar-21 | D6: =SUM(B6:C6) -> 0 | F6: Mar-21 | I6: =SUM(G6:H6) -> 0 | K6: Jun-21 | N6: =SUM(L6:M6) -> 0 | P6: Jun-21 | S6: =SUM(Q6:R6) -> 0
A7: April-21 | D7: =SUM(B7:C7) -> 0 | F7: April-21 | I7: =SUM(G7:H7) -> 0 | K7: July-21 | N7: =SUM(L7:M7) -> 0 | P7: July-21 | S7: =SUM(Q7:R7) -> 0
A8: May-21 | D8: =SUM(B8:C8) -> 0 | F8: May-21 | I8: =SUM(G8:H8) -> 0 | K8: Aug-21 | N8: =SUM(L8:M8) -> 0 | P8: Aug-21 | S8: =SUM(Q8:R8) -> 0
A9: Jun-21 | D9: =SUM(B9:C9) -> 0 | F9: Jun-21 | I9: =SUM(G9:H9) -> 0 | K9: Sep-21 | N9: =SUM(L9:M9) -> 0 | P9: Sep-21 | S9: =SUM(Q9:R9) -> 0
A10: July-21 | D10: =SUM(B10:C10) -> 0 | F10: July-21 | I10: =SUM(G10:H10) -> 0 | K10: Oct-21 | N10: =SUM(L10:M10) -> 0 | P10: Oct-21 | S10: =SUM(Q10:R10) -> 0
A11: Aug-21 | D11: =SUM(B11:C11) -> 0 | F11: Aug-21 | I11: =SUM(G11:H11) -> 0 | K11: Nov-21 | N11: =SUM(L11:M11) -> 0 | P11: Nov-21 | S11: =SUM(Q11:R11) -> 0
A12: Sep-21 | D12: =SUM(B12:C12) -> 0 | F12: Sep-21 | I12: =SUM(G12:H12) -> 0 | K12: Dec-21 | N12: =SUM(L12:M12) -> 0 | P12: Dec-21 | S12: =SUM(Q12:R12) -> 0
A13: Oct-21 | D13: =SUM(B13:C13) -> 0 | F13: Oct-21 | I13: =SUM(G13:H13) -> 0 | K13: Jan-22 | N13: =SUM(L13:M13) -> 0 | P13: Jan-22 | S13: =SUM(Q13:R13) -> 0
A14: Nov-21 | D14: =SUM(B14:C14) -> 0 | F14: Nov-21 | I14: =SUM(G14:H14) -> 0 | K14: Feb -22 | L14: 87.164 | N14: =SUM(L14:M14) -> 87.164 | P14: Feb -22 | S14: =SUM(Q14:R14) -> 0
A15: Dec-21 | D15: =SUM(B15:C15) -> 0 | F15: Dec-21 | I15: =SUM(G15:H15) -> 0 | K15: Mar-22 | L15: 894.47 | N15: =SUM(L15:M15) -> 894.47 | P15: Mar-22 | Q15: 813.843 | S15: =SUM(Q15:R15) -> 813.843
A16: Total | B16: =SUM(B4:B15) -> 0 | C16: =SUM(C4:C15) -> 0 | D16: =SUM(D4:D15) -> 0 | F16: Total | G16: =SUM(G4:G15) -> 0 | H16: =SUM(H4:H15) -> 0 | I16: =SUM(I4:I15) -> 0 | K16: Total | L16: =SUM(L4:L15) -> 981.634 | M16: =SUM(M4:M15) -> 0 | N16: =SUM(N4:N15) -> 981.634 | P16: Total | Q16: =SUM(Q4:Q15) -> 813.843 | R16: =SUM(R4:R15) -> 0 | S16: =SUM(S4:S15) -> 813.843
A18: Month | B18: KEC | C18: OTHER | D18: Total | F18: Month | G18: KEC | H18: OTHER | I18: Total | K18: Month | L18: KEC | M18: OTHER | N18: Total | P18: Month | Q18: KEC | R18: OTHER | S18: Total
A19: Jan-22 | D19: =SUM(B19:C19) -> 0 | F19: Jan-22 | I19: =SUM(G19:H19) -> 0 | K19: April-22 | L19: 1232.595 | N19: =SUM(L19:M19) -> 1232.595 | P19: April-22 | Q19: 729.954 | S19: =SUM(Q19:R19) -> 729.954
A20: Feb -22 | B20: 87.164 | D20: =SUM(B20:C20) -> 87.164 | F20: Feb -22 | I20: =SUM(G20:H20) -> 0 | K20: May-22 | N20: =SUM(L20:M20) -> 0 | P20: May-22 | Q20: =327.425+100.358+4.838+30.665+15.413 -> 478.699 | S20: =SUM(Q20:R20) -> 478.699
A21: Mar-22 | B21: 894.47 | D21: =SUM(B21:C21) -> 894.47 | F21: Mar-22 | G21: 813.843 | I21: =SUM(G21:H21) -> 813.843 | K21: Jun-22 | N21: =SUM(L21:M21) -> 0 | P21: Jun-22 | S21: =SUM(Q21:R21) -> 0
A22: April-22 | B22: 1232.595 | D22: =SUM(B22:C22) -> 1232.595 | F22: April-22 | G22: 729.954 | I22: =SUM(G22:H22) -> 729.954 | K22: July-22 | N22: =SUM(L22:M22) -> 0 | P22: July-22 | S22: =SUM(Q22:R22) -> 0
A23: May-22 | D23: =SUM(B23:C23) -> 0 | F23: May-22 | G23: =327.425+100.358+4.838+30.665+15.413 -> 478.699 | I23: =SUM(G23:H23) -> 478.699 | K23: Aug-22 | N23: =SUM(L23:M23) -> 0 | P23: Aug-22 | S23: =SUM(Q23:R23) -> 0
A24: Jun-22 | D24: =SUM(B24:C24) -> 0 | F24: Jun-22 | I24: =SUM(G24:H24) -> 0 | K24: Sep-22 | N24: =SUM(L24:M24) -> 0 | P24: Sep-22 | S24: =SUM(Q24:R24) -> 0
A25: July-22 | D25: =SUM(B25:C25) -> 0 | F25: July-22 | I25: =SUM(G25:H25) -> 0 | K25: Oct-22 | N25: =SUM(L25:M25) -> 0 | P25: Oct-22 | S25: =SUM(Q25:R25) -> 0
A26: Aug-22 | D26: =SUM(B26:C26) -> 0 | F26: Aug-22 | I26: =SUM(G26:H26) -> 0 | K26: Nov-22 | L26: 797.41 | N26: =SUM(L26:M26) -> 797.41 | P26: Nov-22 | Q26: 357.093 | S26: =SUM(Q26:R26) -> 357.093
A27: Sep-22 | D27: =SUM(B27:C27) -> 0 | F27: Sep-22 | I27: =SUM(G27:H27) -> 0 | K27: Dec-22 | L27: 2515.005 | N27: =SUM(L27:M27) -> 2515.005 | P27: Dec-22 | Q27: 2386.718 | S27: =SUM(Q27:R27) -> 2386.718
A28: Oct-22 | D28: =SUM(B28:C28) -> 0 | F28: Oct-22 | I28: =SUM(G28:H28) -> 0 | K28: Jan-23 | L28: 2736.605 | N28: =SUM(L28:M28) -> 2736.605 | P28: Jan-23 | Q28: 1975.695 | S28: =SUM(Q28:R28) -> 1975.695
A29: Nov-22 | B29: 797.41 | D29: =SUM(B29:C29) -> 797.41 | F29: Nov-22 | G29: 357.093 | I29: =SUM(G29:H29) -> 357.093 | K29: Feb -23 | L29: 2972.848 | N29: =SUM(L29:M29) -> 2972.848 | P29: Feb -23 | Q29: 3247.167 | S29: =SUM(Q29:R29) -> 3247.167
A30: Dec-22 | B30: 2515.005 | D30: =SUM(B30:C30) -> 2515.005 | F30: Dec-22 | G30: 2386.718 | I30: =SUM(G30:H30) -> 2386.718 | K30: Mar-23 | L30: 1282.593 | N30: =SUM(L30:M30) -> 1282.593 | P30: Mar-23 | Q30: 1521.356 | S30: =SUM(Q30:R30) -> 1521.356
A31: Total | B31: =SUM(B19:B30) -> 5526.644 | C31: =SUM(C19:C30) -> 0 | D31: =SUM(D19:D30) -> 5526.644 | F31: Total | G31: =SUM(G19:G30) -> 4766.307 | H31: =SUM(H19:H30) -> 0 | I31: =SUM(I19:I30) -> 4766.307 | K31: Total | L31: =SUM(L19:L30) -> 11537.056 | M31: =SUM(M19:M30) -> 0 | N31: =SUM(N19:N30) -> 11537.056 | P31: Total | Q31: =SUM(Q19:Q30) -> 10696.682 | R31: =SUM(R19:R30) -> 0 | S31: =SUM(S19:S30) -> 10696.682
A34: Month | B34: KEC | C34: OTHER | D34: Total | F34: Month | G34: KEC | H34: OTHER | I34: Total | K34: Month | L34: KEC | M34: OTHER | N34: Total | P34: Month | Q34: KEC | R34: OTHER | S34: Total
A35: Jan-23 | B35: 2736.605 | D35: =SUM(B35:C35) -> 2736.605 | F35: Jan-23 | G35: 1975.695 | I35: =SUM(G35:H35) -> 1975.695 | K35: April-23 | L35: =1822.923-20 -> 1802.923 | N35: =SUM(L35:M35) -> 1802.923 | P35: April-23 | Q35: 2100.572 | S35: =SUM(Q35:R35) -> 2100.572
A36: Feb -23 | B36: 2972.848 | D36: =SUM(B36:C36) -> 2972.848 | F36: Feb -23 | G36: 3247.167 | I36: =SUM(G36:H36) -> 3247.167 | K36: May-23 | L36: =1323.186-1.869 -> 1321.317 | N36: =SUM(L36:M36) -> 1321.317 | P36: May-23 | Q36: 717.3 | S36: =SUM(Q36:R36) -> 717.3
A37: Mar-23 | B37: 1282.593 | D37: =SUM(B37:C37) -> 1282.593 | F37: Mar-23 | G37: 1521.356 | I37: =SUM(G37:H37) -> 1521.356 | K37: Jun-23 | L37: 2294.804 | N37: =SUM(L37:M37) -> 2294.804 | P37: Jun-23 | Q37: 2546.762 | S37: =SUM(Q37:R37) -> 2546.762
A38: April-23 | B38: =1822.923-20 -> 1802.923 | D38: =SUM(B38:C38) -> 1802.923 | F38: April-23 | G38: 2100.572 | I38: =SUM(G38:H38) -> 2100.572 | K38: July-23 | L38: 2819.069 | N38: =SUM(L38:M38) -> 2819.069 | P38: July-23 | Q38: 2561.738 | R38: 16.923 | S38: =SUM(Q38:R38) -> 2578.661
A39: May-23 | B39: =1323.186-1.869 -> 1321.317 | D39: =SUM(B39:C39) -> 1321.317 | F39: May-23 | G39: 717.3 | I39: =SUM(G39:H39) -> 717.3 | K39: Aug-23 | L39: 4024.154 | N39: =SUM(L39:M39) -> 4024.154 | P39: Aug-23 | Q39: =3801.575-33.751 -> 3767.824 | R39: =4.966+28.785 -> 33.751 | S39: =SUM(Q39:R39) -> 3801.575
A40: Jun-23 | B40: 2294.804 | D40: =SUM(B40:C40) -> 2294.804 | F40: Jun-23 | G40: 2546.762 | I40: =SUM(G40:H40) -> 2546.762 | K40: Sep-23 | L40: 2962.095 | N40: =SUM(L40:M40) -> 2962.095 | P40: Sep-23 | Q40: 2821.393 | R40: 114.421 | S40: =SUM(Q40:R40) -> 2935.814
A41: July-23 | B41: 2819.069 | D41: =SUM(B41:C41) -> 2819.069 | F41: July-23 | G41: 2561.738 | H41: 16.923 | I41: =SUM(G41:H41) -> 2578.661 | K41: Oct-23 | N41: =SUM(L41:M41) -> 0 | P41: Oct-23 | S41: =SUM(Q41:R41) -> 0
A42: Aug-23 | B42: 4024.154 | D42: =SUM(B42:C42) -> 4024.154 | F42: Aug-23 | G42: =3801.575-33.751 -> 3767.824 | H42: =4.966+28.785 -> 33.751 | I42: =SUM(G42:H42) -> 3801.575 | K42: Nov-23 | N42: =SUM(L42:M42) -> 0 | P42: Nov-23 | S42: =SUM(Q42:R42) -> 0
A43: Sep-23 | B43: 2962.095 | D43: =SUM(B43:C43) -> 2962.095 | F43: Sep-23 | G43: 2821.393 | H43: 114.421 | I43: =SUM(G43:H43) -> 2935.814 | K43: Dec-23 | N43: =SUM(L43:M43) -> 0 | P43: Dec-23 | S43: =SUM(Q43:R43) -> 0
...

Sheet Sheet1
A1: Vinar Butibori Production 29.05.23
A2: Month | B2: Production | C2: Dispatched
A3: Nov-22 | B3: 797.41 | C3: 357.093
A4: Dec-22 | B4: 2515.005 | C4: 2386.718
A5: Jan-23 | B5: 2736.605 | C5: 1975.695
A6: Feb -23 | B6: 2972.848 | C6: 3247.167
A7: Mar-23 | B7: 1282.593 | C7: 1521.356
A8: April-23 | B8: =1822.923-20 -> 1802.923 | C8: 2100.572
A9: May-23 | B9: 1144.151 | C9: 621.047
A10: Total | B10: =SUM(B3:B9) -> 13251.535 | C10: =SUM(C3:C9) -> 12209.648

Sheet PRODUCTIVITY ANALYSIS 2022-23
B1: Productivity analysis for Month of APRIL . 2023
B3: Mill | C3: Actual Working Days/Shifts | D3: Prod.Qty. in MT. | E3: Mill Coal | F3: Total Coal Consumption
B4: 20" | C4: 14 Day ( 14 Shifts ) | D4: =74.786+56.669+171.088+136.491+164.158+103.355+93.493+216.819+117.038+154.791+181.445+108.675+167.749+76.366-20 -> 1802.923 | E4: 20" => | F4: =+I75 -> 260.1 | T4: =+F4/D6 -> 0.14426573
B6: Total | C6: =+C4 -> 14 Day ( 14 Shifts ) | D6: =SUM(D4:D5) -> 1802.923 | F6: =SUM(F4:F5) -> 260.1
C7: Loss of Working days/Shifts | E7: Reasons for Non working.
C9: * 4 Day ( 4 Shifts ) | E9: Weekly off.
C11: * 7 Day ( 7 Shifts ) | E11: No section planning
C12: * 5 Day ( 5 Shifts ) | E12: No.Section Planning & SHUT DOWN DUE TO PENDING STRAIGHTENING MATERIAL
C17: * 0 Day (0 Shifts ) | E17: * Balance Shift & Day
D25: Production | F25: Kg /mt | H25: `
B26: 12to14 hrs | C26: Average per day | D26: =D6/13 -> 138.68638 | E26: Coal consumption aver/MT | F26: =+T4*1000 -> 144.26573
B27: 1 SHIFT | C27: Average per shift | D27: =+D26 -> 138.68638
B30: Month of APRIL. 2023 | D30: Production | G30: Coal Consumption
B31: Prod.Date | C31: Shift | D31: Mill | E31: Shift Qty | F31: Day Qty | G31: Furnace Heating | H31: Running | I31: TOTAL | J31: Average per | K31: TOTAL | L31: Average per
D32: 16"& 14" | H32: Mill Coal | I32: Consumption | J32: Kg /mt | K32: power unit | L32: mt
B33: 01.to 05.04.23 | C33: No section | F33: =+E33+E34 -> 0
C34: planning
B35: 06.04.23 | C35: Day- 20" Gear box nutbolt broken & Pass change | E35: 74.786 | F35: =+E35+E36 -> 74.786 | I35: 13.6 | J35: =I35/F35*1000 -> 181.85222 | K35: 8940 | L35: =K35/F35 -> 119.54109
B37: 07.04.23 | C37: Day- 20" Size Change | E37: 56.669 | F37: =+E37+E38 -> 56.669 | I37: 8.2 | J37: =I37/F37*1000 -> 144.69992 | K37: 5760 | L37: =K37/F37 -> 101.64287
B39: 08.04.23 | C39: Day- 20" | E39: 171.088 | F39: =+E39+E40 -> 171.088 | I39: 23.2 | J39: =I39/F39*1000 -> 135.60273 | K39: 14760 | L39: =K39/F39 -> 86.271392
B41: 09.04.23 | C41: Day- 20" | E41: =136.491-5 -> 131.491 | F41: =+E41+E42 -> 131.491 | I41: 18.7 | J41: =I41/F41*1000 -> 142.21506 | K41: 11040 | L41: =K41/F41 -> 83.960119
B43: 10.04.23 | C43: Day- 20" | E43: 164.158 | F43: =+E43+E44 -> 164.158 | I43: 22.3 | J43: =I43/F43*1000 -> 135.84473 | K43: 10980 | L43: =K43/F43 -> 66.88678
B45: 11.04.23 | C45: Day- 20" cooling bed jam | E45: =103.355-5 -> 98.355 | F45: =+E45+E46 -> 98.355 | I45: 15.2 | J45: =I45/F45*1000 -> 154.54222 | K45: 8280 | L45: =K45/F45 -> 84.184841
B47: 12.04.23 | C47: Weekly off
B49: 13.04.23 | C49: Day- 20" | E49: =93.493-5 -> 88.493 | F49: =+E49+E50 -> 88.493 | I49: 13.1 | J49: =I49/F49*1000 -> 148.03431 | K49: 6300 | L49: =K49/F49 -> 71.192072
C50: Section change
B51: 14.04.23 | C51: Day- 20" | E51: 216.819 | F51: =+E51+E52 -> 216.819 | I51: 28.4 | J51: =I51/F51*1000 -> 130.98483 | K51: 11340 | L51: =K51/F51 -> 52.301689
B53: 15.04.23 | C53: Day- 20" | E53: 117.038 | F53: =+E53+E54 -> 117.038 | I53: 16.3 | J53: =I53/F53*1000 -> 139.27101 | K53: 6840 | L53: =K53/F53 -> 58.442557
C54: Colling bed jam
B55: 16.04.23 | C55: SHUT DOWN DUE TO PENDING STRAIGHTENING MATERIAL | F55: =+E55+E56 -> 0
B57: 17.04.23 | C57: Day- 20" | E57: 154.791 | F57: =+E57+E58 -> 154.791 | I57: 23.4 | J57: =I57/F57*1000 -> 151.17158 | K57: 7980 | L57: =K57/F57 -> 51.553385
C58: Power off
B59: 18.04.23 | C59: Day- 20" | E59: 181.445 | F59: =+E59+E60 -> 181.445 | I59: 25.8 | J59: =I59/F59*1000 -> 142.19185 | K59: 10320 | L59: =K59/F59 -> 56.87674
B61: 19.04.23 | C61: Weekly off | F61: =+E61+E62 -> 0
B63: 20.04.23 | C63: No section planning | F63: =+E63+E64 -> 0
B65: 21.04.23 | C65: Day- 20" | E65: 108.675 | F65: =+E65+E66 -> 108.675 | I65: 15.7 | J65: =I65/F65*1000 -> 144.46745 | K65: 5640 | L65: =K65/F65 -> 51.897861
B67: 22/23.04.23 | C67: No section planning | F67: =+E67+E68 -> 0
B69: 24.04.23 | C69: Day- 20" | E69: 167.749 | F69: =+E69+E70 -> 167.749 | I69: 25.3 | J69: =I69/F69*1000 -> 150.82057 | K69: 9720 | L69: =K69/F69 -> 57.943714
B71: 25.04.23 | C71: Day- 20" | E71: =76.366-5 -> 71.366 | F71: =+E71+E72 -> 71.366 | I71: 10.9 | J71: =I71/F71*1000 -> 152.73379 | K71: 8160 | L71: =K71/F71 -> 114.34016
C72: Size change
...
