Workbook

Sheet SUMMARY
B2: SUMMARY JOB WORK
B4: KEC BB AS ON DT. | C4: =NOW() -> 45297.536
A8: LOT NO | B8: Do.No. | C8: Size | D8: R.M Receipts Qty | E8: Challan Receipts Qty | F8: Challan Receipts Bal.Qty | G8: Challan Dt.(mm/dd/yy) | H8: Validity | I8: Challan Bal. Days | J8: Angle Dispatched Qty | K8: BL 4.5% & W / S 3.5% | L8: Finesh Good Balance Qty | M8: R.M Balance Qty
A9: HT/MS
A10: 1 | C10: HT-MS | D10: =+'KEC BB JOB WORK '!G1263 -> 37613.458 | E10: =+'KEC BB JOB WORK '!G1263 -> 37613.458 | F10: =D10-E10 -> 0 | J10: =+'KEC BB JOB WORK '!N1263 -> 32665.872 | K10: =+'KEC BB JOB WORK '!Q1263+'KEC BB JOB WORK '!R1263 -> 2711.7339 | L10: =+'KEC BB JOB WORK '!T1263 -> 2235.8521 | M10: =L10/92% -> 2430.274
B13: Total | D13: =+D10 -> 37613.458 | E13: =+E10 -> 37613.458 | F13: =+F10 -> 0 | J13: =+J10 -> 32665.872 | K13: =+K10 -> 2711.7339 | L13: =+L10 -> 2235.8521 | M13: =+M10 -> 2430.274
B14: BILLET STOCK
A15: HT | C15: HT | D15: =+D10 -> 37613.458 | E15: =+E10 -> 37613.458 | F15: =+F10 -> 0 | J15: =+J10 -> 32665.872 | K15: =+K10 -> 2711.7339 | L15: =+L10 -> 2235.8521 | M15: =+M10 -> 2430.274 | N15: =M15-B15 -> 2430.274
A16: MS | C16: MS
A17: TOTAL | B17: =SUM(B15:B16) -> 0 | D17: =SUM(D15:D16) -> 37613.458 | E17: =SUM(E15:E16) -> 37613.458 | F17: =SUM(F15:F16) -> 0 | J17: =SUM(J15:J16) -> 32665.872 | K17: =SUM(K15:K16) -> 2711.7339 | L17: =SUM(L15:L16) -> 2235.8521 | M17: =SUM(M15:M16) -> 2430.274 | N17: =SUM(N15:N16) -> 2430.274
L18: KEC BB
B20: KEC JBP AS ON DT. | C20: =+C4 -> 45297.536
A26: KEC BB | D26: 18.02.2022
A27: Total Qty | B27: ANGLE STOCK | C27: Month | D27: Total Qty | E27: Feb- 2022 | F27: APRIL- 2022 | G27: Today Qty | P27: Today Qty
A28: 2021-2022 | C28: HT | D28: =+J15 -> 32665.872 | E28: 3966.392 | F28: 147.858 | G28: =D28-E28-F28 -> 28551.622 | P28: =D28-E28-G28-#REF!-H28-I28-J28-K28-L28-M28-N28-O28 -> #REF! | R28: =Q28-P28 -> #REF!
C29: MS | D29: =+J16 -> 0 | P29: =D29-E29-G29-#REF!-H29-I29-J29-K29-L29-M29-N29-O29 -> #REF!
D30: =SUM(D28:D29) -> 32665.872 | E30: =SUM(E28:E29) -> 3966.392 | F30: =SUM(F28:F29) -> 147.858 | G30: =SUM(G28:G29) -> 28551.622 | H30: =SUM(H28:H29) -> 0 | I30: =SUM(I28:I29) -> 0 | J30: =SUM(J28:J29) -> 0 | K30: =SUM(K28:K29) -> 0 | ... P30: =SUM(P28:P29) -> #REF!
A34: LOT NO | B34: Do.No. | C34: Size | D34: R.M Receipts Qty | E34: Challan Receipts Qty | F34: Challan Receipts Bal.Qty | G34: Challan Dt.(mm/dd/yy) | H34: Validity | I34: Challan Bal. Days | J34: Angle Dispatched Qty | K34: BL 4.5% & W / S 3.5% | L34: Finesh Good Balance Qty | M34: R.M Balance Qty
A35: HT/MS
A36: 1 | C36: HT-MS | D36: =+'KEC JBP JOB WORK '!G89 -> 2714.04 | E36: =+'KEC JBP JOB WORK '!G89 -> 2714.04 | F36: =D36-E36 -> 0 | J36: =+'KEC JBP JOB WORK '!N89 -> 2511.499 | K36: =+'KEC JBP JOB WORK '!Q89+'KEC JBP JOB WORK '!R89 -> 202.54228 | L36: =+'KEC JBP JOB WORK '!T89 -> -0.00128 | M36: =L36/92% -> -0.0013913043
B39: Total | D39: =+D36 -> 2714.04 | E39: =+E36 -> 2714.04 | F39: =+F36 -> 0 | J39: =+J36 -> 2511.499 | K39: =+K36 -> 202.54228 | L39: =+L36 -> -0.00128 | M39: =+M36 -> -0.0013913043
B40: BILLET STOCK
A41: HT | C41: HT | D41: =+D36 -> 2714.04 | E41: =+E36 -> 2714.04 | F41: =+F36 -> 0 | J41: =+J36 -> 2511.499 | K41: =+K36 -> 202.54228 | L41: =+L36 -> -0.00128 | M41: =+M36 -> -0.0013913043 | N41: =M41-B41 -> -0.0013913043
A42: MS | C42: MS
A43: TOTAL | B43: =SUM(B41:B42) -> 0 | D43: =SUM(D41:D42) -> 2714.04 | E43: =SUM(E41:E42) -> 2714.04 | F43: =SUM(F41:F42) -> 0 | J43: =SUM(J41:J42) -> 2511.499 | K43: =SUM(K41:K42) -> 202.54228 | L43: =SUM(L41:L42) -> -0.00128 | M43: =SUM(M41:M42) -> -0.0013913043 | N43: =SUM(N41:N42) -> -0.0013913043
L44: KEC BB
B46: KEC JBP AS ON DT. | C46: =+C30 -> 0
A52: KEC BB | D52: 21.04.2022
A53: Total Qty | B53: ANGLE STOCK | C53: Month | D53: Total Qty | E53: Feb/May- 2022 | F53: - 2022 | G53: Today Qty | P53: Today Qty
A54: 2021-2022 | C54: HT | D54: =+J41 -> 2511.499 | E54: =629.149+164.143 -> 793.292 | G54: =D54-E54-F54 -> 1718.207 | P54: =D54-E54-G54-#REF!-H54-I54-J54-K54-L54-M54-N54-O54 -> #REF!
C55: MS | D55: =+J42 -> 0 | P55: =D55-E55-G55-#REF!-H55-I55-J55-K55-L55-M55-N55-O55 -> #REF!
D56: =SUM(D54:D55) -> 2511.499 | E56: =SUM(E54:E55) -> 793.292 | F56: =SUM(F54:F55) -> 0 | G56: =SUM(G54:G55) -> 1718.207 | H56: =SUM(H54:H55) -> 0 | I56: =SUM(I54:I55) -> 0 | J56: =SUM(J54:J55) -> 0 | K56: =SUM(K54:K55) -> 0 | ... P56: =SUM(P54:P55) -> #REF!

Sheet KEC BB JOB WORK 
V2: (mm/dd/yy
A3: JOB WORK KEC BB | V3: =+SUMMARY!C4 -> 45297.536
A4: LOT NO. | B4: PARTY | C4: SIZE | D4: INVOICE NO. | E4: Challan No. | F4: Challan Dt.(mm/dd/yy | G4: Challan Qty. | H4: Challan Value | I4: RATE | K4: VIL Challan No. | L4: KEC Challan No. | M4: Dispatched. Dt. | N4: Dispatched. Qty. | P4: Finish Good Qty | Q4: Burning loss 4.5% | R4: Waste & Scrap 3.5% | T4: Finish Good Balance Qty | V4: Challan Balance Days
A5: 1 | B5: IISCO | C5: HT-150X150 | D5: OS0022003321 | E5: 498 | F5: 44562 | G5: 32.079 | H5: 1594700 | I5: =H5/G5 -> 49711.649 | K5: 64, 78 | L5: 498 | M5: 06.03.22, 17.03.22 | N5: =27.033+2.48 -> 29.513 | P5: =G5*0.92 -> 29.51268 | Q5: =G5*4.5% -> 1.443555 | R5: =G5*3.5% -> 1.122765 | T5: =G5-N5-Q5-R5 -> -0.00032 | V5: =360-($V$3-F5) -> -375.53556 | W5: =T5/0.92%/100 -> -0.00034782609
A6: 2 | B6: IISCO | C6: HT-150X150 | D6: OS0022003321 | E6: 499 | F6: 44562 | G6: 29.941 | H6: 1488386 | I6: =H6/G6 -> 49710.631 | K6: 79 | L6: 499 | M6: 17.03.22 | N6: 27.546 | P6: =G6*0.92 -> 27.54572 | Q6: =G6*4.5% -> 1.347345 | R6: =G6*3.5% -> 1.047935 | T6: =G6-N6-Q6-R6 -> -0.00028 | V6: =360-($V$3-F6) -> -375.53556 | W6: =T6/0.92%/100 -> -0.00030434783
A7: 3 | B7: IISCO | C7: HT-150X150 | D7: OS0022003324 | E7: 500 | F7: 44562 | G7: 30.694 | H7: 1524731 | I7: =H7/G7 -> 49675.213 | K7: 80, 81 | L7: 500 | M7: 17.03.22, 17.03.22 | N7: =1.339+26.899 -> 28.238 | P7: =G7*0.92 -> 28.23848 | Q7: =G7*4.5% -> 1.38123 | R7: =G7*3.5% -> 1.07429 | T7: =G7-N7-Q7-R7 -> 0.00048 | V7: =360-($V$3-F7) -> -375.53556 | W7: =T7/0.92%/100 -> 0.00052173913
A8: 4 | B8: IISCO | C8: HT-150X150 | D8: OS0022003324 | E8: 501 | F8: 44562 | G8: 32.886 | H8: 1633640 | I8: =H8/G8 -> 49675.85 | K8: 82, 86 | L8: 501 | M8: 17.03.22, 19.03.22 | N8: =5.054+25.201 -> 30.255 | P8: =G8*0.92 -> 30.25512 | Q8: =G8*4.5% -> 1.47987 | R8: =G8*3.5% -> 1.15101 | T8: =G8-N8-Q8-R8 -> 0.00012 | V8: =360-($V$3-F8) -> -375.53556 | W8: =T8/0.92%/100 -> 0.00013043478
A9: 5 | B9: IISCO | C9: HT-150X150 | D9: OS0022003327 | E9: 502 | F9: 44562 | G9: 30.848 | H9: 1531678 | I9: =H9/G9 -> 49652.425 | K9: 87, 88 | L9: 502 | M9: 19.03.22, 19.03.22 | N9: =7.999+20.381 -> 28.38 | P9: =G9*0.92 -> 28.38016 | Q9: =G9*4.5% -> 1.38816 | R9: =G9*3.5% -> 1.07968 | T9: =G9-N9-Q9-R9 -> 0.00016 | V9: =360-($V$3-F9) -> -375.53556 | W9: =T9/0.92%/100 -> 0.00017391304
A10: 6 | B10: IISCO | C10: HT-150X150 | D10: OS0022003327 | E10: 503 | F10: 44562 | G10: 33.052 | H10: 1641084 | I10: =H10/G10 -> 49651.579 | K10: 89, 90 | L10: 503 | M10: 19.03.22, 20.03.22 | N10: =12.39+18.018 -> 30.408 | P10: =G10*0.92 -> 30.40784 | Q10: =G10*4.5% -> 1.48734 | R10: =G10*3.5% -> 1.15682 | T10: =G10-N10-Q10-R10 -> -0.00016 | V10: =360-($V$3-F10) -> -375.53556 | W10: =T10/0.92%/100 -> -0.00017391304
A11: 7 | B11: IISCO | C11: HT-150X150 | D11: OS0022003326 | E11: 504 | F11: 44562 | G11: 30.897 | H11: 1534403 | I11: =H11/G11 -> 49661.877 | K11: 91, 92 | L11: 504 | M11: 20.03.22, 21.03.22 | N11: =14.633+13.792 -> 28.425 | P11: =G11*0.92 -> 28.42524 | Q11: =G11*4.5% -> 1.390365 | R11: =G11*3.5% -> 1.081395 | T11: =G11-N11-Q11-R11 -> 0.00024 | V11: =360-($V$3-F11) -> -375.53556 | W11: =T11/0.92%/100 -> 0.00026086957
A12: 8 | B12: IISCO | C12: HT-150X150 | D12: OS0022003326 | E12: 505 | F12: 44562 | G12: 33.103 | H12: 1644003 | I12: =H12/G12 -> 49663.263 | K12: 93, 94 | L12: 505 | M12: 21.03.22 , 22.03.22 | N12: =17.442+13.013 -> 30.455 | P12: =G12*0.92 -> 30.45476 | Q12: =G12*4.5% -> 1.489635 | R12: =G12*3.5% -> 1.158605 | T12: =G12-N12-Q12-R12 -> -0.00024 | V12: =360-($V$3-F12) -> -375.53556 | W12: =T12/0.92%/100 -> -0.00026086957
A13: 9 | B13: IISCO | C13: HT-150X150 | D13: OS0022003322 | E13: 506 | F13: 44562 | G13: 32.069 | H13: 1594206 | I13: =H13/G13 -> 49711.747 | K13: 95, 96 | L13: 506 | M13: 22.03.22, 22.03.22 | N13: =20.315+9.188 -> 29.503 | P13: =G13*0.92 -> 29.50348 | Q13: =G13*4.5% -> 1.443105 | R13: =G13*3.5% -> 1.122415 | T13: =G13-N13-Q13-R13 -> 0.00048 | V13: =360-($V$3-F13) -> -375.53556 | W13: =T13/0.92%/100 -> 0.00052173913
A14: 10 | B14: IISCO | C14: HT-150X150 | D14: OS0022003322 | E14: 507 | F14: 44562 | G14: 29.931 | H14: 1487926 | I14: =H14/G14 -> 49711.871 | K14: 97, 98, 101 | L14: 507 | M14: 22.03.22, 22.03.22, 22.03.22 | N14: =23.075+4.372+0.09 -> 27.537 | P14: =G14*0.92 -> 27.53652 | Q14: =G14*4.5% -> 1.346895 | R14: =G14*3.5% -> 1.047585 | T14: =G14-N14-Q14-R14 -> -0.00048 | V14: =360-($V$3-F14) -> -375.53556 | W14: =T14/0.92%/100 -> -0.00052173913
A15: 12 | B15: IISCO | C15: HT-150X150 | D15: OS0022003323 | E15: 508 | F15: 44562 | G15: 29.931 | H15: 1487926 | I15: =H15/G15 -> 49711.871 | K15: 99 | L15: 508 | M15: 22.03.22 | N15: 27.537 | P15: =G15*0.92 -> 27.53652 | Q15: =G15*4.5% -> 1.346895 | R15: =G15*3.5% -> 1.047585 | T15: =G15-N15-Q15-R15 -> -0.00048 | V15: =360-($V$3-F15) -> -375.53556 | W15: =T15/0.92%/100 -> -0.00052173913
A16: 13 | B16: IISCO | C16: HT-150X150 | D16: OS0022003317 | E16: 509 | F16: 44562 | G16: 32.069 | H16: 1594206 | I16: =H16/G16 -> 49711.747 | K16: 100, 102 | L16: 509 | M16: 22.03.22, 22.03.22 | N16: =0.203+29.3 -> 29.503 | P16: =G16*0.92 -> 29.50348 | Q16: =G16*4.5% -> 1.443105 | R16: =G16*3.5% -> 1.122415 | T16: =G16-N16-Q16-R16 -> 0.00048 | V16: =360-($V$3-F16) -> -375.53556 | W16: =T16/0.92%/100 -> 0.00052173913
A17: 14 | B17: IISCO | C17: HT-150X150 | D17: OS0022003317 | E17: 510 | F17: 44562 | G17: 29.931 | H17: 1487926 | I17: =H17/G17 -> 49711.871 | K17: 103, 107 | L17: 510 | M17: 22.03.22, 24.03.22 | N17: =2.74+24.797 -> 27.537 | P17: =G17*0.92 -> 27.53652 | Q17: =G17*4.5% -> 1.346895 | R17: =G17*3.5% -> 1.047585 | T17: =G17-N17-Q17-R17 -> -0.00048 | V17: =360-($V$3-F17) -> -375.53556 | W17: =T17/0.92%/100 -> -0.00052173913
A18: 16 | B18: IISCO | C18: HT-150X150 | D18: OS0022003329 | E18: 511 | F18: 44562 | G18: 32.907 | H18: 1634627 | I18: =H18/G18 -> 49674.142 | K18: 108, 109 | L18: 511 | M18: 24.03.22, 24.03.22 | N18: =8.314+21.96 -> 30.274 | P18: =G18*0.92 -> 30.27444 | Q18: =G18*4.5% -> 1.480815 | R18: =G18*3.5% -> 1.151745 | T18: =G18-N18-Q18-R18 -> 0.00044 | V18: =360-($V$3-F18) -> -375.53556 | W18: =T18/0.92%/100 -> 0.00047826087
A19: 17 | B19: IISCO | C19: HT-150X150 | D19: OS0022003329 | E19: 512 | F19: 44562 | G19: 30.713 | H19: 1525652 | I19: =H19/G19 -> 49674.47 | K19: 110, 111 | L19: 512 | M19: 24.03.22, 25.03.22 | N19: =9.357+18.899 -> 28.256 | P19: =G19*0.92 -> 28.25596 | Q19: =G19*4.5% -> 1.382085 | R19: =G19*3.5% -> 1.074955 | T19: =G19-N19-Q19-R19 -> -4e-05 | V19: =360-($V$3-F19) -> -375.53556 | W19: =T19/0.92%/100 -> -4.3478261e-05
A20: 18 | B20: IISCO | C20: HT-150X150 | D20: OS0022003316 | E20: 513 | F20: 44562 | G20: 29.941 | H20: 1488386 | I20: =H20/G20 -> 49710.631 | K20: 112, 113 | L20: 513 | M20: 25.03.22, 26.03.22 | N20: =12.408+15.138 -> 27.546 | P20: =G20*0.92 -> 27.54572 | Q20: =G20*4.5% -> 1.347345 | R20: =G20*3.5% -> 1.047935 | T20: =G20-N20-Q20-R20 -> -0.00028 | V20: =360-($V$3-F20) -> -375.53556 | W20: =T20/0.92%/100 -> -0.00030434783
A21: 19 | B21: IISCO | C21: HT-150X150 | D21: OS0022003316 | E21: 514 | F21: 44562 | G21: 32.079 | H21: 1594700 | I21: =H21/G21 -> 49711.649 | K21: 68 | L21: 514 | M21: 09.03.22 | N21: 32.079 | T21: =G21-N21-Q21-R21 -> 0 | V21: =360-($V$3-F21) -> -375.53556 | W21: =T21/0.92%/100 -> 0
A22: 20 | B22: IISCO | C22: HT-150X150 | D22: OS0022003323 | E22: 515 | F22: 44563 | G22: 32.069 | H22: 1594206 | I22: =H22/G22 -> 49711.747 | K22: 69 | L22: 515 | M22: 09.03.22 | N22: 32.069 | T22: =G22-N22-Q22-R22 -> 0 | V22: =360-($V$3-F22) -> -374.53556 | W22: =T22/0.92%/100 -> 0
A23: 21 | B23: IISCO | C23: HT-150X150 | D23: OS0022003325 | E23: 516 | F23: 44563 | G23: 32.886 | H23: 1633640 | I23: =H23/G23 -> 49675.85 | K23: 114, 115 | L23: 516 | M23: 26.03.22, 27.03.22 | N23: =17.651+12.604 -> 30.255 | P23: =G23*0.92 -> 30.25512 | Q23: =G23*4.5% -> 1.47987 | R23: =G23*3.5% -> 1.15101 | T23: =G23-N23-Q23-R23 -> 0.00012 | V23: =360-($V$3-F23) -> -374.53556 | W23: =T23/0.92%/100 -> 0.00013043478
A24: 22 | B24: IISCO | C24: HT-150X150 | D24: OS0022003325 | E24: 517 | F24: 44563 | G24: 30.694 | H24: 1524731 | I24: =H24/G24 -> 49675.213 | K24: 116, 120 | L24: 517 | M24: 27.03.22, 29.03.22 | N24: =20.14+8.098 -> 28.238 | P24: =G24*0.92 -> 28.23848 | Q24: =G24*4.5% -> 1.38123 | R24: =G24*3.5% -> 1.07429 | T24: =G24-N24-Q24-R24 -> 0.00048 | V24: =360-($V$3-F24) -> -374.53556 | W24: =T24/0.92%/100 -> 0.00052173913
A25: 23 | B25: IISCO | C25: HT-150X150 | D25: OS0022003328 | E25: 518 | F25: 44563 | G25: 32.886 | H25: 1633189 | I25: =H25/G25 -> 49662.136 | K25: 117, 121 | L25: 518 | M25: 27.03.22, 29.03.22 | N25: =28.891+1.364 -> 30.255 | P25: =G25*0.92 -> 30.25512 | Q25: =G25*4.5% -> 1.47987 | R25: =G25*3.5% -> 1.15101 | T25: =G25-N25-Q25-R25 -> 0.00012 | V25: =360-($V$3-F25) -> -374.53556 | W25: =T25/0.92%/100 -> 0.00013043478
A26: 24 | B26: IISCO | C26: HT-150X150 | D26: OS0022003328 | E26: 519 | F26: 44563 | G26: 30.694 | H26: 1524309 | I26: =H26/G26 -> 49661.465 | K26: 119, 122 | L26: 519 | M26: 28.03.22, 29.03.22 | N26: =20.346+7.892 -> 28.238 | P26: =G26*0.92 -> 28.23848 | Q26: =G26*4.5% -> 1.38123 | R26: =G26*3.5% -> 1.07429 | T26: =G26-N26-Q26-R26 -> 0.00048 | V26: =360-($V$3-F26) -> -374.53556 | W26: =T26/0.92%/100 -> 0.00052173913
A27: 25 | B27: IISCO | C27: HT-150X150 | D27: OS0022003318 | E27: 520 | F27: 44563 | G27: 29.979 | H27: 1490229 | I27: =H27/G27 -> 49709.096 | K27: 123, 15 | L27: 520 | M27: 29.03.22, 02.04.22 | N27: =15.46+12.121 -> 27.581 | P27: =G27*0.92 -> 27.58068 | Q27: =G27*4.5% -> 1.349055 | R27: =G27*3.5% -> 1.049265 | T27: =G27-N27-Q27-R27 -> -0.00032 | V27: =360-($V$3-F27) -> -374.53556 | W27: =T27/0.92%/100 -> -0.00034782609
A28: 26 | B28: IISCO | C28: HT-150X150 | D28: OS0022003318 | E28: 521 | F28: 44563 | G28: 32.121 | H28: 1596676 | I28: =H28/G28 -> 49708.166 | K28: 74 | L28: 521 | M28: 15.03.22 | N28: 32.121 | T28: =G28-N28-Q28-R28 -> 0 | V28: =360-($V$3-F28) -> -374.53556 | W28: =T28/0.92%/100 -> 0 | X28: =+T28+T26+T25 -> 0.0006
A29: 27 | B29: IISCO | C29: HT-150X150 | D29: OS0022003319 | E29: 522 | F29: 44563 | G29: 29.96 | H29: 1489307 | I29: =H29/G29 -> 49709.846 | K29: 124, 16, 109 | L29: 522 | M29: 29.03.22, 02.04.22, 16.04.22 | N29: =16.033+7.234+4.296 -> 27.563 | P29: =G29*0.92 -> 27.5632 | Q29: =G29*4.5% -> 1.3482 | R29: =G29*3.5% -> 1.0486 | T29: =G29-N29-Q29-R29 -> 0.0002 | V29: =360-($V$3-F29) -> -374.53556 | W29: =T29/0.92%/100 -> 0.0002173913
A30: 28 | B30: IISCO | C30: HT-150X150 | D30: OS0022003319 | E30: 523 | F30: 44563 | G30: 32.1 | H30: 1595687 | I30: =H30/G30 -> 49709.875 | K30: 40 | L30: 523 | M30: 24.02.22 | N30: 32.1 | T30: =G30-N30-Q30-R30 -> 0 | V30: =360-($V$3-F30) -> -374.53556 | W30: =T30/0.92%/100 -> 0
A31: 29 | B31: IISCO | C31: HT-150X150 | D31: OS0022003320 | E31: 524 | F31: 44563 | G31: 33.103 | H31: 1643551 | I31: =H31/G31 -> 49649.609 | K31: 128. 129, 110 | L31: 524 | M31: 31.03.22, 31.03.22, 16.04.22 | N31: =19.284+3.89+7.281 -> 30.455 | P31: =G31*0.92 -> 30.45476 | Q31: =G31*4.5% -> 1.489635 | R31: =G31*3.5% -> 1.158605 | T31: =G31-N31-Q31-R31 -> -0.00024 | V31: =360-($V$3-F31) -> -374.53556 | W31: =T31/0.92%/100 -> -0.00026086957
A32: 30 | B32: IISCO | C32: HT-150X150 | D32: OS0022003320 | E32: 525 | F32: 44564 | G32: 20.598 | H32: 1022669 | I32: =H32/G32 -> 49648.946 | K32: 127, 111 | L32: 525 | M32: 30.03.22, 16.04.22 | N32: =16.582+2.368 -> 18.95 | P32: =G32*0.92 -> 18.95016 | Q32: =G32*4.5% -> 0.92691 | R32: =G32*3.5% -> 0.72093 | T32: =G32-N32-Q32-R32 -> 0.00016 | V32: =360-($V$3-F32) -> -373.53556 | W32: =T32/0.92%/100 -> 0.00017391304
A33: 31 | B33: IISCO | C33: HT-150X150 | D33: OS0022003320 | E33: 526 | F33: 44564 | G33: 10.299 | H33: 511312 | I33: =H33/G33 -> 49646.762 | K33: 112 | L33: 526 | M33: 16.04.22 | N33: 9.475 | P33: =G33*0.92 -> 9.47508 | Q33: =G33*4.5% -> 0.463455 | R33: =G33*3.5% -> 0.360465 | T33: =G33-N33-Q33-R33 -> 8e-05 | V33: =360-($V$3-F33) -> -373.53556 | W33: =T33/0.92%/100 -> 8.6956522e-05
A34: 32 | B34: IISCO | C34: HT-150X150 | D34: OS0022003337 | E34: 527 | F34: 44564 | G34: 29.792 | H34: 1479759 | I34: =H34/G34 -> 49669.676 | K34: 65 | L34: 527 | M34: 09.03.22 | N34: 29.792 | T34: =G34-N34-Q34-R34 -> 0 | V34: =360-($V$3-F34) -> -373.53556 | W34: =T34/0.92%/100 -> 0 | X34: 30.051 | Y34: =T34-X34 -> -30.051
A35: 33 | B35: IISCO | C35: HT-150X150 | D35: OS0022003335 | E35: 528 | F35: 44564 | G35: 31.88 | H35: 1583576 | I35: =H35/G35 -> 49673.024 | K35: 16 | L35: 528 | M35: 21.02.22 | N35: 31.88 | T35: =G35-N35-Q35-R35 -> 0 | V35: =360-($V$3-F35) -> -373.53556 | W35: =T35/0.92%/100 -> 0 | Y35: =Y34/2 -> -15.0255
A36: 34 | B36: IISCO | C36: HT-150X150 | D36: OS0022003335 | E36: 529 | F36: 44564 | G36: 31.88 | H36: 1583576 | I36: =H36/G36 -> 49673.024 | K36: 21 | L36: 529 | M36: 21.02.22 | N36: 31.88 | T36: =G36-N36-Q36-R36 -> 0 | V36: =360-($V$3-F36) -> -373.53556 | W36: =T36/0.92%/100 -> 0
A37: 35 | B37: IISCO | C37: HT-150X150 | D37: OS0022003342 | E37: 530 | F37: 44564 | G37: 31.72 | H37: 1575916 | I37: =H37/G37 -> 49682.093 | K37: 67 | L37: 530 | M37: 09.03.22 | N37: 31.72 | T37: =G37-N37-Q37-R37 -> 0 | V37: =360-($V$3-F37) -> -373.53556 | W37: =T37/0.92%/100 -> 0
A38: 36 | B38: IISCO | C38: HT-150X150 | D38: OS0022003343 | E38: 531 | F38: 44564 | G38: 29.699 | H38: 1475307 | I38: =H38/G38 -> 49675.309 | K38: 72, 01 | L38: 531 | M38: 12.03.22, 02.04.22 | N38: =27.69+2.009 -> 29.699 | T38: =G38-N38-Q38-R38 -> 0 | V38: =360-($V$3-F38) -> -373.53556 | W38: =T38/0.92%/100 -> 0
A39: 38 | B39: IISCO | C39: HT-150X150 | D39: OS0022003336 | E39: 532 | F39: 44564 | G39: 31.86 | H39: 1582594 | I39: =H39/G39 -> 49673.384 | K39: 49 | L39: 532 | M39: 28.02.22 | N39: 31.86 | T39: =G39-N39-Q39-R39 -> 0 | V39: =360-($V$3-F39) -> -373.53556 | W39: =T39/0.92%/100 -> 0 | Y39: =+T30+T32+T33+T35+T39 -> 0.00024
A40: 39 | B40: IISCO | C40: HT-150X150 | D40: OS0022003336 | E40: 533 | F40: 44564 | G40: 31.86 | H40: 1582594 | I40: =H40/G40 -> 49673.384 | K40: 18 | L40: 533 | M40: 21.02.22 | N40: 31.86 | T40: =G40-N40-Q40-R40 -> 0 | V40: =360-($V$3-F40) -> -373.53556 | W40: =T40/0.92%/100 -> 0
A41: 40 | B41: IISCO | C41: HT-150X150 | D41: OS0022003347 | E41: 534 | F41: 44564 | G41: 31.98 | H41: 1588318 | I41: =H41/G41 -> 49665.979 | K41: 58 | L41: 534 | M41: 03.03.22 | N41: 31.98 | T41: =G41-N41-Q41-R41 -> 0 | V41: =360-($V$3-F41) -> -373.53556 | W41: =T41/0.92%/100 -> 0 | Y41: =+T41+#REF! -> #REF! | Z41: 14.515 | AA41: =Y41-Z41 -> #REF!
...

Sheet KEC JBP JOB WORK  
V2: (mm/dd/yy
A3: JOB WORK KEC JBP | V3: =+SUMMARY!C4 -> 45297.536
A4: LOT NO. | B4: PARTY | C4: SIZE | D4: INVOICE NO. | E4: Challan No. | F4: Challan Dt.(mm/dd/yy | G4: Challan Qty. | H4: Challan Value | I4: RATE | K4: VIL Challan No. | L4: KEC Challan No. | M4: Dispatched. Dt. | N4: Dispatched. Qty. | P4: Finish Good Qty | Q4: Burning loss 4.5% | R4: Waste & Scrap 3.5% | T4: Finish Good Balance Qty | V4: Challan Balance Days
A5: 1 | B5: CHD TO BUB | C5: HT-150X150 | D5: MH49AT0403 | E5: 119 | F5: 44644 | G5: 37.7 | H5: 1941550 | I5: =H5/G5 -> 51500 | K5: 118, 79 | L5: 119 | M5: 28.03.22, 08.04.22 | N5: =27.627+7.057 -> 34.684 | P5: =G5*0.92 -> 34.684 | Q5: =G5*4.5% -> 1.6965 | R5: =G5*3.5% -> 1.3195 | T5: =G5-N5-Q5-R5 -> 5.1070259e-15 | V5: =360-($V$3-F5) -> -293.53556 | W5: =T5/0.92%/100 -> 5.5511151e-15
A6: 2 | B6: CHD TO BUB | C6: HT-150X150 | D6: MH49AT2907 | E6: 120 | F6: 44645 | G6: 39.37 | H6: 1940741 | I6: =H6/G6 -> 49294.92 | K6: 125, 80 | L6: 120 | M6: 30.03.22, 08.04.22 | N6: =32.431+3.789 -> 36.22 | P6: =G6*0.92 -> 36.2204 | Q6: =G6*4.5% -> 1.77165 | R6: =G6*3.5% -> 1.37795 | T6: =G6-N6-Q6-R6 -> 0.0004 | V6: =360-($V$3-F6) -> -292.53556 | W6: =T6/0.92%/100 -> 0.00043478261
A7: 3 | B7: CHD TO BUB | C7: HT-150X150 | D7: MH49AT1954 | E7: 121 | F7: 44645 | G7: 39.33 | H7: 2011923 | I7: =H7/G7 -> 51154.92 | K7: 126, 81 | L7: 121 | M7: 30.03.22, 08.04.22 | N7: =32.279+3.905 -> 36.184 | P7: =G7*0.92 -> 36.1836 | Q7: =G7*4.5% -> 1.76985 | R7: =G7*3.5% -> 1.37655 | T7: =G7-N7-Q7-R7 -> -0.0004 | V7: =360-($V$3-F7) -> -292.53556 | W7: =T7/0.92%/100 -> -0.00043478261
A8: 4 | B8: CHD TO BUB | C8: HT-165X150 | D8: MH40Y1047 | E8: 122 | F8: 44645 | G8: 39.63 | H8: 2009817 | I8: =H8/G8 -> 50714.534 | K8: 130, 82 | L8: 122 | M8: 31.03.22, 08.04.22 | N8: =29.104+7.356 -> 36.46 | P8: =G8*0.92 -> 36.4596 | Q8: =G8*4.5% -> 1.78335 | R8: =G8*3.5% -> 1.38705 | T8: =G8-N8-Q8-R8 -> -0.0004 | V8: =360-($V$3-F8) -> -292.53556 | W8: =T8/0.92%/100 -> -0.00043478261
A9: 5 | B9: CHD TO BUB | C9: HT-150&165 | D9: MH49AT2947 | E9: 123 | F9: 44645 | G9: 39.44 | H9: 2025872 | I9: =H9/G9 -> 51365.923 | K9: 48, 71 | L9: 123 | M9: 06.04.22, 07.04.22 | N9: =32.25+7.19 -> 39.44 | T9: =G9-N9-Q9-R9 -> 0 | V9: =360-($V$3-F9) -> -292.53556 | W9: =T9/0.92%/100 -> 0
A10: 6 | B10: CHD TO BUB | C10: HT-90X90 | D10: MH49AT0401 | E10: 124 | F10: 44646 | G10: 36.44 | H10: 1869372 | I10: =H10/G10 -> 51300 | K10: 72, 73 | L10: 124 | M10: 07.04.22, 07.04.22 | N10: =25.26+11.18 -> 36.44 | T10: =G10-N10-Q10-R10 -> 0 | V10: =360-($V$3-F10) -> -291.53556 | W10: =T10/0.92%/100 -> 0
A11: 7 | B11: CHD TO BUB | C11: HT-90X90 | D11: MH49AT0405 | E11: 125 | F11: 44646 | G11: 37.91 | H11: 1944783 | I11: =H11/G11 -> 51300 | K11: 74, 75 | L11: 125 | M11: 07.04.22, 07.04.22 | N11: =21.11+16.8 -> 37.91 | T11: =G11-N11-Q11-R11 -> 0 | V11: =360-($V$3-F11) -> -291.53556 | W11: =T11/0.92%/100 -> 0
A12: 8 | B12: CHD TO BUB | C12: HT-90X90 | D12: MH49AT2918 | E12: 126 | F12: 44646 | G12: 37.48 | H12: 1922724 | I12: =H12/G12 -> 51300 | K12: 76, 77 | L12: 126 | M12: 07.04.22, 07.04.22 | N12: =15.62+21.86 -> 37.48 | T12: =G12-N12-Q12-R12 -> 0 | V12: =360-($V$3-F12) -> -291.53556 | W12: =T12/0.92%/100 -> 0
A13: 9 | B13: CHD TO BUB | C13: HT-90X90 | D13: MH40AK6073 | E13: 127 | F13: 44646 | G13: =37.75 -> 37.75 | H13: 1936575 | I13: =H13/G13 -> 51300 | K13: 78, 90, 123 | L13: 127 | M13: 07.04.22, 09.04.22 BILLETS 30.450, 19.04.22 | N13: =10.25+20.2+6.715 -> 37.165 | P13: =6.716+30.45 -> 37.166 | Q13: 0.329 | R13: 0.256 | T13: =G13-N13-Q13-R13 -> 8.3266727e-16 | V13: =360-($V$3-F13) -> -291.53556 | W13: =T13/0.92%/100 -> 9.0507312e-16
A14: 10 | B14: CHD TO BUB | C14: HT-90X90 | D14: MH40BG0311 | E14: 128 | F14: 44646 | G14: 37.43 | H14: 1912941 | I14: =H14/G14 -> 51107.16 | K14: 83, 93 | L14: 128 | M14: 08.04.22, 10.04.22 | N14: =9.134+25.302 -> 34.436 | P14: =G14*0.92 -> 34.4356 | Q14: =G14*4.5% -> 1.68435 | R14: =G14*3.5% -> 1.31005 | T14: =G14-N14-Q14-R14 -> -0.0004 | V14: =360-($V$3-F14) -> -291.53556 | W14: =T14/0.92%/100 -> -0.00043478261
A15: 12 | B15: CHD TO BUB | C15: HT-165X150/ HT-90X90 | D15: MH49AT4593 | E15: 129 | F15: 44647 | G15: 41.41 | H15: 2104763 | I15: =H15/G15 -> 50827.409 | K15: 84, 94 | L15: 129 | M15: 09.04.22, 10.04.22 | N15: =32.666+5.431 -> 38.097 | P15: =G15*0.92 -> 38.0972 | Q15: =G15*4.5% -> 1.86345 | R15: =G15*3.5% -> 1.44935 | T15: =G15-N15-Q15-R15 -> 0.0002 | V15: =360-($V$3-F15) -> -290.53556 | W15: =T15/0.92%/100 -> 0.0002173913
A16: 13 | B16: CHD TO BUB | C16: HT-90X90 | D16: MH40BG0308 | E16: 130 | F16: 44647 | G16: 37.89 | H16: 1943757 | I16: =H16/G16 -> 51300 | K16: 95, 100, 102 | L16: 130 | M16: 10.04.22, 11.04.22, 12.04.22 | N16: =1.867+32.705+0.287 -> 34.859 | P16: =G16*0.92 -> 34.8588 | Q16: =G16*4.5% -> 1.70505 | R16: =G16*3.5% -> 1.32615 | T16: =G16-N16-Q16-R16 -> -0.0002 | V16: =360-($V$3-F16) -> -290.53556 | W16: =T16/0.92%/100 -> -0.0002173913
A17: 14 | B17: CHD TO BUB | C17: HT-90X90 | D17: MH40Y1046 | E17: 131 | F17: 44647 | G17: 37.21 | H17: 1908873 | I17: =H17/G17 -> 51300 | K17: 101, 103 | L17: 131 | M17: 11.04.22, 12.04.22 | N17: =32.851+1.382 -> 34.233 | P17: =G17*0.92 -> 34.2332 | Q17: =G17*4.5% -> 1.67445 | R17: =G17*3.5% -> 1.30235 | T17: =G17-N17-Q17-R17 -> 0.0002 | V17: =360-($V$3-F17) -> -290.53556 | W17: =T17/0.92%/100 -> 0.0002173913
A18: 16 | B18: CHD TO BUB | C18: HT-90X90 | D18: MH40AK2190 | E18: 132 | F18: 44647 | G18: 37.27 | H18: 1842607 | I18: =H18/G18 -> 49439.415 | K18: 104, 106 | L18: 132 | M18: 12.04.22, 14.04.22 | N18: =31+3.288 -> 34.288 | P18: =G18*0.92 -> 34.2884 | Q18: =G18*4.5% -> 1.67715 | R18: =G18*3.5% -> 1.30445 | T18: =G18-N18-Q18-R18 -> 0.0004 | V18: =360-($V$3-F18) -> -290.53556 | W18: =T18/0.92%/100 -> 0.00043478261
A19: 17 | B19: CHD TO BUB | C19: HT-90X90 | D19: MH49AT2914 | E19: 133 | F19: 44647 | G19: 36.87 | H19: 1810317 | I19: =H19/G19 -> 49100 | K19: 105, 107 | L19: 133 | M19: 12.04.22, 14.04.22 | N19: =32.483+1.437 -> 33.92 | P19: =G19*0.92 -> 33.9204 | Q19: =G19*4.5% -> 1.65915 | R19: =G19*3.5% -> 1.29045 | T19: =G19-N19-Q19-R19 -> 0.0004 | V19: =360-($V$3-F19) -> -290.53556 | W19: =T19/0.92%/100 -> 0.00043478261
A20: 18 | B20: CHD TO BUB | C20: HT-125/150 | D20: MH49AT1272 | E20: 1 | F20: 44652 | G20: 39.34 | H20: 1931594 | I20: =H20/G20 -> 49100 | K20: 108, 124 | L20: 1 | M20: 14.04.22, 19.04.22 | N20: =28.151+8.042 -> 36.193 | P20: =G20*0.92 -> 36.1928 | Q20: =G20*4.5% -> 1.7703 | R20: =G20*3.5% -> 1.3769 | T20: =G20-N20-Q20-R20 -> -0.0002 | V20: =360-($V$3-F20) -> -285.53556 | W20: =T20/0.92%/100 -> -0.0002173913
A21: 19 | B21: CHD TO BUB | C21: HT-125X125 | D21: MH49AT0846 | E21: 2 | F21: 44654 | G21: 38.98 | H21: 1913918 | I21: =H21/G21 -> 49100 | K21: 119, 125 | L21: 2 | M21: 17.04.22, 19.04.22 | N21: =32.573+3.289 -> 35.862 | P21: =G21*0.92 -> 35.8616 | Q21: =G21*4.5% -> 1.7541 | R21: =G21*3.5% -> 1.3643 | T21: =G21-N21-Q21-R21 -> -0.0004 | V21: =360-($V$3-F21) -> -283.53556 | W21: =T21/0.92%/100 -> -0.00043478261
A22: 20 | B22: CHD TO BUB | C22: HT-125X125 | D22: MH40CD1152 | E22: 3 | F22: 44654 | G22: 45.07 | H22: 2212937 | I22: =H22/G22 -> 49100 | K22: 126, 134 | L22: 3 | M22: 19.04.22, 29.04.22 | N22: =15.278+26.186 -> 41.464 | P22: =G22*0.92 -> 41.4644 | Q22: =G22*4.5% -> 2.02815 | R22: =G22*3.5% -> 1.57745 | T22: =G22-N22-Q22-R22 -> 0.0004 | V22: =360-($V$3-F22) -> -283.53556 | W22: =T22/0.92%/100 -> 0.00043478261
A23: 21 | B23: CHD TO BUB | C23: HT-125X125 | D23: MH40CD1196 | E23: 4 | F23: 44655 | G23: 44.74 | H23: 2196734 | I23: =H23/G23 -> 49100 | K23: 131, 135,136 | L23: 4 | M23: 24.04.22, 29.04.22,29.04.22 | N23: =33.287+6.305+1.569 -> 41.161 | P23: =G23*0.92 -> 41.1608 | Q23: =G23*4.5% -> 2.0133 | R23: =G23*3.5% -> 1.5659 | T23: =G23-N23-Q23-R23 -> -0.0002 | V23: =360-($V$3-F23) -> -282.53556 | W23: =T23/0.92%/100 -> -0.0002173913
A24: 22 | B24: CHD TO BUB | C24: HT-90/125 | D24: MH40BG0396 | E24: 5 | F24: 44656 | G24: 39.28 | H24: 1928648 | I24: =H24/G24 -> 49100 | K24: 137, 139 | L24: 5 | M24: 29.04.22,30.04.22 | N24: =31.067+5.071 -> 36.138 | P24: =G24*0.92 -> 36.1376 | Q24: =G24*4.5% -> 1.7676 | R24: =G24*3.5% -> 1.3748 | T24: =G24-N24-Q24-R24 -> -0.0004 | V24: =360-($V$3-F24) -> -281.53556 | W24: =T24/0.92%/100 -> -0.00043478261
A25: 23 | B25: CHD TO BUB | C25: HT-90 MS-125 | D25: MH40Y7433 | E25: 12 | F25: 44659 | G25: 29.28 | H25: 1437648 | I25: =H25/G25 -> 49100 | K25: 140 | L25: 12 | M25: 30.04.22 | N25: 26.938 | P25: =G25*0.92 -> 26.9376 | Q25: =G25*4.5% -> 1.3176 | R25: =G25*3.5% -> 1.0248 | T25: =G25-N25-Q25-R25 -> -0.0004 | V25: =360-($V$3-F25) -> -278.53556 | W25: =T25/0.92%/100 -> -0.00043478261
A26: 24 | B26: CHD TO BUB | C26: HT-90/125 | D26: MH40AK4386 | E26: 13 | F26: 44660 | G26: 35.4 | H26: 1738140 | I26: =H26/G26 -> 49100 | K26: 141, 142 | L26: 13 | M26: 30.04.22,02.05.22 | N26: =1.106+31.462 -> 32.568 | P26: =G26*0.92 -> 32.568 | Q26: =G26*4.5% -> 1.593 | R26: =G26*3.5% -> 1.239 | T26: =G26-N26-Q26-R26 -> 0 | V26: =360-($V$3-F26) -> -277.53556 | W26: =T26/0.92%/100 -> 0
A27: 25 | B27: CHD TO BUB | C27: HT-90/125 | D27: MH49AT1277 | E27: 15 | F27: 44662 | G27: 37.83 | H27: 1857453 | I27: =H27/G27 -> 49100 | K27: 143, 150, 580 | L27: 15 | M27: 02.05.22, 11.05.22, 08.02.23 | N27: =1.152+32.707+0.945 -> 34.804 | P27: =G27*0.92 -> 34.8036 | Q27: =G27*4.5% -> 1.70235 | R27: =G27*3.5% -> 1.32405 | T27: =G27-N27-Q27-R27 -> -0.0004 | V27: =360-($V$3-F27) -> -275.53556 | W27: =T27/0.92%/100 -> -0.00043478261
A28: 26 | B28: CHD TO BUB | C28: MS-90X90 | D28: MH40BG0398 | E28: 16 | F28: 44663 | G28: 39.92 | H28: 1960072 | I28: =H28/G28 -> 49100 | K28: 153, 160, 358, 358, 647 | L28: 16 | M28: 13.05.22, 14.05.22, 02.01.23., 19.02.23 | N28: =32.848+2.189+0.998+0.691 -> 36.726 | P28: =G28*0.92 -> 36.7264 | Q28: =G28*4.5% -> 1.7964 | R28: =G28*3.5% -> 1.3972 | T28: =G28-N28-Q28-R28 -> 0.0004 | V28: =360-($V$3-F28) -> -274.53556 | W28: =T28/0.92%/100 -> 0.00043478261 | X28: =+T28+T26+T25 -> 4.4408921e-15
A29: 27 | B29: CHD TO BUB | C29: HT/MS-90/125 | D29: MH40BG0553 | E29: 18 | F29: 44672 | G29: 25.73 | H29: 1263343 | I29: =H29/G29 -> 49100 | K29: 276, 466 | L29: 18 | M29: 18.12.22, 27.01.23 | N29: =7.098+16.574 -> 23.672 | P29: =G29*0.92 -> 23.6716 | Q29: =G29*4.5% -> 1.15785 | R29: =G29*3.5% -> 0.90055 | T29: =G29-N29-Q29-R29 -> -0.0004 | V29: =360-($V$3-F29) -> -265.53556 | W29: =T29/0.92%/100 -> -0.00043478261
A30: 28 | B30: CHD TO BUB | C30: HT-125X125 | D30: MH49AT6296 | E30: 19 | F30: 44673 | G30: 17.038 | H30: 861872 | I30: =H30/G30 -> 50585.28 | K30: 222 | L30: 19 | M30: 08.12.22 | N30: 15.675 | P30: =G30*0.92 -> 15.67496 | Q30: =G30*4.5% -> 0.76671 | R30: =G30*3.5% -> 0.59633 | T30: =G30-N30-Q30-R30 -> -4e-05 | V30: =360-($V$3-F30) -> -264.53556 | W30: =T30/0.92%/100 -> -4.3478261e-05
B31: DSP | C31: HT125X125 | D31: OS0022000543 | E31: 22 | F31: 44712 | G31: 30.25 | H31: 1927569 | I31: =H31/G31 -> 63721.289 | K31: 223, 227 | L31: 22 | M31: 08.12.22 , 09.12.22 | N31: =15.397+12.433 -> 27.83 | P31: =G31*0.92 -> 27.83 | Q31: =G31*4.5% -> 1.36125 | R31: =G31*3.5% -> 1.05875 | T31: =G31-N31-Q31-R31 -> 1.7763568e-15 | V31: =360-($V$3-F31) -> -225.53556 | W31: =T31/0.92%/100 -> 1.9308227e-15
B32: DSP | C32: HT125X125 | D32: OS0022000543 | E32: 23 | F32: 44712 | G32: 30.25 | H32: 1927569 | I32: =H32/G32 -> 63721.289 | K32: 228, 266, 581 | L32: 23 | M32: 09.12.22, 16.12.22, 08.02.23 | N32: =19.894+7.244+0.692 -> 27.83 | P32: =G32*0.92 -> 27.83 | Q32: =G32*4.5% -> 1.36125 | R32: =G32*3.5% -> 1.05875 | T32: =G32-N32-Q32-R32 -> 1.7763568e-15 | V32: =360-($V$3-F32) -> -225.53556 | W32: =T32/0.92%/100 -> 1.9308227e-15
B33: DSP | C33: HT125X125 | D33: OS0022000549 | E33: 24 | F33: 44712 | G33: 30.749 | H33: 1959484 | I33: =H33/G33 -> 63725.129 | K33: 234, 356 | L33: 24 | M33: 10.12.22, 02.01.2023 | N33: =17.699+1.957+8.633 -> 28.289 | P33: =G33*0.92 -> 28.28908 | Q33: =G33*4.5% -> 1.383705 | R33: =G33*3.5% -> 1.076215 | T33: =G33-N33-Q33-R33 -> 8e-05 | V33: =360-($V$3-F33) -> -225.53556 | W33: =T33/0.92%/100 -> 8.6956522e-05
B34: DSP | C34: HT125X125 | D34: OS0022000549 | E34: 25 | F34: 44712 | G34: 29.651 | H34: 1889503 | I34: =H34/G34 -> 63724.765 | K34: 235238 | L34: 25 | M34: 10.12.22,11.12.22 | N34: =12.918+14.361 -> 27.279 | P34: =G34*0.92 -> 27.27892 | Q34: =G34*4.5% -> 1.334295 | R34: =G34*3.5% -> 1.037785 | T34: =G34-N34-Q34-R34 -> -8e-05 | V34: =360-($V$3-F34) -> -225.53556 | W34: =T34/0.92%/100 -> -8.6956522e-05
B35: DSP | C35: HT125X125 | D35: OS0022000544 | E35: 26 | F35: 44712 | G35: 29.363 | H35: 1870588 | I35: =H35/G35 -> 63705.616 | K35: 2, 39, 240, 251, 357,449, 648 | L35: 26 | M35: 11.12.22,11.12.22,13.12.22,02.01.23, 19.02.23 | N35: =16.151+2.47+2.658+1.473+4.124+0.138 -> 27.014 | P35: =G35*0.92 -> 27.01396 | Q35: =G35*4.5% -> 1.321335 | R35: =G35*3.5% -> 1.027705 | T35: =G35-N35-Q35-R35 -> -4e-05 | V35: =360-($V$3-F35) -> -225.53556 | W35: =T35/0.92%/100 -> -4.3478261e-05
B36: DSP | C36: HT125X125 | D36: OS0022000544 | E36: 27 | F36: 44712 | G36: 31.538 | H36: 2009150 | I36: =H36/G36 -> 63705.688 | K36: 252, 257, 649 | L36: 27 | M36: 13.12.22, 14.12.22, 19.02.23 | N36: =9.502+8.627+6.42+3.216+1.25 -> 29.015 | P36: =G36*0.92 -> 29.01496 | Q36: =G36*4.5% -> 1.41921 | R36: =G36*3.5% -> 1.10383 | T36: =G36-N36-Q36-R36 -> -4e-05 | V36: =360-($V$3-F36) -> -225.53556 | W36: =T36/0.92%/100 -> -4.3478261e-05
B37: DSP | C37: HT125X125 | D37: OS0022000548 | E37: 28 | F37: 44712 | G37: 30.25 | H37: 1927569 | I37: =H37/G37 -> 63721.289 | K37: 274, 275, 325 | L37: 28 | M37: 18.12.22, 27.12.22 | N37: =9.734+5.308+12.788 -> 27.83 | P37: =G37*0.92 -> 27.83 | Q37: =G37*4.5% -> 1.36125 | R37: =G37*3.5% -> 1.05875 | T37: =G37-N37-Q37-R37 -> 1.7763568e-15 | V37: =360-($V$3-F37) -> -225.53556 | W37: =T37/0.92%/100 -> 1.9308227e-15
B38: DSP | C38: HT125X125 | D38: OS0022000548 | E38: 29 | F38: 44712 | G38: 30.25 | H38: 1927569 | I38: =H38/G38 -> 63721.289 | K38: 326, 333 | L38: 29 | M38: 27.12.22, 28.12.22 | N38: =20.207+7.623 -> 27.83 | P38: =G38*0.92 -> 27.83 | Q38: =G38*4.5% -> 1.36125 | R38: =G38*3.5% -> 1.05875 | T38: =G38-N38-Q38-R38 -> -1.7763568e-15 | V38: =360-($V$3-F38) -> -225.53556 | W38: =T38/0.92%/100 -> -1.9308227e-15
B39: DSP | C39: HT125X125 | D39: OS0022000542 | E39: 30 | F39: 44714 | G39: 28.832 | H39: 1837971 | I39: =H39/G39 -> 63747.607 | K39: 334, 650 | L39: 30 | M39: 28.12.22, 19.02.23 | N39: =24.932+1.593 -> 26.525 | P39: =G39*0.92 -> 26.52544 | Q39: =G39*4.5% -> 1.29744 | R39: =G39*3.5% -> 1.00912 | T39: =G39-N39-Q39-R39 -> 0.00044 | V39: =360-($V$3-F39) -> -223.53556 | W39: =T39/0.92%/100 -> 0.00047826087
B40: DSP | C40: HT125X125 | D40: OS0022000542 | E40: 31 | F40: 44714 | G40: 30.968 | H40: 1974117 | I40: =H40/G40 -> 63746.997 | K40: 448 | L40: 31 | M40: 23.01.23 | N40: 28.491 | P40: =G40*0.92 -> 28.49056 | Q40: =G40*4.5% -> 1.39356 | R40: =G40*3.5% -> 1.08388 | T40: =G40-N40-Q40-R40 -> -0.00044 | V40: =360-($V$3-F40) -> -223.53556 | W40: =T40/0.92%/100 -> -0.00047826087
B41: DSP | C41: HT125X125 | D41: OS0022000540 | E41: 32 | F41: 44714 | G41: 26.607 | H41: 1696334 | I41: =H41/G41 -> 63755.177 | K41: 453 | L41: 32 | M41: 24.01.23 | N41: 24.478 | P41: =G41*0.92 -> 24.47844 | Q41: =G41*4.5% -> 1.197315 | R41: =G41*3.5% -> 0.931245 | T41: =G41-N41-Q41-R41 -> 0.00044 | V41: =360-($V$3-F41) -> -223.53556 | W41: =T41/0.92%/100 -> 0.00047826087
...

Sheet KEC BB JOB WORK  (returnable c)
V2: (mm/dd/yy
A3: JOB WORK KEC BB RETURNABLE CHALLAN | V3: =+SUMMARY!C4 -> 45297.536
A4: LOT NO. | B4: PARTY | C4: SIZE | D4: INVOICE NO. | E4: Challan No. | F4: Challan Dt.(mm/dd/yy | G4: Challan Qty. | H4: Challan Value | I4: RATE | K4: VIL Challan No. | L4: KEC Challan No. | M4: Dispatched. Dt. | N4: Dispatched. Qty. | P4: Finish Good Qty | Q4: Burning loss 4.5% | R4: Waste & Scrap 3.5% | T4: Finish Good Balance Qty | V4: Challan Balance Days
A5: 1 | E5: 850 | F5: 44649 | G5: 31.505 | H5: 2677925 | I5: =H5/G5 -> 85000 | K5: 39, 51 | L5: 850 | M5: 05.04.22, 06.04.22 | N5: =26.61+4.895 -> 31.505 | P5: =G5 -> 31.505 | T5: =G5-N5-Q5-R5 -> 0 | V5: =360-($V$3-F5) -> -288.53556 | W5: =T5/0.92%/100 -> 0
A6: 2 | E6: 851 | F6: 44650 | G6: 32.402 | H6: 2754170 | I6: =H6/G6 -> 85000 | K6: 40, 52 | L6: 851 | M6: 05.04.22, 06.04.22 | N6: =31.34+1.062 -> 32.402 | P6: =G6 -> 32.402 | T6: =G6-N6-Q6-R6 -> 0 | V6: =360-($V$3-F6) -> -287.53556 | W6: =T6/0.92%/100 -> 0
A7: 3 | E7: 852 | F7: 44651 | G7: 31.894 | H7: 2710990 | I7: =H7/G7 -> 85000 | K7: 45, 53 | L7: 852 | M7: 05.04.22, 06.04.22 | N7: =31.04+0.854 -> 31.894 | P7: =G7 -> 31.894 | T7: =G7-N7-Q7-R7 -> 0 | V7: =360-($V$3-F7) -> -286.53556 | W7: =T7/0.92%/100 -> 0
A8: 4 | E8: 853 | F8: 44651 | G8: 31.023 | H8: 2636955 | I8: =H8/G8 -> 85000 | K8: 50, 54 | L8: 853 | M8: 06.04.22, 06.04.22 | N8: =30.59+0.433 -> 31.023 | P8: =G8 -> 31.023 | T8: =G8-N8-Q8-R8 -> 0 | V8: =360-($V$3-F8) -> -286.53556 | W8: =T8/0.92%/100 -> 0
A9: 5 | E9: 1 | F9: 44652 | G9: 30.908 | H9: 2627180 | I9: =H9/G9 -> 85000 | K9: 55, 56 | L9: 1 | M9: 06.04.22, 06.04.22 | N9: =24.156+6.752 -> 30.908 | P9: =G9 -> 30.908 | T9: =G9-N9-Q9-R9 -> 3.5527137e-15 | V9: =360-($V$3-F9) -> -285.53556 | W9: =T9/0.92%/100 -> 3.8616453e-15
A10: 6 | E10: 8 | F10: 44653 | G10: 41.746 | H10: 2627180 | I10: =H10/G10 -> 62932.497 | K10: 46, 57 | L10: 8 | M10: 05.04.22, 06.04.22 | N10: =41.03+0.716 -> 41.746 | P10: =G10 -> 41.746 | T10: =G10-N10-Q10-R10 -> 0 | V10: =360-($V$3-F10) -> -284.53556 | W10: =T10/0.92%/100 -> 0
A11: 7 | E11: 16 | F11: 44654 | G11: 21.8 | H11: 1853000 | I11: =H11/G11 -> 85000 | K11: 58 | L11: 16 | M11: 06.04.22 | N11: 21.8 | P11: =G11 -> 21.8 | T11: =G11-N11-Q11-R11 -> 0 | V11: =360-($V$3-F11) -> -283.53556 | W11: =T11/0.92%/100 -> 0
A12: 8 | E12: 15 | F12: 44654 | G12: 31.35 | H12: 2627180 | I12: =H12/G12 -> 83801.595 | K12: 59, 60 | L12: 15 | M12: 06.04.22, 06.04.22 | N12: =0.932+30.418 -> 31.35 | P12: =G12 -> 31.35 | T12: =G12-N12-Q12-R12 -> 3.5527137e-15 | V12: =360-($V$3-F12) -> -283.53556 | W12: =T12/0.92%/100 -> 3.8616453e-15
A13: 9 | E13: 1000004644 | F13: 44812 | G13: 6.103 | H13: 387632 | I13: =H13/G13 -> 63514.993 | K13: 526 | L13: 1000004644 | M13: 02.02.2023 | N13: 6.103 | P13: =G13 -> 6.103 | T13: =G13-N13-Q13-R13 -> 0 | V13: =360-($V$3-F13) -> -125.53556 | W13: =T13/0.92%/100 -> 0
A14: 10 | I14: =H14/G14 -> #DIV/0! | P14: =G14 -> 0 | T14: =G14-N14-Q14-R14 -> 0 | V14: =360-($V$3-F14) -> -44937.536 | W14: =T14/0.92%/100 -> 0
A15: 11 | I15: =H15/G15 -> #DIV/0! | P15: =G15 -> 0 | T15: =G15-N15-Q15-R15 -> 0 | V15: =360-($V$3-F15) -> -44937.536 | W15: =T15/0.92%/100 -> 0
A16: 12 | I16: =H16/G16 -> #DIV/0! | P16: =G16 -> 0 | T16: =G16-N16-Q16-R16 -> 0 | V16: =360-($V$3-F16) -> -44937.536 | W16: =T16/0.92%/100 -> 0
A17: 13 | I17: =H17/G17 -> #DIV/0! | P17: =G17 -> 0 | T17: =G17-N17-Q17-R17 -> 0 | V17: =360-($V$3-F17) -> -44937.536 | W17: =T17/0.92%/100 -> 0
A18: 14 | I18: =H18/G18 -> #DIV/0! | P18: =G18 -> 0 | T18: =G18-N18-Q18-R18 -> 0 | V18: =360-($V$3-F18) -> -44937.536 | W18: =T18/0.92%/100 -> 0
A19: 15 | I19: =H19/G19 -> #DIV/0! | P19: =G19 -> 0 | T19: =G19-N19-Q19-R19 -> 0 | V19: =360-($V$3-F19) -> -44937.536 | W19: =T19/0.92%/100 -> 0
I20: =H20/G20 -> #DIV/0! | P20: =G20 -> 0 | T20: =G20-N20-Q20-R20 -> 0 | V20: =360-($V$3-F20) -> -44937.536 | W20: =T20/0.92%/100 -> 0
G21: =SUM(G9:G20) -> 131.907 | N21: =SUM(N9:N20) -> 131.907 | P21: =SUM(P9:P20) -> 131.907 | Q21: =SUM(Q9:Q20) -> 0 | R21: =SUM(R9:R20) -> 0 | T21: =SUM(T9:T20) -> 7.1054274e-15 | W21: =SUM(W9:W20) -> 7.7232906e-15
K26: 2040 | M26: =K26/92% -> 2217.3913
K27: 1650.417 | M27: =K27/92% -> 1793.9315
V93: 9
V94: 9
V95: 9
V96: 9

Sheet Sheet1
A2: 1 | B2: VINAR CHANDRAPUR BALANCE JOB WORK CHALLAN DETAILS
B3: Party Name | C3: Job Work Bal.Qty (Billet wt.) | D3: Job Work Bal.Day | E3: KEC Billets Stock Qty
B4: KEC BUB | C4: 163.481 | D4: 110 | E4: 0
B5: KEC JBP | C5: 0 | D5: 0 | E5: 0
B6: Total | C6: =+C4 -> 163.481 | E6: 0
A9: 2 | B9: VINAR BUTIBORI BALANCE JOB WORK CHALLAN DETAILS
B10: Party Name | C10: Job Work Bal.Qty (Billet wt.) | D10: Job Work Bal.Day | E10: KEC Billets Stock Qty
B11: KEC BUB | C11: 2217.561 | D11: 150 | E11: 2217.561 | K11: 21.996
B12: KEC JBP | C12: 1793.932 | D12: 179 | E12: 1793.932 | K12: 0.025
B13: Total | C13: =SUM(C11:C12) -> 4011.493 | E13: =SUM(E11:E12) -> 4011.493 | K13: =K11+K12 -> 22.021

Sheet Sheet2
A1: JOB WORK KEC JBP | V1: =+SUMMARY!C4 -> 45297.536
A2: LOT NO. | B2: PARTY | C2: SIZE | D2: INVOICE NO. | E2: Challan No. | F2: Challan Dt.(mm/dd/yy | G2: Challan Qty. | H2: Challan Value | I2: RATE | K2: VIL Challan No. | L2: KEC Challan No. | M2: Dispatched. Dt. | N2: Dispatched. Qty. | P2: Finish Good Qty | Q2: Burning loss 4.5% | R2: Waste & Scrap 3.5% | T2: Finish Good Balance Qty | V2: Challan Balance Days
B3: DSP | C3: MS125X125 | D3: OS0022000353 | E3: 65 | F3: 44726 | G3: 33 | H3: 1996008 | I3: =H3/G3 -> 60485.091 | K3: 683 | L3: 65 | M3: 21.02.23 | N3: 30.075 | P3: =G3*0.92 -> 30.36 | Q3: =G3*4.5% -> 1.485 | R3: =G3*3.5% -> 1.155 | T3: =G3-N3-Q3-R3 -> 0.285 | V3: =360-($V$1-F3) -> -211.53556
B4: DSP | C4: MS125X125 | D4: OS0022000352 | E4: 66 | F4: 44727 | G4: 27.021 | H4: 1637527 | I4: =H4/G4 -> 60602.013 | L4: 66 | P4: =G4*0.92 -> 24.85932 | Q4: =G4*4.5% -> 1.215945 | R4: =G4*3.5% -> 0.945735 | T4: =G4-N4-Q4-R4 -> 24.85932 | V4: =360-($V$1-F4) -> -210.53556
B5: DSP | C5: MS125X125 | D5: OS0022000352 | E5: 67 | F5: 44727 | G5: 31.179 | H5: 1889454 | I5: =H5/G5 -> 60600.212 | L5: 67 | P5: =G5*0.92 -> 28.68468 | Q5: =G5*4.5% -> 1.403055 | R5: =G5*3.5% -> 1.091265 | T5: =G5-N5-Q5-R5 -> 28.68468 | V5: =360-($V$1-F5) -> -210.53556
B6: DSP | C6: MS125X125 | D6: OS0022000348 | E6: 68 | F6: 44727 | G6: 29.459 | H6: 1782305 | I6: =H6/G6 -> 60501.205 | L6: 68 | P6: =G6*0.92 -> 27.10228 | Q6: =G6*4.5% -> 1.325655 | R6: =G6*3.5% -> 1.031065 | T6: =G6-N6-Q6-R6 -> 27.10228 | V6: =360-($V$1-F6) -> -210.53556
B7: DSP | C7: MS125X125 | D7: OS0022000348 | E7: 69 | F7: 44727 | G7: 31.641 | H7: 1914327 | I7: =H7/G7 -> 60501.47 | L7: 69 | P7: =G7*0.92 -> 29.10972 | Q7: =G7*4.5% -> 1.423845 | R7: =G7*3.5% -> 1.107435 | T7: =G7-N7-Q7-R7 -> 29.10972 | V7: =360-($V$1-F7) -> -210.53556
B8: DSP | C8: MS125X125 | D8: OS0022000349 | E8: 70 | F8: 44727 | G8: 30.15 | H8: 1824916 | I8: =H8/G8 -> 60527.894 | L8: 70 | P8: =G8*0.92 -> 27.738 | Q8: =G8*4.5% -> 1.35675 | R8: =G8*3.5% -> 1.05525 | T8: =G8-N8-Q8-R8 -> 27.738 | V8: =360-($V$1-F8) -> -210.53556
B9: DSP | C9: MS125X125 | D9: OS0022000349 | E9: 71 | F9: 44727 | G9: 30.15 | H9: 1824916 | I9: =H9/G9 -> 60527.894 | L9: 71 | P9: =G9*0.92 -> 27.738 | Q9: =G9*4.5% -> 1.35675 | R9: =G9*3.5% -> 1.05525 | T9: =G9-N9-Q9-R9 -> 27.738 | V9: =360-($V$1-F9) -> -210.53556
B10: DSP | C10: MS125X125 | D10: OS0022000347 | E10: 72 | F10: 44728 | G10: 31.796 | H10: 1923416 | I10: =H10/G10 -> 60492.389 | L10: 72 | P10: =G10*0.92 -> 29.25232 | Q10: =G10*4.5% -> 1.43082 | R10: =G10*3.5% -> 1.11286 | T10: =G10-N10-Q10-R10 -> 29.25232 | V10: =360-($V$1-F10) -> -209.53556
B11: DSP | C11: MS125X125 | D11: OS0022000347 | E11: 73 | F11: 44728 | G11: 29.604 | H11: 1790766 | I11: =H11/G11 -> 60490.677 | L11: 73 | P11: =G11*0.92 -> 27.23568 | Q11: =G11*4.5% -> 1.33218 | R11: =G11*3.5% -> 1.03614 | T11: =G11-N11-Q11-R11 -> 27.23568 | V11: =360-($V$1-F11) -> -209.53556
B12: DSP | C12: MS125X125 | D12: OS0022000350 | E12: 74 | F12: 44728 | G12: 31.4 | H12: 1898041 | I12: =H12/G12 -> 60447.166 | L12: 74 | P12: =G12*0.92 -> 28.888 | Q12: =G12*4.5% -> 1.413 | R12: =G12*3.5% -> 1.099 | T12: =G12-N12-Q12-R12 -> 28.888 | V12: =360-($V$1-F12) -> -209.53556
B13: DSP | C13: MS125X125 | D13: OS0022000350 | E13: 75 | F13: 44728 | G13: 31.4 | H13: 1898041 | I13: =H13/G13 -> 60447.166 | L13: 75 | P13: =G13*0.92 -> 28.888 | Q13: =G13*4.5% -> 1.413 | R13: =G13*3.5% -> 1.099 | T13: =G13-N13-Q13-R13 -> 28.888 | V13: =360-($V$1-F13) -> -209.53556
B14: DSP | C14: MS125X125 | D14: OS0022000351 | E14: 76 | F14: 44728 | G14: 28.639 | H14: 1734356 | I14: =H14/G14 -> 60559.237 | L14: 76 | P14: =G14*0.92 -> 26.34788 | Q14: =G14*4.5% -> 1.288755 | R14: =G14*3.5% -> 1.002365 | T14: =G14-N14-Q14-R14 -> 26.34788 | V14: =360-($V$1-F14) -> -209.53556
B15: DSP | C15: MS125X125 | D15: OS0022000351 | E15: 77 | F15: 44728 | G15: 30.761 | H15: 1862826 | I15: =H15/G15 -> 60558.044 | L15: 77 | P15: =G15*0.92 -> 28.30012 | Q15: =G15*4.5% -> 1.384245 | R15: =G15*3.5% -> 1.076635 | T15: =G15-N15-Q15-R15 -> 28.30012 | V15: =360-($V$1-F15) -> -209.53556
... B17: DSP | C17: MS125X125 | D17: OS0022000345 | E17: 79 | F17: 44728 | G17: 32.004 | H17: 1935533 | I17: =H17/G17 -> 60477.847 | L17: 79 | P17: =G17*0.92 -> 29.44368 | Q17: =G17*4.5% -> 1.44018 | R17: =G17*3.5% -> 1.12014 | T17: =G17-N17-Q17-R17 -> 29.44368 | V17: =360-($V$1-F17) -> -209.53556
G18: =SUM(G3:G17) -> 458 | N18: =SUM(N3:N17) -> 30.075 | P18: =SUM(P3:P17) -> 421.36 | Q18: =SUM(Q3:Q17) -> 20.61 | R18: =SUM(R3:R17) -> 16.03 | T18: =SUM(T3:T17) -> 391.285
Q22: Biilet wt. | T22: =T18/92% -> 425.30978
Q23: Angle wt. | T23: 391.285
